09:57:34   {"table":"orderBookL2","action":"insert","data":[{"symbol":"XBTZ17","id":22899831755,"side":"Sell","size":5000,"price":16824.5},{"symbol":"XBTZ17","id":22899832005,"side":"Sell","size":5000,"price":16799.5},{"symbol":"XBTZ17","id":22899832250,"side":"Sell","size":5000,"price":16775},{"symbol":"XBTZ17","id":22899832500,"side":"Sell","size":5000,"price":16750},{"symbol":"XBTZ17","id":22899832750,"side":"Sell","size":5000,"price":16725},{"symbol":"XBTZ17","id":22899832995,"side":"Sell","size":5000,"price":16700.5},{"symbol":"XBTZ17","id":22899833245,"side":"Sell","size":5000,"price":16675.5},{"symbol":"XBTZ17","id":22899833490,"side":"Sell","size":5000,"price":16651},{"symbol":"XBTZ17","id":22899836910,"side":"Buy","size":5000,"price":16309},{"symbol":"XBTZ17","id":22899837155,"side":"Buy","size":5000,"price":16284.5},{"symbol":"XBTZ17","id":22899837400,"side":"Buy","size":5000,"price":16260},{"symbol":"XBTZ17","id":22899837650,"side":"Buy","size":5000,"price":16235},{"symbol":"XBTZ17","id":22899837895,"side":"Buy","size":5000,"price":16210.5}]}
09:57:34   {"table":"orderBookL2","action":"delete","data":[{"symbol":"XBTZ17","id":22899833455,"side":"Sell"},{"symbol":"XBTZ17","id":22899835010,"side":"Buy"}]}
09:57:34   {"table":"orderBookL2","action":"insert","data":[{"symbol":"XBTUSD","id":8798353750,"side":"Sell","size":10000,"price":16462.5},{"symbol":"XBTUSD","id":8798364450,"side":"Buy","size":10000,"price":16355.5}]}
09:57:34   {"table":"orderBookL2","action":"delete","data":[{"symbol":"XBTUSD","id":8798351900,"side":"Sell"}]}
09:57:34   {"table":"orderBookL2","action":"insert","data":[{"symbol":"XBTZ17","id":22899833300,"side":"Sell","size":7000,"price":16670},{"symbol":"XBTZ17","id":22899834840,"side":"Buy","size":7050,"price":16516}]}
09:57:34   {"table":"orderBookL2","action":"insert","data":[{"symbol":"XBTZ17","id":22899834135,"side":"Sell","size":50,"price":16586.5}]}
09:57:34   {"table":"orderBookL2","action":"delete","data":[{"symbol":"XBTZ17","id":22899833540,"side":"Sell"}]}
09:57:34   {"table":"orderBookL2","action":"insert","data":[{"symbol":"XBTZ17","id":22899833625,"side":"Sell","size":60,"price":16637.5}]}
09:57:34   {"table":"orderBookL2","action":"update","data":[{"symbol":"XBTUSD","id":8798367000,"side":"Buy","size":25988}]}
09:57:34   {"table":"orderBookL2","action":"insert","data":[{"symbol":"XBTUSD","id":8798353600,"side":"Sell","size":4004,"price":16464}]}
09:57:34   {"table":"orderBookL2","action":"delete","data":[{"symbol":"XBTUSD","id":8798138500,"side":"Sell"},{"symbol":"XBTUSD","id":8798143500,"side":"Sell"},{"symbol":"XBTUSD","id":8798148500,"side":"Sell"},{"symbol":"XBTUSD","id":8798153500,"side":"Sell"},{"symbol":"XBTUSD","id":8798333450,"side":"Sell"},{"symbol":"XBTUSD","id":8798338450,"side":"Sell"},{"symbol":"XBTUSD","id":8798362150,"side":"Buy"},{"symbol":"XBTUSD","id":8798367150,"side":"Buy"},{"symbol":"XBTUSD","id":8798372150,"side":"Buy"},{"symbol":"XBTUSD","id":8798555550,"side":"Buy"},{"symbol":"XBTUSD","id":8798560550,"side":"Buy"},{"symbol":"XBTUSD","id":8798565550,"side":"Buy"},{"symbol":"XBTUSD","id":8798570550,"side":"Buy"}]}
09:57:34   {"table":"orderBookL2","action":"update","data":[{"symbol":"XBTZ17","id":22899831230,"side":"Sell","size":1153}]}
09:57:34   {"table":"orderBookL2","action":"insert","data":[{"symbol":"XBTZ17","id":22899834155,"side":"Sell","size":2258,"price":16584.5}]}
09:57:34   {"table":"orderBookL2","action":"update","data":[{"symbol":"XBTZ17","id":22899834155,"side":"Sell","size":1258}]}
09:57:34   {"table":"orderBookL2","action":"update","data":[{"symbol":"XBTUSD","id":8798140100,"side":"Sell","size":175},{"symbol":"XBTUSD","id":8798145100,"side":"Sell","size":40961},{"symbol":"XBTUSD","id":8798150100,"side":"Sell","size":2675},{"symbol":"XBTUSD","id":8798155100,"side":"Sell","size":250},{"symbol":"XBTUSD","id":8798158500,"side":"Sell","size":50},{"symbol":"XBTUSD","id":8798160100,"side":"Sell","size":95175},{"symbol":"XBTUSD","id":8798172000,"side":"Sell","size":1050},{"symbol":"XBTUSD","id":8798180100,"side":"Sell","size":175},{"symbol":"XBTUSD","id":8798191800,"side":"Sell","size":546},{"symbol":"XBTUSD","id":8798200100,"side":"Sell","size":2175},{"symbol":"XBTUSD","id":8798211500,"side":"Sell","size":92},{"symbol":"XBTUSD","id":8798220100,"side":"Sell","size":200},{"symbol":"XBTUSD","id":8798231400,"side":"Sell","size":59},{"symbol":"XBTUSD","id":8798240100,"side":"Sell","size":200},{"symbol":"XBTUSD","id":8798251200,"side":"Sell","size":45000},{"symbol":"XBTUSD","id":8798260100,"side":"Sell","size":200},{"symbol":"XBTUSD","id":8798270800,"side":"Sell","size":260},{"symbol":"XBTUSD","id":8798280100,"side":"Sell","size":3588},{"symbol":"XBTUSD","id":8798290800,"side":"Sell","size":710},{"symbol":"XBTUSD","id":8798300100,"side":"Sell","size":175},{"symbol":"XBTUSD","id":8798328400,"side":"Sell","size":600},{"symbol":"XBTUSD","id":8798328450,"side":"Sell","size":3245},{"symbol":"XBTUSD","id":8798333400,"side":"Sell","size":2100},{"symbol":"XBTUSD","id":8798345850,"side":"Sell","size":3890},{"symbol":"XBTUSD","id":8798352000,"side":"Sell","size":4150},{"symbol":"XBTUSD","id":8798352850,"side":"Sell","size":200},{"symbol":"XBTUSD","id":8798357000,"side":"Sell","size":3200},{"symbol":"XBTUSD","id":8798357850,"side":"Sell","size":1300},{"symbol":"XBTUSD","id":8798362250,"side":"Buy","size":2100},{"symbol":"XBTUSD","id":8798372250,"side":"Buy","size":7600},{"symbol":"XBTUSD","id":8798510950,"side":"Buy","size":100},{"symbol":"XBTUSD","id":8798511000,"side":"Buy","size":300},{"symbol":"XBTUSD","id":8798559900,"side":"Buy","size":175},{"symbol":"XBTUSD","id":8798564900,"side":"Buy","size":20250},{"symbol":"XBTUSD","id":8798569900,"side":"Buy","size":175},{"symbol":"XBTUSD","id":8798574900,"side":"Buy","size":5250}]}
09:57:34   {"table":"orderBookL2","action":"insert","data":[{"symbol":"XBTUSD","id":8798338400,"side":"Sell","size":100,"price":16616},{"symbol":"XBTUSD","id":8798346900,"side":"Sell","size":100,"price":16531},{"symbol":"XBTUSD","id":8798367250,"side":"Buy","size":100,"price":16327.5}]}
09:57:34   {"table":"orderBookL2","action":"delete","data":[{"symbol":"XBTUSD","id":8798359250,"side":"Sell"}]}
09:57:34   {"table":"orderBookL2","action":"update","data":[{"symbol":"XBTUSD","id":8798359200,"side":"Sell","size":22675}]}
09:57:34   {"table":"orderBookL2","action":"insert","data":[{"symbol":"XBTZ17","id":22899834015,"side":"Sell","size":835,"price":16598.5}]}
09:57:34   {"table":"orderBookL2","action":"insert","data":[{"symbol":"XBTUSD","id":8798359700,"side":"Sell","size":10000,"price":16403}]}
09:57:34   {"table":"orderBookL2","action":"delete","data":[{"symbol":"XBTUSD","id":8798363000,"side":"Buy"},{"symbol":"XBTUSD","id":8798363050,"side":"Buy"},{"symbol":"XBTUSD","id":8798363500,"side":"Buy"}]}
09:57:34   {"table":"orderBookL2","action":"update","data":[{"symbol":"XBTUSD","id":8798363300,"side":"Buy","size":20469},{"symbol":"XBTUSD","id":8798363800,"side":"Buy","size":18050},{"symbol":"XBTUSD","id":8798364000,"side":"Buy","size":10850}]}
09:57:34   {"table":"orderBookL2","action":"update","data":[{"symbol":"XBTUSD","id":8798364500,"side":"Buy","size":240}]}
09:57:34   {"table":"orderBookL2","action":"insert","data":[{"symbol":"XBTZ17","id":22899833500,"side":"Sell","size":6000,"price":16650}]}
09:57:34   {"table":"orderBookL2","action":"delete","data":[{"symbol":"XBTZ17","id":22899834020,"side":"Sell"}]}
09:57:34   {"table":"orderBookL2","action":"insert","data":[{"symbol":"XBTUSD","id":8798365250,"side":"Buy","size":3776,"price":16347.5}]}
09:57:34   {"table":"orderBookL2","action":"update","data":[{"symbol":"XBTZ17","id":22899834015,"side":"Sell","size":4004}]}
09:57:34   {"table":"orderBookL2","action":"insert","data":[{"symbol":"XBTZ17","id":22899834585,"side":"Buy","size":831,"price":16541.5}]}
09:57:34   {"table":"orderBookL2","action":"delete","data":[{"symbol":"XBTZ17","id":22899833630,"side":"Sell"},{"symbol":"XBTZ17","id":22899833660,"side":"Sell"},{"symbol":"XBTZ17","id":22899833695,"side":"Sell"}]}
09:57:34   {"table":"orderBookL2","action":"insert","data":[{"symbol":"XBTZ17","id":22899833820,"side":"Sell","size":8000,"price":16618},{"symbol":"XBTZ17","id":22899833855,"side":"Sell","size":8000,"price":16614.5},{"symbol":"XBTZ17","id":22899833885,"side":"Sell","size":8000,"price":16611.5}]}
09:57:34   {"table":"orderBookL2","action":"update","data":[{"symbol":"XBTUSD","id":8798360000,"side":"Buy","size":64859}]}
09:57:34   {"table":"orderBookL2","action":"update","data":[{"symbol":"XBTUSD","id":8798359950,"side":"Sell","size":153016}]}
09:57:34   {"table":"orderBookL2","action":"delete","data":[{"symbol":"XBTUSD","id":8798240150,"side":"Sell"}]}
09:57:34   {"table":"orderBookL2","action":"insert","data":[{"symbol":"XBTUSD","id":8798258600,"side":"Sell","size":80000,"price":17414}]}
09:57:34   {"table":"orderBookL2","action":"delete","data":[{"symbol":"XBTUSD","id":8798859250,"side":"Buy"}]}
09:57:34   {"table":"orderBookL2","action":"delete","data":[{"symbol":"XBTZ17","id":22899831295,"side":"Sell"}]}
09:57:34   {"table":"orderBookL2","action":"update","data":[{"symbol":"XBTZ17","id":22899833845,"side":"Sell","size":9593}]}
09:57:34   {"table":"orderBookL2","action":"insert","data":[{"symbol":"XBTZ17","id":22899834025,"side":"Sell","size":5418,"price":16597.5}]}
09:57:34   {"table":"orderBookL2","action":"insert","data":[{"symbol":"XBTZ17","id":22899834740,"side":"Buy","size":2306,"price":16526}]}
09:57:34   {"table":"orderBookL2","action":"insert","data":[{"symbol":"XBTZ17","id":22899839685,"side":"Buy","size":152,"price":16031.5}]}
09:57:34   {"table":"orderBookL2","action":"delete","data":[{"symbol":"XBTZ17","id":22899833845,"side":"Sell"}]}
09:57:34   {"table":"orderBookL2","action":"update","data":[{"symbol":"XBTZ17","id":22899834015,"side":"Sell","size":13592},{"symbol":"XBTZ17","id":22899839055,"side":"Buy","size":9449},{"symbol":"XBTZ17","id":22899839065,"side":"Buy","size":151}]}
09:57:34   {"table":"orderBookL2","action":"update","data":[{"symbol":"XBTUSD","id":8798860000,"side":"Buy","size":101}]}
09:57:34   {"table":"orderBookL2","action":"update","data":[{"symbol":"XBTUSD","id":8798363800,"side":"Buy","size":10050}]}
09:57:34   {"table":"orderBookL2","action":"delete","data":[{"symbol":"XBTUSD","id":8798368300,"side":"Buy"},{"symbol":"XBTUSD","id":8798368900,"side":"Buy"},{"symbol":"XBTUSD","id":8798369350,"side":"Buy"}]}
09:57:34   {"table":"orderBookL2","action":"update","data":[{"symbol":"XBTUSD","id":8798368650,"side":"Buy","size":7000},{"symbol":"XBTUSD","id":8798373700,"side":"Buy","size":413},{"symbol":"XBTUSD","id":8798375300,"side":"Buy","size":10050}]}
09:57:34   {"table":"orderBookL2","action":"insert","data":[{"symbol":"XBTUSD","id":8798370100,"side":"Buy","size":7000,"price":16299},{"symbol":"XBTUSD","id":8798370250,"side":"Buy","size":7000,"price":16297.5},{"symbol":"XBTUSD","id":8798370550,"side":"Buy","size":7000,"price":16294.5},{"symbol":"XBTUSD","id":8798371250,"side":"Buy","size":7000,"price":16287.5}]}
09:57:34   {"table":"orderBookL2","action":"update","data":[{"symbol":"XBTZ17","id":22899834025,"side":"Sell","size":57418}]}
09:57:34   {"table":"orderBookL2","action":"update","data":[{"symbol":"XBTZ17","id":22899834025,"side":"Sell","size":64418}]}
09:57:34   {"table":"orderBookL2","action":"delete","data":[{"symbol":"XBTZ17","id":22899826600,"side":"Sell"},{"symbol":"XBTZ17","id":22899828800,"side":"Sell"},{"symbol":"XBTZ17","id":22899835140,"side":"Buy"},{"symbol":"XBTZ17","id":22899835560,"side":"Buy"},{"symbol":"XBTZ17","id":22899835970,"side":"Buy"},{"symbol":"XBTZ17","id":22899836380,"side":"Buy"},{"symbol":"XBTZ17","id":22899836800,"side":"Buy"},{"symbol":"XBTZ17","id":22899837210,"side":"Buy"}]}
09:57:34   {"table":"orderBookL2","action":"update","data":[{"symbol":"XBTUSD","id":8798470000,"side":"Buy","size":1118600}]}
09:57:34   {"table":"orderBookL2","action":"update","data":[{"symbol":"XBTUSD","id":8798369050,"side":"Buy","size":9138},{"symbol":"XBTUSD","id":8798369950,"side":"Buy","size":181458}]}
09:57:34   {"table":"orderBookL2","action":"delete","data":[{"symbol":"XBTUSD","id":8798362750,"side":"Buy"}]}
09:57:34   {"table":"orderBookL2","action":"insert","data":[{"symbol":"XBTUSD","id":8798363500,"side":"Buy","size":3776,"price":16365}]}
09:57:34   {"table":"orderBookL2","action":"delete","data":[{"symbol":"XBTUSD","id":8798360000,"side":"Buy"},{"symbol":"XBTUSD","id":8798360050,"side":"Buy"},{"symbol":"XBTUSD","id":8798360100,"side":"Buy"},{"symbol":"XBTUSD","id":8798360500,"side":"Buy"},{"symbol":"XBTUSD","id":8798360600,"side":"Buy"},{"symbol":"XBTUSD","id":8798360800,"side":"Buy"},{"symbol":"XBTUSD","id":8798361400,"side":"Buy"},{"symbol":"XBTUSD","id":8798361450,"side":"Buy"},{"symbol":"XBTUSD","id":8798361500,"side":"Buy"},{"symbol":"XBTUSD","id":8798361600,"side":"Buy"},{"symbol":"XBTUSD","id":8798362100,"side":"Buy"},{"symbol":"XBTUSD","id":8798362250,"side":"Buy"}]}
09:57:34   {"table":"orderBookL2","action":"update","data":[{"symbol":"XBTUSD","id":8798362300,"side":"Buy","size":304234}]}
09:57:34   {"table":"orderBookL2","action":"update","data":[{"symbol":"XBTUSD","id":8798357800,"side":"Sell","size":79192}]}
09:57:34   {"table":"orderBookL2","action":"insert","data":[{"symbol":"XBTUSD","id":8798358600,"side":"Sell","size":50,"price":16414}]}
09:57:34   {"table":"orderBookL2","action":"update","data":[{"symbol":"XBTUSD","id":8798354450,"side":"Sell","size":313000},{"symbol":"XBTUSD","id":8798356300,"side":"Sell","size":9265}]}
09:57:34   {"table":"orderBookL2","action":"update","data":[{"symbol":"XBTZ17","id":22899832400,"side":"Sell","size":80000},{"symbol":"XBTZ17","id":22899836220,"side":"Buy","size":451}]}
09:57:34   {"table":"orderBookL2","action":"insert","data":[{"symbol":"XBTZ17","id":22899825150,"side":"Sell","size":97,"price":17485},{"symbol":"XBTZ17","id":22899827370,"side":"Sell","size":76,"price":17263},{"symbol":"XBTZ17","id":22899831820,"side":"Sell","size":35,"price":16818},{"symbol":"XBTZ17","id":22899834570,"side":"Buy","size":35,"price":16543},{"symbol":"XBTZ17","id":22899834980,"side":"Buy","size":56,"price":16502},{"symbol":"XBTZ17","id":22899835400,"side":"Buy","size":76,"price":16460},{"symbol":"XBTZ17","id":22899835810,"side":"Buy","size":97,"price":16419},{"symbol":"XBTZ17","id":22899836640,"side":"Buy","size":138,"price":16336}]}
09:57:34   {"table":"orderBookL2","action":"delete","data":[{"symbol":"XBTZ17","id":22899833140,"side":"Sell"},{"symbol":"XBTZ17","id":22899833440,"side":"Sell"},{"symbol":"XBTZ17","id":22899833465,"side":"Sell"},{"symbol":"XBTZ17","id":22899833600,"side":"Sell"},{"symbol":"XBTZ17","id":22899833645,"side":"Sell"}]}
09:57:34   {"table":"orderBookL2","action":"update","data":[{"symbol":"XBTZ17","id":22899833500,"side":"Sell","size":13000}]}
09:57:35   {"table":"orderBookL2","action":"insert","data":[{"symbol":"XBTZ17","id":22899833180,"side":"Sell","size":7000,"price":16682},{"symbol":"XBTZ17","id":22899833530,"side":"Sell","size":7000,"price":16647},{"symbol":"XBTZ17","id":22899833640,"side":"Sell","size":7000,"price":16636},{"symbol":"XBTZ17","id":22899833730,"side":"Sell","size":7000,"price":16627}]}
09:57:34   {"table":"orderBookL2","action":"delete","data":[{"symbol":"XBTUSD","id":8798398800,"side":"Buy"}]}
09:57:35   {"table":"orderBookL2","action":"insert","data":[{"symbol":"XBTUSD","id":8798390650,"side":"Buy","size":8000,"price":16093.5}]}
09:57:35   {"table":"orderBookL2","action":"update","data":[{"symbol":"XBTUSD","id":8798359950,"side":"Sell","size":98016}]}
09:57:35   {"table":"orderBookL2","action":"update","data":[{"symbol":"XBTUSD","id":8798309200,"side":"Sell","size":10044}]}
09:57:35   {"table":"orderBookL2","action":"insert","data":[{"symbol":"XBTUSD","id":8798310300,"side":"Sell","size":40,"price":16897}]}
09:57:35   {"table":"orderBookL2","action":"update","data":[{"symbol":"XBTUSD","id":8798355000,"side":"Sell","size":11710}]}
09:57:35   {"table":"orderBookL2","action":"delete","data":[{"symbol":"XBTUSD","id":8798368700,"side":"Buy"}]}
09:57:35   {"table":"orderBookL2","action":"insert","data":[{"symbol":"XBTUSD","id":8798371550,"side":"Buy","size":5000,"price":16284.5}]}
09:57:35   {"table":"orderBookL2","action":"delete","data":[{"symbol":"XBTZ17","id":22899832945,"side":"Sell"},{"symbol":"XBTZ17","id":22899833250,"side":"Sell"},{"symbol":"XBTZ17","id":22899833275,"side":"Sell"},{"symbol":"XBTZ17","id":22899833420,"side":"Sell"},{"symbol":"XBTZ17","id":22899833480,"side":"Sell"}]}
09:57:35   {"table":"orderBookL2","action":"insert","data":[{"symbol":"XBTZ17","id":22899833030,"side":"Sell","size":7000,"price":16697},{"symbol":"XBTZ17","id":22899833310,"side":"Sell","size":7000,"price":16669},{"symbol":"XBTZ17","id":22899833340,"side":"Sell","size":7000,"price":16666},{"symbol":"XBTZ17","id":22899833450,"side":"Sell","size":7000,"price":16655},{"symbol":"XBTZ17","id":22899833560,"side":"Sell","size":5059,"price":16644}]}
09:57:35   {"table":"orderBookL2","action":"delete","data":[{"symbol":"XBTZ17","id":22899832830,"side":"Sell"},{"symbol":"XBTZ17","id":22899833055,"side":"Sell"},{"symbol":"XBTZ17","id":22899833200,"side":"Sell"},{"symbol":"XBTZ17","id":22899833230,"side":"Sell"},{"symbol":"XBTZ17","id":22899833430,"side":"Sell"},{"symbol":"XBTZ17","id":22899834825,"side":"Buy"},{"symbol":"XBTZ17","id":22899834940,"side":"Buy"}]}
09:57:35   {"table":"orderBookL2","action":"delete","data":[{"symbol":"XBTUSD","id":8798328800,"side":"Sell"},{"symbol":"XBTUSD","id":8798337600,"side":"Sell"},{"symbol":"XBTUSD","id":8798372200,"side":"Buy"},{"symbol":"XBTUSD","id":8798375200,"side":"Buy"},{"symbol":"XBTUSD","id":8798381100,"side":"Buy"}]}
09:57:35   {"table":"orderBookL2","action":"update","data":[{"symbol":"XBTUSD","id":8798290000,"side":"Sell","size":3310},{"symbol":"XBTUSD","id":8798303000,"side":"Sell","size":383},{"symbol":"XBTUSD","id":8798315900,"side":"Sell","size":3500},{"symbol":"XBTUSD","id":8798331200,"side":"Sell","size":12193},{"symbol":"XBTUSD","id":8798344200,"side":"Sell","size":1173},{"symbol":"XBTUSD","id":8798351700,"side":"Sell","size":3000},{"symbol":"XBTUSD","id":8798366400,"side":"Buy","size":123},{"symbol":"XBTUSD","id":8798369000,"side":"Buy","size":517},{"symbol":"XBTUSD","id":8798369300,"side":"Buy","size":18312},{"symbol":"XBTUSD","id":8798378200,"side":"Buy","size":100000}]}
09:57:35   {"table":"orderBookL2","action":"insert","data":[{"symbol":"XBTUSD","id":8798279200,"side":"Sell","size":475,"price":17208},{"symbol":"XBTUSD","id":8798292200,"side":"Sell","size":405,"price":17078},{"symbol":"XBTUSD","id":8798305200,"side":"Sell","size":334,"price":16948},{"symbol":"XBTUSD","id":8798318200,"side":"Sell","size":264,"price":16818},{"symbol":"XBTUSD","id":8798360100,"side":"Buy","size":123,"price":16399},{"symbol":"XBTUSD","id":8798363000,"side":"Buy","size":193,"price":16370},{"symbol":"XBTUSD","id":8798366000,"side":"Buy","size":264,"price":16340},{"symbol":"XBTUSD","id":8798371900,"side":"Buy","size":405,"price":16281},{"symbol":"XBTUSD","id":8798374800,"side":"Buy","size":475,"price":16252}]}
09:57:35   {"table":"orderBookL2","action":"insert","data":[{"symbol":"XBTUSD","id":8798277150,"side":"Sell","size":10044,"price":17228.5}]}
09:57:35   {"table":"orderBookL2","action":"update","data":[{"symbol":"XBTZ17","id":22899833310,"side":"Sell","size":13890},{"symbol":"XBTZ17","id":22899833335,"side":"Sell","size":40000}]}
09:57:35   {"table":"orderBookL2","action":"insert","data":[{"symbol":"XBTZ17","id":22899832915,"side":"Sell","size":6850,"price":16708.5},{"symbol":"XBTZ17","id":22899833135,"side":"Sell","size":3570,"price":16686.5},{"symbol":"XBTZ17","id":22899833240,"side":"Sell","size":6890,"price":16676},{"symbol":"XBTZ17","id":22899833410,"side":"Sell","size":5850,"price":16659},{"symbol":"XBTZ17","id":22899833480,"side":"Sell","size":6850,"price":16652},{"symbol":"XBTZ17","id":22899834865,"side":"Buy","size":630,"price":16513.5},{"symbol":"XBTZ17","id":22899834985,"side":"Buy","size":1570,"price":16501.5}]}
09:57:35   {"table":"orderBookL2","action":"delete","data":[{"symbol":"XBTZ17","id":22899833495,"side":"Sell"}]}
09:57:35   {"table":"orderBookL2","action":"update","data":[{"symbol":"XBTUSD","id":8798365000,"side":"Buy","size":6810}]}
09:57:35   {"table":"orderBookL2","action":"delete","data":[{"symbol":"XBTUSD","id":8798359900,"side":"Sell"}]}
09:57:35   {"table":"orderBookL2","action":"update","data":[{"symbol":"XBTUSD","id":8798359200,"side":"Sell","size":19475}]}
09:57:35   {"table":"orderBookL2","action":"insert","data":[{"symbol":"XBTZ17","id":22899833825,"side":"Sell","size":50000,"price":16617.5}]}
09:57:35   {"table":"orderBookL2","action":"delete","data":[{"symbol":"XBTZ17","id":22899833785,"side":"Sell"}]}
09:57:35   {"table":"orderBookL2","action":"insert","data":[{"symbol":"XBTZ17","id":22899833575,"side":"Sell","size":4650,"price":16642.5}]}
09:57:35   {"table":"orderBookL2","action":"update","data":[{"symbol":"XBTUSD","id":8798359200,"side":"Sell","size":17875}]}
09:57:35   {"table":"orderBookL2","action":"update","data":[{"symbol":"XBTUSD","id":8798410050,"side":"Buy","size":3719}]}
09:57:35   {"table":"orderBookL2","action":"update","data":[{"symbol":"XBTUSD","id":8798359950,"side":"Sell","size":83016}]}
09:57:35   {"table":"orderBookL2","action":"update","data":[{"symbol":"XBTUSD","id":8798360100,"side":"Buy","size":98}]}
09:57:35   {"table":"orderBookL2","action":"update","data":[{"symbol":"XBTZ17","id":22899834155,"side":"Sell","size":958}]}
09:57:35   {"table":"orderBookL2","action":"insert","data":[{"symbol":"XBTZ17","id":22899835110,"side":"Buy","size":5020,"price":16489}]}
09:57:35   {"table":"orderBookL2","action":"update","data":[{"symbol":"XBTUSD","id":8798359400,"side":"Sell","size":67}]}
09:57:35   {"table":"orderBookL2","action":"update","data":[{"symbol":"XBTUSD","id":8798359950,"side":"Sell","size":82716}]}
09:57:35   {"table":"orderBookL2","action":"update","data":[{"symbol":"XBTZ17","id":22899833500,"side":"Sell","size":17650}]}
09:57:35   {"table":"orderBookL2","action":"delete","data":[{"symbol":"XBTZ17","id":22899833625,"side":"Sell"}]}
09:57:35   {"table":"orderBookL2","action":"insert","data":[{"symbol":"XBTZ17","id":22899833700,"side":"Sell","size":60,"price":16630}]}
09:57:35   {"table":"orderBookL2","action":"delete","data":[{"symbol":"XBTZ17","id":22899833045,"side":"Sell"},{"symbol":"XBTZ17","id":22899834720,"side":"Buy"},{"symbol":"XBTZ17","id":22899834915,"side":"Buy"}]}
09:57:35   {"table":"orderBookL2","action":"update","data":[{"symbol":"XBTUSD","id":8798358150,"side":"Sell","size":26000}]}
09:57:35   {"table":"orderBookL2","action":"update","data":[{"symbol":"XBTUSD","id":8798368250,"side":"Buy","size":100}]}
09:57:35   {"table":"orderBookL2","action":"insert","data":[{"symbol":"XBTUSD","id":8798367100,"side":"Buy","size":2500,"price":16329}]}
09:57:35   {"table":"orderBookL2","action":"insert","data":[{"symbol":"XBTZ17","id":22899832955,"side":"Sell","size":7000,"price":16704.5},{"symbol":"XBTZ17","id":22899834640,"side":"Buy","size":7050,"price":16536},{"symbol":"XBTZ17","id":22899834815,"side":"Buy","size":7050,"price":16518.5}]}
09:57:35   {"table":"orderBookL2","action":"delete","data":[{"symbol":"XBTZ17","id":22899834155,"side":"Sell"}]}
09:57:35   {"table":"orderBookL2","action":"delete","data":[{"symbol":"XBTZ17","id":22899831755,"side":"Sell"},{"symbol":"XBTZ17","id":22899832005,"side":"Sell"},{"symbol":"XBTZ17","id":22899832250,"side":"Sell"},{"symbol":"XBTZ17","id":22899832500,"side":"Sell"},{"symbol":"XBTZ17","id":22899832750,"side":"Sell"},{"symbol":"XBTZ17","id":22899832995,"side":"Sell"},{"symbol":"XBTZ17","id":22899833245,"side":"Sell"},{"symbol":"XBTZ17","id":22899833490,"side":"Sell"}]}
09:57:35   {"table":"orderBookL2","action":"delete","data":[{"symbol":"XBTUSD","id":8798366700,"side":"Buy"}]}
09:57:35   {"table":"orderBookL2","action":"insert","data":[{"symbol":"XBTUSD","id":8798365100,"side":"Buy","size":3000,"price":16349}]}
09:57:35   {"table":"orderBookL2","action":"update","data":[{"symbol":"XBTUSD","id":8798359950,"side":"Sell","size":82816}]}
09:57:35   {"table":"orderBookL2","action":"update","data":[{"symbol":"XBTZ17","id":22899833300,"side":"Sell","size":12000}]}
09:57:35   {"table":"orderBookL2","action":"insert","data":[{"symbol":"XBTZ17","id":22899831810,"side":"Sell","size":5000,"price":16819},{"symbol":"XBTZ17","id":22899832060,"side":"Sell","size":5000,"price":16794},{"symbol":"XBTZ17","id":22899832310,"side":"Sell","size":5000,"price":16769},{"symbol":"XBTZ17","id":22899832555,"side":"Sell","size":5000,"price":16744.5},{"symbol":"XBTZ17","id":22899832805,"side":"Sell","size":5000,"price":16719.5},{"symbol":"XBTZ17","id":22899833050,"side":"Sell","size":5000,"price":16695},{"symbol":"XBTZ17","id":22899833550,"side":"Sell","size":5000,"price":16645}]}
09:57:35   {"table":"orderBookL2","action":"insert","data":[{"symbol":"XBTUSD","id":8798359450,"side":"Sell","size":500,"price":16405.5},{"symbol":"XBTUSD","id":8798360000,"side":"Buy","size":200,"price":16400}]}
09:57:35   {"table":"orderBookL2","action":"insert","data":[{"symbol":"XBTUSD","id":8798410300,"side":"Buy","size":51,"price":15897}]}
09:57:35   {"table":"orderBookL2","action":"delete","data":[{"symbol":"XBTZ17","id":22899840745,"side":"Buy"}]}
09:57:35   {"table":"orderBookL2","action":"delete","data":[{"symbol":"XBTZ17","id":22899834585,"side":"Buy"}]}
09:57:35   {"table":"orderBookL2","action":"update","data":[{"symbol":"XBTZ17","id":22899834015,"side":"Sell","size":10423},{"symbol":"XBTZ17","id":22899834025,"side":"Sell","size":67670},{"symbol":"XBTZ17","id":22899834640,"side":"Buy","size":7798}]}
09:57:35   {"table":"orderBookL2","action":"update","data":[{"symbol":"XBTUSD","id":8798359950,"side":"Sell","size":87616}]}
09:57:35   {"table":"orderBookL2","action":"delete","data":[{"symbol":"XBTUSD","id":8798363550,"side":"Buy"}]}
09:57:35   {"table":"orderBookL2","action":"insert","data":[{"symbol":"XBTZ17","id":22899831300,"side":"Sell","size":2000,"price":16870}]}
09:57:35   {"table":"orderBookL2","action":"delete","data":[{"symbol":"XBTZ17","id":22899834765,"side":"Buy"}]}
09:57:35   {"table":"orderBookL2","action":"delete","data":[{"symbol":"XBTZ17","id":22899836930,"side":"Buy"}]}
09:57:35   {"table":"orderBookL2","action":"update","data":[{"symbol":"XBTUSD","id":8798363800,"side":"Buy","size":13826}]}
09:57:35   {"table":"orderBookL2","action":"update","data":[{"symbol":"XBTUSD","id":8798175000,"side":"Sell","size":5661}]}
09:57:35   {"table":"orderBookL2","action":"update","data":[{"symbol":"XBTZ17","id":22899831230,"side":"Sell","size":153}]}
09:57:35   {"table":"orderBookL2","action":"insert","data":[{"symbol":"XBTZ17","id":22899833505,"side":"Sell","size":42100,"price":16649.5},{"symbol":"XBTZ17","id":22899834340,"side":"Buy","size":47000,"price":16566},{"symbol":"XBTZ17","id":22899834505,"side":"Buy","size":44600,"price":16549.5}]}
09:57:35   {"table":"orderBookL2","action":"update","data":[{"symbol":"XBTZ17","id":22899834640,"side":"Buy","size":10798}]}
09:57:35   {"table":"orderBookL2","action":"insert","data":[{"symbol":"XBTUSD","id":8798361000,"side":"Buy","size":2500,"price":16390}]}
09:57:35   {"table":"orderBookL2","action":"delete","data":[{"symbol":"XBTUSD","id":8798349250,"side":"Sell"},{"symbol":"XBTUSD","id":8798350950,"side":"Sell"},{"symbol":"XBTUSD","id":8798352600,"side":"Sell"},{"symbol":"XBTUSD","id":8798354100,"side":"Sell"},{"symbol":"XBTUSD","id":8798354950,"side":"Sell"},{"symbol":"XBTUSD","id":8798356150,"side":"Sell"},{"symbol":"XBTUSD","id":8798362800,"side":"Buy"}]}
09:57:35   {"table":"orderBookL2","action":"update","data":[{"symbol":"XBTUSD","id":8798348750,"side":"Sell","size":64800},{"symbol":"XBTUSD","id":8798354800,"side":"Sell","size":20408},{"symbol":"XBTUSD","id":8798355100,"side":"Sell","size":30000},{"symbol":"XBTUSD","id":8798355900,"side":"Sell","size":1104},{"symbol":"XBTUSD","id":8798358050,"side":"Sell","size":101},{"symbol":"XBTUSD","id":8798364450,"side":"Buy","size":11083}]}
09:57:35   {"table":"orderBookL2","action":"update","data":[{"symbol":"XBTZ17","id":22899834015,"side":"Sell","size":835},{"symbol":"XBTZ17","id":22899839055,"side":"Buy","size":153}]}
09:57:35   {"table":"orderBookL2","action":"insert","data":[{"symbol":"XBTZ17","id":22899834030,"side":"Sell","size":9587,"price":16597},{"symbol":"XBTZ17","id":22899839120,"side":"Buy","size":9292,"price":16088}]}
09:57:35   {"table":"orderBookL2","action":"update","data":[{"symbol":"XBTZ17","id":22899834640,"side":"Buy","size":17798}]}
09:57:35   {"table":"orderBookL2","action":"delete","data":[{"symbol":"XBTZ17","id":22899834740,"side":"Buy"}]}
09:57:35   {"table":"orderBookL2","action":"insert","data":[{"symbol":"XBTUSD","id":8798350350,"side":"Sell","size":464,"price":16496.5},{"symbol":"XBTUSD","id":8798352050,"side":"Sell","size":300,"price":16479.5},{"symbol":"XBTUSD","id":8798356950,"side":"Sell","size":102,"price":16430.5},{"symbol":"XBTUSD","id":8798361500,"side":"Buy","size":779,"price":16385},{"symbol":"XBTUSD","id":8798362700,"side":"Buy","size":924,"price":16373}]}
09:57:35   {"table":"orderBookL2","action":"update","data":[{"symbol":"XBTUSD","id":8798353600,"side":"Sell","size":4820}]}
09:57:35   {"table":"orderBookL2","action":"insert","data":[{"symbol":"XBTZ17","id":22899861790,"side":"Buy","size":25000,"price":13821}]}
09:57:35   {"table":"orderBookL2","action":"delete","data":[{"symbol":"XBTZ17","id":22899834645,"side":"Buy"}]}
09:57:35   {"table":"orderBookL2","action":"update","data":[{"symbol":"XBTUSD","id":8798356300,"side":"Sell","size":1265}]}
09:57:35   {"table":"orderBookL2","action":"update","data":[{"symbol":"XBTUSD","id":8798360000,"side":"Buy","size":360}]}
09:57:35   {"table":"orderBookL2","action":"update","data":[{"symbol":"XBTUSD","id":8798357550,"side":"Sell","size":12400}]}
09:57:35   {"table":"orderBookL2","action":"delete","data":[{"symbol":"XBTUSD","id":8798342700,"side":"Sell"},{"symbol":"XBTUSD","id":8798374900,"side":"Buy"}]}
09:57:35   {"table":"orderBookL2","action":"update","data":[{"symbol":"XBTUSD","id":8798357800,"side":"Sell","size":76692},{"symbol":"XBTUSD","id":8798392000,"side":"Buy","size":800}]}
09:57:35   {"table":"orderBookL2","action":"update","data":[{"symbol":"XBTUSD","id":8798359950,"side":"Sell","size":87626}]}
09:57:35   {"table":"orderBookL2","action":"insert","data":[{"symbol":"XBTZ17","id":22899834785,"side":"Buy","size":8000,"price":16521.5}]}
09:57:35   {"table":"orderBookL2","action":"delete","data":[{"symbol":"XBTZ17","id":22899834840,"side":"Buy"}]}
09:57:35   {"table":"orderBookL2","action":"update","data":[{"symbol":"XBTZ17","id":22899833300,"side":"Sell","size":5000}]}
09:57:35   {"table":"orderBookL2","action":"insert","data":[{"symbol":"XBTZ17","id":22899833210,"side":"Sell","size":7000,"price":16679},{"symbol":"XBTZ17","id":22899834745,"side":"Buy","size":7050,"price":16525.5}]}
09:57:35   {"table":"orderBookL2","action":"delete","data":[{"symbol":"XBTUSD","id":8798366100,"side":"Buy"}]}
09:57:35   {"table":"orderBookL2","action":"insert","data":[{"symbol":"XBTUSD","id":8798365700,"side":"Buy","size":4000,"price":16343}]}
09:57:35   {"table":"orderBookL2","action":"update","data":[{"symbol":"XBTUSD","id":8798377800,"side":"Buy","size":1000}]}
09:57:35   {"table":"orderBookL2","action":"insert","data":[{"symbol":"XBTUSD","id":8798374850,"side":"Buy","size":50000,"price":16251.5}]}
09:57:35   {"table":"orderBookL2","action":"delete","data":[{"symbol":"XBTZ17","id":22899834135,"side":"Sell"}]}
09:57:35   {"table":"orderBookL2","action":"insert","data":[{"symbol":"XBTZ17","id":22899834115,"side":"Buy","size":750,"price":16588.5}]}
09:57:35   {"table":"orderBookL2","action":"delete","data":[{"symbol":"XBTUSD","id":8798360000,"side":"Buy"},{"symbol":"XBTUSD","id":8798360100,"side":"Buy"},{"symbol":"XBTUSD","id":8798361000,"side":"Buy"},{"symbol":"XBTUSD","id":8798361500,"side":"Buy"}]}
09:57:35   {"table":"orderBookL2","action":"update","data":[{"symbol":"XBTUSD","id":8798362300,"side":"Buy","size":277971}]}
09:57:35   {"table":"orderBookL2","action":"update","data":[{"symbol":"XBTZ17","id":22899833575,"side":"Sell","size":9300}]}
09:57:35   {"table":"orderBookL2","action":"update","data":[{"symbol":"XBTZ17","id":22899835110,"side":"Buy","size":11020}]}
09:57:35   {"table":"orderBookL2","action":"update","data":[{"symbol":"XBTZ17","id":22899834025,"side":"Sell","size":15670}]}
09:57:35   {"table":"orderBookL2","action":"update","data":[{"symbol":"XBTUSD","id":8798359950,"side":"Sell","size":90126}]}
09:57:35   {"table":"orderBookL2","action":"delete","data":[{"symbol":"XBTUSD","id":8798357250,"side":"Sell"}]}
09:57:35   {"table":"orderBookL2","action":"update","data":[{"symbol":"XBTUSD","id":8798359950,"side":"Sell","size":96707}]}
09:57:35   {"table":"orderBookL2","action":"update","data":[{"symbol":"XBTZ17","id":22899834025,"side":"Sell","size":8670}]}
09:57:35   {"table":"orderBookL2","action":"delete","data":[{"symbol":"XBTZ17","id":22899834015,"side":"Sell"}]}
09:57:35   {"table":"orderBookL2","action":"insert","data":[{"symbol":"XBTUSD","id":8798360500,"side":"Sell","size":3192,"price":16395}]}
09:57:35   {"table":"orderBookL2","action":"delete","data":[{"symbol":"XBTUSD","id":8798363350,"side":"Buy"},{"symbol":"XBTUSD","id":8798364300,"side":"Buy"}]}
09:57:35   {"table":"orderBookL2","action":"update","data":[{"symbol":"XBTUSD","id":8798363600,"side":"Buy","size":43},{"symbol":"XBTUSD","id":8798363900,"side":"Buy","size":344078},{"symbol":"XBTUSD","id":8798364100,"side":"Buy","size":4032},{"symbol":"XBTUSD","id":8798364700,"side":"Buy","size":27992},{"symbol":"XBTUSD","id":8798364850,"side":"Buy","size":23776},{"symbol":"XBTUSD","id":8798364900,"side":"Buy","size":10000},{"symbol":"XBTUSD","id":8798366000,"side":"Buy","size":10264}]}
09:57:35   {"table":"orderBookL2","action":"insert","data":[{"symbol":"XBTUSD","id":8798365200,"side":"Buy","size":10000,"price":16348}]}
09:57:35   {"table":"orderBookL2","action":"update","data":[{"symbol":"XBTUSD","id":8798367800,"side":"Buy","size":21681}]}
09:57:35   {"table":"orderBookL2","action":"update","data":[{"symbol":"XBTZ17","id":22899834025,"side":"Sell","size":3252}]}
09:57:35   {"table":"orderBookL2","action":"delete","data":[{"symbol":"XBTZ17","id":22899833060,"side":"Sell"}]}
09:57:35   {"table":"orderBookL2","action":"delete","data":[{"symbol":"XBTUSD","id":8798188500,"side":"Sell"},{"symbol":"XBTUSD","id":8798362600,"side":"Buy"},{"symbol":"XBTUSD","id":8798363600,"side":"Buy"},{"symbol":"XBTUSD","id":8798364600,"side":"Buy"},{"symbol":"XBTUSD","id":8798367600,"side":"Buy"},{"symbol":"XBTUSD","id":8798369600,"side":"Buy"},{"symbol":"XBTUSD","id":8798372600,"side":"Buy"},{"symbol":"XBTUSD","id":8798374600,"side":"Buy"},{"symbol":"XBTUSD","id":8798375600,"side":"Buy"},{"symbol":"XBTUSD","id":8798377600,"side":"Buy"},{"symbol":"XBTUSD","id":8798379600,"side":"Buy"},{"symbol":"XBTUSD","id":8798382600,"side":"Buy"},{"symbol":"XBTUSD","id":8798384600,"side":"Buy"},{"symbol":"XBTUSD","id":8798385600,"side":"Buy"},{"symbol":"XBTUSD","id":8798386600,"side":"Buy"},{"symbol":"XBTUSD","id":8798387600,"side":"Buy"},{"symbol":"XBTUSD","id":8798388600,"side":"Buy"},{"symbol":"XBTUSD","id":8798389600,"side":"Buy"},{"symbol":"XBTUSD","id":8798390600,"side":"Buy"},{"symbol":"XBTUSD","id":8798391600,"side":"Buy"},{"symbol":"XBTUSD","id":8798392600,"side":"Buy"},{"symbol":"XBTUSD","id":8798393600,"side":"Buy"},{"symbol":"XBTUSD","id":8798394600,"side":"Buy"},{"symbol":"XBTUSD","id":8798395600,"side":"Buy"},{"symbol":"XBTUSD","id":8798396600,"side":"Buy"},{"symbol":"XBTUSD","id":8798397600,"side":"Buy"},{"symbol":"XBTUSD","id":8798398600,"side":"Buy"},{"symbol":"XBTUSD","id":8798399600,"side":"Buy"},{"symbol":"XBTUSD","id":8798400600,"side":"Buy"},{"symbol":"XBTUSD","id":8798401600,"side":"Buy"},{"symbol":"XBTUSD","id":8798402600,"side":"Buy"},{"symbol":"XBTUSD","id":8798403600,"side":"Buy"},{"symbol":"XBTUSD","id":8798404600,"side":"Buy"}]}
09:57:35   {"table":"orderBookL2","action":"update","data":[{"symbol":"XBTUSD","id":8798193500,"side":"Sell","size":135},{"symbol":"XBTUSD","id":8798365600,"side":"Buy","size":171},{"symbol":"XBTUSD","id":8798366600,"side":"Buy","size":46},{"symbol":"XBTUSD","id":8798368600,"side":"Buy","size":150000},{"symbol":"XBTUSD","id":8798370600,"side":"Buy","size":52},{"symbol":"XBTUSD","id":8798371600,"side":"Buy","size":306000},{"symbol":"XBTUSD","id":8798373600,"side":"Buy","size":258},{"symbol":"XBTUSD","id":8798376600,"side":"Buy","size":50000},{"symbol":"XBTUSD","id":8798378600,"side":"Buy","size":2000},{"symbol":"XBTUSD","id":8798380600,"side":"Buy","size":64000},{"symbol":"XBTUSD","id":8798381600,"side":"Buy","size":15000},{"symbol":"XBTUSD","id":8798383600,"side":"Buy","size":662},{"symbol":"XBTUSD","id":8798405600,"side":"Buy","size":200},{"symbol":"XBTUSD","id":8798406600,"side":"Buy","size":500000}]}
09:57:35   {"table":"orderBookL2","action":"delete","data":[{"symbol":"XBTUSD","id":8798334600,"side":"Sell"},{"symbol":"XBTUSD","id":8798339550,"side":"Sell"},{"symbol":"XBTUSD","id":8798349500,"side":"Sell"}]}
09:57:35   {"table":"orderBookL2","action":"update","data":[{"symbol":"XBTZ17","id":22899833505,"side":"Sell","size":131192}]}
09:57:35   {"table":"orderBookL2","action":"update","data":[{"symbol":"XBTZ17","id":22899835110,"side":"Buy","size":6000}]}
09:57:35   {"table":"orderBookL2","action":"insert","data":[{"symbol":"XBTZ17","id":22899834995,"side":"Buy","size":2500,"price":16500.5}]}
09:57:35   {"table":"orderBookL2","action":"update","data":[{"symbol":"XBTUSD","id":8798329600,"side":"Sell","size":218},{"symbol":"XBTUSD","id":8798344550,"side":"Sell","size":77},{"symbol":"XBTUSD","id":8798345300,"side":"Sell","size":15061},{"symbol":"XBTUSD","id":8798354450,"side":"Sell","size":310500},{"symbol":"XBTUSD","id":8798355200,"side":"Sell","size":6100}]}
09:57:35   {"table":"orderBookL2","action":"insert","data":[{"symbol":"XBTUSD","id":8798330350,"side":"Sell","size":15000,"price":16696.5},{"symbol":"XBTUSD","id":8798335350,"side":"Sell","size":12500,"price":16646.5},{"symbol":"XBTUSD","id":8798340350,"side":"Sell","size":10000,"price":16596.5},{"symbol":"XBTUSD","id":8798350250,"side":"Sell","size":5000,"price":16497.5}]}
09:57:35   {"table":"orderBookL2","action":"delete","data":[{"symbol":"XBTUSD","id":8798356050,"side":"Sell"},{"symbol":"XBTUSD","id":8798363950,"side":"Buy"}]}
09:57:35   {"table":"orderBookL2","action":"update","data":[{"symbol":"XBTUSD","id":8798356000,"side":"Sell","size":16200},{"symbol":"XBTUSD","id":8798363900,"side":"Buy","size":344278}]}
09:57:35   {"table":"orderBookL2","action":"update","data":[{"symbol":"XBTUSD","id":8798355850,"side":"Sell","size":17698},{"symbol":"XBTUSD","id":8798355900,"side":"Sell","size":904},{"symbol":"XBTUSD","id":8798364050,"side":"Buy","size":338},{"symbol":"XBTUSD","id":8798364100,"side":"Buy","size":3832}]}
09:57:35   {"table":"orderBookL2","action":"update","data":[{"symbol":"XBTUSD","id":8798340800,"side":"Sell","size":7362}]}
09:57:35   {"table":"orderBookL2","action":"insert","data":[{"symbol":"XBTUSD","id":8798368750,"side":"Buy","size":4100,"price":16312.5}]}
09:57:35   {"table":"orderBookL2","action":"delete","data":[{"symbol":"XBTUSD","id":8798330700,"side":"Sell"},{"symbol":"XBTUSD","id":8798346150,"side":"Sell"},{"symbol":"XBTUSD","id":8798350450,"side":"Sell"},{"symbol":"XBTUSD","id":8798353350,"side":"Sell"},{"symbol":"XBTUSD","id":8798365500,"side":"Buy"},{"symbol":"XBTUSD","id":8798368400,"side":"Buy"},{"symbol":"XBTUSD","id":8798372650,"side":"Buy"},{"symbol":"XBTUSD","id":8798378850,"side":"Buy"},{"symbol":"XBTUSD","id":8798387700,"side":"Buy"}]}
09:57:35   {"table":"orderBookL2","action":"update","data":[{"symbol":"XBTUSD","id":8798339800,"side":"Sell","size":500},{"symbol":"XBTUSD","id":8798352050,"side":"Sell","size":2800},{"symbol":"XBTUSD","id":8798378100,"side":"Buy","size":5100}]}
09:57:35   {"table":"orderBookL2","action":"update","data":[{"symbol":"XBTZ17","id":22899833500,"side":"Sell","size":11650}]}
09:57:35   {"table":"orderBookL2","action":"delete","data":[{"symbol":"XBTZ17","id":22899832955,"side":"Sell"},{"symbol":"XBTZ17","id":22899834815,"side":"Buy"}]}
09:57:35   {"table":"orderBookL2","action":"update","data":[{"symbol":"XBTZ17","id":22899834640,"side":"Buy","size":10748}]}
09:57:35   {"table":"orderBookL2","action":"insert","data":[{"symbol":"XBTUSD","id":8798332300,"side":"Sell","size":6250,"price":16677},{"symbol":"XBTUSD","id":8798341400,"side":"Sell","size":5000,"price":16586},{"symbol":"XBTUSD","id":8798347750,"side":"Sell","size":3750,"price":16522.5},{"symbol":"XBTUSD","id":8798354950,"side":"Sell","size":1250,"price":16450.5},{"symbol":"XBTUSD","id":8798364750,"side":"Buy","size":1250,"price":16352.5},{"symbol":"XBTUSD","id":8798367600,"side":"Buy","size":2500,"price":16324},{"symbol":"XBTUSD","id":8798371850,"side":"Buy","size":3750,"price":16281.5},{"symbol":"XBTUSD","id":8798386900,"side":"Buy","size":6250,"price":16131}]}
09:57:35   {"table":"orderBookL2","action":"insert","data":[{"symbol":"XBTUSD","id":8798360000,"side":"Sell","size":2017947,"price":16400}]}
09:57:35   {"table":"orderBookL2","action":"insert","data":[{"symbol":"XBTUSD","id":8798354650,"side":"Sell","size":3100,"price":16453.5}]}
09:57:35   {"table":"orderBookL2","action":"update","data":[{"symbol":"XBTUSD","id":8798360500,"side":"Sell","size":3190}]}
09:57:35   {"table":"orderBookL2","action":"update","data":[{"symbol":"XBTUSD","id":8798358150,"side":"Sell","size":22000}]}
09:57:35   {"table":"orderBookL2","action":"insert","data":[{"symbol":"XBTUSD","id":8798358100,"side":"Sell","size":10000,"price":16419}]}
09:57:35   {"table":"orderBookL2","action":"update","data":[{"symbol":"XBTUSD","id":8798390000,"side":"Buy","size":122640},{"symbol":"XBTUSD","id":8798500000,"side":"Buy","size":1063558}]}
09:57:35   {"table":"orderBookL2","action":"insert","data":[{"symbol":"XBTZ17","id":22899833045,"side":"Sell","size":7000,"price":16695.5},{"symbol":"XBTZ17","id":22899834720,"side":"Buy","size":7050,"price":16528},{"symbol":"XBTZ17","id":22899834910,"side":"Buy","size":7050,"price":16509}]}
09:57:35   {"table":"orderBookL2","action":"delete","data":[{"symbol":"XBTZ17","id":22899834025,"side":"Sell"}]}
09:57:35   {"table":"orderBookL2","action":"update","data":[{"symbol":"XBTZ17","id":22899834030,"side":"Sell","size":12839}]}
09:57:35   {"table":"orderBookL2","action":"delete","data":[{"symbol":"XBTZ17","id":22899832820,"side":"Sell"},{"symbol":"XBTZ17","id":22899833360,"side":"Sell"},{"symbol":"XBTZ17","id":22899836140,"side":"Buy"},{"symbol":"XBTZ17","id":22899837960,"side":"Buy"},{"symbol":"XBTZ17","id":22899838500,"side":"Buy"},{"symbol":"XBTZ17","id":22899839020,"side":"Buy"}]}
09:57:35   {"table":"orderBookL2","action":"update","data":[{"symbol":"XBTUSD","id":8798363300,"side":"Buy","size":20000}]}
09:57:35   {"table":"orderBookL2","action":"insert","data":[{"symbol":"XBTUSD","id":8798361850,"side":"Buy","size":469,"price":16381.5}]}
09:57:35   {"table":"orderBookL2","action":"update","data":[{"symbol":"XBTUSD","id":8798360500,"side":"Sell","size":2787},{"symbol":"XBTUSD","id":8798362500,"side":"Buy","size":1043},{"symbol":"XBTUSD","id":8798367400,"side":"Buy","size":2518},{"symbol":"XBTUSD","id":8798377200,"side":"Buy","size":3631},{"symbol":"XBTUSD","id":8798386900,"side":"Buy","size":14045},{"symbol":"XBTUSD","id":8798434900,"side":"Buy","size":10315},{"symbol":"XBTUSD","id":8798527400,"side":"Buy","size":10075}]}
09:57:35   {"table":"orderBookL2","action":"insert","data":[{"symbol":"XBTUSD","id":8798411100,"side":"Buy","size":18708,"price":15889},{"symbol":"XBTUSD","id":8798481900,"side":"Buy","size":10000,"price":15181},{"symbol":"XBTUSD","id":8798571600,"side":"Buy","size":10000,"price":14284}]}
09:57:35   {"table":"orderBookL2","action":"update","data":[{"symbol":"XBTUSD","id":8798449900,"side":"Buy","size":11075}]}
09:57:35   {"table":"orderBookL2","action":"delete","data":[{"symbol":"XBTUSD","id":8798365050,"side":"Buy"}]}
09:57:35   {"table":"orderBookL2","action":"insert","data":[{"symbol":"XBTUSD","id":8798364250,"side":"Buy","size":2000,"price":16357.5}]}
09:57:35   {"table":"orderBookL2","action":"update","data":[{"symbol":"XBTZ17","id":22899827900,"side":"Sell","size":10316},{"symbol":"XBTZ17","id":22899831300,"side":"Sell","size":2183},{"symbol":"XBTZ17","id":22899835110,"side":"Buy","size":6116},{"symbol":"XBTZ17","id":22899835740,"side":"Buy","size":40233},{"symbol":"XBTZ17","id":22899836660,"side":"Buy","size":5000},{"symbol":"XBTZ17","id":22899837200,"side":"Buy","size":300}]}
09:57:35   {"table":"orderBookL2","action":"insert","data":[{"symbol":"XBTZ17","id":22899824490,"side":"Sell","size":449,"price":17551},{"symbol":"XBTZ17","id":22899826190,"side":"Sell","size":383,"price":17381},{"symbol":"XBTZ17","id":22899829600,"side":"Sell","size":250,"price":17040},{"symbol":"XBTZ17","id":22899835420,"side":"Buy","size":183,"price":16458},{"symbol":"XBTZ17","id":22899836060,"side":"Buy","size":316,"price":16394},{"symbol":"XBTZ17","id":22899836380,"side":"Buy","size":383,"price":16362},{"symbol":"XBTZ17","id":22899836700,"side":"Buy","size":449,"price":16330}]}
09:57:35   {"table":"orderBookL2","action":"update","data":[{"symbol":"XBTZ17","id":22899834640,"side":"Buy","size":10000}]}
09:57:35   {"table":"orderBookL2","action":"update","data":[{"symbol":"XBTZ17","id":22899836420,"side":"Buy","size":2166}]}
09:57:35   {"table":"orderBookL2","action":"update","data":[{"symbol":"XBTUSD","id":8798355000,"side":"Sell","size":24210}]}
09:57:35   {"table":"orderBookL2","action":"update","data":[{"symbol":"XBTUSD","id":8798188800,"side":"Sell","size":51473},{"symbol":"XBTUSD","id":8798366950,"side":"Buy","size":331043},{"symbol":"XBTUSD","id":8798368950,"side":"Buy","size":7820},{"symbol":"XBTUSD","id":8798369950,"side":"Buy","size":181501},{"symbol":"XBTUSD","id":8798381950,"side":"Buy","size":12543},{"symbol":"XBTUSD","id":8798387950,"side":"Buy","size":1494},{"symbol":"XBTUSD","id":8798388950,"side":"Buy","size":143},{"symbol":"XBTUSD","id":8798391950,"side":"Buy","size":93},{"symbol":"XBTUSD","id":8798401950,"side":"Buy","size":2043},{"symbol":"XBTUSD","id":8798402950,"side":"Buy","size":1044},{"symbol":"XBTUSD","id":8798408950,"side":"Buy","size":100043}]}
09:57:35   {"table":"orderBookL2","action":"insert","data":[{"symbol":"XBTUSD","id":8798193800,"side":"Sell","size":50974,"price":18062},{"symbol":"XBTUSD","id":8798360950,"side":"Buy","size":43,"price":16390.5},{"symbol":"XBTUSD","id":8798361950,"side":"Buy","size":43,"price":16380.5},{"symbol":"XBTUSD","id":8798362950,"side":"Buy","size":43,"price":16370.5},{"symbol":"XBTUSD","id":8798363950,"side":"Buy","size":43,"price":16360.5},{"symbol":"XBTUSD","id":8798364950,"side":"Buy","size":43,"price":16350.5},{"symbol":"XBTUSD","id":8798365950,"side":"Buy","size":43,"price":16340.5},{"symbol":"XBTUSD","id":8798367950,"side":"Buy","size":43,"price":16320.5},{"symbol":"XBTUSD","id":8798370950,"side":"Buy","size":43,"price":16290.5},{"symbol":"XBTUSD","id":8798371950,"side":"Buy","size":43,"price":16280.5},{"symbol":"XBTUSD","id":8798372950,"side":"Buy","size":43,"price":16270.5},{"symbol":"XBTUSD","id":8798373950,"side":"Buy","size":43,"price":16260.5},{"symbol":"XBTUSD","id":8798374950,"side":"Buy","size":43,"price":16250.5},{"symbol":"XBTUSD","id":8798375950,"side":"Buy","size":43,"price":16240.5},{"symbol":"XBTUSD","id":8798376950,"side":"Buy","size":43,"price":16230.5},{"symbol":"XBTUSD","id":8798377950,"side":"Buy","size":43,"price":16220.5},{"symbol":"XBTUSD","id":8798378950,"side":"Buy","size":43,"price":16210.5},{"symbol":"XBTUSD","id":8798379950,"side":"Buy","size":43,"price":16200.5},{"symbol":"XBTUSD","id":8798380950,"side":"Buy","size":43,"price":16190.5},{"symbol":"XBTUSD","id":8798382950,"side":"Buy","size":43,"price":16170.5},{"symbol":"XBTUSD","id":8798383950,"side":"Buy","size":43,"price":16160.5},{"symbol":"XBTUSD","id":8798384950,"side":"Buy","size":43,"price":16150.5},{"symbol":"XBTUSD","id":8798385950,"side":"Buy","size":43,"price":16140.5},{"symbol":"XBTUSD","id":8798386950,"side":"Buy","size":43,"price":16130.5},{"symbol":"XBTUSD","id":8798389950,"side":"Buy","size":43,"price":16100.5},{"symbol":"XBTUSD","id":8798390950,"side":"Buy","size":43,"price":16090.5},{"symbol":"XBTUSD","id":8798392950,"side":"Buy","size":43,"price":16070.5},{"symbol":"XBTUSD","id":8798393950,"side":"Buy","size":43,"price":16060.5},{"symbol":"XBTUSD","id":8798394950,"side":"Buy","size":43,"price":16050.5},{"symbol":"XBTUSD","id":8798395950,"side":"Buy","size":43,"price":16040.5},{"symbol":"XBTUSD","id":8798396950,"side":"Buy","size":43,"price":16030.5},{"symbol":"XBTUSD","id":8798397950,"side":"Buy","size":43,"price":16020.5},{"symbol":"XBTUSD","id":8798398950,"side":"Buy","size":43,"price":16010.5},{"symbol":"XBTUSD","id":8798399950,"side":"Buy","size":43,"price":16000.5},{"symbol":"XBTUSD","id":8798400950,"side":"Buy","size":43,"price":15990.5},{"symbol":"XBTUSD","id":8798403950,"side":"Buy","size":43,"price":15960.5},{"symbol":"XBTUSD","id":8798404950,"side":"Buy","size":43,"price":15950.5},{"symbol":"XBTUSD","id":8798405950,"side":"Buy","size":43,"price":15940.5},{"symbol":"XBTUSD","id":8798406950,"side":"Buy","size":43,"price":15930.5},{"symbol":"XBTUSD","id":8798407950,"side":"Buy","size":43,"price":15920.5}]}
09:57:35   {"table":"orderBookL2","action":"delete","data":[{"symbol":"XBTZ17","id":22899834115,"side":"Buy"}]}
09:57:35   {"table":"orderBookL2","action":"insert","data":[{"symbol":"XBTZ17","id":22899834125,"side":"Sell","size":1541,"price":16587.5}]}
09:57:35   {"table":"orderBookL2","action":"update","data":[{"symbol":"XBTZ17","id":22899834995,"side":"Buy","size":6600}]}
09:57:35   {"table":"orderBookL2","action":"delete","data":[{"symbol":"XBTZ17","id":22899831810,"side":"Sell"},{"symbol":"XBTZ17","id":22899832060,"side":"Sell"},{"symbol":"XBTZ17","id":22899832310,"side":"Sell"},{"symbol":"XBTZ17","id":22899832555,"side":"Sell"},{"symbol":"XBTZ17","id":22899832805,"side":"Sell"},{"symbol":"XBTZ17","id":22899833050,"side":"Sell"},{"symbol":"XBTZ17","id":22899833300,"side":"Sell"},{"symbol":"XBTZ17","id":22899833550,"side":"Sell"},{"symbol":"XBTZ17","id":22899836660,"side":"Buy"},{"symbol":"XBTZ17","id":22899836910,"side":"Buy"},{"symbol":"XBTZ17","id":22899837155,"side":"Buy"},{"symbol":"XBTZ17","id":22899837400,"side":"Buy"},{"symbol":"XBTZ17","id":22899837650,"side":"Buy"},{"symbol":"XBTZ17","id":22899837895,"side":"Buy"}]}
09:57:35   {"table":"orderBookL2","action":"update","data":[{"symbol":"XBTZ17","id":22899832230,"side":"Sell","size":52100},{"symbol":"XBTZ17","id":22899838140,"side":"Buy","size":302},{"symbol":"XBTZ17","id":22899838390,"side":"Buy","size":151}]}
09:57:35   {"table":"orderBookL2","action":"delete","data":[{"symbol":"XBTUSD","id":8798374850,"side":"Buy"}]}
09:57:35   {"table":"orderBookL2","action":"delete","data":[{"symbol":"XBTUSD","id":8798258600,"side":"Sell"}]}
09:57:35   {"table":"orderBookL2","action":"insert","data":[{"symbol":"XBTUSD","id":8798203250,"side":"Sell","size":80000,"price":17967.5}]}
09:57:35   {"table":"orderBookL2","action":"update","data":[{"symbol":"XBTUSD","id":8798359950,"side":"Sell","size":146707}]}
09:57:35   {"table":"orderBookL2","action":"update","data":[{"symbol":"XBTUSD","id":8798367100,"side":"Buy","size":6600}]}
09:57:35   {"table":"orderBookL2","action":"insert","data":[{"symbol":"XBTZ17","id":22899831735,"side":"Sell","size":5000,"price":16826.5},{"symbol":"XBTZ17","id":22899831985,"side":"Sell","size":5000,"price":16801.5},{"symbol":"XBTZ17","id":22899832480,"side":"Sell","size":5000,"price":16752},{"symbol":"XBTZ17","id":22899832730,"side":"Sell","size":5000,"price":16727},{"symbol":"XBTZ17","id":22899832975,"side":"Sell","size":5000,"price":16702.5},{"symbol":"XBTZ17","id":22899833225,"side":"Sell","size":5000,"price":16677.5},{"symbol":"XBTZ17","id":22899833470,"side":"Sell","size":5000,"price":16653},{"symbol":"XBTZ17","id":22899836580,"side":"Buy","size":5000,"price":16342},{"symbol":"XBTZ17","id":22899836825,"side":"Buy","size":5000,"price":16317.5},{"symbol":"XBTZ17","id":22899837070,"side":"Buy","size":5000,"price":16293},{"symbol":"XBTZ17","id":22899837320,"side":"Buy","size":5000,"price":16268},{"symbol":"XBTZ17","id":22899837565,"side":"Buy","size":5000,"price":16243.5},{"symbol":"XBTZ17","id":22899837810,"side":"Buy","size":5000,"price":16219},{"symbol":"XBTZ17","id":22899838060,"side":"Buy","size":5000,"price":16194},{"symbol":"XBTZ17","id":22899838305,"side":"Buy","size":5000,"price":16169.5}]}
09:57:35   {"table":"orderBookL2","action":"insert","data":[{"symbol":"XBTUSD","id":8798425650,"side":"Buy","size":403,"price":15743.5}]}
09:57:35   {"table":"orderBookL2","action":"insert","data":[{"symbol":"XBTZ17","id":22899834565,"side":"Buy","size":3000,"price":16543.5}]}
09:57:35   {"table":"orderBookL2","action":"update","data":[{"symbol":"XBTUSD","id":8798373500,"side":"Buy","size":5400}]}
09:57:35   {"table":"orderBookL2","action":"update","data":[{"symbol":"XBTUSD","id":8798366950,"side":"Buy","size":326043}]}
09:57:35   {"table":"orderBookL2","action":"insert","data":[{"symbol":"XBTZ17","id":22899834620,"side":"Buy","size":50000,"price":16538}]}
09:57:35   {"table":"orderBookL2","action":"update","data":[{"symbol":"XBTZ17","id":22899835440,"side":"Buy","size":54580}]}
09:57:35   {"table":"orderBookL2","action":"insert","data":[{"symbol":"XBTUSD","id":8798360900,"side":"Buy","size":189,"price":16391}]}
09:57:35   {"table":"orderBookL2","action":"update","data":[{"symbol":"XBTUSD","id":8798359950,"side":"Sell","size":196707}]}
09:57:35   {"table":"orderBookL2","action":"insert","data":[{"symbol":"XBTZ17","id":22899833290,"side":"Sell","size":14000,"price":16671}]}
09:57:35   {"table":"orderBookL2","action":"insert","data":[{"symbol":"XBTZ17","id":22899839445,"side":"Buy","size":153,"price":16055.5}]}
09:57:35   {"table":"orderBookL2","action":"delete","data":[{"symbol":"XBTUSD","id":8798360900,"side":"Buy"},{"symbol":"XBTUSD","id":8798360950,"side":"Buy"},{"symbol":"XBTUSD","id":8798361850,"side":"Buy"},{"symbol":"XBTUSD","id":8798361950,"side":"Buy"}]}
09:57:35   {"table":"orderBookL2","action":"update","data":[{"symbol":"XBTUSD","id":8798362300,"side":"Buy","size":258715}]}
09:57:35   {"table":"orderBookL2","action":"delete","data":[{"symbol":"XBTZ17","id":22899833835,"side":"Sell"},{"symbol":"XBTZ17","id":22899836000,"side":"Buy"}]}
09:57:35   {"table":"orderBookL2","action":"insert","data":[{"symbol":"XBTZ17","id":22899833870,"side":"Sell","size":2896,"price":16613},{"symbol":"XBTZ17","id":22899835510,"side":"Buy","size":3428,"price":16449}]}
09:57:35   {"table":"orderBookL2","action":"update","data":[{"symbol":"XBTUSD","id":8798360500,"side":"Sell","size":2687}]}
09:57:35   {"table":"orderBookL2","action":"update","data":[{"symbol":"XBTUSD","id":8798373500,"side":"Buy","size":5150}]}
09:57:35   {"table":"orderBookL2","action":"delete","data":[{"symbol":"XBTZ17","id":22899832630,"side":"Sell"}]}
09:57:35   {"table":"orderBookL2","action":"delete","data":[{"symbol":"XBTZ17","id":22899832075,"side":"Sell"},{"symbol":"XBTZ17","id":22899834340,"side":"Buy"}]}
09:57:35   {"table":"orderBookL2","action":"delete","data":[{"symbol":"XBTUSD","id":8798321100,"side":"Sell"},{"symbol":"XBTUSD","id":8798345700,"side":"Sell"},{"symbol":"XBTUSD","id":8798351500,"side":"Sell"}]}
09:57:35   {"table":"orderBookL2","action":"update","data":[{"symbol":"XBTUSD","id":8798339400,"side":"Sell","size":11867},{"symbol":"XBTUSD","id":8798340000,"side":"Sell","size":415220},{"symbol":"XBTUSD","id":8798346300,"side":"Sell","size":14767},{"symbol":"XBTUSD","id":8798352000,"side":"Sell","size":4398},{"symbol":"XBTUSD","id":8798356300,"side":"Sell","size":1100}]}
09:57:35   {"table":"orderBookL2","action":"delete","data":[{"symbol":"XBTZ17","id":22899834870,"side":"Buy"}]}
09:57:35   {"table":"orderBookL2","action":"insert","data":[{"symbol":"XBTZ17","id":22899835060,"side":"Buy","size":6609,"price":16494}]}
09:57:35   {"table":"orderBookL2","action":"insert","data":[{"symbol":"XBTUSD","id":8798321700,"side":"Sell","size":1320,"price":16783},{"symbol":"XBTUSD","id":8798356900,"side":"Sell","size":165,"price":16431}]}
09:57:35   {"table":"orderBookL2","action":"delete","data":[{"symbol":"XBTUSD","id":8798254600,"side":"Sell"}]}
09:57:35   {"table":"orderBookL2","action":"delete","data":[{"symbol":"XBTZ17","id":22899839120,"side":"Buy"}]}
09:57:35   {"table":"orderBookL2","action":"update","data":[{"symbol":"XBTZ17","id":22899834030,"side":"Sell","size":3252}]}
09:57:35   {"table":"orderBookL2","action":"delete","data":[{"symbol":"XBTUSD","id":8798367700,"side":"Buy"}]}
09:57:35   {"table":"orderBookL2","action":"update","data":[{"symbol":"XBTUSD","id":8798364100,"side":"Buy","size":3776},{"symbol":"XBTUSD","id":8798365800,"side":"Buy","size":815},{"symbol":"XBTUSD","id":8798369400,"side":"Buy","size":338}]}
09:57:35   {"table":"orderBookL2","action":"insert","data":[{"symbol":"XBTUSD","id":8798362200,"side":"Buy","size":35,"price":16378}]}
09:57:35   {"table":"orderBookL2","action":"insert","data":[{"symbol":"XBTZ17","id":22899834140,"side":"Sell","size":9572,"price":16586},{"symbol":"XBTZ17","id":22899839345,"side":"Buy","size":9271,"price":16065.5}]}
09:57:35   {"table":"orderBookL2","action":"update","data":[{"symbol":"XBTZ17","id":22899833450,"side":"Sell","size":11800},{"symbol":"XBTZ17","id":22899833500,"side":"Sell","size":7000}]}
09:57:35   {"table":"orderBookL2","action":"delete","data":[{"symbol":"XBTUSD","id":8798362300,"side":"Buy"}]}
09:57:35   {"table":"orderBookL2","action":"update","data":[{"symbol":"XBTUSD","id":8798340000,"side":"Sell","size":73720}]}
09:57:35   {"table":"orderBookL2","action":"update","data":[{"symbol":"XBTUSD","id":8798358150,"side":"Sell","size":24200}]}
09:57:35   {"table":"orderBookL2","action":"update","data":[{"symbol":"XBTZ17","id":22899833505,"side":"Sell","size":134592},{"symbol":"XBTZ17","id":22899833575,"side":"Sell","size":4650}]}
09:57:35   {"table":"orderBookL2","action":"delete","data":[{"symbol":"XBTZ17","id":22899826360,"side":"Sell"},{"symbol":"XBTZ17","id":22899828160,"side":"Sell"},{"symbol":"XBTZ17","id":22899829980,"side":"Sell"},{"symbol":"XBTZ17","id":22899831140,"side":"Sell"},{"symbol":"XBTZ17","id":22899832960,"side":"Sell"},{"symbol":"XBTZ17","id":22899835200,"side":"Buy"},{"symbol":"XBTZ17","id":22899835540,"side":"Buy"},{"symbol":"XBTZ17","id":22899835880,"side":"Buy"},{"symbol":"XBTZ17","id":22899836560,"side":"Buy"},{"symbol":"XBTZ17","id":22899836900,"side":"Buy"}]}
09:57:35   {"table":"orderBookL2","action":"delete","data":[{"symbol":"XBTUSD","id":8798372300,"side":"Buy"}]}
09:57:35   {"table":"orderBookL2","action":"update","data":[{"symbol":"XBTUSD","id":8798372800,"side":"Buy","size":281},{"symbol":"XBTUSD","id":8798373600,"side":"Buy","size":358},{"symbol":"XBTUSD","id":8798374100,"side":"Buy","size":340}]}
09:57:35   {"table":"orderBookL2","action":"update","data":[{"symbol":"XBTZ17","id":22899834570,"side":"Buy","size":158},{"symbol":"XBTZ17","id":22899834910,"side":"Buy","size":7243},{"symbol":"XBTZ17","id":22899836220,"side":"Buy","size":117}]}
09:57:35   {"table":"orderBookL2","action":"update","data":[{"symbol":"XBTUSD","id":8798357800,"side":"Sell","size":85392}]}
09:57:35   {"table":"orderBookL2","action":"delete","data":[{"symbol":"XBTUSD","id":8798356300,"side":"Sell"},{"symbol":"XBTUSD","id":8798365850,"side":"Buy"}]}
09:57:35   {"table":"orderBookL2","action":"update","data":[{"symbol":"XBTUSD","id":8798352800,"side":"Sell","size":50},{"symbol":"XBTUSD","id":8798357550,"side":"Sell","size":13500},{"symbol":"XBTUSD","id":8798357850,"side":"Sell","size":200},{"symbol":"XBTUSD","id":8798364650,"side":"Buy","size":2301}]}
09:57:35   {"table":"orderBookL2","action":"insert","data":[{"symbol":"XBTZ17","id":22899825020,"side":"Sell","size":405,"price":17498},{"symbol":"XBTZ17","id":22899826840,"side":"Sell","size":334,"price":17316},{"symbol":"XBTZ17","id":22899828660,"side":"Sell","size":264,"price":17134},{"symbol":"XBTZ17","id":22899830480,"side":"Sell","size":193,"price":16952},{"symbol":"XBTZ17","id":22899832310,"side":"Sell","size":123,"price":16769},{"symbol":"XBTZ17","id":22899835250,"side":"Buy","size":264,"price":16475},{"symbol":"XBTZ17","id":22899835590,"side":"Buy","size":334,"price":16441},{"symbol":"XBTZ17","id":22899835930,"side":"Buy","size":405,"price":16407},{"symbol":"XBTZ17","id":22899836270,"side":"Buy","size":475,"price":16373}]}
09:57:35   {"table":"orderBookL2","action":"delete","data":[{"symbol":"XBTZ17","id":22899828820,"side":"Sell"},{"symbol":"XBTZ17","id":22899830880,"side":"Sell"},{"symbol":"XBTZ17","id":22899832950,"side":"Sell"},{"symbol":"XBTZ17","id":22899835520,"side":"Buy"},{"symbol":"XBTZ17","id":22899836280,"side":"Buy"},{"symbol":"XBTZ17","id":22899836670,"side":"Buy"},{"symbol":"XBTZ17","id":22899837060,"side":"Buy"}]}
09:57:35   {"table":"orderBookL2","action":"insert","data":[{"symbol":"XBTUSD","id":8798358400,"side":"Sell","size":1100,"price":16416},{"symbol":"XBTUSD","id":8798359500,"side":"Sell","size":1100,"price":16405},{"symbol":"XBTUSD","id":8798365400,"side":"Buy","size":5359,"price":16346},{"symbol":"XBTUSD","id":8798369900,"side":"Buy","size":5359,"price":16301}]}
09:57:35   {"table":"orderBookL2","action":"update","data":[{"symbol":"XBTUSD","id":8798360000,"side":"Sell","size":2067947}]}
09:57:35   {"table":"orderBookL2","action":"update","data":[{"symbol":"XBTZ17","id":22899829800,"side":"Sell","size":150073},{"symbol":"XBTZ17","id":22899834860,"side":"Buy","size":25168},{"symbol":"XBTZ17","id":22899835900,"side":"Buy","size":201},{"symbol":"XBTZ17","id":22899837440,"side":"Buy","size":246500}]}
09:57:35   {"table":"orderBookL2","action":"insert","data":[{"symbol":"XBTZ17","id":22899827720,"side":"Sell","size":100,"price":17228},{"symbol":"XBTZ17","id":22899831880,"side":"Sell","size":46,"price":16812},{"symbol":"XBTZ17","id":22899834460,"side":"Buy","size":46,"price":16554},{"symbol":"XBTZ17","id":22899835240,"side":"Buy","size":100,"price":16476},{"symbol":"XBTZ17","id":22899835630,"side":"Buy","size":126,"price":16437},{"symbol":"XBTZ17","id":22899836020,"side":"Buy","size":153,"price":16398},{"symbol":"XBTZ17","id":22899836400,"side":"Buy","size":180,"price":16360}]}
09:57:35   {"table":"orderBookL2","action":"delete","data":[{"symbol":"XBTUSD","id":8798383800,"side":"Buy"}]}
09:57:35   {"table":"orderBookL2","action":"update","data":[{"symbol":"XBTUSD","id":8798364850,"side":"Buy","size":26776}]}
09:57:35   {"table":"orderBookL2","action":"delete","data":[{"symbol":"XBTUSD","id":8798365100,"side":"Buy"}]}
09:57:35   {"table":"orderBookL2","action":"update","data":[{"symbol":"XBTZ17","id":22899834820,"side":"Buy","size":46000}]}
09:57:35   {"table":"orderBookL2","action":"insert","data":[{"symbol":"XBTZ17","id":22899834875,"side":"Buy","size":6461,"price":16512.5}]}
09:57:35   {"table":"orderBookL2","action":"delete","data":[{"symbol":"XBTUSD","id":8798308750,"side":"Sell"}]}
09:57:35   {"table":"orderBookL2","action":"insert","data":[{"symbol":"XBTUSD","id":8798309350,"side":"Sell","size":40,"price":16906.5}]}
09:57:35   {"table":"orderBookL2","action":"delete","data":[{"symbol":"XBTZ17","id":22899833030,"side":"Sell"}]}
09:57:35   {"table":"orderBookL2","action":"update","data":[{"symbol":"XBTZ17","id":22899833450,"side":"Sell","size":4800}]}
09:57:35   {"table":"orderBookL2","action":"update","data":[{"symbol":"XBTUSD","id":8798359950,"side":"Sell","size":256809}]}
09:57:35   {"table":"orderBookL2","action":"update","data":[{"symbol":"XBTUSD","id":8798359950,"side":"Sell","size":258409}]}
09:57:35   {"table":"orderBookL2","action":"insert","data":[{"symbol":"XBTZ17","id":22899833125,"side":"Sell","size":7000,"price":16687.5},{"symbol":"XBTZ17","id":22899833490,"side":"Sell","size":7000,"price":16651}]}
09:57:35   {"table":"orderBookL2","action":"update","data":[{"symbol":"XBTZ17","id":22899834140,"side":"Sell","size":15825}]}
09:57:35   {"table":"orderBookL2","action":"delete","data":[{"symbol":"XBTUSD","id":8798357350,"side":"Sell"}]}
09:57:35   {"table":"orderBookL2","action":"delete","data":[{"symbol":"XBTUSD","id":8798365700,"side":"Buy"}]}
09:57:35   {"table":"orderBookL2","action":"delete","data":[{"symbol":"XBTZ17","id":22899835060,"side":"Buy"}]}
09:57:35   {"table":"orderBookL2","action":"insert","data":[{"symbol":"XBTZ17","id":22899835295,"side":"Buy","size":6609,"price":16470.5}]}
09:57:35   {"table":"orderBookL2","action":"update","data":[{"symbol":"XBTUSD","id":8798359950,"side":"Sell","size":261609}]}
09:57:35   {"table":"orderBookL2","action":"update","data":[{"symbol":"XBTUSD","id":8798600000,"side":"Buy","size":461895}]}
09:57:35   {"table":"orderBookL2","action":"insert","data":[{"symbol":"XBTUSD","id":8798501100,"side":"Buy","size":80000,"price":14989}]}
09:57:35   {"table":"orderBookL2","action":"delete","data":[{"symbol":"XBTZ17","id":22899834010,"side":"Sell"}]}
09:57:35   {"table":"orderBookL2","action":"update","data":[{"symbol":"XBTZ17","id":22899834140,"side":"Sell","size":45825}]}
09:57:35   {"table":"orderBookL2","action":"delete","data":[{"symbol":"XBTUSD","id":8798340400,"side":"Sell"},{"symbol":"XBTUSD","id":8798408200,"side":"Buy"}]}
09:57:35   {"table":"orderBookL2","action":"update","data":[{"symbol":"XBTUSD","id":8798343150,"side":"Sell","size":336650},{"symbol":"XBTUSD","id":8798412050,"side":"Buy","size":442}]}
09:57:35   {"table":"orderBookL2","action":"update","data":[{"symbol":"XBTUSD","id":8798359950,"side":"Sell","size":361609}]}
09:57:35   {"table":"orderBookL2","action":"delete","data":[{"symbol":"XBTUSD","id":8798359550,"side":"Sell"}]}
09:57:35   {"table":"orderBookL2","action":"insert","data":[{"symbol":"XBTZ17","id":22899834335,"side":"Buy","size":12017,"price":16566.5}]}
09:57:35   {"table":"orderBookL2","action":"insert","data":[{"symbol":"XBTZ17","id":22899833590,"side":"Sell","size":1000,"price":16641}]}
09:57:35   {"table":"orderBookL2","action":"delete","data":[{"symbol":"XBTZ17","id":22899834030,"side":"Sell"}]}
09:57:35   {"table":"orderBookL2","action":"insert","data":[{"symbol":"XBTZ17","id":22899834035,"side":"Sell","size":3252,"price":16596.5}]}
09:57:35   {"table":"orderBookL2","action":"update","data":[{"symbol":"XBTUSD","id":8798359950,"side":"Sell","size":371609}]}
09:57:35   {"table":"orderBookL2","action":"delete","data":[{"symbol":"XBTUSD","id":8798364550,"side":"Buy"}]}
09:57:36   {"table":"orderBookL2","action":"insert","data":[{"symbol":"XBTUSD","id":8798364600,"side":"Buy","size":3776,"price":16354}]}
09:57:35   {"table":"orderBookL2","action":"update","data":[{"symbol":"XBTZ17","id":22899831300,"side":"Sell","size":183}]}
09:57:36   {"table":"orderBookL2","action":"delete","data":[{"symbol":"XBTZ17","id":22899833500,"side":"Sell"},{"symbol":"XBTZ17","id":22899833530,"side":"Sell"}]}
09:57:36   {"table":"orderBookL2","action":"insert","data":[{"symbol":"XBTZ17","id":22899833625,"side":"Sell","size":7000,"price":16637.5},{"symbol":"XBTZ17","id":22899833660,"side":"Sell","size":7000,"price":16634}]}
09:57:36   {"table":"orderBookL2","action":"update","data":[{"symbol":"XBTZ17","id":22899834860,"side":"Buy","size":73}]}
09:57:36   {"table":"orderBookL2","action":"insert","data":[{"symbol":"XBTZ17","id":22899835185,"side":"Buy","size":25095,"price":16481.5}]}
09:57:36   {"table":"orderBookL2","action":"delete","data":[{"symbol":"XBTUSD","id":8798360500,"side":"Sell"}]}
09:57:36   {"table":"orderBookL2","action":"update","data":[{"symbol":"XBTUSD","id":8798360000,"side":"Sell","size":2064224}]}
09:57:36   {"table":"orderBookL2","action":"delete","data":[{"symbol":"XBTUSD","id":8798373450,"side":"Buy"},{"symbol":"XBTUSD","id":8798409350,"side":"Buy"}]}
09:57:36   {"table":"orderBookL2","action":"update","data":[{"symbol":"XBTUSD","id":8798345850,"side":"Sell","size":500},{"symbol":"XBTUSD","id":8798346500,"side":"Sell","size":6802}]}
09:57:36   {"table":"orderBookL2","action":"insert","data":[{"symbol":"XBTUSD","id":8798372550,"side":"Buy","size":6780,"price":16274.5},{"symbol":"XBTUSD","id":8798410900,"side":"Buy","size":40,"price":15891}]}
09:57:36   {"table":"orderBookL2","action":"insert","data":[{"symbol":"XBTZ17","id":22899833000,"side":"Sell","size":116,"price":16700}]}
09:57:36   {"table":"orderBookL2","action":"delete","data":[{"symbol":"XBTZ17","id":22899833340,"side":"Sell"},{"symbol":"XBTZ17","id":22899833560,"side":"Sell"}]}
09:57:36   {"table":"orderBookL2","action":"update","data":[{"symbol":"XBTZ17","id":22899833310,"side":"Sell","size":6890},{"symbol":"XBTZ17","id":22899833470,"side":"Sell","size":12000}]}
09:57:36   {"table":"orderBookL2","action":"insert","data":[{"symbol":"XBTZ17","id":22899833435,"side":"Sell","size":7000,"price":16656.5},{"symbol":"XBTZ17","id":22899833585,"side":"Sell","size":5059,"price":16641.5}]}
09:57:36   {"table":"orderBookL2","action":"delete","data":[{"symbol":"XBTZ17","id":22899833240,"side":"Sell"},{"symbol":"XBTZ17","id":22899833480,"side":"Sell"},{"symbol":"XBTZ17","id":22899834865,"side":"Buy"},{"symbol":"XBTZ17","id":22899834985,"side":"Buy"}]}
09:57:36   {"table":"orderBookL2","action":"insert","data":[{"symbol":"XBTUSD","id":8798360100,"side":"Buy","size":500,"price":16399}]}
09:57:36   {"table":"orderBookL2","action":"update","data":[{"symbol":"XBTUSD","id":8798353600,"side":"Sell","size":11239},{"symbol":"XBTUSD","id":8798366900,"side":"Buy","size":13397},{"symbol":"XBTUSD","id":8798367000,"side":"Buy","size":17988}]}
09:57:36   {"table":"orderBookL2","action":"delete","data":[{"symbol":"XBTUSD","id":8798359700,"side":"Sell"}]}
09:57:36   {"table":"orderBookL2","action":"update","data":[{"symbol":"XBTUSD","id":8798359950,"side":"Sell","size":381609}]}
09:57:36   {"table":"orderBookL2","action":"insert","data":[{"symbol":"XBTZ17","id":22899833300,"side":"Sell","size":6890,"price":16670},{"symbol":"XBTZ17","id":22899833455,"side":"Sell","size":6850,"price":16654.5},{"symbol":"XBTZ17","id":22899835095,"side":"Buy","size":630,"price":16490.5},{"symbol":"XBTZ17","id":22899835220,"side":"Buy","size":1570,"price":16478}]}
09:57:36   {"table":"orderBookL2","action":"delete","data":[{"symbol":"XBTZ17","id":22899833855,"side":"Sell"},{"symbol":"XBTZ17","id":22899833885,"side":"Sell"}]}
09:57:36   {"table":"orderBookL2","action":"delete","data":[{"symbol":"XBTUSD","id":8798319550,"side":"Sell"},{"symbol":"XBTUSD","id":8798324550,"side":"Sell"},{"symbol":"XBTUSD","id":8798337850,"side":"Sell"},{"symbol":"XBTUSD","id":8798347850,"side":"Sell"},{"symbol":"XBTUSD","id":8798367500,"side":"Buy"},{"symbol":"XBTUSD","id":8798372500,"side":"Buy"},{"symbol":"XBTUSD","id":8798382500,"side":"Buy"},{"symbol":"XBTUSD","id":8798542750,"side":"Buy"}]}
09:57:36   {"table":"orderBookL2","action":"update","data":[{"symbol":"XBTUSD","id":8798149000,"side":"Sell","size":5000},{"symbol":"XBTUSD","id":8798150100,"side":"Sell","size":2775},{"symbol":"XBTUSD","id":8798154000,"side":"Sell","size":50},{"symbol":"XBTUSD","id":8798155100,"side":"Sell","size":350},{"symbol":"XBTUSD","id":8798159000,"side":"Sell","size":5192},{"symbol":"XBTUSD","id":8798160100,"side":"Sell","size":95275},{"symbol":"XBTUSD","id":8798164000,"side":"Sell","size":12298},{"symbol":"XBTUSD","id":8798180100,"side":"Sell","size":275},{"symbol":"XBTUSD","id":8798183500,"side":"Sell","size":92},{"symbol":"XBTUSD","id":8798200100,"side":"Sell","size":2275},{"symbol":"XBTUSD","id":8798203500,"side":"Sell","size":2500},{"symbol":"XBTUSD","id":8798220100,"side":"Sell","size":300},{"symbol":"XBTUSD","id":8798223500,"side":"Sell","size":50},{"symbol":"XBTUSD","id":8798240100,"side":"Sell","size":300},{"symbol":"XBTUSD","id":8798242600,"side":"Sell","size":125},{"symbol":"XBTUSD","id":8798260100,"side":"Sell","size":300},{"symbol":"XBTUSD","id":8798262600,"side":"Sell","size":13745},{"symbol":"XBTUSD","id":8798280100,"side":"Sell","size":3688},{"symbol":"XBTUSD","id":8798282100,"side":"Sell","size":600},{"symbol":"XBTUSD","id":8798300100,"side":"Sell","size":275},{"symbol":"XBTUSD","id":8798302000,"side":"Sell","size":30372},{"symbol":"XBTUSD","id":8798310000,"side":"Sell","size":122610},{"symbol":"XBTUSD","id":8798311900,"side":"Sell","size":603},{"symbol":"XBTUSD","id":8798322300,"side":"Sell","size":50100},{"symbol":"XBTUSD","id":8798329550,"side":"Sell","size":8232},{"symbol":"XBTUSD","id":8798342850,"side":"Sell","size":402},{"symbol":"XBTUSD","id":8798352850,"side":"Sell","size":100},{"symbol":"XBTUSD","id":8798354250,"side":"Sell","size":6600},{"symbol":"XBTUSD","id":8798357850,"side":"Sell","size":100},{"symbol":"XBTUSD","id":8798362500,"side":"Buy","size":943},{"symbol":"XBTUSD","id":8798367600,"side":"Buy","size":2600},{"symbol":"XBTUSD","id":8798377500,"side":"Buy","size":25000},{"symbol":"XBTUSD","id":8798547750,"side":"Buy","size":100},{"symbol":"XBTUSD","id":8798557750,"side":"Buy","size":2150}]}
09:57:36   {"table":"orderBookL2","action":"insert","data":[{"symbol":"XBTZ17","id":22899833755,"side":"Sell","size":8000,"price":16624.5},{"symbol":"XBTZ17","id":22899833785,"side":"Sell","size":8000,"price":16621.5}]}
09:57:36   {"table":"orderBookL2","action":"update","data":[{"symbol":"XBTZ17","id":22899834140,"side":"Sell","size":97825}]}
09:57:36   {"table":"orderBookL2","action":"insert","data":[{"symbol":"XBTUSD","id":8798317300,"side":"Sell","size":100,"price":16827},{"symbol":"XBTUSD","id":8798329250,"side":"Sell","size":100,"price":16707.5},{"symbol":"XBTUSD","id":8798334250,"side":"Sell","size":100,"price":16657.5},{"symbol":"XBTUSD","id":8798339250,"side":"Sell","size":100,"price":16607.5},{"symbol":"XBTUSD","id":8798344250,"side":"Sell","size":100,"price":16557.5},{"symbol":"XBTUSD","id":8798349250,"side":"Sell","size":100,"price":16507.5},{"symbol":"XBTUSD","id":8798359250,"side":"Sell","size":100,"price":16407.5},{"symbol":"XBTUSD","id":8798362600,"side":"Buy","size":100,"price":16374},{"symbol":"XBTUSD","id":8798372600,"side":"Buy","size":100,"price":16274},{"symbol":"XBTUSD","id":8798377600,"side":"Buy","size":100,"price":16224},{"symbol":"XBTUSD","id":8798382600,"side":"Buy","size":100,"price":16174},{"symbol":"XBTUSD","id":8798562750,"side":"Buy","size":100,"price":14372.5}]}
09:57:36   {"table":"orderBookL2","action":"insert","data":[{"symbol":"XBTUSD","id":8798351800,"side":"Sell","size":408,"price":16482}]}
09:57:36   {"table":"orderBookL2","action":"update","data":[{"symbol":"XBTZ17","id":22899834640,"side":"Buy","size":7000}]}
09:57:36   {"table":"orderBookL2","action":"delete","data":[{"symbol":"XBTZ17","id":22899833180,"side":"Sell"},{"symbol":"XBTZ17","id":22899833640,"side":"Sell"}]}
09:57:36   {"table":"orderBookL2","action":"delete","data":[{"symbol":"XBTUSD","id":8798370900,"side":"Buy"}]}
09:57:36   {"table":"orderBookL2","action":"update","data":[{"symbol":"XBTUSD","id":8798368800,"side":"Buy","size":3558}]}
09:57:36   {"table":"orderBookL2","action":"insert","data":[{"symbol":"XBTZ17","id":22899833270,"side":"Sell","size":7000,"price":16673},{"symbol":"XBTZ17","id":22899833670,"side":"Sell","size":7000,"price":16633}]}
09:57:36   {"table":"orderBookL2","action":"update","data":[{"symbol":"XBTUSD","id":8798359950,"side":"Sell","size":298923},{"symbol":"XBTUSD","id":8798360000,"side":"Sell","size":2153206}]}
09:57:36   {"table":"orderBookL2","action":"update","data":[{"symbol":"XBTUSD","id":8798359950,"side":"Sell","size":318923}]}
09:57:36   {"table":"orderBookL2","action":"delete","data":[{"symbol":"XBTZ17","id":22899834640,"side":"Buy"}]}
09:57:36   {"table":"orderBookL2","action":"update","data":[{"symbol":"XBTZ17","id":22899834035,"side":"Sell","size":10252}]}
09:57:36   {"table":"orderBookL2","action":"delete","data":[{"symbol":"XBTUSD","id":8798368650,"side":"Buy"},{"symbol":"XBTUSD","id":8798369100,"side":"Buy"},{"symbol":"XBTUSD","id":8798374450,"side":"Buy"}]}
09:57:36   {"table":"orderBookL2","action":"delete","data":[{"symbol":"XBTZ17","id":22899833210,"side":"Sell"},{"symbol":"XBTZ17","id":22899834745,"side":"Buy"}]}
09:57:36   {"table":"orderBookL2","action":"insert","data":[{"symbol":"XBTZ17","id":22899833340,"side":"Sell","size":7000,"price":16666},{"symbol":"XBTZ17","id":22899834870,"side":"Buy","size":7050,"price":16513}]}
09:57:36   {"table":"orderBookL2","action":"update","data":[{"symbol":"XBTZ17","id":22899834140,"side":"Sell","size":96625}]}
09:57:36   {"table":"orderBookL2","action":"update","data":[{"symbol":"XBTUSD","id":8798368150,"side":"Buy","size":18450},{"symbol":"XBTUSD","id":8798370000,"side":"Buy","size":101383},{"symbol":"XBTUSD","id":8798372950,"side":"Buy","size":7043}]}
09:57:36   {"table":"orderBookL2","action":"insert","data":[{"symbol":"XBTUSD","id":8798368050,"side":"Buy","size":7000,"price":16319.5},{"symbol":"XBTUSD","id":8798368400,"side":"Buy","size":7000,"price":16316}]}
09:57:36   {"table":"orderBookL2","action":"insert","data":[{"symbol":"XBTUSD","id":8798362250,"side":"Buy","size":655,"price":16377.5}]}
09:57:36   {"table":"orderBookL2","action":"update","data":[{"symbol":"XBTUSD","id":8798362250,"side":"Buy","size":20655}]}
09:57:36   {"table":"orderBookL2","action":"delete","data":[{"symbol":"XBTZ17","id":22899834785,"side":"Buy"}]}
09:57:36   {"table":"orderBookL2","action":"insert","data":[{"symbol":"XBTZ17","id":22899834660,"side":"Buy","size":8000,"price":16534}]}
09:57:36   {"table":"orderBookL2","action":"update","data":[{"symbol":"XBTUSD","id":8798357550,"side":"Sell","size":11800}]}
09:57:36   {"table":"orderBookL2","action":"update","data":[{"symbol":"XBTUSD","id":8798336000,"side":"Sell","size":2500}]}
09:57:36   {"table":"orderBookL2","action":"insert","data":[{"symbol":"XBTZ17","id":22899833430,"side":"Sell","size":2700,"price":16657}]}
09:57:36   {"table":"orderBookL2","action":"insert","data":[{"symbol":"XBTZ17","id":22899833405,"side":"Sell","size":2700,"price":16659.5}]}
09:57:36   {"table":"orderBookL2","action":"insert","data":[{"symbol":"XBTUSD","id":8798361950,"side":"Buy","size":3000,"price":16380.5}]}
09:57:36   {"table":"orderBookL2","action":"delete","data":[{"symbol":"XBTUSD","id":8798350350,"side":"Sell"},{"symbol":"XBTUSD","id":8798356950,"side":"Sell"}]}
09:57:36   {"table":"orderBookL2","action":"delete","data":[{"symbol":"XBTZ17","id":22899833700,"side":"Sell"}]}
09:57:36   {"table":"orderBookL2","action":"update","data":[{"symbol":"XBTZ17","id":22899833755,"side":"Sell","size":8060}]}
09:57:36   {"table":"orderBookL2","action":"update","data":[{"symbol":"XBTUSD","id":8798348750,"side":"Sell","size":64200},{"symbol":"XBTUSD","id":8798352050,"side":"Sell","size":2500},{"symbol":"XBTUSD","id":8798352850,"side":"Sell","size":304},{"symbol":"XBTUSD","id":8798354050,"side":"Sell","size":1202},{"symbol":"XBTUSD","id":8798354800,"side":"Sell","size":20000},{"symbol":"XBTUSD","id":8798355900,"side":"Sell","size":700},{"symbol":"XBTUSD","id":8798358050,"side":"Sell","size":50},{"symbol":"XBTUSD","id":8798364450,"side":"Buy","size":10000}]}
09:57:36   {"table":"orderBookL2","action":"insert","data":[{"symbol":"XBTUSD","id":8798345750,"side":"Sell","size":600,"price":16542.5},{"symbol":"XBTUSD","id":8798347350,"side":"Sell","size":464,"price":16526.5},{"symbol":"XBTUSD","id":8798348950,"side":"Sell","size":300,"price":16510.5},{"symbol":"XBTUSD","id":8798350750,"side":"Sell","size":816,"price":16492.5},{"symbol":"XBTUSD","id":8798355050,"side":"Sell","size":51,"price":16449.5},{"symbol":"XBTUSD","id":8798361500,"side":"Buy","size":1083,"price":16385}]}
09:57:36   {"table":"orderBookL2","action":"delete","data":[{"symbol":"XBTZ17","id":22899834125,"side":"Sell"}]}
09:57:36   {"table":"orderBookL2","action":"delete","data":[{"symbol":"XBTZ17","id":22899840955,"side":"Buy"}]}
09:57:36   {"table":"orderBookL2","action":"update","data":[{"symbol":"XBTUSD","id":8798363900,"side":"Buy","size":340278}]}
09:57:36   {"table":"orderBookL2","action":"update","data":[{"symbol":"XBTUSD","id":8798359950,"side":"Sell","size":318933}]}
09:57:36   {"table":"orderBookL2","action":"update","data":[{"symbol":"XBTUSD","id":8798359950,"side":"Sell","size":318923}]}
09:57:36   {"table":"orderBookL2","action":"delete","data":[{"symbol":"XBTZ17","id":22899833575,"side":"Sell"}]}
09:57:36   {"table":"orderBookL2","action":"delete","data":[{"symbol":"XBTZ17","id":22899834980,"side":"Buy"}]}
09:57:36   {"table":"orderBookL2","action":"update","data":[{"symbol":"XBTZ17","id":22899834570,"side":"Buy","size":123}]}
09:57:36   {"table":"orderBookL2","action":"insert","data":[{"symbol":"XBTZ17","id":22899834730,"side":"Buy","size":35,"price":16527},{"symbol":"XBTZ17","id":22899835140,"side":"Buy","size":56,"price":16486}]}
09:57:36   {"table":"orderBookL2","action":"delete","data":[{"symbol":"XBTZ17","id":22899831735,"side":"Sell"},{"symbol":"XBTZ17","id":22899831985,"side":"Sell"},{"symbol":"XBTZ17","id":22899832480,"side":"Sell"},{"symbol":"XBTZ17","id":22899832730,"side":"Sell"},{"symbol":"XBTZ17","id":22899832975,"side":"Sell"},{"symbol":"XBTZ17","id":22899833225,"side":"Sell"},{"symbol":"XBTZ17","id":22899836580,"side":"Buy"},{"symbol":"XBTZ17","id":22899836825,"side":"Buy"},{"symbol":"XBTZ17","id":22899837070,"side":"Buy"},{"symbol":"XBTZ17","id":22899837320,"side":"Buy"},{"symbol":"XBTZ17","id":22899837565,"side":"Buy"},{"symbol":"XBTZ17","id":22899837810,"side":"Buy"},{"symbol":"XBTZ17","id":22899838060,"side":"Buy"},{"symbol":"XBTZ17","id":22899838305,"side":"Buy"}]}
09:57:36   {"table":"orderBookL2","action":"update","data":[{"symbol":"XBTZ17","id":22899832230,"side":"Sell","size":47100},{"symbol":"XBTZ17","id":22899833405,"side":"Sell","size":7700},{"symbol":"XBTZ17","id":22899833470,"side":"Sell","size":7000}]}
09:57:36   {"table":"orderBookL2","action":"insert","data":[{"symbol":"XBTZ17","id":22899831670,"side":"Sell","size":5000,"price":16833},{"symbol":"XBTZ17","id":22899831915,"side":"Sell","size":5000,"price":16808.5},{"symbol":"XBTZ17","id":22899832165,"side":"Sell","size":5000,"price":16783.5},{"symbol":"XBTZ17","id":22899832415,"side":"Sell","size":5000,"price":16758.5},{"symbol":"XBTZ17","id":22899832660,"side":"Sell","size":5000,"price":16734},{"symbol":"XBTZ17","id":22899832910,"side":"Sell","size":5000,"price":16709},{"symbol":"XBTZ17","id":22899833160,"side":"Sell","size":5000,"price":16684},{"symbol":"XBTZ17","id":22899836495,"side":"Buy","size":5000,"price":16350.5},{"symbol":"XBTZ17","id":22899836740,"side":"Buy","size":5000,"price":16326},{"symbol":"XBTZ17","id":22899836990,"side":"Buy","size":5000,"price":16301},{"symbol":"XBTZ17","id":22899837235,"side":"Buy","size":5000,"price":16276.5},{"symbol":"XBTZ17","id":22899837480,"side":"Buy","size":5000,"price":16252},{"symbol":"XBTZ17","id":22899837730,"side":"Buy","size":5000,"price":16227},{"symbol":"XBTZ17","id":22899837975,"side":"Buy","size":5000,"price":16202.5},{"symbol":"XBTZ17","id":22899838220,"side":"Buy","size":5000,"price":16178}]}
09:57:36   {"table":"orderBookL2","action":"delete","data":[{"symbol":"XBTUSD","id":8798363500,"side":"Buy"}]}
09:57:36   {"table":"orderBookL2","action":"update","data":[{"symbol":"XBTZ17","id":22899834140,"side":"Sell","size":96025}]}
09:57:36   {"table":"orderBookL2","action":"insert","data":[{"symbol":"XBTZ17","id":22899834880,"side":"Buy","size":5761,"price":16512}]}
09:57:36   {"table":"orderBookL2","action":"update","data":[{"symbol":"XBTZ17","id":22899835110,"side":"Buy","size":116}]}
09:57:36   {"table":"orderBookL2","action":"update","data":[{"symbol":"XBTUSD","id":8798364650,"side":"Buy","size":6077}]}
09:57:36   {"table":"orderBookL2","action":"insert","data":[{"symbol":"XBTUSD","id":8798362300,"side":"Buy","size":6000,"price":16377}]}
09:57:36   {"table":"orderBookL2","action":"update","data":[{"symbol":"XBTUSD","id":8798359950,"side":"Sell","size":320923}]}
09:57:36   {"table":"orderBookL2","action":"update","data":[{"symbol":"XBTUSD","id":8798359950,"side":"Sell","size":316123}]}
09:57:36   {"table":"orderBookL2","action":"update","data":[{"symbol":"XBTZ17","id":22899834335,"side":"Buy","size":15017}]}
09:57:36   {"table":"orderBookL2","action":"delete","data":[{"symbol":"XBTZ17","id":22899834565,"side":"Buy"}]}
09:57:36   {"table":"orderBookL2","action":"delete","data":[{"symbol":"XBTZ17","id":22899834620,"side":"Buy"}]}
09:57:36   {"table":"orderBookL2","action":"update","data":[{"symbol":"XBTUSD","id":8798360000,"side":"Sell","size":2153706}]}
09:57:36   {"table":"orderBookL2","action":"update","data":[{"symbol":"XBTUSD","id":8798359950,"side":"Sell","size":316113}]}
09:57:36   {"table":"orderBookL2","action":"delete","data":[{"symbol":"XBTZ17","id":22899829605,"side":"Sell"},{"symbol":"XBTZ17","id":22899830370,"side":"Sell"},{"symbol":"XBTZ17","id":22899831130,"side":"Sell"},{"symbol":"XBTZ17","id":22899831885,"side":"Sell"},{"symbol":"XBTZ17","id":22899832640,"side":"Sell"},{"symbol":"XBTZ17","id":22899833390,"side":"Sell"},{"symbol":"XBTZ17","id":22899835175,"side":"Buy"},{"symbol":"XBTZ17","id":22899835915,"side":"Buy"},{"symbol":"XBTZ17","id":22899836650,"side":"Buy"},{"symbol":"XBTZ17","id":22899837380,"side":"Buy"},{"symbol":"XBTZ17","id":22899838110,"side":"Buy"},{"symbol":"XBTZ17","id":22899838835,"side":"Buy"}]}
09:57:36   {"table":"orderBookL2","action":"update","data":[{"symbol":"XBTZ17","id":22899834995,"side":"Buy","size":4100}]}
09:57:36   {"table":"orderBookL2","action":"update","data":[{"symbol":"XBTZ17","id":22899834140,"side":"Sell","size":95025}]}
09:57:36   {"table":"orderBookL2","action":"insert","data":[{"symbol":"XBTZ17","id":22899862040,"side":"Buy","size":25000,"price":13796}]}
09:57:36   {"table":"orderBookL2","action":"insert","data":[{"symbol":"XBTZ17","id":22899833350,"side":"Sell","size":6000,"price":16665}]}
09:57:36   {"table":"orderBookL2","action":"delete","data":[{"symbol":"XBTZ17","id":22899839345,"side":"Buy"}]}
09:57:36   {"table":"orderBookL2","action":"insert","data":[{"symbol":"XBTUSD","id":8798361850,"side":"Buy","size":469,"price":16381.5}]}
09:57:36   {"table":"orderBookL2","action":"update","data":[{"symbol":"XBTUSD","id":8798361500,"side":"Buy","size":4083}]}
09:57:36   {"table":"orderBookL2","action":"insert","data":[{"symbol":"XBTUSD","id":8798360550,"side":"Buy","size":10000,"price":16394.5}]}
09:57:36   {"table":"orderBookL2","action":"delete","data":[{"symbol":"XBTUSD","id":8798362700,"side":"Buy"}]}
09:57:36   {"table":"orderBookL2","action":"update","data":[{"symbol":"XBTUSD","id":8798372800,"side":"Buy","size":1215},{"symbol":"XBTUSD","id":8798389100,"side":"Buy","size":50934}]}
09:57:36   {"table":"orderBookL2","action":"update","data":[{"symbol":"XBTZ17","id":22899834140,"side":"Sell","size":88253}]}
09:57:36   {"table":"orderBookL2","action":"insert","data":[{"symbol":"XBTZ17","id":22899833875,"side":"Sell","size":6762,"price":16612.5},{"symbol":"XBTZ17","id":22899839045,"side":"Buy","size":9264,"price":16095.5}]}
09:57:36   {"table":"orderBookL2","action":"update","data":[{"symbol":"XBTUSD","id":8798359950,"side":"Sell","size":316213}]}
09:57:36   {"table":"orderBookL2","action":"update","data":[{"symbol":"XBTUSD","id":8798860000,"side":"Buy","size":100}]}
09:57:36   {"table":"orderBookL2","action":"insert","data":[{"symbol":"XBTUSD","id":8798862300,"side":"Buy","size":1,"price":11377}]}
09:57:36   {"table":"orderBookL2","action":"update","data":[{"symbol":"XBTZ17","id":22899836420,"side":"Buy","size":166}]}
09:57:36   {"table":"orderBookL2","action":"update","data":[{"symbol":"XBTZ17","id":22899835440,"side":"Buy","size":40580}]}
09:57:36   {"table":"orderBookL2","action":"update","data":[{"symbol":"XBTZ17","id":22899834335,"side":"Buy","size":14017}]}
09:57:36   {"table":"orderBookL2","action":"update","data":[{"symbol":"XBTUSD","id":8798363100,"side":"Buy","size":20290},{"symbol":"XBTUSD","id":8798363300,"side":"Buy","size":10000},{"symbol":"XBTUSD","id":8798363800,"side":"Buy","size":3776},{"symbol":"XBTUSD","id":8798364000,"side":"Buy","size":800},{"symbol":"XBTUSD","id":8798365400,"side":"Buy","size":15409}]}
09:57:36   {"table":"orderBookL2","action":"insert","data":[{"symbol":"XBTUSD","id":8798364350,"side":"Buy","size":10050,"price":16356.5}]}
09:57:37   {"table":"orderBookL2","action":"update","data":[{"symbol":"XBTUSD","id":8798356000,"side":"Sell","size":16000},{"symbol":"XBTUSD","id":8798363900,"side":"Buy","size":340078},{"symbol":"XBTUSD","id":8798363950,"side":"Buy","size":243}]}
09:57:36   {"table":"orderBookL2","action":"delete","data":[{"symbol":"XBTZ17","id":22899832915,"side":"Sell"},{"symbol":"XBTZ17","id":22899833135,"side":"Sell"},{"symbol":"XBTZ17","id":22899833310,"side":"Sell"},{"symbol":"XBTZ17","id":22899833410,"side":"Sell"}]}
09:57:37   {"table":"orderBookL2","action":"update","data":[{"symbol":"XBTZ17","id":22899833000,"side":"Sell","size":6966},{"symbol":"XBTZ17","id":22899833470,"side":"Sell","size":12850}]}
09:57:37   {"table":"orderBookL2","action":"insert","data":[{"symbol":"XBTZ17","id":22899833200,"side":"Sell","size":3570,"price":16680},{"symbol":"XBTZ17","id":22899833375,"side":"Sell","size":6890,"price":16662.5}]}
09:57:37   {"table":"orderBookL2","action":"insert","data":[{"symbol":"XBTUSD","id":8798356050,"side":"Sell","size":200,"price":16439.5}]}
09:57:37   {"table":"orderBookL2","action":"update","data":[{"symbol":"XBTUSD","id":8798355850,"side":"Sell","size":17498},{"symbol":"XBTUSD","id":8798355900,"side":"Sell","size":900},{"symbol":"XBTUSD","id":8798364050,"side":"Buy","size":138},{"symbol":"XBTUSD","id":8798364100,"side":"Buy","size":3976}]}
09:57:37   {"table":"orderBookL2","action":"update","data":[{"symbol":"XBTUSD","id":8798360550,"side":"Buy","size":10010}]}
09:57:37   {"table":"orderBookL2","action":"delete","data":[{"symbol":"XBTZ17","id":22899833290,"side":"Sell"}]}
09:57:37   {"table":"orderBookL2","action":"update","data":[{"symbol":"XBTZ17","id":22899834140,"side":"Sell","size":82000}]}
09:57:37   {"table":"orderBookL2","action":"insert","data":[{"symbol":"XBTZ17","id":22899833580,"side":"Sell","size":2000,"price":16642}]}
09:57:37   {"table":"orderBookL2","action":"update","data":[{"symbol":"XBTUSD","id":8798358150,"side":"Sell","size":34800}]}
09:57:37   {"table":"orderBookL2","action":"update","data":[{"symbol":"XBTUSD","id":8798364850,"side":"Buy","size":23000}]}
09:57:37   {"table":"orderBookL2","action":"insert","data":[{"symbol":"XBTUSD","id":8798366250,"side":"Buy","size":3776,"price":16337.5}]}
09:57:37   {"table":"orderBookL2","action":"update","data":[{"symbol":"XBTUSD","id":8798309900,"side":"Sell","size":75}]}
09:57:37   {"table":"orderBookL2","action":"insert","data":[{"symbol":"XBTZ17","id":22899834615,"side":"Buy","size":417,"price":16538.5}]}
09:57:37   {"table":"orderBookL2","action":"update","data":[{"symbol":"XBTZ17","id":22899834035,"side":"Sell","size":7000}]}
09:57:37   {"table":"orderBookL2","action":"insert","data":[{"symbol":"XBTUSD","id":8798311050,"side":"Sell","size":50,"price":16889.5}]}
09:57:37   {"table":"orderBookL2","action":"insert","data":[{"symbol":"XBTUSD","id":8798361400,"side":"Buy","size":80,"price":16386}]}
09:57:37   {"table":"orderBookL2","action":"delete","data":[{"symbol":"XBTUSD","id":8798360100,"side":"Buy"}]}
09:57:37   {"table":"orderBookL2","action":"insert","data":[{"symbol":"XBTZ17","id":22899834145,"side":"Sell","size":3583,"price":16585.5}]}
09:57:37   {"table":"orderBookL2","action":"delete","data":[{"symbol":"XBTZ17","id":22899833625,"side":"Sell"},{"symbol":"XBTZ17","id":22899833660,"side":"Sell"},{"symbol":"XBTZ17","id":22899833730,"side":"Sell"}]}
09:57:37   {"table":"orderBookL2","action":"update","data":[{"symbol":"XBTZ17","id":22899833520,"side":"Sell","size":17000},{"symbol":"XBTZ17","id":22899833755,"side":"Sell","size":15060}]}
09:57:37   {"table":"orderBookL2","action":"update","data":[{"symbol":"XBTUSD","id":8798360550,"side":"Buy","size":8010}]}
09:57:37   {"table":"orderBookL2","action":"delete","data":[{"symbol":"XBTUSD","id":8798257200,"side":"Sell"}]}
09:57:37   {"table":"orderBookL2","action":"insert","data":[{"symbol":"XBTUSD","id":8798257250,"side":"Sell","size":200,"price":17427.5}]}
09:57:37   {"table":"orderBookL2","action":"update","data":[{"symbol":"XBTUSD","id":8798359950,"side":"Sell","size":316203}]}
09:57:37   {"table":"orderBookL2","action":"insert","data":[{"symbol":"XBTZ17","id":22899833555,"side":"Sell","size":7000,"price":16644.5}]}
09:57:37   {"table":"orderBookL2","action":"delete","data":[{"symbol":"XBTZ17","id":22899833125,"side":"Sell"},{"symbol":"XBTZ17","id":22899833490,"side":"Sell"}]}
09:57:37   {"table":"orderBookL2","action":"update","data":[{"symbol":"XBTZ17","id":22899833375,"side":"Sell","size":13890}]}
09:57:37   {"table":"orderBookL2","action":"insert","data":[{"symbol":"XBTZ17","id":22899832975,"side":"Sell","size":7000,"price":16702.5}]}
09:57:37   {"table":"orderBookL2","action":"update","data":[{"symbol":"XBTZ17","id":22899834335,"side":"Buy","size":3000}]}
09:57:37   {"table":"orderBookL2","action":"update","data":[{"symbol":"XBTUSD","id":8798363900,"side":"Buy","size":330078},{"symbol":"XBTUSD","id":8798364450,"side":"Buy","size":20000},{"symbol":"XBTUSD","id":8798364700,"side":"Buy","size":17992},{"symbol":"XBTUSD","id":8798364850,"side":"Buy","size":3000},{"symbol":"XBTUSD","id":8798364950,"side":"Buy","size":10043},{"symbol":"XBTUSD","id":8798365400,"side":"Buy","size":35409},{"symbol":"XBTUSD","id":8798366000,"side":"Buy","size":264},{"symbol":"XBTUSD","id":8798366250,"side":"Buy","size":13776}]}
09:57:37   {"table":"orderBookL2","action":"delete","data":[{"symbol":"XBTUSD","id":8798353750,"side":"Sell"},{"symbol":"XBTUSD","id":8798363300,"side":"Buy"}]}
09:57:37   {"table":"orderBookL2","action":"update","data":[{"symbol":"XBTUSD","id":8798363100,"side":"Buy","size":10290},{"symbol":"XBTUSD","id":8798366650,"side":"Buy","size":10250}]}
09:57:37   {"table":"orderBookL2","action":"insert","data":[{"symbol":"XBTUSD","id":8798355300,"side":"Sell","size":10000,"price":16447},{"symbol":"XBTUSD","id":8798366050,"side":"Buy","size":10000,"price":16339.5}]}
09:57:37   {"table":"orderBookL2","action":"delete","data":[{"symbol":"XBTUSD","id":8798365250,"side":"Buy"}]}
09:57:37   {"table":"orderBookL2","action":"delete","data":[{"symbol":"XBTZ17","id":22899833435,"side":"Sell"}]}
09:57:37   {"table":"orderBookL2","action":"update","data":[{"symbol":"XBTZ17","id":22899833470,"side":"Sell","size":5850}]}
09:57:37   {"table":"orderBookL2","action":"insert","data":[{"symbol":"XBTZ17","id":22899833330,"side":"Sell","size":7000,"price":16667},{"symbol":"XBTZ17","id":22899833365,"side":"Sell","size":7000,"price":16663.5}]}
09:57:37   {"table":"orderBookL2","action":"insert","data":[{"symbol":"XBTUSD","id":8798366700,"side":"Buy","size":3776,"price":16333}]}
09:57:37   {"table":"orderBookL2","action":"delete","data":[{"symbol":"XBTZ17","id":22899833300,"side":"Sell"},{"symbol":"XBTZ17","id":22899833455,"side":"Sell"},{"symbol":"XBTZ17","id":22899835095,"side":"Buy"},{"symbol":"XBTZ17","id":22899835220,"side":"Buy"}]}
09:57:37   {"table":"orderBookL2","action":"update","data":[{"symbol":"XBTZ17","id":22899833160,"side":"Sell","size":11890},{"symbol":"XBTZ17","id":22899833375,"side":"Sell","size":20740},{"symbol":"XBTZ17","id":22899834875,"side":"Buy","size":7091},{"symbol":"XBTZ17","id":22899834995,"side":"Buy","size":5670}]}
09:57:38   {"table":"orderBookL2","action":"delete","data":[{"symbol":"XBTZ17","id":22899833590,"side":"Sell"}]}
09:57:37   {"table":"orderBookL2","action":"update","data":[{"symbol":"XBTUSD","id":8798360550,"side":"Buy","size":5010}]}
09:57:38   {"table":"orderBookL2","action":"delete","data":[{"symbol":"XBTUSD","id":8798308550,"side":"Sell"}]}
09:57:38   {"table":"orderBookL2","action":"insert","data":[{"symbol":"XBTUSD","id":8798310650,"side":"Sell","size":40,"price":16893.5}]}
09:57:38   {"table":"orderBookL2","action":"delete","data":[{"symbol":"XBTZ17","id":22899833785,"side":"Sell"},{"symbol":"XBTZ17","id":22899833820,"side":"Sell"}]}
09:57:38   {"table":"orderBookL2","action":"update","data":[{"symbol":"XBTZ17","id":22899833755,"side":"Sell","size":7060},{"symbol":"XBTZ17","id":22899833875,"side":"Sell","size":14762}]}
09:57:38   {"table":"orderBookL2","action":"insert","data":[{"symbol":"XBTZ17","id":22899833810,"side":"Sell","size":8000,"price":16619},{"symbol":"XBTZ17","id":22899833840,"side":"Sell","size":8000,"price":16616}]}
09:57:38   {"table":"orderBookL2","action":"update","data":[{"symbol":"XBTZ17","id":22899834140,"side":"Sell","size":30000},{"symbol":"XBTZ17","id":22899834145,"side":"Sell","size":55583}]}
09:57:38   {"table":"orderBookL2","action":"delete","data":[{"symbol":"XBTUSD","id":8798359450,"side":"Sell"}]}
09:57:38   {"table":"orderBookL2","action":"update","data":[{"symbol":"XBTUSD","id":8798359950,"side":"Sell","size":316103}]}
09:57:38   {"table":"orderBookL2","action":"update","data":[{"symbol":"XBTUSD","id":8798359950,"side":"Sell","size":316093}]}
09:57:38   {"table":"orderBookL2","action":"delete","data":[{"symbol":"XBTUSD","id":8798501100,"side":"Buy"}]}
09:57:38   {"table":"orderBookL2","action":"delete","data":[{"symbol":"XBTZ17","id":22899833270,"side":"Sell"},{"symbol":"XBTZ17","id":22899833670,"side":"Sell"}]}
09:57:38   {"table":"orderBookL2","action":"insert","data":[{"symbol":"XBTZ17","id":22899833115,"side":"Sell","size":7000,"price":16688.5},{"symbol":"XBTZ17","id":22899833550,"side":"Sell","size":7000,"price":16645}]}
09:57:38   {"table":"orderBookL2","action":"insert","data":[{"symbol":"XBTUSD","id":8798498600,"side":"Buy","size":80000,"price":15014}]}
09:57:38   {"table":"orderBookL2","action":"delete","data":[{"symbol":"XBTUSD","id":8798370100,"side":"Buy"},{"symbol":"XBTUSD","id":8798370550,"side":"Buy"},{"symbol":"XBTUSD","id":8798371250,"side":"Buy"}]}
09:57:38   {"table":"orderBookL2","action":"update","data":[{"symbol":"XBTUSD","id":8798370250,"side":"Buy","size":50},{"symbol":"XBTUSD","id":8798375300,"side":"Buy","size":10000}]}
09:57:38   {"table":"orderBookL2","action":"delete","data":[{"symbol":"XBTZ17","id":22899834660,"side":"Buy"}]}
09:57:38   {"table":"orderBookL2","action":"insert","data":[{"symbol":"XBTUSD","id":8798365250,"side":"Buy","size":7000,"price":16347.5},{"symbol":"XBTUSD","id":8798366500,"side":"Buy","size":7000,"price":16335},{"symbol":"XBTUSD","id":8798367150,"side":"Buy","size":7000,"price":16328.5},{"symbol":"XBTUSD","id":8798367500,"side":"Buy","size":7000,"price":16325}]}
09:57:38   {"table":"orderBookL2","action":"update","data":[{"symbol":"XBTUSD","id":8798364100,"side":"Buy","size":200}]}
09:57:38   {"table":"orderBookL2","action":"insert","data":[{"symbol":"XBTUSD","id":8798365550,"side":"Buy","size":3776,"price":16344.5}]}
09:57:38   {"table":"orderBookL2","action":"insert","data":[{"symbol":"XBTZ17","id":22899834770,"side":"Buy","size":8000,"price":16523}]}
09:57:38   {"table":"orderBookL2","action":"insert","data":[{"symbol":"XBTZ17","id":22899834500,"side":"Buy","size":3000,"price":16550}]}
09:57:38   {"table":"orderBookL2","action":"update","data":[{"symbol":"XBTUSD","id":8798359400,"side":"Sell","size":20},{"symbol":"XBTUSD","id":8798359950,"side":"Sell","size":316245}]}
09:57:38   {"table":"orderBookL2","action":"update","data":[{"symbol":"XBTUSD","id":8798360550,"side":"Buy","size":3510}]}
09:57:38   {"table":"orderBookL2","action":"update","data":[{"symbol":"XBTZ17","id":22899834995,"side":"Buy","size":1570}]}
09:57:38   {"table":"orderBookL2","action":"insert","data":[{"symbol":"XBTZ17","id":22899835195,"side":"Buy","size":8000,"price":16480.5}]}
09:57:38   {"table":"orderBookL2","action":"delete","data":[{"symbol":"XBTUSD","id":8798298600,"side":"Sell"},{"symbol":"XBTUSD","id":8798370600,"side":"Buy"},{"symbol":"XBTUSD","id":8798376800,"side":"Buy"},{"symbol":"XBTUSD","id":8798386200,"side":"Buy"}]}
09:57:38   {"table":"orderBookL2","action":"delete","data":[{"symbol":"XBTZ17","id":22899834035,"side":"Sell"}]}
09:57:38   {"table":"orderBookL2","action":"insert","data":[{"symbol":"XBTZ17","id":22899839430,"side":"Buy","size":152,"price":16057}]}
09:57:38   {"table":"orderBookL2","action":"update","data":[{"symbol":"XBTUSD","id":8798302300,"side":"Sell","size":530},{"symbol":"XBTUSD","id":8798312300,"side":"Sell","size":601},{"symbol":"XBTUSD","id":8798326100,"side":"Sell","size":2301},{"symbol":"XBTUSD","id":8798330000,"side":"Sell","size":99492},{"symbol":"XBTUSD","id":8798339900,"side":"Sell","size":450},{"symbol":"XBTUSD","id":8798364000,"side":"Buy","size":882},{"symbol":"XBTUSD","id":8798373400,"side":"Buy","size":272},{"symbol":"XBTUSD","id":8798373700,"side":"Buy","size":330},{"symbol":"XBTUSD","id":8798376600,"side":"Buy","size":50202},{"symbol":"XBTUSD","id":8798380000,"side":"Buy","size":2773},{"symbol":"XBTUSD","id":8798383100,"side":"Buy","size":100}]}
09:57:38   {"table":"orderBookL2","action":"delete","data":[{"symbol":"XBTZ17","id":22899834880,"side":"Buy"}]}
09:57:38   {"table":"orderBookL2","action":"insert","data":[{"symbol":"XBTZ17","id":22899835000,"side":"Buy","size":8000,"price":16500}]}
09:57:38   {"table":"orderBookL2","action":"insert","data":[{"symbol":"XBTUSD","id":8798288400,"side":"Sell","size":172,"price":17116},{"symbol":"XBTUSD","id":8798316200,"side":"Sell","size":112,"price":16838},{"symbol":"XBTUSD","id":8798360800,"side":"Buy","size":52,"price":16392},{"symbol":"XBTUSD","id":8798367200,"side":"Buy","size":112,"price":16328},{"symbol":"XBTUSD","id":8798370300,"side":"Buy","size":142,"price":16297}]}
09:57:38   {"table":"orderBookL2","action":"delete","data":[{"symbol":"XBTUSD","id":8798309850,"side":"Sell"}]}
09:57:38   {"table":"orderBookL2","action":"delete","data":[{"symbol":"XBTZ17","id":22899834335,"side":"Buy"}]}
09:57:38   {"table":"orderBookL2","action":"delete","data":[{"symbol":"XBTZ17","id":22899831670,"side":"Sell"},{"symbol":"XBTZ17","id":22899831915,"side":"Sell"},{"symbol":"XBTZ17","id":22899832165,"side":"Sell"},{"symbol":"XBTZ17","id":22899832415,"side":"Sell"},{"symbol":"XBTZ17","id":22899832660,"side":"Sell"},{"symbol":"XBTZ17","id":22899832910,"side":"Sell"},{"symbol":"XBTZ17","id":22899836495,"side":"Buy"},{"symbol":"XBTZ17","id":22899836740,"side":"Buy"},{"symbol":"XBTZ17","id":22899836990,"side":"Buy"},{"symbol":"XBTZ17","id":22899837235,"side":"Buy"},{"symbol":"XBTZ17","id":22899837480,"side":"Buy"},{"symbol":"XBTZ17","id":22899837730,"side":"Buy"},{"symbol":"XBTZ17","id":22899837975,"side":"Buy"},{"symbol":"XBTZ17","id":22899838220,"side":"Buy"}]}
09:57:38   {"table":"orderBookL2","action":"insert","data":[{"symbol":"XBTUSD","id":8798310250,"side":"Sell","size":40,"price":16897.5}]}
09:57:38   {"table":"orderBookL2","action":"update","data":[{"symbol":"XBTUSD","id":8798394000,"side":"Buy","size":5807}]}
09:57:38   {"table":"orderBookL2","action":"update","data":[{"symbol":"XBTZ17","id":22899833160,"side":"Sell","size":6890},{"symbol":"XBTZ17","id":22899833405,"side":"Sell","size":2700},{"symbol":"XBTZ17","id":22899836940,"side":"Buy","size":5255},{"symbol":"XBTZ17","id":22899838175,"side":"Buy","size":5153}]}
09:57:38   {"table":"orderBookL2","action":"update","data":[{"symbol":"XBTUSD","id":8798360000,"side":"Sell","size":2174787}]}
09:57:38   {"table":"orderBookL2","action":"insert","data":[{"symbol":"XBTZ17","id":22899831495,"side":"Sell","size":5000,"price":16850.5},{"symbol":"XBTZ17","id":22899831745,"side":"Sell","size":5000,"price":16825.5},{"symbol":"XBTZ17","id":22899831995,"side":"Sell","size":5000,"price":16800.5},{"symbol":"XBTZ17","id":22899832240,"side":"Sell","size":5000,"price":16776},{"symbol":"XBTZ17","id":22899832490,"side":"Sell","size":5000,"price":16751},{"symbol":"XBTZ17","id":22899832740,"side":"Sell","size":5000,"price":16726},{"symbol":"XBTZ17","id":22899832985,"side":"Sell","size":5000,"price":16701.5},{"symbol":"XBTZ17","id":22899833235,"side":"Sell","size":5000,"price":16676.5},{"symbol":"XBTZ17","id":22899836445,"side":"Buy","size":5000,"price":16355.5},{"symbol":"XBTZ17","id":22899836695,"side":"Buy","size":5000,"price":16330.5},{"symbol":"XBTZ17","id":22899837190,"side":"Buy","size":5000,"price":16281},{"symbol":"XBTZ17","id":22899837435,"side":"Buy","size":5000,"price":16256.5},{"symbol":"XBTZ17","id":22899837680,"side":"Buy","size":5000,"price":16232},{"symbol":"XBTZ17","id":22899837930,"side":"Buy","size":5000,"price":16207}]}
09:57:38   {"table":"orderBookL2","action":"update","data":[{"symbol":"XBTZ17","id":22899833505,"side":"Sell","size":131192}]}
09:57:38   {"table":"orderBookL2","action":"insert","data":[{"symbol":"XBTUSD","id":8798360500,"side":"Sell","size":820,"price":16395}]}
09:57:38   {"table":"orderBookL2","action":"delete","data":[{"symbol":"XBTZ17","id":22899831400,"side":"Sell"},{"symbol":"XBTZ17","id":22899832800,"side":"Sell"},{"symbol":"XBTZ17","id":22899836160,"side":"Buy"},{"symbol":"XBTZ17","id":22899836420,"side":"Buy"},{"symbol":"XBTZ17","id":22899836680,"side":"Buy"},{"symbol":"XBTZ17","id":22899837200,"side":"Buy"}]}
09:57:38   {"table":"orderBookL2","action":"update","data":[{"symbol":"XBTZ17","id":22899830020,"side":"Sell","size":78},{"symbol":"XBTZ17","id":22899833340,"side":"Sell","size":7077},{"symbol":"XBTZ17","id":22899835590,"side":"Buy","size":500},{"symbol":"XBTZ17","id":22899835900,"side":"Buy","size":123},{"symbol":"XBTZ17","id":22899836940,"side":"Buy","size":5000}]}
09:57:38   {"table":"orderBookL2","action":"delete","data":[{"symbol":"XBTUSD","id":8798382650,"side":"Buy"}]}
09:57:38   {"table":"orderBookL2","action":"insert","data":[{"symbol":"XBTUSD","id":8798372650,"side":"Buy","size":10549,"price":16273.5}]}
09:57:38   {"table":"orderBookL2","action":"insert","data":[{"symbol":"XBTZ17","id":22899829150,"side":"Sell","size":210,"price":17085},{"symbol":"XBTZ17","id":22899830540,"side":"Sell","size":166,"price":16946},{"symbol":"XBTZ17","id":22899831940,"side":"Sell","size":122,"price":16806},{"symbol":"XBTZ17","id":22899835070,"side":"Buy","size":77,"price":16493},{"symbol":"XBTZ17","id":22899835330,"side":"Buy","size":122,"price":16467},{"symbol":"XBTZ17","id":22899835850,"side":"Buy","size":210,"price":16415},{"symbol":"XBTZ17","id":22899836110,"side":"Buy","size":255,"price":16389},{"symbol":"XBTZ17","id":22899836370,"side":"Buy","size":299,"price":16363}]}
09:57:38   {"table":"orderBookL2","action":"update","data":[{"symbol":"XBTUSD","id":8798357800,"side":"Sell","size":79092}]}
09:57:38   {"table":"orderBookL2","action":"insert","data":[{"symbol":"XBTUSD","id":8798426200,"side":"Buy","size":401,"price":15738}]}
09:57:38   {"table":"orderBookL2","action":"delete","data":[{"symbol":"XBTZ17","id":22899833045,"side":"Sell"},{"symbol":"XBTZ17","id":22899834720,"side":"Buy"},{"symbol":"XBTZ17","id":22899834870,"side":"Buy"}]}
09:57:38   {"table":"orderBookL2","action":"update","data":[{"symbol":"XBTUSD","id":8798360500,"side":"Sell","size":70}]}
09:57:38   {"table":"orderBookL2","action":"update","data":[{"symbol":"XBTUSD","id":8798359950,"side":"Sell","size":266245}]}
09:57:38   {"table":"orderBookL2","action":"update","data":[{"symbol":"XBTZ17","id":22899833340,"side":"Sell","size":77},{"symbol":"XBTZ17","id":22899834910,"side":"Buy","size":193}]}
09:57:38   {"table":"orderBookL2","action":"delete","data":[{"symbol":"XBTUSD","id":8798363800,"side":"Buy"}]}
09:57:38   {"table":"orderBookL2","action":"insert","data":[{"symbol":"XBTZ17","id":22899833180,"side":"Sell","size":7000,"price":16682},{"symbol":"XBTZ17","id":22899833435,"side":"Sell","size":7000,"price":16656.5},{"symbol":"XBTZ17","id":22899834845,"side":"Buy","size":7050,"price":16515.5},{"symbol":"XBTZ17","id":22899834955,"side":"Buy","size":7050,"price":16504.5},{"symbol":"XBTZ17","id":22899835010,"side":"Buy","size":7050,"price":16499}]}
09:57:38   {"table":"orderBookL2","action":"delete","data":[{"symbol":"XBTZ17","id":22899833430,"side":"Sell"}]}
09:57:38   {"table":"orderBookL2","action":"update","data":[{"symbol":"XBTUSD","id":8798365000,"side":"Buy","size":10586}]}
09:57:38   {"table":"orderBookL2","action":"update","data":[{"symbol":"XBTUSD","id":8798357800,"side":"Sell","size":74092}]}
09:57:38   {"table":"orderBookL2","action":"update","data":[{"symbol":"XBTZ17","id":22899833520,"side":"Sell","size":25000}]}
09:57:38   {"table":"orderBookL2","action":"update","data":[{"symbol":"XBTZ17","id":22899834145,"side":"Sell","size":54783}]}
09:57:38   {"table":"orderBookL2","action":"update","data":[{"symbol":"XBTUSD","id":8798351800,"side":"Sell","size":508},{"symbol":"XBTUSD","id":8798368150,"side":"Buy","size":18550}]}
09:57:38   {"table":"orderBookL2","action":"delete","data":[{"symbol":"XBTZ17","id":22899833405,"side":"Sell"}]}
09:57:38   {"table":"orderBookL2","action":"insert","data":[{"symbol":"XBTZ17","id":22899833515,"side":"Sell","size":8000,"price":16648.5}]}
09:57:38   {"table":"orderBookL2","action":"update","data":[{"symbol":"XBTUSD","id":8798358150,"side":"Sell","size":30800}]}
09:57:38   {"table":"orderBookL2","action":"insert","data":[{"symbol":"XBTUSD","id":8798358200,"side":"Sell","size":1000,"price":16418}]}
09:57:38   {"table":"orderBookL2","action":"insert","data":[{"symbol":"XBTZ17","id":22899835135,"side":"Buy","size":5020,"price":16486.5}]}
09:57:38   {"table":"orderBookL2","action":"delete","data":[{"symbol":"XBTZ17","id":22899833450,"side":"Sell"}]}
09:57:38   {"table":"orderBookL2","action":"update","data":[{"symbol":"XBTUSD","id":8798359950,"side":"Sell","size":216245}]}
09:57:38   {"table":"orderBookL2","action":"update","data":[{"symbol":"XBTUSD","id":8798373500,"side":"Buy","size":4900}]}
09:57:38   {"table":"orderBookL2","action":"update","data":[{"symbol":"XBTUSD","id":8798373500,"side":"Buy","size":4650}]}
09:57:38   {"table":"orderBookL2","action":"insert","data":[{"symbol":"XBTZ17","id":22899834590,"side":"Buy","size":6000,"price":16541}]}
09:57:38   {"table":"orderBookL2","action":"update","data":[{"symbol":"XBTUSD","id":8798373500,"side":"Buy","size":1650}]}
09:57:38   {"table":"orderBookL2","action":"update","data":[{"symbol":"XBTUSD","id":8798373500,"side":"Buy","size":650}]}
09:57:38   {"table":"orderBookL2","action":"update","data":[{"symbol":"XBTUSD","id":8798360550,"side":"Buy","size":2710}]}
09:57:38   {"table":"orderBookL2","action":"insert","data":[{"symbol":"XBTZ17","id":22899835180,"side":"Buy","size":2000,"price":16482}]}
09:57:38   {"table":"orderBookL2","action":"delete","data":[{"symbol":"XBTZ17","id":22899839045,"side":"Buy"}]}
09:57:38   {"table":"orderBookL2","action":"update","data":[{"symbol":"XBTZ17","id":22899833875,"side":"Sell","size":8000}]}
09:57:38   {"table":"orderBookL2","action":"insert","data":[{"symbol":"XBTZ17","id":22899833675,"side":"Sell","size":6750,"price":16632.5},{"symbol":"XBTZ17","id":22899838920,"side":"Buy","size":9248,"price":16108}]}
09:57:38   {"table":"orderBookL2","action":"update","data":[{"symbol":"XBTUSD","id":8798372600,"side":"Buy","size":200},{"symbol":"XBTUSD","id":8798373100,"side":"Buy","size":151},{"symbol":"XBTUSD","id":8798373600,"side":"Buy","size":258},{"symbol":"XBTUSD","id":8798374100,"side":"Buy","size":240}]}
09:57:38   {"table":"orderBookL2","action":"update","data":[{"symbol":"XBTUSD","id":8798373500,"side":"Buy","size":250}]}
09:57:38   {"table":"orderBookL2","action":"update","data":[{"symbol":"XBTUSD","id":8798361850,"side":"Buy","size":4851}]}
09:57:38   {"table":"orderBookL2","action":"update","data":[{"symbol":"XBTUSD","id":8798357800,"side":"Sell","size":80392}]}
09:57:38   {"table":"orderBookL2","action":"insert","data":[{"symbol":"XBTUSD","id":8798363200,"side":"Buy","size":250,"price":16368}]}
09:57:38   {"table":"orderBookL2","action":"update","data":[{"symbol":"XBTZ17","id":22899835000,"side":"Buy","size":16000}]}
09:57:38   {"table":"orderBookL2","action":"insert","data":[{"symbol":"XBTZ17","id":22899834330,"side":"Buy","size":3000,"price":16567}]}
09:57:38   {"table":"orderBookL2","action":"update","data":[{"symbol":"XBTZ17","id":22899833515,"side":"Sell","size":16000}]}
09:57:38   {"table":"orderBookL2","action":"delete","data":[{"symbol":"XBTZ17","id":22899841160,"side":"Buy"}]}
09:57:38   {"table":"orderBookL2","action":"update","data":[{"symbol":"XBTZ17","id":22899833520,"side":"Sell","size":33000}]}
09:57:38   {"table":"orderBookL2","action":"delete","data":[{"symbol":"XBTUSD","id":8798330900,"side":"Sell"},{"symbol":"XBTUSD","id":8798360550,"side":"Buy"},{"symbol":"XBTUSD","id":8798360800,"side":"Buy"},{"symbol":"XBTUSD","id":8798361400,"side":"Buy"},{"symbol":"XBTUSD","id":8798361500,"side":"Buy"},{"symbol":"XBTUSD","id":8798361850,"side":"Buy"},{"symbol":"XBTUSD","id":8798361950,"side":"Buy"},{"symbol":"XBTUSD","id":8798362200,"side":"Buy"},{"symbol":"XBTUSD","id":8798362250,"side":"Buy"},{"symbol":"XBTUSD","id":8798362300,"side":"Buy"},{"symbol":"XBTUSD","id":8798362400,"side":"Buy"},{"symbol":"XBTUSD","id":8798362450,"side":"Buy"},{"symbol":"XBTUSD","id":8798362500,"side":"Buy"},{"symbol":"XBTUSD","id":8798362600,"side":"Buy"},{"symbol":"XBTUSD","id":8798362850,"side":"Buy"},{"symbol":"XBTUSD","id":8798362950,"side":"Buy"},{"symbol":"XBTUSD","id":8798363000,"side":"Buy"},{"symbol":"XBTUSD","id":8798363100,"side":"Buy"},{"symbol":"XBTUSD","id":8798363200,"side":"Buy"},{"symbol":"XBTUSD","id":8798363850,"side":"Buy"}]}
09:57:38   {"table":"orderBookL2","action":"update","data":[{"symbol":"XBTUSD","id":8798363900,"side":"Buy","size":249214}]}
09:57:38   {"table":"orderBookL2","action":"delete","data":[{"symbol":"XBTZ17","id":22899833585,"side":"Sell"}]}
09:57:38   {"table":"orderBookL2","action":"insert","data":[{"symbol":"XBTZ17","id":22899833805,"side":"Sell","size":5059,"price":16619.5}]}
09:57:38   {"table":"orderBookL2","action":"delete","data":[{"symbol":"XBTZ17","id":22899834615,"side":"Buy"}]}
09:57:38   {"table":"orderBookL2","action":"delete","data":[{"symbol":"XBTZ17","id":22899834330,"side":"Buy"},{"symbol":"XBTZ17","id":22899834460,"side":"Buy"}]}
09:57:38   {"table":"orderBookL2","action":"update","data":[{"symbol":"XBTZ17","id":22899834500,"side":"Buy","size":1046}]}
09:57:38   {"table":"orderBookL2","action":"insert","data":[{"symbol":"XBTUSD","id":8798360100,"side":"Sell","size":17992,"price":16399}]}
09:57:38   {"table":"orderBookL2","action":"update","data":[{"symbol":"XBTUSD","id":8798363900,"side":"Buy","size":244214}]}
09:57:38   {"table":"orderBookL2","action":"update","data":[{"symbol":"XBTUSD","id":8798363900,"side":"Buy","size":244114}]}
09:57:38   {"table":"orderBookL2","action":"insert","data":[{"symbol":"XBTUSD","id":8798363300,"side":"Buy","size":1637,"price":16367}]}
09:57:38   {"table":"orderBookL2","action":"delete","data":[{"symbol":"XBTZ17","id":22899833580,"side":"Sell"}]}
09:57:38   {"table":"orderBookL2","action":"insert","data":[{"symbol":"XBTZ17","id":22899834285,"side":"Sell","size":666,"price":16571.5}]}
09:57:38   {"table":"orderBookL2","action":"delete","data":[{"symbol":"XBTZ17","id":22899833810,"side":"Sell"},{"symbol":"XBTZ17","id":22899833840,"side":"Sell"},{"symbol":"XBTZ17","id":22899833875,"side":"Sell"}]}
09:57:38   {"table":"orderBookL2","action":"insert","data":[{"symbol":"XBTZ17","id":22899833940,"side":"Sell","size":8000,"price":16606},{"symbol":"XBTZ17","id":22899833970,"side":"Sell","size":8000,"price":16603},{"symbol":"XBTZ17","id":22899834005,"side":"Sell","size":8000,"price":16599.5}]}
09:57:38   {"table":"orderBookL2","action":"insert","data":[{"symbol":"XBTUSD","id":8798365750,"side":"Buy","size":30000,"price":16342.5}]}
09:57:38   {"table":"orderBookL2","action":"insert","data":[{"symbol":"XBTUSD","id":8798363200,"side":"Buy","size":250,"price":16368}]}
09:57:38   {"table":"orderBookL2","action":"update","data":[{"symbol":"XBTUSD","id":8798331200,"side":"Sell","size":6193}]}
09:57:38   {"table":"orderBookL2","action":"update","data":[{"symbol":"XBTZ17","id":22899834145,"side":"Sell","size":52000}]}
09:57:38   {"table":"orderBookL2","action":"insert","data":[{"symbol":"XBTZ17","id":22899834150,"side":"Sell","size":4000,"price":16585}]}
09:57:38   {"table":"orderBookL2","action":"insert","data":[{"symbol":"XBTUSD","id":8798306800,"side":"Sell","size":6000,"price":16932}]}
09:57:38   {"table":"orderBookL2","action":"delete","data":[{"symbol":"XBTZ17","id":22899833350,"side":"Sell"}]}
09:57:38   {"table":"orderBookL2","action":"delete","data":[{"symbol":"XBTZ17","id":22899833160,"side":"Sell"},{"symbol":"XBTZ17","id":22899833200,"side":"Sell"},{"symbol":"XBTZ17","id":22899833470,"side":"Sell"},{"symbol":"XBTZ17","id":22899834995,"side":"Buy"}]}
09:57:38   {"table":"orderBookL2","action":"insert","data":[{"symbol":"XBTUSD","id":8798362400,"side":"Buy","size":400,"price":16376}]}
09:57:38   {"table":"orderBookL2","action":"update","data":[{"symbol":"XBTUSD","id":8798362400,"side":"Buy","size":300}]}
09:57:38   {"table":"orderBookL2","action":"update","data":[{"symbol":"XBTZ17","id":22899833000,"side":"Sell","size":116},{"symbol":"XBTZ17","id":22899833330,"side":"Sell","size":13850},{"symbol":"XBTZ17","id":22899833340,"side":"Sell","size":6967},{"symbol":"XBTZ17","id":22899833375,"side":"Sell","size":7000},{"symbol":"XBTZ17","id":22899834875,"side":"Buy","size":6461}]}
09:57:38   {"table":"orderBookL2","action":"insert","data":[{"symbol":"XBTZ17","id":22899832970,"side":"Sell","size":6850,"price":16703},{"symbol":"XBTZ17","id":22899833120,"side":"Sell","size":6890,"price":16688},{"symbol":"XBTZ17","id":22899833165,"side":"Sell","size":3570,"price":16683.5},{"symbol":"XBTZ17","id":22899833430,"side":"Sell","size":5850,"price":16657},{"symbol":"XBTZ17","id":22899835105,"side":"Buy","size":630,"price":16489.5},{"symbol":"XBTZ17","id":22899835225,"side":"Buy","size":1570,"price":16477.5}]}
09:57:38   {"table":"orderBookL2","action":"delete","data":[{"symbol":"XBTZ17","id":22899833335,"side":"Sell"}]}
09:57:38   {"table":"orderBookL2","action":"update","data":[{"symbol":"XBTUSD","id":8798359950,"side":"Sell","size":213745}]}
09:57:38   {"table":"orderBookL2","action":"delete","data":[{"symbol":"XBTUSD","id":8798498600,"side":"Buy"}]}
09:57:38   {"table":"orderBookL2","action":"insert","data":[{"symbol":"XBTZ17","id":22899833795,"side":"Sell","size":40000,"price":16620.5}]}
09:57:38   {"table":"orderBookL2","action":"delete","data":[{"symbol":"XBTZ17","id":22899834730,"side":"Buy"},{"symbol":"XBTZ17","id":22899835140,"side":"Buy"}]}
09:57:38   {"table":"orderBookL2","action":"update","data":[{"symbol":"XBTUSD","id":8798500000,"side":"Buy","size":1143558}]}
09:57:38   {"table":"orderBookL2","action":"update","data":[{"symbol":"XBTUSD","id":8798350000,"side":"Sell","size":125370}]}
09:57:38   {"table":"orderBookL2","action":"update","data":[{"symbol":"XBTUSD","id":8798370050,"side":"Buy","size":344000}]}
09:57:38   {"table":"orderBookL2","action":"insert","data":[{"symbol":"XBTZ17","id":22899834600,"side":"Buy","size":35,"price":16540},{"symbol":"XBTZ17","id":22899835020,"side":"Buy","size":56,"price":16498}]}
09:57:38   {"table":"orderBookL2","action":"delete","data":[{"symbol":"XBTZ17","id":22899833555,"side":"Sell"}]}
09:57:38   {"table":"orderBookL2","action":"update","data":[{"symbol":"XBTUSD","id":8798367100,"side":"Buy","size":4100}]}
09:57:38   {"table":"orderBookL2","action":"delete","data":[{"symbol":"XBTUSD","id":8798360500,"side":"Sell"}]}
09:57:38   {"table":"orderBookL2","action":"update","data":[{"symbol":"XBTZ17","id":22899833520,"side":"Sell","size":26000},{"symbol":"XBTZ17","id":22899833755,"side":"Sell","size":60},{"symbol":"XBTZ17","id":22899833970,"side":"Sell","size":15000}]}
09:57:38   {"table":"orderBookL2","action":"update","data":[{"symbol":"XBTUSD","id":8798360100,"side":"Sell","size":17162}]}
09:57:38   {"table":"orderBookL2","action":"insert","data":[{"symbol":"XBTUSD","id":8798361850,"side":"Buy","size":469,"price":16381.5}]}
09:57:38   {"table":"orderBookL2","action":"insert","data":[{"symbol":"XBTZ17","id":22899833790,"side":"Sell","size":7000,"price":16621},{"symbol":"XBTZ17","id":22899833830,"side":"Sell","size":7000,"price":16617}]}
09:57:38   {"table":"orderBookL2","action":"delete","data":[{"symbol":"XBTZ17","id":22899833115,"side":"Sell"},{"symbol":"XBTZ17","id":22899833550,"side":"Sell"}]}
09:57:38   {"table":"orderBookL2","action":"insert","data":[{"symbol":"XBTZ17","id":22899833230,"side":"Sell","size":7000,"price":16677},{"symbol":"XBTZ17","id":22899833680,"side":"Sell","size":7000,"price":16632}]}
09:57:38   {"table":"orderBookL2","action":"delete","data":[{"symbol":"XBTZ17","id":22899832975,"side":"Sell"},{"symbol":"XBTZ17","id":22899833365,"side":"Sell"},{"symbol":"XBTZ17","id":22899833375,"side":"Sell"}]}
09:57:38   {"table":"orderBookL2","action":"insert","data":[{"symbol":"XBTUSD","id":8798362250,"side":"Buy","size":8000,"price":16377.5}]}
09:57:38   {"table":"orderBookL2","action":"update","data":[{"symbol":"XBTZ17","id":22899833330,"side":"Sell","size":6850}]}
09:57:38   {"table":"orderBookL2","action":"insert","data":[{"symbol":"XBTZ17","id":22899833105,"side":"Sell","size":7000,"price":16689.5},{"symbol":"XBTZ17","id":22899833510,"side":"Sell","size":7000,"price":16649},{"symbol":"XBTZ17","id":22899833605,"side":"Sell","size":7000,"price":16639.5},{"symbol":"XBTZ17","id":22899833640,"side":"Sell","size":7000,"price":16636}]}
09:57:38   {"table":"orderBookL2","action":"insert","data":[{"symbol":"XBTZ17","id":22899834135,"side":"Sell","size":1133,"price":16586.5}]}
09:57:38   {"table":"orderBookL2","action":"update","data":[{"symbol":"XBTUSD","id":8798360100,"side":"Sell","size":12162}]}
09:57:38   {"table":"orderBookL2","action":"delete","data":[{"symbol":"XBTUSD","id":8798361850,"side":"Buy"},{"symbol":"XBTUSD","id":8798362250,"side":"Buy"},{"symbol":"XBTUSD","id":8798362400,"side":"Buy"},{"symbol":"XBTUSD","id":8798363200,"side":"Buy"}]}
09:57:38   {"table":"orderBookL2","action":"insert","data":[{"symbol":"XBTZ17","id":22899832795,"side":"Sell","size":1000,"price":16720.5}]}
09:57:38   {"table":"orderBookL2","action":"insert","data":[{"symbol":"XBTZ17","id":22899831980,"side":"Sell","size":20000,"price":16802}]}
09:57:38   {"table":"orderBookL2","action":"update","data":[{"symbol":"XBTUSD","id":8798363300,"side":"Buy","size":656}]}
09:57:38   {"table":"orderBookL2","action":"delete","data":[{"symbol":"XBTZ17","id":22899833755,"side":"Sell"}]}
09:57:38   {"table":"orderBookL2","action":"update","data":[{"symbol":"XBTUSD","id":8798359950,"side":"Sell","size":212145}]}
09:57:38   {"table":"orderBookL2","action":"update","data":[{"symbol":"XBTUSD","id":8798359500,"side":"Sell","size":3600}]}
09:57:38   {"table":"orderBookL2","action":"insert","data":[{"symbol":"XBTZ17","id":22899833925,"side":"Sell","size":60,"price":16607.5}]}
09:57:38   {"table":"orderBookL2","action":"delete","data":[{"symbol":"XBTZ17","id":22899835295,"side":"Buy"}]}
09:57:38   {"table":"orderBookL2","action":"update","data":[{"symbol":"XBTUSD","id":8798359950,"side":"Sell","size":112145}]}
09:57:38   {"table":"orderBookL2","action":"update","data":[{"symbol":"XBTUSD","id":8798357550,"side":"Sell","size":9800}]}
09:57:38   {"table":"orderBookL2","action":"insert","data":[{"symbol":"XBTZ17","id":22899835475,"side":"Buy","size":6609,"price":16452.5}]}
09:57:38   {"table":"orderBookL2","action":"delete","data":[{"symbol":"XBTZ17","id":22899834145,"side":"Sell"}]}
09:57:38   {"table":"orderBookL2","action":"insert","data":[{"symbol":"XBTUSD","id":8798362150,"side":"Sell","size":2000,"price":16378.5}]}
09:57:38   {"table":"orderBookL2","action":"insert","data":[{"symbol":"XBTUSD","id":8798360050,"side":"Sell","size":3000,"price":16399.5}]}
09:57:38   {"table":"orderBookL2","action":"update","data":[{"symbol":"XBTZ17","id":22899834150,"side":"Sell","size":56000}]}
09:57:38   {"table":"orderBookL2","action":"delete","data":[{"symbol":"XBTZ17","id":22899831495,"side":"Sell"},{"symbol":"XBTZ17","id":22899831745,"side":"Sell"},{"symbol":"XBTZ17","id":22899831995,"side":"Sell"},{"symbol":"XBTZ17","id":22899832240,"side":"Sell"},{"symbol":"XBTZ17","id":22899832490,"side":"Sell"},{"symbol":"XBTZ17","id":22899832740,"side":"Sell"},{"symbol":"XBTZ17","id":22899832985,"side":"Sell"},{"symbol":"XBTZ17","id":22899833235,"side":"Sell"},{"symbol":"XBTZ17","id":22899836445,"side":"Buy"},{"symbol":"XBTZ17","id":22899836695,"side":"Buy"},{"symbol":"XBTZ17","id":22899836940,"side":"Buy"},{"symbol":"XBTZ17","id":22899837190,"side":"Buy"},{"symbol":"XBTZ17","id":22899837435,"side":"Buy"},{"symbol":"XBTZ17","id":22899837680,"side":"Buy"},{"symbol":"XBTZ17","id":22899837930,"side":"Buy"}]}
09:57:38   {"table":"orderBookL2","action":"update","data":[{"symbol":"XBTUSD","id":8798368800,"side":"Buy","size":168}]}
09:57:38   {"table":"orderBookL2","action":"insert","data":[{"symbol":"XBTUSD","id":8798371250,"side":"Buy","size":3390,"price":16287.5}]}
09:57:38   {"table":"orderBookL2","action":"update","data":[{"symbol":"XBTZ17","id":22899836995,"side":"Buy","size":10000},{"symbol":"XBTZ17","id":22899838175,"side":"Buy","size":153}]}
09:57:38   {"table":"orderBookL2","action":"insert","data":[{"symbol":"XBTZ17","id":22899831625,"side":"Sell","size":5000,"price":16837.5},{"symbol":"XBTZ17","id":22899831870,"side":"Sell","size":5000,"price":16813},{"symbol":"XBTZ17","id":22899832120,"side":"Sell","size":5000,"price":16788},{"symbol":"XBTZ17","id":22899832370,"side":"Sell","size":5000,"price":16763},{"symbol":"XBTZ17","id":22899832615,"side":"Sell","size":5000,"price":16738.5},{"symbol":"XBTZ17","id":22899832865,"side":"Sell","size":5000,"price":16713.5},{"symbol":"XBTZ17","id":22899833115,"side":"Sell","size":5000,"price":16688.5},{"symbol":"XBTZ17","id":22899833360,"side":"Sell","size":5000,"price":16664},{"symbol":"XBTZ17","id":22899836500,"side":"Buy","size":5000,"price":16350},{"symbol":"XBTZ17","id":22899836750,"side":"Buy","size":5000,"price":16325},{"symbol":"XBTZ17","id":22899837245,"side":"Buy","size":5000,"price":16275.5},{"symbol":"XBTZ17","id":22899837490,"side":"Buy","size":5000,"price":16251},{"symbol":"XBTZ17","id":22899837735,"side":"Buy","size":5000,"price":16226.5},{"symbol":"XBTZ17","id":22899837985,"side":"Buy","size":5000,"price":16201.5},{"symbol":"XBTZ17","id":22899838230,"side":"Buy","size":5000,"price":16177}]}
09:57:38   {"table":"orderBookL2","action":"delete","data":[{"symbol":"XBTUSD","id":8798372550,"side":"Buy"}]}
09:57:38   {"table":"orderBookL2","action":"update","data":[{"symbol":"XBTZ17","id":22899833505,"side":"Sell","size":42100},{"symbol":"XBTZ17","id":22899833510,"side":"Sell","size":95526}]}
09:57:38   {"table":"orderBookL2","action":"delete","data":[{"symbol":"XBTZ17","id":22899834500,"side":"Buy"}]}
09:57:38   {"table":"orderBookL2","action":"update","data":[{"symbol":"XBTUSD","id":8798346500,"side":"Sell","size":3412},{"symbol":"XBTUSD","id":8798373400,"side":"Buy","size":7052}]}
09:57:38   {"table":"orderBookL2","action":"delete","data":[{"symbol":"XBTZ17","id":22899833180,"side":"Sell"},{"symbol":"XBTZ17","id":22899833435,"side":"Sell"},{"symbol":"XBTZ17","id":22899834845,"side":"Buy"},{"symbol":"XBTZ17","id":22899834955,"side":"Buy"},{"symbol":"XBTZ17","id":22899835010,"side":"Buy"}]}
09:57:38   {"table":"orderBookL2","action":"update","data":[{"symbol":"XBTZ17","id":22899835120,"side":"Buy","size":49950}]}
09:57:38   {"table":"orderBookL2","action":"insert","data":[{"symbol":"XBTUSD","id":8798346800,"side":"Sell","size":3390,"price":16532}]}
09:57:38   {"table":"orderBookL2","action":"delete","data":[{"symbol":"XBTUSD","id":8798368050,"side":"Buy"},{"symbol":"XBTUSD","id":8798368400,"side":"Buy"}]}
09:57:38   {"table":"orderBookL2","action":"insert","data":[{"symbol":"XBTZ17","id":22899833315,"side":"Sell","size":7000,"price":16668.5},{"symbol":"XBTZ17","id":22899833565,"side":"Sell","size":7000,"price":16643.5},{"symbol":"XBTZ17","id":22899834970,"side":"Buy","size":7050,"price":16503},{"symbol":"XBTZ17","id":22899835075,"side":"Buy","size":7050,"price":16492.5}]}
09:57:39   {"table":"orderBookL2","action":"delete","data":[{"symbol":"XBTZ17","id":22899835135,"side":"Buy"}]}
09:57:39   {"table":"orderBookL2","action":"update","data":[{"symbol":"XBTUSD","id":8798367500,"side":"Buy","size":14000},{"symbol":"XBTUSD","id":8798367850,"side":"Buy","size":57000},{"symbol":"XBTUSD","id":8798368150,"side":"Buy","size":11550},{"symbol":"XBTUSD","id":8798372950,"side":"Buy","size":43},{"symbol":"XBTUSD","id":8798373500,"side":"Buy","size":7250}]}
09:57:39   {"table":"orderBookL2","action":"insert","data":[{"symbol":"XBTUSD","id":8798367050,"side":"Buy","size":7000,"price":16329.5}]}
09:57:39   {"table":"orderBookL2","action":"insert","data":[{"symbol":"XBTZ17","id":22899835040,"side":"Buy","size":2420,"price":16496}]}
09:57:39   {"table":"orderBookL2","action":"delete","data":[{"symbol":"XBTZ17","id":22899834875,"side":"Buy"}]}
09:57:39   {"table":"orderBookL2","action":"update","data":[{"symbol":"XBTUSD","id":8798360000,"side":"Sell","size":2085805}]}
09:57:39   {"table":"orderBookL2","action":"update","data":[{"symbol":"XBTZ17","id":22899834505,"side":"Buy","size":42000}]}
09:57:39   {"table":"orderBookL2","action":"delete","data":[{"symbol":"XBTZ17","id":22899833675,"side":"Sell"}]}
09:57:39   {"table":"orderBookL2","action":"delete","data":[{"symbol":"XBTUSD","id":8798321400,"side":"Sell"},{"symbol":"XBTUSD","id":8798338400,"side":"Sell"},{"symbol":"XBTUSD","id":8798346900,"side":"Sell"},{"symbol":"XBTUSD","id":8798357850,"side":"Sell"},{"symbol":"XBTUSD","id":8798367250,"side":"Buy"},{"symbol":"XBTUSD","id":8798383100,"side":"Buy"}]}
09:57:39   {"table":"orderBookL2","action":"insert","data":[{"symbol":"XBTZ17","id":22899833880,"side":"Sell","size":6792,"price":16612}]}
09:57:39   {"table":"orderBookL2","action":"delete","data":[{"symbol":"XBTZ17","id":22899835195,"side":"Buy"}]}
09:57:39   {"table":"orderBookL2","action":"delete","data":[{"symbol":"XBTZ17","id":22899825880,"side":"Sell"},{"symbol":"XBTZ17","id":22899827810,"side":"Sell"},{"symbol":"XBTZ17","id":22899829740,"side":"Sell"},{"symbol":"XBTZ17","id":22899831040,"side":"Sell"},{"symbol":"XBTZ17","id":22899832980,"side":"Sell"},{"symbol":"XBTZ17","id":22899835380,"side":"Buy"},{"symbol":"XBTZ17","id":22899836100,"side":"Buy"},{"symbol":"XBTZ17","id":22899836460,"side":"Buy"},{"symbol":"XBTZ17","id":22899837180,"side":"Buy"}]}
09:57:39   {"table":"orderBookL2","action":"update","data":[{"symbol":"XBTUSD","id":8798140100,"side":"Sell","size":75},{"symbol":"XBTUSD","id":8798145100,"side":"Sell","size":40861},{"symbol":"XBTUSD","id":8798150100,"side":"Sell","size":2675},{"symbol":"XBTUSD","id":8798155100,"side":"Sell","size":250},{"symbol":"XBTUSD","id":8798160100,"side":"Sell","size":95175},{"symbol":"XBTUSD","id":8798160750,"side":"Sell","size":192},{"symbol":"XBTUSD","id":8798168000,"side":"Sell","size":900},{"symbol":"XBTUSD","id":8798180100,"side":"Sell","size":175},{"symbol":"XBTUSD","id":8798188000,"side":"Sell","size":3000},{"symbol":"XBTUSD","id":8798200100,"side":"Sell","size":2175},{"symbol":"XBTUSD","id":8798207800,"side":"Sell","size":150},{"symbol":"XBTUSD","id":8798220100,"side":"Sell","size":200},{"symbol":"XBTUSD","id":8798227700,"side":"Sell","size":229},{"symbol":"XBTUSD","id":8798240100,"side":"Sell","size":200},{"symbol":"XBTUSD","id":8798247000,"side":"Sell","size":30472},{"symbol":"XBTUSD","id":8798260100,"side":"Sell","size":200},{"symbol":"XBTUSD","id":8798265800,"side":"Sell","size":410},{"symbol":"XBTUSD","id":8798280100,"side":"Sell","size":3588},{"symbol":"XBTUSD","id":8798285650,"side":"Sell","size":488},{"symbol":"XBTUSD","id":8798300100,"side":"Sell","size":175},{"symbol":"XBTUSD","id":8798305350,"side":"Sell","size":20910},{"symbol":"XBTUSD","id":8798310150,"side":"Sell","size":601},{"symbol":"XBTUSD","id":8798328300,"side":"Sell","size":4225},{"symbol":"XBTUSD","id":8798328400,"side":"Sell","size":500},{"symbol":"XBTUSD","id":8798333300,"side":"Sell","size":5360},{"symbol":"XBTUSD","id":8798333400,"side":"Sell","size":2000},{"symbol":"XBTUSD","id":8798338300,"side":"Sell","size":150},{"symbol":"XBTUSD","id":8798352850,"side":"Sell","size":204},{"symbol":"XBTUSD","id":8798354500,"side":"Sell","size":3800},{"symbol":"XBTUSD","id":8798365350,"side":"Buy","size":10100},{"symbol":"XBTUSD","id":8798372250,"side":"Buy","size":7500},{"symbol":"XBTUSD","id":8798378100,"side":"Buy","size":5000},{"symbol":"XBTUSD","id":8798380750,"side":"Buy","size":1100},{"symbol":"XBTUSD","id":8798388850,"side":"Buy","size":310},{"symbol":"XBTUSD","id":8798392100,"side":"Buy","size":5118},{"symbol":"XBTUSD","id":8798394000,"side":"Buy","size":5907},{"symbol":"XBTUSD","id":8798409200,"side":"Buy","size":5118},{"symbol":"XBTUSD","id":8798559900,"side":"Buy","size":75},{"symbol":"XBTUSD","id":8798561850,"side":"Buy","size":15100},{"symbol":"XBTUSD","id":8798564900,"side":"Buy","size":20150},{"symbol":"XBTUSD","id":8798569900,"side":"Buy","size":75},{"symbol":"XBTUSD","id":8798574900,"side":"Buy","size":5150}]}
09:57:39   {"table":"orderBookL2","action":"insert","data":[{"symbol":"XBTUSD","id":8798145750,"side":"Sell","size":100,"price":18542.5},{"symbol":"XBTUSD","id":8798150750,"side":"Sell","size":100,"price":18492.5},{"symbol":"XBTUSD","id":8798155750,"side":"Sell","size":100,"price":18442.5},{"symbol":"XBTUSD","id":8798319550,"side":"Sell","size":100,"price":16804.5},{"symbol":"XBTUSD","id":8798344500,"side":"Sell","size":100,"price":16555},{"symbol":"XBTUSD","id":8798349500,"side":"Sell","size":100,"price":16505},{"symbol":"XBTUSD","id":8798360500,"side":"Sell","size":100,"price":16395},{"symbol":"XBTUSD","id":8798370350,"side":"Buy","size":100,"price":16296.5},{"symbol":"XBTUSD","id":8798375350,"side":"Buy","size":100,"price":16246.5},{"symbol":"XBTUSD","id":8798409350,"side":"Buy","size":100,"price":15906.5},{"symbol":"XBTUSD","id":8798566850,"side":"Buy","size":100,"price":14331.5},{"symbol":"XBTUSD","id":8798571850,"side":"Buy","size":100,"price":14281.5}]}
09:57:39   {"table":"orderBookL2","action":"update","data":[{"symbol":"XBTUSD","id":8798360050,"side":"Sell","size":6000}]}
09:57:39   {"table":"orderBookL2","action":"update","data":[{"symbol":"XBTZ17","id":22899835000,"side":"Buy","size":16082},{"symbol":"XBTZ17","id":22899835740,"side":"Buy","size":40150},{"symbol":"XBTZ17","id":22899836820,"side":"Buy","size":317}]}
09:57:39   {"table":"orderBookL2","action":"insert","data":[{"symbol":"XBTZ17","id":22899824430,"side":"Sell","size":172,"price":17557},{"symbol":"XBTZ17","id":22899826380,"side":"Sell","size":142,"price":17362},{"symbol":"XBTZ17","id":22899828320,"side":"Sell","size":112,"price":17168},{"symbol":"XBTZ17","id":22899830280,"side":"Sell","size":82,"price":16972},{"symbol":"XBTZ17","id":22899832220,"side":"Sell","size":52,"price":16778},{"symbol":"XBTZ17","id":22899834640,"side":"Buy","size":52,"price":16536},{"symbol":"XBTZ17","id":22899835360,"side":"Buy","size":112,"price":16464},{"symbol":"XBTZ17","id":22899835720,"side":"Buy","size":142,"price":16428},{"symbol":"XBTZ17","id":22899836080,"side":"Buy","size":172,"price":16392},{"symbol":"XBTZ17","id":22899836440,"side":"Buy","size":202,"price":16356}]}
09:57:39   {"table":"orderBookL2","action":"insert","data":[{"symbol":"XBTZ17","id":22899839435,"side":"Buy","size":152,"price":16056.5}]}
09:57:39   {"table":"orderBookL2","action":"update","data":[{"symbol":"XBTUSD","id":8798367850,"side":"Buy","size":64000},{"symbol":"XBTUSD","id":8798368950,"side":"Buy","size":820}]}
09:57:39   {"table":"orderBookL2","action":"update","data":[{"symbol":"XBTUSD","id":8798359950,"side":"Sell","size":102145}]}
09:57:39   {"table":"orderBookL2","action":"update","data":[{"symbol":"XBTZ17","id":22899833000,"side":"Sell","size":2116}]}
09:57:39   {"table":"orderBookL2","action":"insert","data":[{"symbol":"XBTZ17","id":22899833585,"side":"Sell","size":2000,"price":16641.5}]}
09:57:39   {"table":"orderBookL2","action":"delete","data":[{"symbol":"XBTZ17","id":22899833825,"side":"Sell"}]}
09:57:39   {"table":"orderBookL2","action":"insert","data":[{"symbol":"XBTUSD","id":8798361500,"side":"Sell","size":10000,"price":16385}]}
09:57:39   {"table":"orderBookL2","action":"update","data":[{"symbol":"XBTUSD","id":8798359950,"side":"Sell","size":82145},{"symbol":"XBTUSD","id":8798360050,"side":"Sell","size":26000}]}
09:57:39   {"table":"orderBookL2","action":"update","data":[{"symbol":"XBTUSD","id":8798363300,"side":"Buy","size":356}]}
09:57:39   {"table":"orderBookL2","action":"insert","data":[{"symbol":"XBTZ17","id":22899834210,"side":"Sell","size":50000,"price":16579}]}
09:57:39   {"table":"orderBookL2","action":"update","data":[{"symbol":"XBTUSD","id":8798359950,"side":"Sell","size":82135},{"symbol":"XBTUSD","id":8798360050,"side":"Sell","size":26010}]}
09:57:39   {"table":"orderBookL2","action":"update","data":[{"symbol":"XBTUSD","id":8798500000,"side":"Buy","size":1223558},{"symbol":"XBTUSD","id":8798600000,"side":"Buy","size":381895}]}
09:57:39   {"table":"orderBookL2","action":"update","data":[{"symbol":"XBTUSD","id":8798360050,"side":"Sell","size":26110}]}
09:57:39   {"table":"orderBookL2","action":"update","data":[{"symbol":"XBTUSD","id":8798359950,"side":"Sell","size":80135},{"symbol":"XBTUSD","id":8798360050,"side":"Sell","size":28110}]}
09:57:39   {"table":"orderBookL2","action":"update","data":[{"symbol":"XBTZ17","id":22899834150,"side":"Sell","size":63253}]}
09:57:39   {"table":"orderBookL2","action":"delete","data":[{"symbol":"XBTZ17","id":22899834285,"side":"Sell"}]}
09:57:39   {"table":"orderBookL2","action":"delete","data":[{"symbol":"XBTZ17","id":22899833805,"side":"Sell"}]}
09:57:39   {"table":"orderBookL2","action":"update","data":[{"symbol":"XBTUSD","id":8798359950,"side":"Sell","size":76935}]}
09:57:39   {"table":"orderBookL2","action":"update","data":[{"symbol":"XBTUSD","id":8798360050,"side":"Sell","size":28120}]}
09:57:39   {"table":"orderBookL2","action":"update","data":[{"symbol":"XBTUSD","id":8798359950,"side":"Sell","size":76835},{"symbol":"XBTUSD","id":8798360050,"side":"Sell","size":28220}]}
09:57:39   {"table":"orderBookL2","action":"delete","data":[{"symbol":"XBTUSD","id":8798345750,"side":"Sell"},{"symbol":"XBTUSD","id":8798350750,"side":"Sell"},{"symbol":"XBTUSD","id":8798352850,"side":"Sell"},{"symbol":"XBTUSD","id":8798355050,"side":"Sell"}]}
09:57:39   {"table":"orderBookL2","action":"update","data":[{"symbol":"XBTUSD","id":8798347350,"side":"Sell","size":600},{"symbol":"XBTUSD","id":8798348950,"side":"Sell","size":464},{"symbol":"XBTUSD","id":8798351800,"side":"Sell","size":100},{"symbol":"XBTUSD","id":8798353600,"side":"Sell","size":10423},{"symbol":"XBTUSD","id":8798354050,"side":"Sell","size":1100},{"symbol":"XBTUSD","id":8798360050,"side":"Sell","size":28280}]}
09:57:39   {"table":"orderBookL2","action":"insert","data":[{"symbol":"XBTZ17","id":22899833910,"side":"Sell","size":5059,"price":16609}]}
09:57:39   {"table":"orderBookL2","action":"insert","data":[{"symbol":"XBTZ17","id":22899834325,"side":"Sell","size":17000,"price":16567.5}]}
09:57:39   {"table":"orderBookL2","action":"update","data":[{"symbol":"XBTZ17","id":22899834140,"side":"Sell","size":30050},{"symbol":"XBTZ17","id":22899838855,"side":"Buy","size":263}]}
09:57:39   {"table":"orderBookL2","action":"insert","data":[{"symbol":"XBTZ17","id":22899829615,"side":"Sell","size":110,"price":17038.5},{"symbol":"XBTZ17","id":22899830375,"side":"Sell","size":100,"price":16962.5},{"symbol":"XBTZ17","id":22899831135,"side":"Sell","size":90,"price":16886.5},{"symbol":"XBTZ17","id":22899831895,"side":"Sell","size":80,"price":16810.5},{"symbol":"XBTZ17","id":22899832645,"side":"Sell","size":70,"price":16735.5},{"symbol":"XBTZ17","id":22899833395,"side":"Sell","size":60,"price":16660.5},{"symbol":"XBTZ17","id":22899834455,"side":"Buy","size":50,"price":16554.5},{"symbol":"XBTZ17","id":22899835195,"side":"Buy","size":60,"price":16480.5},{"symbol":"XBTZ17","id":22899835935,"side":"Buy","size":70,"price":16406.5},{"symbol":"XBTZ17","id":22899836670,"side":"Buy","size":80,"price":16333},{"symbol":"XBTZ17","id":22899837400,"side":"Buy","size":90,"price":16260},{"symbol":"XBTZ17","id":22899838130,"side":"Buy","size":100,"price":16187}]}
09:57:39   {"table":"orderBookL2","action":"insert","data":[{"symbol":"XBTUSD","id":8798350600,"side":"Sell","size":300,"price":16494},{"symbol":"XBTUSD","id":8798352250,"side":"Sell","size":1920,"price":16477.5},{"symbol":"XBTUSD","id":8798353800,"side":"Sell","size":960,"price":16462},{"symbol":"XBTUSD","id":8798355550,"side":"Sell","size":480,"price":16444.5},{"symbol":"XBTUSD","id":8798357150,"side":"Sell","size":240,"price":16428.5},{"symbol":"XBTUSD","id":8798358450,"side":"Sell","size":120,"price":16415.5},{"symbol":"XBTUSD","id":8798363750,"side":"Buy","size":1170,"price":16362.5}]}
09:57:39   {"table":"orderBookL2","action":"update","data":[{"symbol":"XBTUSD","id":8798366900,"side":"Buy","size":14953}]}
09:57:39   {"table":"orderBookL2","action":"update","data":[{"symbol":"XBTZ17","id":22899835040,"side":"Buy","size":4840}]}
09:57:39   {"table":"orderBookL2","action":"insert","data":[{"symbol":"XBTUSD","id":8798365300,"side":"Buy","size":1353,"price":16347}]}
09:57:39   {"table":"orderBookL2","action":"update","data":[{"symbol":"XBTUSD","id":8798373850,"side":"Buy","size":502},{"symbol":"XBTUSD","id":8798373900,"side":"Buy","size":18605}]}
09:57:39   {"table":"orderBookL2","action":"delete","data":[{"symbol":"XBTZ17","id":22899833940,"side":"Sell"},{"symbol":"XBTZ17","id":22899834005,"side":"Sell"}]}
09:57:39   {"table":"orderBookL2","action":"delete","data":[{"symbol":"XBTUSD","id":8798350150,"side":"Sell"}]}
09:57:39   {"table":"orderBookL2","action":"update","data":[{"symbol":"XBTZ17","id":22899833925,"side":"Sell","size":8060},{"symbol":"XBTZ17","id":22899833970,"side":"Sell","size":7000}]}
09:57:39   {"table":"orderBookL2","action":"insert","data":[{"symbol":"XBTZ17","id":22899833890,"side":"Sell","size":8000,"price":16611},{"symbol":"XBTZ17","id":22899833955,"side":"Sell","size":8000,"price":16604.5}]}
09:57:39   {"table":"orderBookL2","action":"update","data":[{"symbol":"XBTUSD","id":8798351200,"side":"Sell","size":186252},{"symbol":"XBTUSD","id":8798369950,"side":"Buy","size":43},{"symbol":"XBTUSD","id":8798371550,"side":"Buy","size":186458}]}
09:57:39   {"table":"orderBookL2","action":"insert","data":[{"symbol":"XBTUSD","id":8798345500,"side":"Sell","size":2500,"price":16545},{"symbol":"XBTUSD","id":8798359900,"side":"Sell","size":2500,"price":16401}]}
09:57:39   {"table":"orderBookL2","action":"update","data":[{"symbol":"XBTZ17","id":22899834150,"side":"Sell","size":59253}]}
09:57:39   {"table":"orderBookL2","action":"insert","data":[{"symbol":"XBTZ17","id":22899834290,"side":"Sell","size":4000,"price":16571}]}
09:57:39   {"table":"orderBookL2","action":"update","data":[{"symbol":"XBTUSD","id":8798373850,"side":"Buy","size":702},{"symbol":"XBTUSD","id":8798373900,"side":"Buy","size":18405}]}
09:57:39   {"table":"orderBookL2","action":"update","data":[{"symbol":"XBTUSD","id":8798360500,"side":"Sell","size":600}]}
09:57:39   {"table":"orderBookL2","action":"delete","data":[{"symbol":"XBTZ17","id":22899832970,"side":"Sell"},{"symbol":"XBTZ17","id":22899833120,"side":"Sell"},{"symbol":"XBTZ17","id":22899833165,"side":"Sell"},{"symbol":"XBTZ17","id":22899833330,"side":"Sell"},{"symbol":"XBTZ17","id":22899833430,"side":"Sell"},{"symbol":"XBTZ17","id":22899835105,"side":"Buy"},{"symbol":"XBTZ17","id":22899835225,"side":"Buy"}]}
09:57:39   {"table":"orderBookL2","action":"delete","data":[{"symbol":"XBTUSD","id":8798862300,"side":"Buy"}]}
09:57:39   {"table":"orderBookL2","action":"update","data":[{"symbol":"XBTZ17","id":22899833340,"side":"Sell","size":77},{"symbol":"XBTZ17","id":22899833565,"side":"Sell","size":13850},{"symbol":"XBTZ17","id":22899835240,"side":"Buy","size":730},{"symbol":"XBTZ17","id":22899835360,"side":"Buy","size":1682}]}
09:57:39   {"table":"orderBookL2","action":"insert","data":[{"symbol":"XBTUSD","id":8798860100,"side":"Buy","size":1,"price":11399}]}
09:57:39   {"table":"orderBookL2","action":"insert","data":[{"symbol":"XBTZ17","id":22899833290,"side":"Sell","size":6850,"price":16671},{"symbol":"XBTZ17","id":22899833305,"side":"Sell","size":6890,"price":16669.5},{"symbol":"XBTZ17","id":22899833480,"side":"Sell","size":3570,"price":16652},{"symbol":"XBTZ17","id":22899833655,"side":"Sell","size":6890,"price":16634.5},{"symbol":"XBTZ17","id":22899833750,"side":"Sell","size":5850,"price":16625}]}
09:57:39   {"table":"orderBookL2","action":"update","data":[{"symbol":"XBTUSD","id":8798360500,"side":"Sell","size":3600}]}
09:57:39   {"table":"orderBookL2","action":"update","data":[{"symbol":"XBTUSD","id":8798362150,"side":"Sell","size":11331}]}
09:57:39   {"table":"orderBookL2","action":"delete","data":[{"symbol":"XBTZ17","id":22899834455,"side":"Buy"}]}
09:57:39   {"table":"orderBookL2","action":"update","data":[{"symbol":"XBTZ17","id":22899834505,"side":"Buy","size":37050}]}
09:57:39   {"table":"orderBookL2","action":"update","data":[{"symbol":"XBTZ17","id":22899834325,"side":"Sell","size":16500}]}
09:57:39   {"table":"orderBookL2","action":"update","data":[{"symbol":"XBTUSD","id":8798359500,"side":"Sell","size":3850}]}
09:57:39   {"table":"orderBookL2","action":"delete","data":[{"symbol":"XBTZ17","id":22899834590,"side":"Buy"}]}
09:57:39   {"table":"orderBookL2","action":"update","data":[{"symbol":"XBTUSD","id":8798357500,"side":"Sell","size":142265}]}
09:57:39   {"table":"orderBookL2","action":"update","data":[{"symbol":"XBTUSD","id":8798360500,"side":"Sell","size":6600}]}
09:57:39   {"table":"orderBookL2","action":"update","data":[{"symbol":"XBTZ17","id":22899834325,"side":"Sell","size":15500}]}
09:57:39   {"table":"orderBookL2","action":"update","data":[{"symbol":"XBTUSD","id":8798363950,"side":"Buy","size":10243},{"symbol":"XBTUSD","id":8798364450,"side":"Buy","size":10000},{"symbol":"XBTUSD","id":8798364900,"side":"Buy","size":30000},{"symbol":"XBTUSD","id":8798364950,"side":"Buy","size":43},{"symbol":"XBTUSD","id":8798365250,"side":"Buy","size":17000},{"symbol":"XBTUSD","id":8798365400,"side":"Buy","size":15409},{"symbol":"XBTUSD","id":8798366250,"side":"Buy","size":3776}]}
09:57:39   {"table":"orderBookL2","action":"insert","data":[{"symbol":"XBTUSD","id":8798366550,"side":"Buy","size":10000,"price":16334.5}]}
09:57:39   {"table":"orderBookL2","action":"delete","data":[{"symbol":"XBTZ17","id":22899834135,"side":"Sell"}]}
09:57:39   {"table":"orderBookL2","action":"update","data":[{"symbol":"XBTUSD","id":8798373500,"side":"Buy","size":7000}]}
09:57:39   {"table":"orderBookL2","action":"insert","data":[{"symbol":"XBTUSD","id":8798360200,"side":"Sell","size":30000,"price":16398}]}
09:57:39   {"table":"orderBookL2","action":"update","data":[{"symbol":"XBTZ17","id":22899833520,"side":"Sell","size":18000}]}
09:57:39   {"table":"orderBookL2","action":"insert","data":[{"symbol":"XBTZ17","id":22899833600,"side":"Sell","size":8000,"price":16640}]}
09:57:39   {"table":"orderBookL2","action":"delete","data":[{"symbol":"XBTZ17","id":22899833105,"side":"Sell"}]}
09:57:39   {"table":"orderBookL2","action":"insert","data":[{"symbol":"XBTUSD","id":8798297150,"side":"Sell","size":10044,"price":17028.5}]}
09:57:39   {"table":"orderBookL2","action":"update","data":[{"symbol":"XBTUSD","id":8798360500,"side":"Sell","size":6610}]}
09:57:39   {"table":"orderBookL2","action":"update","data":[{"symbol":"XBTUSD","id":8798358150,"side":"Sell","size":34800}]}
09:57:39   {"table":"orderBookL2","action":"update","data":[{"symbol":"XBTZ17","id":22899833510,"side":"Sell","size":88526}]}
09:57:39   {"table":"orderBookL2","action":"insert","data":[{"symbol":"XBTZ17","id":22899832990,"side":"Sell","size":7000,"price":16701},{"symbol":"XBTZ17","id":22899833420,"side":"Sell","size":7000,"price":16658}]}
09:57:39   {"table":"orderBookL2","action":"delete","data":[{"symbol":"XBTZ17","id":22899833790,"side":"Sell"},{"symbol":"XBTZ17","id":22899833830,"side":"Sell"},{"symbol":"XBTZ17","id":22899833970,"side":"Sell"}]}
09:57:39   {"table":"orderBookL2","action":"update","data":[{"symbol":"XBTZ17","id":22899833910,"side":"Sell","size":12059}]}
09:57:39   {"table":"orderBookL2","action":"update","data":[{"symbol":"XBTUSD","id":8798359950,"side":"Sell","size":66835},{"symbol":"XBTUSD","id":8798360500,"side":"Sell","size":16610}]}
09:57:39   {"table":"orderBookL2","action":"update","data":[{"symbol":"XBTUSD","id":8798358350,"side":"Sell","size":62500}]}
09:57:39   {"table":"orderBookL2","action":"insert","data":[{"symbol":"XBTZ17","id":22899833875,"side":"Sell","size":7000,"price":16612.5},{"symbol":"XBTZ17","id":22899834070,"side":"Sell","size":7000,"price":16593}]}
09:57:39   {"table":"orderBookL2","action":"delete","data":[{"symbol":"XBTUSD","id":8798366500,"side":"Buy"},{"symbol":"XBTUSD","id":8798367150,"side":"Buy"},{"symbol":"XBTUSD","id":8798370250,"side":"Buy"}]}
09:57:39   {"table":"orderBookL2","action":"update","data":[{"symbol":"XBTUSD","id":8798365250,"side":"Buy","size":10000},{"symbol":"XBTUSD","id":8798367500,"side":"Buy","size":7000},{"symbol":"XBTUSD","id":8798368750,"side":"Buy","size":11100},{"symbol":"XBTUSD","id":8798373550,"side":"Buy","size":5120}]}
09:57:39   {"table":"orderBookL2","action":"insert","data":[{"symbol":"XBTZ17","id":22899836290,"side":"Buy","size":20000,"price":16371}]}
09:57:39   {"table":"orderBookL2","action":"delete","data":[{"symbol":"XBTZ17","id":22899833230,"side":"Sell"},{"symbol":"XBTZ17","id":22899833680,"side":"Sell"}]}
09:57:39   {"table":"orderBookL2","action":"insert","data":[{"symbol":"XBTUSD","id":8798367450,"side":"Buy","size":7000,"price":16325.5},{"symbol":"XBTUSD","id":8798369100,"side":"Buy","size":7000,"price":16309},{"symbol":"XBTUSD","id":8798369600,"side":"Buy","size":7000,"price":16304}]}
09:57:39   {"table":"orderBookL2","action":"update","data":[{"symbol":"XBTZ17","id":22899833585,"side":"Sell","size":9000}]}
09:57:39   {"table":"orderBookL2","action":"insert","data":[{"symbol":"XBTZ17","id":22899833110,"side":"Sell","size":7000,"price":16689}]}
09:57:39   {"table":"orderBookL2","action":"update","data":[{"symbol":"XBTZ17","id":22899834150,"side":"Sell","size":7253},{"symbol":"XBTZ17","id":22899834290,"side":"Sell","size":56000}]}
09:57:39   {"table":"orderBookL2","action":"delete","data":[{"symbol":"XBTZ17","id":22899832795,"side":"Sell"}]}
09:57:39   {"table":"orderBookL2","action":"delete","data":[{"symbol":"XBTZ17","id":22899841550,"side":"Buy"}]}
09:57:39   {"table":"orderBookL2","action":"update","data":[{"symbol":"XBTUSD","id":8798355000,"side":"Sell","size":31210}]}
09:57:39   {"table":"orderBookL2","action":"delete","data":[{"symbol":"XBTUSD","id":8798359400,"side":"Sell"}]}
09:57:39   {"table":"orderBookL2","action":"update","data":[{"symbol":"XBTZ17","id":22899833515,"side":"Sell","size":8000}]}
09:57:39   {"table":"orderBookL2","action":"delete","data":[{"symbol":"XBTZ17","id":22899831625,"side":"Sell"},{"symbol":"XBTZ17","id":22899831870,"side":"Sell"},{"symbol":"XBTZ17","id":22899832120,"side":"Sell"},{"symbol":"XBTZ17","id":22899832370,"side":"Sell"},{"symbol":"XBTZ17","id":22899832615,"side":"Sell"},{"symbol":"XBTZ17","id":22899832865,"side":"Sell"},{"symbol":"XBTZ17","id":22899833115,"side":"Sell"},{"symbol":"XBTZ17","id":22899833360,"side":"Sell"},{"symbol":"XBTZ17","id":22899836500,"side":"Buy"},{"symbol":"XBTZ17","id":22899836750,"side":"Buy"},{"symbol":"XBTZ17","id":22899837245,"side":"Buy"},{"symbol":"XBTZ17","id":22899837490,"side":"Buy"},{"symbol":"XBTZ17","id":22899837735,"side":"Buy"},{"symbol":"XBTZ17","id":22899837985,"side":"Buy"},{"symbol":"XBTZ17","id":22899838230,"side":"Buy"}]}
09:57:39   {"table":"orderBookL2","action":"update","data":[{"symbol":"XBTUSD","id":8798359950,"side":"Sell","size":66967}]}
09:57:39   {"table":"orderBookL2","action":"delete","data":[{"symbol":"XBTUSD","id":8798353600,"side":"Sell"}]}
09:57:39   {"table":"orderBookL2","action":"update","data":[{"symbol":"XBTZ17","id":22899836995,"side":"Buy","size":5000}]}
09:57:39   {"table":"orderBookL2","action":"insert","data":[{"symbol":"XBTZ17","id":22899831665,"side":"Sell","size":5000,"price":16833.5},{"symbol":"XBTZ17","id":22899831910,"side":"Sell","size":5000,"price":16809},{"symbol":"XBTZ17","id":22899832160,"side":"Sell","size":5000,"price":16784},{"symbol":"XBTZ17","id":22899832410,"side":"Sell","size":5000,"price":16759},{"symbol":"XBTZ17","id":22899832655,"side":"Sell","size":5000,"price":16734.5},{"symbol":"XBTZ17","id":22899832905,"side":"Sell","size":5000,"price":16709.5},{"symbol":"XBTZ17","id":22899833155,"side":"Sell","size":5000,"price":16684.5},{"symbol":"XBTZ17","id":22899833400,"side":"Sell","size":5000,"price":16660},{"symbol":"XBTZ17","id":22899836525,"side":"Buy","size":5000,"price":16347.5},{"symbol":"XBTZ17","id":22899836770,"side":"Buy","size":5000,"price":16323},{"symbol":"XBTZ17","id":22899837020,"side":"Buy","size":5000,"price":16298},{"symbol":"XBTZ17","id":22899837265,"side":"Buy","size":5000,"price":16273.5},{"symbol":"XBTZ17","id":22899837510,"side":"Buy","size":5000,"price":16249},{"symbol":"XBTZ17","id":22899837760,"side":"Buy","size":5000,"price":16224},{"symbol":"XBTZ17","id":22899838005,"side":"Buy","size":5000,"price":16199.5},{"symbol":"XBTZ17","id":22899838255,"side":"Buy","size":5000,"price":16174.5}]}
09:57:39   {"table":"orderBookL2","action":"update","data":[{"symbol":"XBTUSD","id":8798353800,"side":"Sell","size":4212},{"symbol":"XBTUSD","id":8798366900,"side":"Buy","size":7155}]}
09:57:39   {"table":"orderBookL2","action":"insert","data":[{"symbol":"XBTUSD","id":8798365500,"side":"Buy","size":12017,"price":16345}]}
09:57:39   {"table":"orderBookL2","action":"delete","data":[{"symbol":"XBTZ17","id":22899834325,"side":"Sell"}]}
09:57:39   {"table":"orderBookL2","action":"update","data":[{"symbol":"XBTUSD","id":8798360500,"side":"Sell","size":16620}]}
09:57:39   {"table":"orderBookL2","action":"update","data":[{"symbol":"XBTZ17","id":22899835120,"side":"Buy","size":63950}]}
09:57:39   {"table":"orderBookL2","action":"update","data":[{"symbol":"XBTUSD","id":8798360500,"side":"Sell","size":16630}]}
09:57:39   {"table":"orderBookL2","action":"delete","data":[{"symbol":"XBTUSD","id":8798364600,"side":"Buy"}]}
09:57:39   {"table":"orderBookL2","action":"insert","data":[{"symbol":"XBTZ17","id":22899834490,"side":"Buy","size":50000,"price":16551}]}
09:57:39   {"table":"orderBookL2","action":"update","data":[{"symbol":"XBTUSD","id":8798364850,"side":"Buy","size":6776}]}
09:57:39   {"table":"orderBookL2","action":"update","data":[{"symbol":"XBTUSD","id":8798360500,"side":"Sell","size":16640}]}
09:57:39   {"table":"orderBookL2","action":"insert","data":[{"symbol":"XBTZ17","id":22899833470,"side":"Sell","size":14000,"price":16653}]}
09:57:39   {"table":"orderBookL2","action":"delete","data":[{"symbol":"XBTZ17","id":22899833315,"side":"Sell"},{"symbol":"XBTZ17","id":22899834970,"side":"Buy"},{"symbol":"XBTZ17","id":22899835075,"side":"Buy"}]}
09:57:39   {"table":"orderBookL2","action":"update","data":[{"symbol":"XBTUSD","id":8798359950,"side":"Sell","size":60386}]}
09:57:39   {"table":"orderBookL2","action":"update","data":[{"symbol":"XBTZ17","id":22899833480,"side":"Sell","size":10570},{"symbol":"XBTZ17","id":22899833565,"side":"Sell","size":6850},{"symbol":"XBTZ17","id":22899834975,"side":"Buy","size":49450},{"symbol":"XBTZ17","id":22899835120,"side":"Buy","size":56900}]}
09:57:39   {"table":"orderBookL2","action":"update","data":[{"symbol":"XBTUSD","id":8798359200,"side":"Sell","size":17675},{"symbol":"XBTUSD","id":8798359950,"side":"Sell","size":60586}]}
09:57:39   {"table":"orderBookL2","action":"update","data":[{"symbol":"XBTUSD","id":8798360050,"side":"Sell","size":25280}]}
09:57:39   {"table":"orderBookL2","action":"insert","data":[{"symbol":"XBTZ17","id":22899833225,"side":"Sell","size":7000,"price":16677.5},{"symbol":"XBTZ17","id":22899834875,"side":"Buy","size":7050,"price":16512.5},{"symbol":"XBTZ17","id":22899835010,"side":"Buy","size":7050,"price":16499}]}
09:57:39   {"table":"orderBookL2","action":"delete","data":[{"symbol":"XBTZ17","id":22899833515,"side":"Sell"}]}
09:57:39   {"table":"orderBookL2","action":"update","data":[{"symbol":"XBTUSD","id":8798360050,"side":"Sell","size":22280}]}
09:57:39   {"table":"orderBookL2","action":"update","data":[{"symbol":"XBTZ17","id":22899833520,"side":"Sell","size":10000}]}
09:57:39   {"table":"orderBookL2","action":"delete","data":[{"symbol":"XBTUSD","id":8798367100,"side":"Buy"}]}
09:57:39   {"table":"orderBookL2","action":"update","data":[{"symbol":"XBTUSD","id":8798370200,"side":"Buy","size":6425}]}
09:57:39   {"table":"orderBookL2","action":"insert","data":[{"symbol":"XBTZ17","id":22899839805,"side":"Buy","size":152,"price":16019.5}]}
09:57:39   {"table":"orderBookL2","action":"delete","data":[{"symbol":"XBTZ17","id":22899833880,"side":"Sell"},{"symbol":"XBTZ17","id":22899838920,"side":"Buy"}]}
09:57:39   {"table":"orderBookL2","action":"update","data":[{"symbol":"XBTUSD","id":8798360000,"side":"Sell","size":2064724}]}
09:57:39   {"table":"orderBookL2","action":"insert","data":[{"symbol":"XBTZ17","id":22899834155,"side":"Sell","size":6653,"price":16584.5},{"symbol":"XBTZ17","id":22899839175,"side":"Buy","size":9167,"price":16082.5}]}
09:57:39   {"table":"orderBookL2","action":"update","data":[{"symbol":"XBTZ17","id":22899833585,"side":"Sell","size":7000}]}
09:57:39   {"table":"orderBookL2","action":"insert","data":[{"symbol":"XBTUSD","id":8798426250,"side":"Buy","size":403,"price":15737.5}]}
09:57:39   {"table":"orderBookL2","action":"delete","data":[{"symbol":"XBTUSD","id":8798310300,"side":"Sell"}]}
09:57:39   {"table":"orderBookL2","action":"insert","data":[{"symbol":"XBTUSD","id":8798309250,"side":"Sell","size":40,"price":16907.5}]}
09:57:39   {"table":"orderBookL2","action":"update","data":[{"symbol":"XBTUSD","id":8798358350,"side":"Sell","size":57300}]}
09:57:39   {"table":"orderBookL2","action":"insert","data":[{"symbol":"XBTZ17","id":22899834305,"side":"Sell","size":1541,"price":16569.5}]}
09:57:39   {"table":"orderBookL2","action":"update","data":[{"symbol":"XBTUSD","id":8798364000,"side":"Buy","size":1007}]}
09:57:39   {"table":"orderBookL2","action":"delete","data":[{"symbol":"XBTUSD","id":8798377500,"side":"Buy"}]}
09:57:39   {"table":"orderBookL2","action":"delete","data":[{"symbol":"XBTZ17","id":22899834150,"side":"Sell"}]}
09:57:39   {"table":"orderBookL2","action":"delete","data":[{"symbol":"XBTZ17","id":22899834770,"side":"Buy"}]}
09:57:39   {"table":"orderBookL2","action":"update","data":[{"symbol":"XBTUSD","id":8798365800,"side":"Buy","size":759},{"symbol":"XBTUSD","id":8798367200,"side":"Buy","size":168}]}
09:57:39   {"table":"orderBookL2","action":"insert","data":[{"symbol":"XBTUSD","id":8798363600,"side":"Buy","size":35,"price":16364}]}
09:57:39   {"table":"orderBookL2","action":"insert","data":[{"symbol":"XBTZ17","id":22899834840,"side":"Buy","size":8000,"price":16516}]}
09:57:39   {"table":"orderBookL2","action":"update","data":[{"symbol":"XBTZ17","id":22899834490,"side":"Buy","size":46817}]}
09:57:39   {"table":"orderBookL2","action":"delete","data":[{"symbol":"XBTZ17","id":22899833290,"side":"Sell"},{"symbol":"XBTZ17","id":22899833305,"side":"Sell"},{"symbol":"XBTZ17","id":22899833565,"side":"Sell"},{"symbol":"XBTZ17","id":22899833655,"side":"Sell"},{"symbol":"XBTZ17","id":22899833750,"side":"Sell"}]}
09:57:39   {"table":"orderBookL2","action":"insert","data":[{"symbol":"XBTUSD","id":8798355950,"side":"Sell","size":319000,"price":16440.5}]}
09:57:39   {"table":"orderBookL2","action":"update","data":[{"symbol":"XBTUSD","id":8798364050,"side":"Buy","size":3914},{"symbol":"XBTUSD","id":8798364650,"side":"Buy","size":2301}]}
09:57:39   {"table":"orderBookL2","action":"update","data":[{"symbol":"XBTUSD","id":8798360050,"side":"Sell","size":32280}]}
09:57:39   {"table":"orderBookL2","action":"update","data":[{"symbol":"XBTZ17","id":22899833395,"side":"Sell","size":3630},{"symbol":"XBTZ17","id":22899833480,"side":"Sell","size":7000},{"symbol":"XBTZ17","id":22899835240,"side":"Buy","size":100},{"symbol":"XBTZ17","id":22899835360,"side":"Buy","size":112}]}
09:57:39   {"table":"orderBookL2","action":"insert","data":[{"symbol":"XBTZ17","id":22899833210,"side":"Sell","size":6850,"price":16679},{"symbol":"XBTZ17","id":22899833275,"side":"Sell","size":6890,"price":16672.5},{"symbol":"XBTZ17","id":22899833455,"side":"Sell","size":6850,"price":16654.5},{"symbol":"XBTZ17","id":22899833570,"side":"Sell","size":6890,"price":16643},{"symbol":"XBTZ17","id":22899833660,"side":"Sell","size":5850,"price":16634},{"symbol":"XBTZ17","id":22899835100,"side":"Buy","size":630,"price":16490},{"symbol":"XBTZ17","id":22899835220,"side":"Buy","size":1570,"price":16478}]}
09:57:39   {"table":"orderBookL2","action":"delete","data":[{"symbol":"XBTZ17","id":22899832990,"side":"Sell"},{"symbol":"XBTZ17","id":22899833420,"side":"Sell"}]}
09:57:39   {"table":"orderBookL2","action":"update","data":[{"symbol":"XBTUSD","id":8798360500,"side":"Sell","size":17640}]}
09:57:40   {"table":"orderBookL2","action":"update","data":[{"symbol":"XBTUSD","id":8798358150,"side":"Sell","size":29800}]}
09:57:40   {"table":"orderBookL2","action":"update","data":[{"symbol":"XBTUSD","id":8798371000,"side":"Buy","size":8000}]}
09:57:40   {"table":"orderBookL2","action":"insert","data":[{"symbol":"XBTZ17","id":22899833080,"side":"Sell","size":7000,"price":16692},{"symbol":"XBTZ17","id":22899833460,"side":"Sell","size":7000,"price":16654}]}
09:57:40   {"table":"orderBookL2","action":"update","data":[{"symbol":"XBTUSD","id":8798371700,"side":"Buy","size":340},{"symbol":"XBTUSD","id":8798372600,"side":"Buy","size":100},{"symbol":"XBTUSD","id":8798373100,"side":"Buy","size":51}]}
09:57:40   {"table":"orderBookL2","action":"update","data":[{"symbol":"XBTZ17","id":22899834490,"side":"Buy","size":41817}]}
09:57:40   {"table":"orderBookL2","action":"insert","data":[{"symbol":"XBTUSD","id":8798372200,"side":"Buy","size":100,"price":16278}]}
09:57:40   {"table":"orderBookL2","action":"update","data":[{"symbol":"XBTUSD","id":8798371000,"side":"Buy","size":5500}]}
09:57:40   {"table":"orderBookL2","action":"delete","data":[{"symbol":"XBTZ17","id":22899826660,"side":"Sell"},{"symbol":"XBTZ17","id":22899828140,"side":"Sell"},{"symbol":"XBTZ17","id":22899829630,"side":"Sell"},{"symbol":"XBTZ17","id":22899831120,"side":"Sell"},{"symbol":"XBTZ17","id":22899833780,"side":"Sell"},{"symbol":"XBTZ17","id":22899835620,"side":"Buy"},{"symbol":"XBTZ17","id":22899835900,"side":"Buy"},{"symbol":"XBTZ17","id":22899836180,"side":"Buy"},{"symbol":"XBTZ17","id":22899836450,"side":"Buy"},{"symbol":"XBTZ17","id":22899836730,"side":"Buy"},{"symbol":"XBTZ17","id":22899837000,"side":"Buy"}]}
09:57:40   {"table":"orderBookL2","action":"update","data":[{"symbol":"XBTUSD","id":8798360500,"side":"Sell","size":67640}]}
09:57:40   {"table":"orderBookL2","action":"update","data":[{"symbol":"XBTZ17","id":22899828100,"side":"Sell","size":225472},{"symbol":"XBTZ17","id":22899829600,"side":"Sell","size":418},{"symbol":"XBTZ17","id":22899832600,"side":"Sell","size":78},{"symbol":"XBTZ17","id":22899835010,"side":"Buy","size":7218}]}
09:57:40   {"table":"orderBookL2","action":"insert","data":[{"symbol":"XBTZ17","id":22899825110,"side":"Sell","size":302,"price":17489},{"symbol":"XBTZ17","id":22899826600,"side":"Sell","size":257,"price":17340},{"symbol":"XBTZ17","id":22899831100,"side":"Sell","size":123,"price":16890},{"symbol":"XBTZ17","id":22899834450,"side":"Buy","size":78,"price":16555},{"symbol":"XBTZ17","id":22899834730,"side":"Buy","size":123,"price":16527},{"symbol":"XBTZ17","id":22899835290,"side":"Buy","size":212,"price":16471},{"symbol":"XBTZ17","id":22899835570,"side":"Buy","size":257,"price":16443},{"symbol":"XBTZ17","id":22899835840,"side":"Buy","size":302,"price":16416}]}
09:57:40   {"table":"orderBookL2","action":"update","data":[{"symbol":"XBTUSD","id":8798357800,"side":"Sell","size":75392}]}
09:57:40   {"table":"orderBookL2","action":"delete","data":[{"symbol":"XBTUSD","id":8798366250,"side":"Buy"}]}
09:57:40   {"table":"orderBookL2","action":"delete","data":[{"symbol":"XBTZ17","id":22899833890,"side":"Sell"},{"symbol":"XBTZ17","id":22899833955,"side":"Sell"}]}
09:57:40   {"table":"orderBookL2","action":"update","data":[{"symbol":"XBTZ17","id":22899833925,"side":"Sell","size":60}]}
09:57:40   {"table":"orderBookL2","action":"update","data":[{"symbol":"XBTUSD","id":8798365400,"side":"Buy","size":19185}]}
09:57:40   {"table":"orderBookL2","action":"update","data":[{"symbol":"XBTUSD","id":8798380100,"side":"Buy","size":90494}]}
09:57:40   {"table":"orderBookL2","action":"delete","data":[{"symbol":"XBTUSD","id":8798365550,"side":"Buy"}]}
09:57:40   {"table":"orderBookL2","action":"insert","data":[{"symbol":"XBTZ17","id":22899833950,"side":"Sell","size":8000,"price":16605},{"symbol":"XBTZ17","id":22899833985,"side":"Sell","size":8000,"price":16601.5},{"symbol":"XBTZ17","id":22899834015,"side":"Sell","size":8000,"price":16598.5}]}
09:57:40   {"table":"orderBookL2","action":"delete","data":[{"symbol":"XBTZ17","id":22899833640,"side":"Sell"}]}
09:57:40   {"table":"orderBookL2","action":"update","data":[{"symbol":"XBTUSD","id":8798364650,"side":"Buy","size":6077}]}
09:57:40   {"table":"orderBookL2","action":"delete","data":[{"symbol":"XBTUSD","id":8798366700,"side":"Buy"}]}
09:57:40   {"table":"orderBookL2","action":"update","data":[{"symbol":"XBTZ17","id":22899833570,"side":"Sell","size":13890},{"symbol":"XBTZ17","id":22899833910,"side":"Sell","size":7000}]}
09:57:40   {"table":"orderBookL2","action":"insert","data":[{"symbol":"XBTZ17","id":22899833810,"side":"Sell","size":5059,"price":16619}]}
09:57:40   {"table":"orderBookL2","action":"update","data":[{"symbol":"XBTUSD","id":8798365800,"side":"Buy","size":4535}]}
09:57:40   {"table":"orderBookL2","action":"delete","data":[{"symbol":"XBTUSD","id":8798363300,"side":"Buy"},{"symbol":"XBTUSD","id":8798363600,"side":"Buy"},{"symbol":"XBTUSD","id":8798363750,"side":"Buy"}]}
09:57:40   {"table":"orderBookL2","action":"delete","data":[{"symbol":"XBTZ17","id":22899833875,"side":"Sell"},{"symbol":"XBTZ17","id":22899833910,"side":"Sell"},{"symbol":"XBTZ17","id":22899834070,"side":"Sell"}]}
09:57:40   {"table":"orderBookL2","action":"update","data":[{"symbol":"XBTZ17","id":22899833795,"side":"Sell","size":47000}]}
09:57:40   {"table":"orderBookL2","action":"update","data":[{"symbol":"XBTUSD","id":8798363900,"side":"Buy","size":242675}]}
09:57:40   {"table":"orderBookL2","action":"insert","data":[{"symbol":"XBTZ17","id":22899833755,"side":"Sell","size":7000,"price":16624.5},{"symbol":"XBTZ17","id":22899833975,"side":"Sell","size":7000,"price":16602.5}]}
09:57:40   {"table":"orderBookL2","action":"update","data":[{"symbol":"XBTUSD","id":8798358350,"side":"Sell","size":63500}]}
09:57:40   {"table":"orderBookL2","action":"update","data":[{"symbol":"XBTUSD","id":8798358400,"side":"Sell","size":11100}]}
09:57:40   {"table":"orderBookL2","action":"delete","data":[{"symbol":"XBTZ17","id":22899833110,"side":"Sell"},{"symbol":"XBTZ17","id":22899833585,"side":"Sell"}]}
09:57:40   {"table":"orderBookL2","action":"update","data":[{"symbol":"XBTUSD","id":8798360000,"side":"Sell","size":2014724}]}
09:57:40   {"table":"orderBookL2","action":"insert","data":[{"symbol":"XBTZ17","id":22899833200,"side":"Sell","size":7000,"price":16680},{"symbol":"XBTZ17","id":22899833625,"side":"Sell","size":7000,"price":16637.5}]}
09:57:40   {"table":"orderBookL2","action":"insert","data":[{"symbol":"XBTZ17","id":22899833590,"side":"Sell","size":1000,"price":16641}]}
09:57:40   {"table":"orderBookL2","action":"insert","data":[{"symbol":"XBTUSD","id":8798354100,"side":"Sell","size":50000,"price":16459}]}
09:57:40   {"table":"orderBookL2","action":"update","data":[{"symbol":"XBTUSD","id":8798361500,"side":"Sell","size":16000}]}
09:57:40   {"table":"orderBookL2","action":"update","data":[{"symbol":"XBTZ17","id":22899834290,"side":"Sell","size":4000}]}
09:57:40   {"table":"orderBookL2","action":"insert","data":[{"symbol":"XBTZ17","id":22899834330,"side":"Sell","size":52000,"price":16567}]}
09:57:40   {"table":"orderBookL2","action":"insert","data":[{"symbol":"XBTUSD","id":8798361950,"side":"Sell","size":6000,"price":16380.5}]}
09:57:40   {"table":"orderBookL2","action":"insert","data":[{"symbol":"XBTUSD","id":8798362250,"side":"Buy","size":6000,"price":16377.5}]}
09:57:40   {"table":"orderBookL2","action":"insert","data":[{"symbol":"XBTZ17","id":22899839995,"side":"Buy","size":10000,"price":16000.5}]}
09:57:40   {"table":"orderBookL2","action":"insert","data":[{"symbol":"XBTZ17","id":22899834500,"side":"Buy","size":5555,"price":16550}]}
09:57:40   {"table":"orderBookL2","action":"update","data":[{"symbol":"XBTUSD","id":8798362150,"side":"Sell","size":11081}]}
09:57:40   {"table":"orderBookL2","action":"update","data":[{"symbol":"XBTUSD","id":8798361500,"side":"Sell","size":22000}]}
09:57:40   {"table":"orderBookL2","action":"insert","data":[{"symbol":"XBTZ17","id":22899833530,"side":"Sell","size":6000,"price":16647}]}
09:57:40   {"table":"orderBookL2","action":"delete","data":[{"symbol":"XBTZ17","id":22899836525,"side":"Buy"},{"symbol":"XBTZ17","id":22899836770,"side":"Buy"},{"symbol":"XBTZ17","id":22899837020,"side":"Buy"},{"symbol":"XBTZ17","id":22899837265,"side":"Buy"},{"symbol":"XBTZ17","id":22899837510,"side":"Buy"},{"symbol":"XBTZ17","id":22899837760,"side":"Buy"},{"symbol":"XBTZ17","id":22899838005,"side":"Buy"},{"symbol":"XBTZ17","id":22899838255,"side":"Buy"}]}
09:57:40   {"table":"orderBookL2","action":"update","data":[{"symbol":"XBTZ17","id":22899838285,"side":"Buy","size":5305}]}
09:57:40   {"table":"orderBookL2","action":"update","data":[{"symbol":"XBTUSD","id":8798362150,"side":"Sell","size":10831}]}
09:57:40   {"table":"orderBookL2","action":"insert","data":[{"symbol":"XBTUSD","id":8798362400,"side":"Buy","size":3000,"price":16376}]}
09:57:40   {"table":"orderBookL2","action":"update","data":[{"symbol":"XBTUSD","id":8798362150,"side":"Sell","size":9831}]}
09:57:40   {"table":"orderBookL2","action":"update","data":[{"symbol":"XBTUSD","id":8798362150,"side":"Sell","size":6831}]}
09:57:40   {"table":"orderBookL2","action":"delete","data":[{"symbol":"XBTUSD","id":8798355300,"side":"Sell"},{"symbol":"XBTUSD","id":8798364450,"side":"Buy"},{"symbol":"XBTUSD","id":8798366050,"side":"Buy"}]}
09:57:40   {"table":"orderBookL2","action":"insert","data":[{"symbol":"XBTZ17","id":22899836555,"side":"Buy","size":5000,"price":16344.5},{"symbol":"XBTZ17","id":22899836800,"side":"Buy","size":5000,"price":16320},{"symbol":"XBTZ17","id":22899837050,"side":"Buy","size":5000,"price":16295},{"symbol":"XBTZ17","id":22899837295,"side":"Buy","size":5000,"price":16270.5},{"symbol":"XBTZ17","id":22899837545,"side":"Buy","size":5000,"price":16245.5},{"symbol":"XBTZ17","id":22899837790,"side":"Buy","size":5000,"price":16221},{"symbol":"XBTZ17","id":22899838035,"side":"Buy","size":5000,"price":16196.5}]}
09:57:40   {"table":"orderBookL2","action":"delete","data":[{"symbol":"XBTZ17","id":22899834490,"side":"Buy"}]}
09:57:40   {"table":"orderBookL2","action":"delete","data":[{"symbol":"XBTZ17","id":22899829220,"side":"Sell"},{"symbol":"XBTZ17","id":22899830800,"side":"Sell"},{"symbol":"XBTZ17","id":22899832390,"side":"Sell"},{"symbol":"XBTZ17","id":22899836820,"side":"Buy"},{"symbol":"XBTZ17","id":22899837120,"side":"Buy"},{"symbol":"XBTZ17","id":22899837420,"side":"Buy"}]}
09:57:40   {"table":"orderBookL2","action":"update","data":[{"symbol":"XBTZ17","id":22899835040,"side":"Buy","size":4957},{"symbol":"XBTZ17","id":22899835940,"side":"Buy","size":317},{"symbol":"XBTZ17","id":22899836240,"side":"Buy","size":384},{"symbol":"XBTZ17","id":22899836530,"side":"Buy","size":450}]}
09:57:40   {"table":"orderBookL2","action":"insert","data":[{"symbol":"XBTZ17","id":22899828290,"side":"Sell","size":317,"price":17171},{"symbol":"XBTZ17","id":22899829880,"side":"Sell","size":250,"price":17012},{"symbol":"XBTZ17","id":22899831480,"side":"Sell","size":183,"price":16852},{"symbol":"XBTZ17","id":22899833070,"side":"Sell","size":117,"price":16693},{"symbol":"XBTZ17","id":22899835340,"side":"Buy","size":183,"price":16466},{"symbol":"XBTZ17","id":22899835640,"side":"Buy","size":250,"price":16436}]}
09:57:40   {"table":"orderBookL2","action":"update","data":[{"symbol":"XBTUSD","id":8798364900,"side":"Buy","size":20000},{"symbol":"XBTUSD","id":8798365900,"side":"Buy","size":94434},{"symbol":"XBTUSD","id":8798366400,"side":"Buy","size":10123},{"symbol":"XBTUSD","id":8798366650,"side":"Buy","size":250},{"symbol":"XBTUSD","id":8798368550,"side":"Buy","size":10400}]}
09:57:40   {"table":"orderBookL2","action":"insert","data":[{"symbol":"XBTUSD","id":8798356750,"side":"Sell","size":10000,"price":16432.5},{"symbol":"XBTUSD","id":8798367700,"side":"Buy","size":10000,"price":16323}]}
09:57:40   {"table":"orderBookL2","action":"delete","data":[{"symbol":"XBTUSD","id":8798366000,"side":"Buy"}]}
09:57:40   {"table":"orderBookL2","action":"update","data":[{"symbol":"XBTUSD","id":8798367800,"side":"Buy","size":21945}]}
09:57:40   {"table":"orderBookL2","action":"delete","data":[{"symbol":"XBTZ17","id":22899834450,"side":"Buy"}]}
09:57:40   {"table":"orderBookL2","action":"update","data":[{"symbol":"XBTZ17","id":22899834500,"side":"Buy","size":3033}]}
09:57:40   {"table":"orderBookL2","action":"delete","data":[{"symbol":"XBTZ17","id":22899833510,"side":"Sell"}]}
09:57:40   {"table":"orderBookL2","action":"insert","data":[{"symbol":"XBTZ17","id":22899833360,"side":"Sell","size":88526,"price":16664}]}
09:57:40   {"table":"orderBookL2","action":"delete","data":[{"symbol":"XBTZ17","id":22899833925,"side":"Sell"}]}
09:57:40   {"table":"orderBookL2","action":"insert","data":[{"symbol":"XBTUSD","id":8798364800,"side":"Buy","size":193,"price":16352}]}
09:57:40   {"table":"orderBookL2","action":"delete","data":[{"symbol":"XBTUSD","id":8798362250,"side":"Buy"},{"symbol":"XBTUSD","id":8798362400,"side":"Buy"}]}
09:57:40   {"table":"orderBookL2","action":"update","data":[{"symbol":"XBTUSD","id":8798363900,"side":"Buy","size":231675}]}
09:57:40   {"table":"orderBookL2","action":"delete","data":[{"symbol":"XBTUSD","id":8798319100,"side":"Sell"},{"symbol":"XBTUSD","id":8798366600,"side":"Buy"},{"symbol":"XBTUSD","id":8798376700,"side":"Buy"},{"symbol":"XBTUSD","id":8798383400,"side":"Buy"}]}
09:57:40   {"table":"orderBookL2","action":"update","data":[{"symbol":"XBTUSD","id":8798312600,"side":"Sell","size":412},{"symbol":"XBTUSD","id":8798327400,"side":"Sell","size":5298},{"symbol":"XBTUSD","id":8798333800,"side":"Sell","size":700},{"symbol":"XBTUSD","id":8798342300,"side":"Sell","size":296},{"symbol":"XBTUSD","id":8798348600,"side":"Sell","size":13441},{"symbol":"XBTUSD","id":8798370000,"side":"Buy","size":101310},{"symbol":"XBTUSD","id":8798373400,"side":"Buy","size":6952},{"symbol":"XBTUSD","id":8798377200,"side":"Buy","size":3811},{"symbol":"XBTUSD","id":8798380000,"side":"Buy","size":2620}]}
09:57:40   {"table":"orderBookL2","action":"insert","data":[{"symbol":"XBTZ17","id":22899833710,"side":"Sell","size":60,"price":16629}]}
09:57:40   {"table":"orderBookL2","action":"delete","data":[{"symbol":"XBTZ17","id":22899835185,"side":"Buy"},{"symbol":"XBTZ17","id":22899835535,"side":"Buy"}]}
09:57:40   {"table":"orderBookL2","action":"insert","data":[{"symbol":"XBTZ17","id":22899835545,"side":"Buy","size":25095,"price":16445.5},{"symbol":"XBTZ17","id":22899836010,"side":"Buy","size":80000,"price":16399}]}
09:57:40   {"table":"orderBookL2","action":"delete","data":[{"symbol":"XBTZ17","id":22899833480,"side":"Sell"},{"symbol":"XBTZ17","id":22899834875,"side":"Buy"}]}
09:57:40   {"table":"orderBookL2","action":"insert","data":[{"symbol":"XBTZ17","id":22899833025,"side":"Sell","size":7000,"price":16697.5},{"symbol":"XBTZ17","id":22899834485,"side":"Buy","size":7050,"price":16551.5}]}
09:57:40   {"table":"orderBookL2","action":"insert","data":[{"symbol":"XBTUSD","id":8798363800,"side":"Buy","size":73,"price":16362},{"symbol":"XBTUSD","id":8798367100,"side":"Buy","size":100,"price":16329},{"symbol":"XBTUSD","id":8798370400,"side":"Buy","size":126,"price":16296},{"symbol":"XBTUSD","id":8798373800,"side":"Buy","size":153,"price":16262}]}
09:57:40   {"table":"orderBookL2","action":"update","data":[{"symbol":"XBTUSD","id":8798365000,"side":"Buy","size":6810},{"symbol":"XBTUSD","id":8798365300,"side":"Buy","size":5129}]}
09:57:40   {"table":"orderBookL2","action":"update","data":[{"symbol":"XBTUSD","id":8798362150,"side":"Sell","size":6431}]}
09:57:40   {"table":"orderBookL2","action":"update","data":[{"symbol":"XBTZ17","id":22899835010,"side":"Buy","size":168}]}
09:57:40   {"table":"orderBookL2","action":"insert","data":[{"symbol":"XBTZ17","id":22899834605,"side":"Buy","size":7050,"price":16539.5}]}
09:57:40   {"table":"orderBookL2","action":"update","data":[{"symbol":"XBTUSD","id":8798354450,"side":"Sell","size":308000}]}
09:57:40   {"table":"orderBookL2","action":"update","data":[{"symbol":"XBTZ17","id":22899834485,"side":"Buy","size":5050}]}
09:57:40   {"table":"orderBookL2","action":"delete","data":[{"symbol":"XBTZ17","id":22899835475,"side":"Buy"}]}
09:57:40   {"table":"orderBookL2","action":"update","data":[{"symbol":"XBTUSD","id":8798371000,"side":"Buy","size":3000}]}
09:57:40   {"table":"orderBookL2","action":"update","data":[{"symbol":"XBTUSD","id":8798360000,"side":"Sell","size":500}]}
09:57:40   {"table":"orderBookL2","action":"insert","data":[{"symbol":"XBTZ17","id":22899835660,"side":"Buy","size":6609,"price":16434}]}
09:57:40   {"table":"orderBookL2","action":"update","data":[{"symbol":"XBTUSD","id":8798357600,"side":"Sell","size":33900}]}
09:57:40   {"table":"orderBookL2","action":"update","data":[{"symbol":"XBTUSD","id":8798368450,"side":"Buy","size":341920}]}
09:57:40   {"table":"orderBookL2","action":"delete","data":[{"symbol":"XBTZ17","id":22899834600,"side":"Buy"},{"symbol":"XBTZ17","id":22899835020,"side":"Buy"}]}
09:57:40   {"table":"orderBookL2","action":"insert","data":[{"symbol":"XBTUSD","id":8798357350,"side":"Sell","size":2000,"price":16426.5}]}
09:57:40   {"table":"orderBookL2","action":"update","data":[{"symbol":"XBTUSD","id":8798371550,"side":"Buy","size":190745}]}
09:57:40   {"table":"orderBookL2","action":"insert","data":[{"symbol":"XBTZ17","id":22899834760,"side":"Buy","size":35,"price":16524},{"symbol":"XBTZ17","id":22899835170,"side":"Buy","size":56,"price":16483}]}
09:57:40   {"table":"orderBookL2","action":"delete","data":[{"symbol":"XBTZ17","id":22899834485,"side":"Buy"},{"symbol":"XBTZ17","id":22899834500,"side":"Buy"}]}
09:57:40   {"table":"orderBookL2","action":"update","data":[{"symbol":"XBTUSD","id":8798355000,"side":"Sell","size":18710},{"symbol":"XBTUSD","id":8798360000,"side":"Sell","size":13000}]}
09:57:40   {"table":"orderBookL2","action":"insert","data":[{"symbol":"XBTUSD","id":8798362350,"side":"Sell","size":4800,"price":16376.5}]}
09:57:40   {"table":"orderBookL2","action":"update","data":[{"symbol":"XBTZ17","id":22899834505,"side":"Buy","size":35133}]}
09:57:40   {"table":"orderBookL2","action":"delete","data":[{"symbol":"XBTZ17","id":22899832400,"side":"Sell"}]}
09:57:40   {"table":"orderBookL2","action":"delete","data":[{"symbol":"XBTUSD","id":8798371000,"side":"Buy"}]}
09:57:40   {"table":"orderBookL2","action":"insert","data":[{"symbol":"XBTZ17","id":22899833140,"side":"Sell","size":80000,"price":16686}]}
09:57:40   {"table":"orderBookL2","action":"insert","data":[{"symbol":"XBTUSD","id":8798360550,"side":"Sell","size":1600,"price":16394.5}]}
09:57:40   {"table":"orderBookL2","action":"insert","data":[{"symbol":"XBTUSD","id":8798576850,"side":"Buy","size":100,"price":14231.5}]}
09:57:40   {"table":"orderBookL2","action":"update","data":[{"symbol":"XBTZ17","id":22899834330,"side":"Sell","size":51200}]}
09:57:40   {"table":"orderBookL2","action":"delete","data":[{"symbol":"XBTZ17","id":22899841730,"side":"Buy"}]}
09:57:40   {"table":"orderBookL2","action":"update","data":[{"symbol":"XBTUSD","id":8798360550,"side":"Sell","size":4800}]}
09:57:40   {"table":"orderBookL2","action":"update","data":[{"symbol":"XBTUSD","id":8798360550,"side":"Sell","size":5455}]}
09:57:40   {"table":"orderBookL2","action":"insert","data":[{"symbol":"XBTZ17","id":22899833655,"side":"Sell","size":46700,"price":16634.5},{"symbol":"XBTZ17","id":22899835905,"side":"Buy","size":50300,"price":16409.5}]}
09:57:40   {"table":"orderBookL2","action":"update","data":[{"symbol":"XBTUSD","id":8798364850,"side":"Buy","size":8115}]}
09:57:40   {"table":"orderBookL2","action":"insert","data":[{"symbol":"XBTUSD","id":8798366600,"side":"Buy","size":1540,"price":16334},{"symbol":"XBTUSD","id":8798368350,"side":"Buy","size":1763,"price":16316.5}]}
09:57:40   {"table":"orderBookL2","action":"insert","data":[{"symbol":"XBTZ17","id":22899834295,"side":"Sell","size":7000,"price":16570.5}]}
09:57:40   {"table":"orderBookL2","action":"delete","data":[{"symbol":"XBTUSD","id":8798347350,"side":"Sell"},{"symbol":"XBTUSD","id":8798348950,"side":"Sell"},{"symbol":"XBTUSD","id":8798350600,"side":"Sell"},{"symbol":"XBTUSD","id":8798352250,"side":"Sell"},{"symbol":"XBTUSD","id":8798355550,"side":"Sell"},{"symbol":"XBTUSD","id":8798357150,"side":"Sell"},{"symbol":"XBTUSD","id":8798358450,"side":"Sell"}]}
09:57:40   {"table":"orderBookL2","action":"update","data":[{"symbol":"XBTZ17","id":22899833605,"side":"Sell","size":9000}]}
09:57:40   {"table":"orderBookL2","action":"update","data":[{"symbol":"XBTUSD","id":8798348750,"side":"Sell","size":64664},{"symbol":"XBTUSD","id":8798352050,"side":"Sell","size":4996},{"symbol":"XBTUSD","id":8798353800,"side":"Sell","size":3252},{"symbol":"XBTUSD","id":8798357600,"side":"Sell","size":34212},{"symbol":"XBTUSD","id":8798360050,"side":"Sell","size":32220},{"symbol":"XBTUSD","id":8798360550,"side":"Sell","size":5533}]}
09:57:40   {"table":"orderBookL2","action":"insert","data":[{"symbol":"XBTUSD","id":8798347050,"side":"Sell","size":600,"price":16529.5},{"symbol":"XBTUSD","id":8798350350,"side":"Sell","size":300,"price":16496.5},{"symbol":"XBTUSD","id":8798353250,"side":"Sell","size":1248,"price":16467.5},{"symbol":"XBTUSD","id":8798355650,"side":"Sell","size":624,"price":16443.5},{"symbol":"XBTUSD","id":8798359300,"side":"Sell","size":156,"price":16407}]}
09:57:40   {"table":"orderBookL2","action":"delete","data":[{"symbol":"XBTZ17","id":22899834840,"side":"Buy"}]}
09:57:40   {"table":"orderBookL2","action":"update","data":[{"symbol":"XBTUSD","id":8798364350,"side":"Buy","size":50},{"symbol":"XBTUSD","id":8798365400,"side":"Buy","size":9185}]}
09:57:40   {"table":"orderBookL2","action":"delete","data":[{"symbol":"XBTUSD","id":8798356050,"side":"Sell"}]}
09:57:40   {"table":"orderBookL2","action":"insert","data":[{"symbol":"XBTZ17","id":22899834935,"side":"Buy","size":8000,"price":16506.5}]}
09:57:40   {"table":"orderBookL2","action":"delete","data":[{"symbol":"XBTZ17","id":22899834305,"side":"Sell"}]}
09:57:40   {"table":"orderBookL2","action":"delete","data":[{"symbol":"XBTZ17","id":22899835100,"side":"Buy"},{"symbol":"XBTZ17","id":22899835220,"side":"Buy"}]}
09:57:40   {"table":"orderBookL2","action":"update","data":[{"symbol":"XBTZ17","id":22899835360,"side":"Buy","size":742}]}
09:57:40   {"table":"orderBookL2","action":"update","data":[{"symbol":"XBTUSD","id":8798356550,"side":"Sell","size":3642},{"symbol":"XBTUSD","id":8798363950,"side":"Buy","size":10043}]}
09:57:40   {"table":"orderBookL2","action":"insert","data":[{"symbol":"XBTUSD","id":8798364450,"side":"Buy","size":200,"price":16355.5}]}
09:57:40   {"table":"orderBookL2","action":"insert","data":[{"symbol":"XBTUSD","id":8798361200,"side":"Sell","size":100,"price":16388}]}
09:57:40   {"table":"orderBookL2","action":"insert","data":[{"symbol":"XBTZ17","id":22899835475,"side":"Buy","size":1570,"price":16452.5}]}
09:57:40   {"table":"orderBookL2","action":"delete","data":[{"symbol":"XBTUSD","id":8798364100,"side":"Buy"}]}
09:57:40   {"table":"orderBookL2","action":"update","data":[{"symbol":"XBTUSD","id":8798355900,"side":"Sell","size":700},{"symbol":"XBTUSD","id":8798356400,"side":"Sell","size":567}]}
09:57:40   {"table":"orderBookL2","action":"insert","data":[{"symbol":"XBTUSD","id":8798364600,"side":"Buy","size":200,"price":16354}]}
09:57:40   {"table":"orderBookL2","action":"delete","data":[{"symbol":"XBTZ17","id":22899833470,"side":"Sell"}]}
09:57:40   {"table":"orderBookL2","action":"insert","data":[{"symbol":"XBTUSD","id":8798364300,"side":"Buy","size":2500,"price":16357}]}
09:57:40   {"table":"orderBookL2","action":"delete","data":[{"symbol":"XBTZ17","id":22899834155,"side":"Sell"}]}
09:57:40   {"table":"orderBookL2","action":"update","data":[{"symbol":"XBTUSD","id":8798360050,"side":"Sell","size":32120},{"symbol":"XBTUSD","id":8798362350,"side":"Sell","size":4900}]}
09:57:40   {"table":"orderBookL2","action":"insert","data":[{"symbol":"XBTZ17","id":22899834215,"side":"Sell","size":6681,"price":16578.5}]}
09:57:40   {"table":"orderBookL2","action":"delete","data":[{"symbol":"XBTZ17","id":22899834570,"side":"Buy"}]}
09:57:40   {"table":"orderBookL2","action":"update","data":[{"symbol":"XBTUSD","id":8798360050,"side":"Sell","size":32020},{"symbol":"XBTUSD","id":8798362350,"side":"Sell","size":5000}]}
09:57:40   {"table":"orderBookL2","action":"insert","data":[{"symbol":"XBTZ17","id":22899834620,"side":"Buy","size":123,"price":16538}]}
09:57:40   {"table":"orderBookL2","action":"delete","data":[{"symbol":"XBTZ17","id":22899833225,"side":"Sell"}]}
09:57:40   {"table":"orderBookL2","action":"update","data":[{"symbol":"XBTUSD","id":8798375000,"side":"Buy","size":6228}]}
09:57:40   {"table":"orderBookL2","action":"update","data":[{"symbol":"XBTUSD","id":8798362350,"side":"Sell","size":5010}]}
09:57:40   {"table":"orderBookL2","action":"insert","data":[{"symbol":"XBTZ17","id":22899832765,"side":"Sell","size":7000,"price":16723.5}]}
09:57:40   {"table":"orderBookL2","action":"update","data":[{"symbol":"XBTZ17","id":22899835010,"side":"Buy","size":6168}]}
09:57:40   {"table":"orderBookL2","action":"update","data":[{"symbol":"XBTZ17","id":22899835120,"side":"Buy","size":42900}]}
09:57:40   {"table":"orderBookL2","action":"update","data":[{"symbol":"XBTUSD","id":8798362350,"side":"Sell","size":4210}]}
09:57:40   {"table":"orderBookL2","action":"delete","data":[{"symbol":"XBTZ17","id":22899833950,"side":"Sell"},{"symbol":"XBTZ17","id":22899833985,"side":"Sell"},{"symbol":"XBTZ17","id":22899834015,"side":"Sell"}]}
09:57:40   {"table":"orderBookL2","action":"update","data":[{"symbol":"XBTUSD","id":8798360500,"side":"Sell","size":57640}]}
09:57:40   {"table":"orderBookL2","action":"insert","data":[{"symbol":"XBTZ17","id":22899833900,"side":"Sell","size":8000,"price":16610},{"symbol":"XBTZ17","id":22899833935,"side":"Sell","size":8000,"price":16606.5},{"symbol":"XBTZ17","id":22899833965,"side":"Sell","size":8000,"price":16603.5}]}
09:57:40   {"table":"orderBookL2","action":"insert","data":[{"symbol":"XBTUSD","id":8798362050,"side":"Sell","size":10000,"price":16379.5}]}
09:57:40   {"table":"orderBookL2","action":"update","data":[{"symbol":"XBTZ17","id":22899834505,"side":"Buy","size":32533}]}
09:57:40   {"table":"orderBookL2","action":"delete","data":[{"symbol":"XBTZ17","id":22899833200,"side":"Sell"},{"symbol":"XBTZ17","id":22899833625,"side":"Sell"}]}
09:57:40   {"table":"orderBookL2","action":"update","data":[{"symbol":"XBTUSD","id":8798360050,"side":"Sell","size":12020}]}
09:57:40   {"table":"orderBookL2","action":"update","data":[{"symbol":"XBTUSD","id":8798360500,"side":"Sell","size":57140}]}
09:57:40   {"table":"orderBookL2","action":"insert","data":[{"symbol":"XBTZ17","id":22899833325,"side":"Sell","size":7000,"price":16667.5},{"symbol":"XBTZ17","id":22899833720,"side":"Sell","size":7000,"price":16628}]}
09:57:40   {"table":"orderBookL2","action":"delete","data":[{"symbol":"XBTZ17","id":22899833755,"side":"Sell"},{"symbol":"XBTZ17","id":22899833975,"side":"Sell"}]}
09:57:40   {"table":"orderBookL2","action":"insert","data":[{"symbol":"XBTUSD","id":8798363250,"side":"Sell","size":500,"price":16367.5}]}
09:57:40   {"table":"orderBookL2","action":"delete","data":[{"symbol":"XBTUSD","id":8798317300,"side":"Sell"},{"symbol":"XBTUSD","id":8798329250,"side":"Sell"},{"symbol":"XBTUSD","id":8798334250,"side":"Sell"},{"symbol":"XBTUSD","id":8798339250,"side":"Sell"},{"symbol":"XBTUSD","id":8798344250,"side":"Sell"},{"symbol":"XBTUSD","id":8798349250,"side":"Sell"},{"symbol":"XBTUSD","id":8798359250,"side":"Sell"},{"symbol":"XBTUSD","id":8798372600,"side":"Buy"},{"symbol":"XBTUSD","id":8798377600,"side":"Buy"},{"symbol":"XBTUSD","id":8798382600,"side":"Buy"},{"symbol":"XBTUSD","id":8798408350,"side":"Buy"},{"symbol":"XBTUSD","id":8798562750,"side":"Buy"}]}
09:57:40   {"table":"orderBookL2","action":"update","data":[{"symbol":"XBTZ17","id":22899833795,"side":"Sell","size":40000}]}
09:57:40   {"table":"orderBookL2","action":"insert","data":[{"symbol":"XBTZ17","id":22899833840,"side":"Sell","size":7000,"price":16616},{"symbol":"XBTZ17","id":22899833880,"side":"Sell","size":7000,"price":16612},{"symbol":"XBTZ17","id":22899834045,"side":"Sell","size":7000,"price":16595.5}]}
09:57:40   {"table":"orderBookL2","action":"update","data":[{"symbol":"XBTUSD","id":8798150100,"side":"Sell","size":2575},{"symbol":"XBTUSD","id":8798150750,"side":"Sell","size":200},{"symbol":"XBTUSD","id":8798155100,"side":"Sell","size":150},{"symbol":"XBTUSD","id":8798155750,"side":"Sell","size":200},{"symbol":"XBTUSD","id":8798160100,"side":"Sell","size":95075},{"symbol":"XBTUSD","id":8798160750,"side":"Sell","size":292},{"symbol":"XBTUSD","id":8798310000,"side":"Sell","size":122510},{"symbol":"XBTUSD","id":8798310150,"side":"Sell","size":701},{"symbol":"XBTUSD","id":8798319550,"side":"Sell","size":200},{"symbol":"XBTUSD","id":8798322300,"side":"Sell","size":50000},{"symbol":"XBTUSD","id":8798329550,"side":"Sell","size":8332},{"symbol":"XBTUSD","id":8798335100,"side":"Sell","size":3512},{"symbol":"XBTUSD","id":8798345100,"side":"Sell","size":20100},{"symbol":"XBTUSD","id":8798350100,"side":"Sell","size":21110},{"symbol":"XBTUSD","id":8798354250,"side":"Sell","size":6500},{"symbol":"XBTUSD","id":8798355100,"side":"Sell","size":30100},{"symbol":"XBTUSD","id":8798360100,"side":"Sell","size":12262},{"symbol":"XBTUSD","id":8798365400,"side":"Buy","size":9285},{"symbol":"XBTUSD","id":8798367600,"side":"Buy","size":2500},{"symbol":"XBTUSD","id":8798370400,"side":"Buy","size":226},{"symbol":"XBTUSD","id":8798375400,"side":"Buy","size":350},{"symbol":"XBTUSD","id":8798380750,"side":"Buy","size":1200},{"symbol":"XBTUSD","id":8798399950,"side":"Buy","size":143},{"symbol":"XBTUSD","id":8798403350,"side":"Buy","size":2401},{"symbol":"XBTUSD","id":8798406000,"side":"Buy","size":140},{"symbol":"XBTUSD","id":8798411500,"side":"Buy","size":502},{"symbol":"XBTUSD","id":8798413350,"side":"Buy","size":777},{"symbol":"XBTUSD","id":8798419950,"side":"Buy","size":602},{"symbol":"XBTUSD","id":8798433300,"side":"Buy","size":9496},{"symbol":"XBTUSD","id":8798436200,"side":"Buy","size":20100},{"symbol":"XBTUSD","id":8798439950,"side":"Buy","size":50},{"symbol":"XBTUSD","id":8798455750,"side":"Buy","size":30472},{"symbol":"XBTUSD","id":8798461100,"side":"Buy","size":10100},{"symbol":"XBTUSD","id":8798470000,"side":"Buy","size":1118500},{"symbol":"XBTUSD","id":8798479900,"side":"Buy","size":1175},{"symbol":"XBTUSD","id":8798489900,"side":"Buy","size":75},{"symbol":"XBTUSD","id":8798490000,"side":"Buy","size":335500},{"symbol":"XBTUSD","id":8798499950,"side":"Buy","size":100750},{"symbol":"XBTUSD","id":8798502350,"side":"Buy","size":144},{"symbol":"XBTUSD","id":8798517750,"side":"Buy","size":150},{"symbol":"XBTUSD","id":8798522050,"side":"Buy","size":200},{"symbol":"XBTUSD","id":8798537750,"side":"Buy","size":150},{"symbol":"XBTUSD","id":8798541250,"side":"Buy","size":200},{"symbol":"XBTUSD","id":8798557750,"side":"Buy","size":2050}]}
09:57:40   {"table":"orderBookL2","action":"insert","data":[{"symbol":"XBTUSD","id":8798324550,"side":"Sell","size":100,"price":16754.5},{"symbol":"XBTUSD","id":8798340100,"side":"Sell","size":100,"price":16599},{"symbol":"XBTUSD","id":8798441200,"side":"Buy","size":100,"price":15588},{"symbol":"XBTUSD","id":8798546250,"side":"Buy","size":100,"price":14537.5}]}
09:57:40   {"table":"orderBookL2","action":"delete","data":[{"symbol":"XBTZ17","id":22899835180,"side":"Buy"}]}
09:57:40   {"table":"orderBookL2","action":"delete","data":[{"symbol":"XBTZ17","id":22899833080,"side":"Sell"},{"symbol":"XBTZ17","id":22899833460,"side":"Sell"},{"symbol":"XBTZ17","id":22899833810,"side":"Sell"}]}
09:57:40   {"table":"orderBookL2","action":"update","data":[{"symbol":"XBTZ17","id":22899833210,"side":"Sell","size":13850},{"symbol":"XBTZ17","id":22899833570,"side":"Sell","size":6890},{"symbol":"XBTZ17","id":22899833605,"side":"Sell","size":2000},{"symbol":"XBTZ17","id":22899833880,"side":"Sell","size":12059}]}
09:57:40   {"table":"orderBookL2","action":"delete","data":[{"symbol":"XBTUSD","id":8798346800,"side":"Sell"},{"symbol":"XBTUSD","id":8798371250,"side":"Buy"}]}
09:57:40   {"table":"orderBookL2","action":"insert","data":[{"symbol":"XBTZ17","id":22899833555,"side":"Sell","size":7000,"price":16644.5},{"symbol":"XBTZ17","id":22899833650,"side":"Sell","size":7000,"price":16635},{"symbol":"XBTZ17","id":22899833690,"side":"Sell","size":7000,"price":16631}]}
09:57:40   {"table":"orderBookL2","action":"update","data":[{"symbol":"XBTUSD","id":8798372250,"side":"Buy","size":14280},{"symbol":"XBTUSD","id":8798373400,"side":"Buy","size":172}]}
09:57:40   {"table":"orderBookL2","action":"insert","data":[{"symbol":"XBTZ17","id":22899834445,"side":"Buy","size":2184,"price":16555.5}]}
09:57:40   {"table":"orderBookL2","action":"delete","data":[{"symbol":"XBTZ17","id":22899833275,"side":"Sell"},{"symbol":"XBTZ17","id":22899833455,"side":"Sell"},{"symbol":"XBTZ17","id":22899833570,"side":"Sell"},{"symbol":"XBTZ17","id":22899833660,"side":"Sell"}]}
09:57:40   {"table":"orderBookL2","action":"insert","data":[{"symbol":"XBTUSD","id":8798347600,"side":"Sell","size":3390,"price":16524},{"symbol":"XBTUSD","id":8798370150,"side":"Buy","size":3390,"price":16298.5}]}
09:57:40   {"table":"orderBookL2","action":"update","data":[{"symbol":"XBTZ17","id":22899833210,"side":"Sell","size":7000},{"symbol":"XBTZ17","id":22899833395,"side":"Sell","size":60},{"symbol":"XBTZ17","id":22899833505,"side":"Sell","size":48950}]}
09:57:40   {"table":"orderBookL2","action":"update","data":[{"symbol":"XBTUSD","id":8798362350,"side":"Sell","size":14210}]}
09:57:40   {"table":"orderBookL2","action":"insert","data":[{"symbol":"XBTZ17","id":22899833285,"side":"Sell","size":6850,"price":16671.5},{"symbol":"XBTZ17","id":22899833385,"side":"Sell","size":6890,"price":16661.5},{"symbol":"XBTZ17","id":22899833465,"side":"Sell","size":3570,"price":16653.5},{"symbol":"XBTZ17","id":22899833640,"side":"Sell","size":6890,"price":16636},{"symbol":"XBTZ17","id":22899833725,"side":"Sell","size":5850,"price":16627.5}]}
09:57:40   {"table":"orderBookL2","action":"insert","data":[{"symbol":"XBTZ17","id":22899834310,"side":"Sell","size":7253,"price":16569}]}
09:57:40   {"table":"orderBookL2","action":"update","data":[{"symbol":"XBTUSD","id":8798360050,"side":"Sell","size":12010},{"symbol":"XBTUSD","id":8798363250,"side":"Sell","size":510}]}
09:57:40   {"table":"orderBookL2","action":"delete","data":[{"symbol":"XBTZ17","id":22899833590,"side":"Sell"}]}
09:57:40   {"table":"orderBookL2","action":"delete","data":[{"symbol":"XBTZ17","id":22899833710,"side":"Sell"}]}
09:57:40   {"table":"orderBookL2","action":"insert","data":[{"symbol":"XBTUSD","id":8798362200,"side":"Sell","size":500,"price":16378}]}
09:57:40   {"table":"orderBookL2","action":"update","data":[{"symbol":"XBTUSD","id":8798369800,"side":"Buy","size":700}]}
09:57:40   {"table":"orderBookL2","action":"insert","data":[{"symbol":"XBTZ17","id":22899833830,"side":"Sell","size":60,"price":16617}]}
09:57:40   {"table":"orderBookL2","action":"delete","data":[{"symbol":"XBTZ17","id":22899834330,"side":"Sell"}]}
09:57:40   {"table":"orderBookL2","action":"delete","data":[{"symbol":"XBTUSD","id":8798367050,"side":"Buy"},{"symbol":"XBTUSD","id":8798367500,"side":"Buy"},{"symbol":"XBTUSD","id":8798373500,"side":"Buy"}]}
09:57:40   {"table":"orderBookL2","action":"update","data":[{"symbol":"XBTUSD","id":8798365800,"side":"Buy","size":11535},{"symbol":"XBTUSD","id":8798367200,"side":"Buy","size":7168},{"symbol":"XBTUSD","id":8798367850,"side":"Buy","size":57000}]}
09:57:40   {"table":"orderBookL2","action":"update","data":[{"symbol":"XBTZ17","id":22899834310,"side":"Sell","size":59253}]}
09:57:40   {"table":"orderBookL2","action":"insert","data":[{"symbol":"XBTZ17","id":22899839800,"side":"Buy","size":153,"price":16020}]}
09:57:40   {"table":"orderBookL2","action":"update","data":[{"symbol":"XBTZ17","id":22899835000,"side":"Buy","size":8082}]}
09:57:40   {"table":"orderBookL2","action":"insert","data":[{"symbol":"XBTZ17","id":22899833440,"side":"Sell","size":1950,"price":16656}]}
09:57:40   {"table":"orderBookL2","action":"insert","data":[{"symbol":"XBTUSD","id":8798366850,"side":"Buy","size":7000,"price":16331.5},{"symbol":"XBTUSD","id":8798373000,"side":"Buy","size":7000,"price":16270}]}
09:57:40   {"table":"orderBookL2","action":"update","data":[{"symbol":"XBTUSD","id":8798358350,"side":"Sell","size":68000}]}
09:57:40   {"table":"orderBookL2","action":"update","data":[{"symbol":"XBTUSD","id":8798358150,"side":"Sell","size":39900}]}
09:57:40   {"table":"orderBookL2","action":"delete","data":[{"symbol":"XBTZ17","id":22899831665,"side":"Sell"},{"symbol":"XBTZ17","id":22899831910,"side":"Sell"},{"symbol":"XBTZ17","id":22899832160,"side":"Sell"},{"symbol":"XBTZ17","id":22899832410,"side":"Sell"},{"symbol":"XBTZ17","id":22899832655,"side":"Sell"},{"symbol":"XBTZ17","id":22899832905,"side":"Sell"},{"symbol":"XBTZ17","id":22899833155,"side":"Sell"},{"symbol":"XBTZ17","id":22899833400,"side":"Sell"},{"symbol":"XBTZ17","id":22899836555,"side":"Buy"},{"symbol":"XBTZ17","id":22899836800,"side":"Buy"},{"symbol":"XBTZ17","id":22899837050,"side":"Buy"},{"symbol":"XBTZ17","id":22899837295,"side":"Buy"},{"symbol":"XBTZ17","id":22899837545,"side":"Buy"},{"symbol":"XBTZ17","id":22899837790,"side":"Buy"},{"symbol":"XBTZ17","id":22899838035,"side":"Buy"}]}
09:57:40   {"table":"orderBookL2","action":"update","data":[{"symbol":"XBTZ17","id":22899838285,"side":"Buy","size":305}]}
09:57:40   {"table":"orderBookL2","action":"insert","data":[{"symbol":"XBTZ17","id":22899831615,"side":"Sell","size":5000,"price":16838.5},{"symbol":"XBTZ17","id":22899831860,"side":"Sell","size":5000,"price":16814},{"symbol":"XBTZ17","id":22899832110,"side":"Sell","size":5000,"price":16789},{"symbol":"XBTZ17","id":22899832360,"side":"Sell","size":5000,"price":16764},{"symbol":"XBTZ17","id":22899832605,"side":"Sell","size":5000,"price":16739.5},{"symbol":"XBTZ17","id":22899832855,"side":"Sell","size":5000,"price":16714.5},{"symbol":"XBTZ17","id":22899833105,"side":"Sell","size":5000,"price":16689.5},{"symbol":"XBTZ17","id":22899833350,"side":"Sell","size":5000,"price":16665},{"symbol":"XBTZ17","id":22899836515,"side":"Buy","size":5000,"price":16348.5},{"symbol":"XBTZ17","id":22899836765,"side":"Buy","size":5000,"price":16323.5},{"symbol":"XBTZ17","id":22899837010,"side":"Buy","size":5000,"price":16299},{"symbol":"XBTZ17","id":22899837255,"side":"Buy","size":5000,"price":16274.5},{"symbol":"XBTZ17","id":22899837505,"side":"Buy","size":5000,"price":16249.5},{"symbol":"XBTZ17","id":22899837750,"side":"Buy","size":5000,"price":16225},{"symbol":"XBTZ17","id":22899837995,"side":"Buy","size":5000,"price":16200.5},{"symbol":"XBTZ17","id":22899838245,"side":"Buy","size":5000,"price":16175.5}]}
09:57:40   {"table":"orderBookL2","action":"delete","data":[{"symbol":"XBTUSD","id":8798320100,"side":"Sell"}]}
