09:57:40   {"table":"orderBookL2","action":"update","data":[{"symbol":"XBTZ17","id":22899835040,"side":"Buy","size":2537}]}
09:57:40   {"table":"orderBookL2","action":"delete","data":[{"symbol":"XBTZ17","id":22899827075,"side":"Sell"},{"symbol":"XBTZ17","id":22899832230,"side":"Sell"},{"symbol":"XBTZ17","id":22899832395,"side":"Sell"},{"symbol":"XBTZ17","id":22899834505,"side":"Buy"},{"symbol":"XBTZ17","id":22899834655,"side":"Buy"}]}
09:57:40   {"table":"orderBookL2","action":"delete","data":[{"symbol":"XBTZ17","id":22899834605,"side":"Buy"}]}
09:57:40   {"table":"orderBookL2","action":"delete","data":[{"symbol":"XBTUSD","id":8798365200,"side":"Buy"}]}
09:57:40   {"table":"orderBookL2","action":"insert","data":[{"symbol":"XBTUSD","id":8798366750,"side":"Buy","size":10000,"price":16332.5}]}
09:57:40   {"table":"orderBookL2","action":"insert","data":[{"symbol":"XBTZ17","id":22899834690,"side":"Buy","size":7050,"price":16531}]}
09:57:40   {"table":"orderBookL2","action":"delete","data":[{"symbol":"XBTUSD","id":8798345500,"side":"Sell"},{"symbol":"XBTUSD","id":8798359900,"side":"Sell"}]}
09:57:40   {"table":"orderBookL2","action":"update","data":[{"symbol":"XBTUSD","id":8798372800,"side":"Buy","size":281},{"symbol":"XBTUSD","id":8798389100,"side":"Buy","size":50000}]}
09:57:40   {"table":"orderBookL2","action":"delete","data":[{"symbol":"XBTZ17","id":22899834290,"side":"Sell"}]}
09:57:40   {"table":"orderBookL2","action":"insert","data":[{"symbol":"XBTUSD","id":8798381800,"side":"Buy","size":50,"price":16182}]}
09:57:40   {"table":"orderBookL2","action":"insert","data":[{"symbol":"XBTZ17","id":22899834335,"side":"Sell","size":1591,"price":16566.5}]}
09:57:40   {"table":"orderBookL2","action":"insert","data":[{"symbol":"XBTZ17","id":22899834370,"side":"Sell","size":666,"price":16563}]}
09:57:40   {"table":"orderBookL2","action":"update","data":[{"symbol":"XBTUSD","id":8798361200,"side":"Sell","size":3100}]}
09:57:40   {"table":"orderBookL2","action":"delete","data":[{"symbol":"XBTZ17","id":22899835475,"side":"Buy"}]}
09:57:40   {"table":"orderBookL2","action":"update","data":[{"symbol":"XBTZ17","id":22899835360,"side":"Buy","size":112}]}
09:57:40   {"table":"orderBookL2","action":"delete","data":[{"symbol":"XBTUSD","id":8798364900,"side":"Buy"}]}
09:57:40   {"table":"orderBookL2","action":"update","data":[{"symbol":"XBTUSD","id":8798363950,"side":"Buy","size":43}]}
09:57:40   {"table":"orderBookL2","action":"insert","data":[{"symbol":"XBTZ17","id":22899835200,"side":"Buy","size":630,"price":16480},{"symbol":"XBTZ17","id":22899835315,"side":"Buy","size":1570,"price":16468.5}]}
09:57:40   {"table":"orderBookL2","action":"delete","data":[{"symbol":"XBTZ17","id":22899834295,"side":"Sell"}]}
09:57:40   {"table":"orderBookL2","action":"insert","data":[{"symbol":"XBTUSD","id":8798366100,"side":"Buy","size":10000,"price":16339},{"symbol":"XBTUSD","id":8798367050,"side":"Buy","size":20000,"price":16329.5}]}
09:57:40   {"table":"orderBookL2","action":"update","data":[{"symbol":"XBTZ17","id":22899834975,"side":"Buy","size":42400}]}
09:57:40   {"table":"orderBookL2","action":"insert","data":[{"symbol":"XBTZ17","id":22899834570,"side":"Buy","size":7050,"price":16543}]}
09:57:40   {"table":"orderBookL2","action":"update","data":[{"symbol":"XBTUSD","id":8798361500,"side":"Sell","size":12000}]}
09:57:40   {"table":"orderBookL2","action":"delete","data":[{"symbol":"XBTZ17","id":22899834860,"side":"Buy"}]}
09:57:40   {"table":"orderBookL2","action":"insert","data":[{"symbol":"XBTUSD","id":8798362000,"side":"Sell","size":10000,"price":16380}]}
09:57:40   {"table":"orderBookL2","action":"update","data":[{"symbol":"XBTUSD","id":8798363250,"side":"Sell","size":410}]}
09:57:40   {"table":"orderBookL2","action":"update","data":[{"symbol":"XBTZ17","id":22899834640,"side":"Buy","size":98}]}
09:57:40   {"table":"orderBookL2","action":"insert","data":[{"symbol":"XBTZ17","id":22899835030,"side":"Buy","size":73,"price":16497}]}
09:57:40   {"table":"orderBookL2","action":"insert","data":[{"symbol":"XBTUSD","id":8798425800,"side":"Buy","size":403,"price":15742}]}
09:57:40   {"table":"orderBookL2","action":"delete","data":[{"symbol":"XBTUSD","id":8798364250,"side":"Buy"}]}
09:57:40   {"table":"orderBookL2","action":"delete","data":[{"symbol":"XBTZ17","id":22899836290,"side":"Buy"}]}
09:57:40   {"table":"orderBookL2","action":"delete","data":[{"symbol":"XBTZ17","id":22899834215,"side":"Sell"}]}
09:57:40   {"table":"orderBookL2","action":"update","data":[{"symbol":"XBTUSD","id":8798360500,"side":"Sell","size":7140}]}
09:57:40   {"table":"orderBookL2","action":"update","data":[{"symbol":"XBTUSD","id":8798360050,"side":"Sell","size":10010}]}
09:57:40   {"table":"orderBookL2","action":"insert","data":[{"symbol":"XBTZ17","id":22899833990,"side":"Sell","size":6685,"price":16601}]}
09:57:40   {"table":"orderBookL2","action":"delete","data":[{"symbol":"XBTZ17","id":22899833530,"side":"Sell"}]}
09:57:40   {"table":"orderBookL2","action":"insert","data":[{"symbol":"XBTUSD","id":8798360150,"side":"Sell","size":2000,"price":16398.5}]}
09:57:40   {"table":"orderBookL2","action":"update","data":[{"symbol":"XBTUSD","id":8798369800,"side":"Buy","size":200}]}
09:57:40   {"table":"orderBookL2","action":"delete","data":[{"symbol":"XBTZ17","id":22899833605,"side":"Sell"}]}
09:57:40   {"table":"orderBookL2","action":"delete","data":[{"symbol":"XBTZ17","id":22899833900,"side":"Sell"},{"symbol":"XBTZ17","id":22899833935,"side":"Sell"},{"symbol":"XBTZ17","id":22899833965,"side":"Sell"},{"symbol":"XBTZ17","id":22899834935,"side":"Buy"}]}
09:57:40   {"table":"orderBookL2","action":"update","data":[{"symbol":"XBTUSD","id":8798358350,"side":"Sell","size":63500}]}
09:57:40   {"table":"orderBookL2","action":"update","data":[{"symbol":"XBTUSD","id":8798360050,"side":"Sell","size":10000},{"symbol":"XBTUSD","id":8798363250,"side":"Sell","size":420}]}
09:57:40   {"table":"orderBookL2","action":"update","data":[{"symbol":"XBTZ17","id":22899834045,"side":"Sell","size":15000}]}
09:57:40   {"table":"orderBookL2","action":"update","data":[{"symbol":"XBTUSD","id":8798341650,"side":"Sell","size":1602},{"symbol":"XBTUSD","id":8798363900,"side":"Buy","size":78}]}
09:57:40   {"table":"orderBookL2","action":"insert","data":[{"symbol":"XBTZ17","id":22899833980,"side":"Sell","size":8000,"price":16602},{"symbol":"XBTZ17","id":22899834015,"side":"Sell","size":8000,"price":16598.5},{"symbol":"XBTZ17","id":22899834960,"side":"Buy","size":8000,"price":16504}]}
09:57:40   {"table":"orderBookL2","action":"insert","data":[{"symbol":"XBTUSD","id":8798363300,"side":"Buy","size":820,"price":16367}]}
09:57:40   {"table":"orderBookL2","action":"update","data":[{"symbol":"XBTZ17","id":22899836400,"side":"Buy","size":2180}]}
09:57:40   {"table":"orderBookL2","action":"delete","data":[{"symbol":"XBTZ17","id":22899834370,"side":"Sell"}]}
09:57:40   {"table":"orderBookL2","action":"update","data":[{"symbol":"XBTUSD","id":8798360500,"side":"Sell","size":7130},{"symbol":"XBTUSD","id":8798363250,"side":"Sell","size":430}]}
09:57:40   {"table":"orderBookL2","action":"update","data":[{"symbol":"XBTUSD","id":8798367850,"side":"Buy","size":50000}]}
09:57:40   {"table":"orderBookL2","action":"insert","data":[{"symbol":"XBTUSD","id":8798368700,"side":"Buy","size":7000,"price":16313}]}
09:57:40   {"table":"orderBookL2","action":"update","data":[{"symbol":"XBTZ17","id":22899834335,"side":"Sell","size":1457}]}
09:57:40   {"table":"orderBookL2","action":"delete","data":[{"symbol":"XBTZ17","id":22899831590,"side":"Sell"},{"symbol":"XBTZ17","id":22899841535,"side":"Buy"}]}
09:57:40   {"table":"orderBookL2","action":"delete","data":[{"symbol":"XBTZ17","id":22899833830,"side":"Sell"}]}
09:57:40   {"table":"orderBookL2","action":"insert","data":[{"symbol":"XBTUSD","id":8798366000,"side":"Buy","size":80,"price":16340}]}
09:57:40   {"table":"orderBookL2","action":"insert","data":[{"symbol":"XBTZ17","id":22899834040,"side":"Sell","size":60,"price":16596}]}
09:57:40   {"table":"orderBookL2","action":"update","data":[{"symbol":"XBTUSD","id":8798360500,"side":"Sell","size":7120},{"symbol":"XBTUSD","id":8798363250,"side":"Sell","size":440}]}
09:57:40   {"table":"orderBookL2","action":"delete","data":[{"symbol":"XBTUSD","id":8798363250,"side":"Sell"}]}
09:57:40   {"table":"orderBookL2","action":"update","data":[{"symbol":"XBTZ17","id":22899834335,"side":"Sell","size":457}]}
09:57:40   {"table":"orderBookL2","action":"update","data":[{"symbol":"XBTUSD","id":8798362350,"side":"Sell","size":12650}]}
09:57:40   {"table":"orderBookL2","action":"delete","data":[{"symbol":"XBTUSD","id":8798309350,"side":"Sell"}]}
09:57:40   {"table":"orderBookL2","action":"update","data":[{"symbol":"XBTZ17","id":22899834140,"side":"Sell","size":50},{"symbol":"XBTZ17","id":22899834335,"side":"Sell","size":30457}]}
09:57:40   {"table":"orderBookL2","action":"update","data":[{"symbol":"XBTZ17","id":22899834445,"side":"Buy","size":184}]}
09:57:40   {"table":"orderBookL2","action":"update","data":[{"symbol":"XBTZ17","id":22899835010,"side":"Buy","size":168}]}
09:57:40   {"table":"orderBookL2","action":"update","data":[{"symbol":"XBTUSD","id":8798312050,"side":"Sell","size":642}]}
09:57:40   {"table":"orderBookL2","action":"delete","data":[{"symbol":"XBTZ17","id":22899834445,"side":"Buy"}]}
09:57:40   {"table":"orderBookL2","action":"update","data":[{"symbol":"XBTZ17","id":22899834310,"side":"Sell","size":52000}]}
09:57:40   {"table":"orderBookL2","action":"update","data":[{"symbol":"XBTUSD","id":8798359200,"side":"Sell","size":17275},{"symbol":"XBTUSD","id":8798359950,"side":"Sell","size":60986}]}
09:57:40   {"table":"orderBookL2","action":"delete","data":[{"symbol":"XBTUSD","id":8798860100,"side":"Buy"}]}
09:57:40   {"table":"orderBookL2","action":"insert","data":[{"symbol":"XBTUSD","id":8798863300,"side":"Buy","size":1,"price":11367}]}
09:57:40   {"table":"orderBookL2","action":"update","data":[{"symbol":"XBTUSD","id":8798363300,"side":"Buy","size":720}]}
09:57:40   {"table":"orderBookL2","action":"delete","data":[{"symbol":"XBTZ17","id":22899834310,"side":"Sell"}]}
09:57:41   {"table":"orderBookL2","action":"update","data":[{"symbol":"XBTZ17","id":22899834335,"side":"Sell","size":81657}]}
09:57:41   {"table":"orderBookL2","action":"update","data":[{"symbol":"XBTZ17","id":22899834335,"side":"Sell","size":81200}]}
09:57:41   {"table":"orderBookL2","action":"delete","data":[{"symbol":"XBTUSD","id":8798374150,"side":"Buy"}]}
09:57:41   {"table":"orderBookL2","action":"insert","data":[{"symbol":"XBTUSD","id":8798371050,"side":"Buy","size":500,"price":16289.5}]}
09:57:41   {"table":"orderBookL2","action":"update","data":[{"symbol":"XBTUSD","id":8798360500,"side":"Sell","size":7110}]}
09:57:41   {"table":"orderBookL2","action":"insert","data":[{"symbol":"XBTZ17","id":22899834315,"side":"Sell","size":2005,"price":16568.5}]}
09:57:41   {"table":"orderBookL2","action":"insert","data":[{"symbol":"XBTUSD","id":8798363250,"side":"Sell","size":10,"price":16367.5}]}
09:57:41   {"table":"orderBookL2","action":"update","data":[{"symbol":"XBTUSD","id":8798360500,"side":"Sell","size":7100},{"symbol":"XBTUSD","id":8798363250,"side":"Sell","size":20}]}
09:57:41   {"table":"orderBookL2","action":"update","data":[{"symbol":"XBTZ17","id":22899831300,"side":"Sell","size":2183}]}
09:57:41   {"table":"orderBookL2","action":"insert","data":[{"symbol":"XBTZ17","id":22899834375,"side":"Sell","size":5000,"price":16562.5}]}
09:57:41   {"table":"orderBookL2","action":"update","data":[{"symbol":"XBTUSD","id":8798358400,"side":"Sell","size":1100},{"symbol":"XBTUSD","id":8798359200,"side":"Sell","size":27275}]}
09:57:41   {"table":"orderBookL2","action":"update","data":[{"symbol":"XBTUSD","id":8798368150,"side":"Buy","size":11300}]}
09:57:41   {"table":"orderBookL2","action":"delete","data":[{"symbol":"XBTZ17","id":22899833210,"side":"Sell"},{"symbol":"XBTZ17","id":22899833555,"side":"Sell"},{"symbol":"XBTZ17","id":22899833650,"side":"Sell"},{"symbol":"XBTZ17","id":22899833690,"side":"Sell"}]}
09:57:41   {"table":"orderBookL2","action":"insert","data":[{"symbol":"XBTUSD","id":8798361700,"side":"Sell","size":250,"price":16383}]}
09:57:41   {"table":"orderBookL2","action":"insert","data":[{"symbol":"XBTUSD","id":8798364100,"side":"Buy","size":8000,"price":16359}]}
09:57:41   {"table":"orderBookL2","action":"update","data":[{"symbol":"XBTZ17","id":22899833880,"side":"Sell","size":7000}]}
09:57:41   {"table":"orderBookL2","action":"insert","data":[{"symbol":"XBTUSD","id":8798363850,"side":"Buy","size":1609,"price":16361.5}]}
09:57:41   {"table":"orderBookL2","action":"update","data":[{"symbol":"XBTUSD","id":8798358350,"side":"Sell","size":58500}]}
09:57:41   {"table":"orderBookL2","action":"update","data":[{"symbol":"XBTUSD","id":8798343150,"side":"Sell","size":329700},{"symbol":"XBTUSD","id":8798343500,"side":"Sell","size":8950},{"symbol":"XBTUSD","id":8798412050,"side":"Buy","size":402},{"symbol":"XBTUSD","id":8798413300,"side":"Buy","size":130441}]}
09:57:41   {"table":"orderBookL2","action":"insert","data":[{"symbol":"XBTZ17","id":22899833300,"side":"Sell","size":7000,"price":16670},{"symbol":"XBTZ17","id":22899833610,"side":"Sell","size":7000,"price":16639},{"symbol":"XBTZ17","id":22899833780,"side":"Sell","size":7000,"price":16622},{"symbol":"XBTZ17","id":22899833820,"side":"Sell","size":7000,"price":16618},{"symbol":"XBTZ17","id":22899833915,"side":"Sell","size":5059,"price":16608.5}]}
09:57:41   {"table":"orderBookL2","action":"delete","data":[{"symbol":"XBTUSD","id":8798365250,"side":"Buy"},{"symbol":"XBTUSD","id":8798366550,"side":"Buy"}]}
09:57:41   {"table":"orderBookL2","action":"delete","data":[{"symbol":"XBTZ17","id":22899833285,"side":"Sell"},{"symbol":"XBTZ17","id":22899833385,"side":"Sell"},{"symbol":"XBTZ17","id":22899833465,"side":"Sell"},{"symbol":"XBTZ17","id":22899833640,"side":"Sell"},{"symbol":"XBTZ17","id":22899833725,"side":"Sell"},{"symbol":"XBTZ17","id":22899835200,"side":"Buy"},{"symbol":"XBTZ17","id":22899835315,"side":"Buy"}]}
09:57:41   {"table":"orderBookL2","action":"update","data":[{"symbol":"XBTUSD","id":8798365750,"side":"Buy","size":40000},{"symbol":"XBTUSD","id":8798367050,"side":"Buy","size":30000}]}
09:57:41   {"table":"orderBookL2","action":"update","data":[{"symbol":"XBTZ17","id":22899833505,"side":"Sell","size":52520},{"symbol":"XBTZ17","id":22899835400,"side":"Buy","size":706}]}
09:57:41   {"table":"orderBookL2","action":"update","data":[{"symbol":"XBTUSD","id":8798357600,"side":"Sell","size":19212}]}
09:57:41   {"table":"orderBookL2","action":"insert","data":[{"symbol":"XBTZ17","id":22899833330,"side":"Sell","size":6850,"price":16667},{"symbol":"XBTZ17","id":22899833455,"side":"Sell","size":6890,"price":16654.5},{"symbol":"XBTZ17","id":22899833675,"side":"Sell","size":6890,"price":16632.5},{"symbol":"XBTZ17","id":22899833760,"side":"Sell","size":5850,"price":16624},{"symbol":"XBTZ17","id":22899835520,"side":"Buy","size":1570,"price":16448}]}
09:57:41   {"table":"orderBookL2","action":"delete","data":[{"symbol":"XBTZ17","id":22899833325,"side":"Sell"},{"symbol":"XBTZ17","id":22899833720,"side":"Sell"},{"symbol":"XBTZ17","id":22899833840,"side":"Sell"},{"symbol":"XBTZ17","id":22899833880,"side":"Sell"}]}
09:57:41   {"table":"orderBookL2","action":"delete","data":[{"symbol":"XBTUSD","id":8798361950,"side":"Sell"}]}
09:57:41   {"table":"orderBookL2","action":"update","data":[{"symbol":"XBTZ17","id":22899834045,"side":"Sell","size":8000}]}
09:57:41   {"table":"orderBookL2","action":"update","data":[{"symbol":"XBTUSD","id":8798361500,"side":"Sell","size":6000}]}
09:57:41   {"table":"orderBookL2","action":"update","data":[{"symbol":"XBTUSD","id":8798360500,"side":"Sell","size":4100},{"symbol":"XBTUSD","id":8798362200,"side":"Sell","size":3500}]}
09:57:41   {"table":"orderBookL2","action":"update","data":[{"symbol":"XBTUSD","id":8798359200,"side":"Sell","size":32075}]}
09:57:41   {"table":"orderBookL2","action":"insert","data":[{"symbol":"XBTZ17","id":22899833410,"side":"Sell","size":7000,"price":16659},{"symbol":"XBTZ17","id":22899833765,"side":"Sell","size":7000,"price":16623.5},{"symbol":"XBTZ17","id":22899833895,"side":"Sell","size":7000,"price":16610.5},{"symbol":"XBTZ17","id":22899833935,"side":"Sell","size":7000,"price":16606.5},{"symbol":"XBTZ17","id":22899834075,"side":"Sell","size":7000,"price":16592.5}]}
09:57:41   {"table":"orderBookL2","action":"update","data":[{"symbol":"XBTUSD","id":8798360500,"side":"Sell","size":1100},{"symbol":"XBTUSD","id":8798362200,"side":"Sell","size":9336}]}
09:57:41   {"table":"orderBookL2","action":"update","data":[{"symbol":"XBTUSD","id":8798358150,"side":"Sell","size":34900}]}
09:57:41   {"table":"orderBookL2","action":"delete","data":[{"symbol":"XBTZ17","id":22899831980,"side":"Sell"}]}
09:57:41   {"table":"orderBookL2","action":"delete","data":[{"symbol":"XBTZ17","id":22899833980,"side":"Sell"},{"symbol":"XBTZ17","id":22899834015,"side":"Sell"},{"symbol":"XBTZ17","id":22899834045,"side":"Sell"}]}
09:57:41   {"table":"orderBookL2","action":"update","data":[{"symbol":"XBTUSD","id":8798362200,"side":"Sell","size":88062}]}
09:57:41   {"table":"orderBookL2","action":"delete","data":[{"symbol":"XBTUSD","id":8798361500,"side":"Sell"}]}
09:57:41   {"table":"orderBookL2","action":"insert","data":[{"symbol":"XBTZ17","id":22899834135,"side":"Sell","size":8000,"price":16586.5},{"symbol":"XBTZ17","id":22899834165,"side":"Sell","size":8000,"price":16583.5},{"symbol":"XBTZ17","id":22899834200,"side":"Sell","size":8000,"price":16580}]}
09:57:41   {"table":"orderBookL2","action":"delete","data":[{"symbol":"XBTZ17","id":22899836515,"side":"Buy"},{"symbol":"XBTZ17","id":22899836765,"side":"Buy"},{"symbol":"XBTZ17","id":22899837010,"side":"Buy"},{"symbol":"XBTZ17","id":22899837255,"side":"Buy"},{"symbol":"XBTZ17","id":22899837505,"side":"Buy"},{"symbol":"XBTZ17","id":22899837750,"side":"Buy"},{"symbol":"XBTZ17","id":22899837995,"side":"Buy"},{"symbol":"XBTZ17","id":22899838245,"side":"Buy"}]}
09:57:41   {"table":"orderBookL2","action":"update","data":[{"symbol":"XBTZ17","id":22899838115,"side":"Buy","size":5152},{"symbol":"XBTZ17","id":22899838360,"side":"Buy","size":5152}]}
09:57:41   {"table":"orderBookL2","action":"delete","data":[{"symbol":"XBTUSD","id":8798363250,"side":"Sell"}]}
09:57:41   {"table":"orderBookL2","action":"insert","data":[{"symbol":"XBTUSD","id":8798362400,"side":"Buy","size":3780,"price":16376}]}
09:57:41   {"table":"orderBookL2","action":"insert","data":[{"symbol":"XBTZ17","id":22899836635,"side":"Buy","size":5000,"price":16336.5},{"symbol":"XBTZ17","id":22899836880,"side":"Buy","size":5000,"price":16312},{"symbol":"XBTZ17","id":22899837125,"side":"Buy","size":5000,"price":16287.5},{"symbol":"XBTZ17","id":22899837375,"side":"Buy","size":5000,"price":16262.5},{"symbol":"XBTZ17","id":22899837620,"side":"Buy","size":5000,"price":16238},{"symbol":"XBTZ17","id":22899837865,"side":"Buy","size":5000,"price":16213.5}]}
09:57:41   {"table":"orderBookL2","action":"delete","data":[{"symbol":"XBTUSD","id":8798367450,"side":"Buy"},{"symbol":"XBTUSD","id":8798369100,"side":"Buy"},{"symbol":"XBTUSD","id":8798369600,"side":"Buy"}]}
09:57:41   {"table":"orderBookL2","action":"insert","data":[{"symbol":"XBTZ17","id":22899834395,"side":"Sell","size":875,"price":16560.5}]}
09:57:41   {"table":"orderBookL2","action":"delete","data":[{"symbol":"XBTZ17","id":22899834570,"side":"Buy"},{"symbol":"XBTZ17","id":22899834690,"side":"Buy"}]}
09:57:41   {"table":"orderBookL2","action":"update","data":[{"symbol":"XBTUSD","id":8798371800,"side":"Buy","size":7250},{"symbol":"XBTUSD","id":8798373550,"side":"Buy","size":5070}]}
09:57:41   {"table":"orderBookL2","action":"insert","data":[{"symbol":"XBTZ17","id":22899834605,"side":"Buy","size":7050,"price":16539.5},{"symbol":"XBTZ17","id":22899834775,"side":"Buy","size":7050,"price":16522.5}]}
09:57:41   {"table":"orderBookL2","action":"insert","data":[{"symbol":"XBTUSD","id":8798369350,"side":"Buy","size":7000,"price":16306.5},{"symbol":"XBTUSD","id":8798369700,"side":"Buy","size":7000,"price":16303},{"symbol":"XBTUSD","id":8798375900,"side":"Buy","size":50,"price":16241}]}
09:57:41   {"table":"orderBookL2","action":"delete","data":[{"symbol":"XBTUSD","id":8798410900,"side":"Buy"}]}
09:57:41   {"table":"orderBookL2","action":"insert","data":[{"symbol":"XBTUSD","id":8798412350,"side":"Buy","size":40,"price":15876.5}]}
09:57:41   {"table":"orderBookL2","action":"insert","data":[{"symbol":"XBTZ17","id":22899834295,"side":"Sell","size":1000,"price":16570.5}]}
09:57:41   {"table":"orderBookL2","action":"delete","data":[{"symbol":"XBTUSD","id":8798362150,"side":"Sell"}]}
09:57:41   {"table":"orderBookL2","action":"update","data":[{"symbol":"XBTZ17","id":22899834640,"side":"Buy","size":46}]}
09:57:41   {"table":"orderBookL2","action":"insert","data":[{"symbol":"XBTZ17","id":22899834720,"side":"Buy","size":52,"price":16528}]}
09:57:41   {"table":"orderBookL2","action":"update","data":[{"symbol":"XBTUSD","id":8798362350,"side":"Sell","size":7650}]}
09:57:41   {"table":"orderBookL2","action":"delete","data":[{"symbol":"XBTZ17","id":22899834605,"side":"Buy"},{"symbol":"XBTZ17","id":22899834620,"side":"Buy"},{"symbol":"XBTZ17","id":22899834640,"side":"Buy"},{"symbol":"XBTZ17","id":22899834720,"side":"Buy"},{"symbol":"XBTZ17","id":22899834730,"side":"Buy"},{"symbol":"XBTZ17","id":22899834760,"side":"Buy"},{"symbol":"XBTZ17","id":22899834775,"side":"Buy"}]}
09:57:41   {"table":"orderBookL2","action":"update","data":[{"symbol":"XBTZ17","id":22899834820,"side":"Buy","size":23932}]}
09:57:41   {"table":"orderBookL2","action":"update","data":[{"symbol":"XBTUSD","id":8798371700,"side":"Buy","size":240},{"symbol":"XBTUSD","id":8798372650,"side":"Buy","size":10649}]}
09:57:41   {"table":"orderBookL2","action":"delete","data":[{"symbol":"XBTUSD","id":8798354200,"side":"Sell"}]}
09:57:41   {"table":"orderBookL2","action":"insert","data":[{"symbol":"XBTZ17","id":22899839635,"side":"Buy","size":153,"price":16036.5}]}
09:57:41   {"table":"orderBookL2","action":"update","data":[{"symbol":"XBTUSD","id":8798306950,"side":"Sell","size":2127},{"symbol":"XBTUSD","id":8798333700,"side":"Sell","size":1198},{"symbol":"XBTUSD","id":8798350900,"side":"Sell","size":17510},{"symbol":"XBTUSD","id":8798352550,"side":"Sell","size":8800},{"symbol":"XBTUSD","id":8798355850,"side":"Sell","size":16550},{"symbol":"XBTUSD","id":8798357500,"side":"Sell","size":141633}]}
09:57:41   {"table":"orderBookL2","action":"insert","data":[{"symbol":"XBTUSD","id":8798293400,"side":"Sell","size":1897,"price":17066},{"symbol":"XBTUSD","id":8798320400,"side":"Sell","size":1265,"price":16796},{"symbol":"XBTUSD","id":8798346950,"side":"Sell","size":632,"price":16530.5}]}
09:57:41   {"table":"orderBookL2","action":"update","data":[{"symbol":"XBTZ17","id":22899835400,"side":"Buy","size":630}]}
09:57:41   {"table":"orderBookL2","action":"insert","data":[{"symbol":"XBTZ17","id":22899835600,"side":"Buy","size":76,"price":16440}]}
09:57:41   {"table":"orderBookL2","action":"insert","data":[{"symbol":"XBTUSD","id":8798362250,"side":"Sell","size":6000,"price":16377.5}]}
09:57:41   {"table":"orderBookL2","action":"insert","data":[{"symbol":"XBTZ17","id":22899834340,"side":"Sell","size":7000,"price":16566}]}
09:57:41   {"table":"orderBookL2","action":"delete","data":[{"symbol":"XBTZ17","id":22899834040,"side":"Sell"}]}
09:57:41   {"table":"orderBookL2","action":"update","data":[{"symbol":"XBTUSD","id":8798364300,"side":"Buy","size":2700}]}
09:57:41   {"table":"orderBookL2","action":"update","data":[{"symbol":"XBTUSD","id":8798362250,"side":"Sell","size":12000}]}
09:57:41   {"table":"orderBookL2","action":"delete","data":[{"symbol":"XBTUSD","id":8798353800,"side":"Sell"}]}
09:57:41   {"table":"orderBookL2","action":"insert","data":[{"symbol":"XBTZ17","id":22899834085,"side":"Sell","size":60,"price":16591.5}]}
09:57:41   {"table":"orderBookL2","action":"delete","data":[{"symbol":"XBTZ17","id":22899829615,"side":"Sell"},{"symbol":"XBTZ17","id":22899830375,"side":"Sell"},{"symbol":"XBTZ17","id":22899831135,"side":"Sell"},{"symbol":"XBTZ17","id":22899831895,"side":"Sell"},{"symbol":"XBTZ17","id":22899832645,"side":"Sell"},{"symbol":"XBTZ17","id":22899833395,"side":"Sell"},{"symbol":"XBTZ17","id":22899834140,"side":"Sell"}]}
09:57:41   {"table":"orderBookL2","action":"update","data":[{"symbol":"XBTUSD","id":8798354800,"side":"Sell","size":36721},{"symbol":"XBTUSD","id":8798365500,"side":"Buy","size":3000}]}
09:57:41   {"table":"orderBookL2","action":"insert","data":[{"symbol":"XBTUSD","id":8798363150,"side":"Buy","size":3000,"price":16368.5}]}
09:57:41   {"table":"orderBookL2","action":"insert","data":[{"symbol":"XBTUSD","id":8798362150,"side":"Sell","size":3000,"price":16378.5},{"symbol":"XBTUSD","id":8798362850,"side":"Buy","size":3000,"price":16371.5}]}
09:57:41   {"table":"orderBookL2","action":"update","data":[{"symbol":"XBTZ17","id":22899834340,"side":"Sell","size":7050}]}
09:57:41   {"table":"orderBookL2","action":"delete","data":[{"symbol":"XBTUSD","id":8798367350,"side":"Buy"},{"symbol":"XBTUSD","id":8798386800,"side":"Buy"}]}
09:57:41   {"table":"orderBookL2","action":"update","data":[{"symbol":"XBTUSD","id":8798367900,"side":"Buy","size":5248},{"symbol":"XBTUSD","id":8798372250,"side":"Buy","size":6780},{"symbol":"XBTUSD","id":8798372800,"side":"Buy","size":7781},{"symbol":"XBTUSD","id":8798377100,"side":"Buy","size":5500},{"symbol":"XBTUSD","id":8798381950,"side":"Buy","size":43}]}
09:57:41   {"table":"orderBookL2","action":"insert","data":[{"symbol":"XBTZ17","id":22899829815,"side":"Sell","size":110,"price":17018.5},{"symbol":"XBTZ17","id":22899830580,"side":"Sell","size":100,"price":16942},{"symbol":"XBTZ17","id":22899831340,"side":"Sell","size":90,"price":16866},{"symbol":"XBTZ17","id":22899832095,"side":"Sell","size":80,"price":16790.5},{"symbol":"XBTZ17","id":22899832845,"side":"Sell","size":70,"price":16715.5},{"symbol":"XBTZ17","id":22899833595,"side":"Sell","size":60,"price":16640.5}]}
09:57:41   {"table":"orderBookL2","action":"update","data":[{"symbol":"XBTZ17","id":22899834820,"side":"Buy","size":21932}]}
09:57:41   {"table":"orderBookL2","action":"insert","data":[{"symbol":"XBTUSD","id":8798377650,"side":"Buy","size":10000,"price":16223.5},{"symbol":"XBTUSD","id":8798382500,"side":"Buy","size":12500,"price":16175},{"symbol":"XBTUSD","id":8798387350,"side":"Buy","size":15000,"price":16126.5}]}
09:57:41   {"table":"orderBookL2","action":"update","data":[{"symbol":"XBTUSD","id":8798361700,"side":"Sell","size":500}]}
09:57:41   {"table":"orderBookL2","action":"update","data":[{"symbol":"XBTZ17","id":22899834340,"side":"Sell","size":16487}]}
09:57:41   {"table":"orderBookL2","action":"delete","data":[{"symbol":"XBTZ17","id":22899834910,"side":"Buy"}]}
09:57:41   {"table":"orderBookL2","action":"delete","data":[{"symbol":"XBTUSD","id":8798356750,"side":"Sell"},{"symbol":"XBTUSD","id":8798367700,"side":"Buy"}]}
09:57:41   {"table":"orderBookL2","action":"update","data":[{"symbol":"XBTUSD","id":8798357550,"side":"Sell","size":19800},{"symbol":"XBTUSD","id":8798365900,"side":"Buy","size":84434},{"symbol":"XBTUSD","id":8798366400,"side":"Buy","size":123},{"symbol":"XBTUSD","id":8798366750,"side":"Buy","size":20000},{"symbol":"XBTUSD","id":8798368550,"side":"Buy","size":400},{"symbol":"XBTUSD","id":8798368600,"side":"Buy","size":160000},{"symbol":"XBTUSD","id":8798368800,"side":"Buy","size":10168}]}
09:57:41   {"table":"orderBookL2","action":"insert","data":[{"symbol":"XBTZ17","id":22899834720,"side":"Buy","size":123,"price":16528},{"symbol":"XBTZ17","id":22899835060,"side":"Buy","size":193,"price":16494}]}
09:57:41   {"table":"orderBookL2","action":"insert","data":[{"symbol":"XBTUSD","id":8798367250,"side":"Buy","size":10000,"price":16327.5}]}
09:57:41   {"table":"orderBookL2","action":"update","data":[{"symbol":"XBTUSD","id":8798350000,"side":"Sell","size":75370}]}
09:57:41   {"table":"orderBookL2","action":"insert","data":[{"symbol":"XBTUSD","id":8798354700,"side":"Sell","size":50000,"price":16453}]}
09:57:41   {"table":"orderBookL2","action":"delete","data":[{"symbol":"XBTUSD","id":8798332300,"side":"Sell"},{"symbol":"XBTUSD","id":8798341400,"side":"Sell"},{"symbol":"XBTUSD","id":8798347750,"side":"Sell"},{"symbol":"XBTUSD","id":8798354950,"side":"Sell"},{"symbol":"XBTUSD","id":8798364750,"side":"Buy"},{"symbol":"XBTUSD","id":8798367600,"side":"Buy"},{"symbol":"XBTUSD","id":8798371850,"side":"Buy"},{"symbol":"XBTUSD","id":8798378100,"side":"Buy"}]}
09:57:41   {"table":"orderBookL2","action":"update","data":[{"symbol":"XBTZ17","id":22899834335,"side":"Sell","size":30000},{"symbol":"XBTZ17","id":22899834340,"side":"Sell","size":67687}]}
09:57:41   {"table":"orderBookL2","action":"delete","data":[{"symbol":"XBTZ17","id":22899833360,"side":"Sell"},{"symbol":"XBTZ17","id":22899835270,"side":"Buy"}]}
09:57:41   {"table":"orderBookL2","action":"update","data":[{"symbol":"XBTZ17","id":22899835590,"side":"Buy","size":90871}]}
09:57:41   {"table":"orderBookL2","action":"insert","data":[{"symbol":"XBTZ17","id":22899833660,"side":"Sell","size":88526,"price":16634}]}
09:57:41   {"table":"orderBookL2","action":"delete","data":[{"symbol":"XBTZ17","id":22899834315,"side":"Sell"}]}
09:57:41   {"table":"orderBookL2","action":"update","data":[{"symbol":"XBTZ17","id":22899834340,"side":"Sell","size":69125}]}
09:57:41   {"table":"orderBookL2","action":"delete","data":[{"symbol":"XBTZ17","id":22899834960,"side":"Buy"}]}
09:57:41   {"table":"orderBookL2","action":"insert","data":[{"symbol":"XBTZ17","id":22899835005,"side":"Buy","size":8000,"price":16499.5}]}
09:57:41   {"table":"orderBookL2","action":"update","data":[{"symbol":"XBTUSD","id":8798334550,"side":"Sell","size":7263},{"symbol":"XBTUSD","id":8798352050,"side":"Sell","size":2496},{"symbol":"XBTUSD","id":8798354250,"side":"Sell","size":9000},{"symbol":"XBTUSD","id":8798366950,"side":"Buy","size":327293},{"symbol":"XBTUSD","id":8798369800,"side":"Buy","size":2700},{"symbol":"XBTUSD","id":8798374100,"side":"Buy","size":3990},{"symbol":"XBTUSD","id":8798380300,"side":"Buy","size":5200},{"symbol":"XBTUSD","id":8798386900,"side":"Buy","size":7795}]}
09:57:41   {"table":"orderBookL2","action":"insert","data":[{"symbol":"XBTUSD","id":8798343600,"side":"Sell","size":5000,"price":16564},{"symbol":"XBTUSD","id":8798349950,"side":"Sell","size":3750,"price":16500.5},{"symbol":"XBTUSD","id":8798357150,"side":"Sell","size":1250,"price":16428.5},{"symbol":"XBTUSD","id":8798389150,"side":"Buy","size":6250,"price":16108.5}]}
09:57:41   {"table":"orderBookL2","action":"insert","data":[{"symbol":"XBTUSD","id":8798364900,"side":"Buy","size":2500,"price":16351}]}
09:57:41   {"table":"orderBookL2","action":"update","data":[{"symbol":"XBTUSD","id":8798369800,"side":"Buy","size":2500}]}
09:57:41   {"table":"orderBookL2","action":"update","data":[{"symbol":"XBTUSD","id":8798368150,"side":"Buy","size":10850}]}
09:57:41   {"table":"orderBookL2","action":"insert","data":[{"symbol":"XBTZ17","id":22899833800,"side":"Sell","size":6000,"price":16620}]}
09:57:41   {"table":"orderBookL2","action":"update","data":[{"symbol":"XBTZ17","id":22899834395,"side":"Sell","size":75}]}
09:57:41   {"table":"orderBookL2","action":"insert","data":[{"symbol":"XBTZ17","id":22899848780,"side":"Buy","size":10000,"price":15122}]}
09:57:41   {"table":"orderBookL2","action":"delete","data":[{"symbol":"XBTZ17","id":22899834395,"side":"Sell"}]}
09:57:41   {"table":"orderBookL2","action":"delete","data":[{"symbol":"XBTZ17","id":22899831395,"side":"Sell"},{"symbol":"XBTZ17","id":22899841820,"side":"Buy"}]}
09:57:41   {"table":"orderBookL2","action":"insert","data":[{"symbol":"XBTUSD","id":8798363750,"side":"Buy","size":5000,"price":16362.5}]}
09:57:41   {"table":"orderBookL2","action":"update","data":[{"symbol":"XBTUSD","id":8798368450,"side":"Buy","size":336900}]}
09:57:41   {"table":"orderBookL2","action":"insert","data":[{"symbol":"XBTUSD","id":8798367500,"side":"Buy","size":2420,"price":16325}]}
09:57:41   {"table":"orderBookL2","action":"update","data":[{"symbol":"XBTUSD","id":8798362400,"side":"Buy","size":3680}]}
09:57:41   {"table":"orderBookL2","action":"update","data":[{"symbol":"XBTUSD","id":8798364850,"side":"Buy","size":4339}]}
09:57:41   {"table":"orderBookL2","action":"insert","data":[{"symbol":"XBTUSD","id":8798367550,"side":"Buy","size":3776,"price":16324.5}]}
09:57:41   {"table":"orderBookL2","action":"delete","data":[{"symbol":"XBTZ17","id":22899833330,"side":"Sell"},{"symbol":"XBTZ17","id":22899833455,"side":"Sell"},{"symbol":"XBTZ17","id":22899833675,"side":"Sell"},{"symbol":"XBTZ17","id":22899833760,"side":"Sell"},{"symbol":"XBTZ17","id":22899835520,"side":"Buy"}]}
09:57:41   {"table":"orderBookL2","action":"update","data":[{"symbol":"XBTZ17","id":22899833505,"side":"Sell","size":42100},{"symbol":"XBTZ17","id":22899833820,"side":"Sell","size":12850},{"symbol":"XBTZ17","id":22899835400,"side":"Buy","size":1570}]}
09:57:41   {"table":"orderBookL2","action":"insert","data":[{"symbol":"XBTZ17","id":22899833395,"side":"Sell","size":6850,"price":16660.5},{"symbol":"XBTZ17","id":22899833525,"side":"Sell","size":6890,"price":16647.5},{"symbol":"XBTZ17","id":22899833565,"side":"Sell","size":3570,"price":16643.5},{"symbol":"XBTZ17","id":22899833570,"side":"Sell","size":6850,"price":16643},{"symbol":"XBTZ17","id":22899833740,"side":"Sell","size":6890,"price":16626},{"symbol":"XBTZ17","id":22899835285,"side":"Buy","size":630,"price":16471.5}]}
09:57:41   {"table":"orderBookL2","action":"update","data":[{"symbol":"XBTUSD","id":8798364900,"side":"Buy","size":2750}]}
09:57:41   {"table":"orderBookL2","action":"update","data":[{"symbol":"XBTUSD","id":8798359950,"side":"Sell","size":60834},{"symbol":"XBTUSD","id":8798362150,"side":"Sell","size":3122}]}
09:57:41   {"table":"orderBookL2","action":"delete","data":[{"symbol":"XBTUSD","id":8798354050,"side":"Sell"},{"symbol":"XBTUSD","id":8798355150,"side":"Sell"},{"symbol":"XBTUSD","id":8798358400,"side":"Sell"}]}
09:57:41   {"table":"orderBookL2","action":"update","data":[{"symbol":"XBTUSD","id":8798351200,"side":"Sell","size":187352},{"symbol":"XBTUSD","id":8798352800,"side":"Sell","size":1150},{"symbol":"XBTUSD","id":8798354500,"side":"Sell","size":4900},{"symbol":"XBTUSD","id":8798359500,"side":"Sell","size":2750},{"symbol":"XBTUSD","id":8798360050,"side":"Sell","size":11100},{"symbol":"XBTUSD","id":8798367800,"side":"Buy","size":16586}]}
09:57:41   {"table":"orderBookL2","action":"insert","data":[{"symbol":"XBTUSD","id":8798368400,"side":"Buy","size":4287,"price":16316}]}
09:57:41   {"table":"orderBookL2","action":"update","data":[{"symbol":"XBTUSD","id":8798368150,"side":"Buy","size":10250}]}
09:57:41   {"table":"orderBookL2","action":"update","data":[{"symbol":"XBTZ17","id":22899833410,"side":"Sell","size":14000}]}
09:57:41   {"table":"orderBookL2","action":"insert","data":[{"symbol":"XBTZ17","id":22899833430,"side":"Sell","size":7000,"price":16657}]}
09:57:41   {"table":"orderBookL2","action":"delete","data":[{"symbol":"XBTZ17","id":22899834295,"side":"Sell"}]}
09:57:41   {"table":"orderBookL2","action":"update","data":[{"symbol":"XBTUSD","id":8798360150,"side":"Sell","size":12000}]}
09:57:41   {"table":"orderBookL2","action":"update","data":[{"symbol":"XBTUSD","id":8798364050,"side":"Buy","size":138}]}
09:57:41   {"table":"orderBookL2","action":"insert","data":[{"symbol":"XBTUSD","id":8798366500,"side":"Buy","size":3776,"price":16335}]}
09:57:41   {"table":"orderBookL2","action":"delete","data":[{"symbol":"XBTZ17","id":22899833990,"side":"Sell"},{"symbol":"XBTZ17","id":22899839175,"side":"Buy"}]}
09:57:41   {"table":"orderBookL2","action":"update","data":[{"symbol":"XBTZ17","id":22899839205,"side":"Buy","size":9389}]}
09:57:41   {"table":"orderBookL2","action":"insert","data":[{"symbol":"XBTZ17","id":22899834320,"side":"Sell","size":6718,"price":16568}]}
09:57:41   {"table":"orderBookL2","action":"update","data":[{"symbol":"XBTUSD","id":8798365400,"side":"Buy","size":5509},{"symbol":"XBTUSD","id":8798367800,"side":"Buy","size":20362}]}
09:57:41   {"table":"orderBookL2","action":"update","data":[{"symbol":"XBTUSD","id":8798363800,"side":"Buy","size":4501}]}
09:57:41   {"table":"orderBookL2","action":"insert","data":[{"symbol":"XBTZ17","id":22899832245,"side":"Sell","size":259100,"price":16775.5},{"symbol":"XBTZ17","id":22899833815,"side":"Sell","size":49421,"price":16618.5}]}
09:57:41   {"table":"orderBookL2","action":"insert","data":[{"symbol":"XBTZ17","id":22899832830,"side":"Sell","size":30000,"price":16717},{"symbol":"XBTZ17","id":22899836105,"side":"Buy","size":30000,"price":16389.5}]}
09:57:41   {"table":"orderBookL2","action":"delete","data":[{"symbol":"XBTZ17","id":22899833765,"side":"Sell"},{"symbol":"XBTZ17","id":22899833895,"side":"Sell"},{"symbol":"XBTZ17","id":22899833935,"side":"Sell"},{"symbol":"XBTZ17","id":22899834075,"side":"Sell"}]}
09:57:41   {"table":"orderBookL2","action":"update","data":[{"symbol":"XBTZ17","id":22899833410,"side":"Sell","size":7000},{"symbol":"XBTZ17","id":22899834135,"side":"Sell","size":15000}]}
09:57:41   {"table":"orderBookL2","action":"update","data":[{"symbol":"XBTUSD","id":8798365800,"side":"Buy","size":7759},{"symbol":"XBTUSD","id":8798368250,"side":"Buy","size":3876}]}
09:57:41   {"table":"orderBookL2","action":"delete","data":[{"symbol":"XBTUSD","id":8798310650,"side":"Sell"}]}
09:57:41   {"table":"orderBookL2","action":"insert","data":[{"symbol":"XBTUSD","id":8798314600,"side":"Sell","size":40,"price":16854}]}
09:57:41   {"table":"orderBookL2","action":"delete","data":[{"symbol":"XBTUSD","id":8798310250,"side":"Sell"}]}
09:57:41   {"table":"orderBookL2","action":"insert","data":[{"symbol":"XBTZ17","id":22899833500,"side":"Sell","size":7000,"price":16650},{"symbol":"XBTZ17","id":22899833835,"side":"Sell","size":7000,"price":16616.5},{"symbol":"XBTZ17","id":22899833945,"side":"Sell","size":7000,"price":16605.5},{"symbol":"XBTZ17","id":22899833985,"side":"Sell","size":7000,"price":16601.5}]}
09:57:41   {"table":"orderBookL2","action":"delete","data":[{"symbol":"XBTZ17","id":22899834165,"side":"Sell"},{"symbol":"XBTZ17","id":22899834200,"side":"Sell"}]}
09:57:41   {"table":"orderBookL2","action":"update","data":[{"symbol":"XBTZ17","id":22899834135,"side":"Sell","size":7000}]}
09:57:42   {"table":"orderBookL2","action":"insert","data":[{"symbol":"XBTZ17","id":22899834190,"side":"Sell","size":8000,"price":16581},{"symbol":"XBTZ17","id":22899834220,"side":"Sell","size":8000,"price":16578},{"symbol":"XBTZ17","id":22899834255,"side":"Sell","size":8000,"price":16574.5}]}
09:57:41   {"table":"orderBookL2","action":"update","data":[{"symbol":"XBTUSD","id":8798314600,"side":"Sell","size":80}]}
09:57:42   {"table":"orderBookL2","action":"update","data":[{"symbol":"XBTUSD","id":8798370000,"side":"Buy","size":201310}]}
09:57:42   {"table":"orderBookL2","action":"update","data":[{"symbol":"XBTUSD","id":8798368150,"side":"Buy","size":9850}]}
09:57:42   {"table":"orderBookL2","action":"update","data":[{"symbol":"XBTUSD","id":8798364650,"side":"Buy","size":2301},{"symbol":"XBTUSD","id":8798367100,"side":"Buy","size":3876}]}
09:57:42   {"table":"orderBookL2","action":"delete","data":[{"symbol":"XBTZ17","id":22899831615,"side":"Sell"},{"symbol":"XBTZ17","id":22899831860,"side":"Sell"},{"symbol":"XBTZ17","id":22899832110,"side":"Sell"},{"symbol":"XBTZ17","id":22899832360,"side":"Sell"},{"symbol":"XBTZ17","id":22899832605,"side":"Sell"},{"symbol":"XBTZ17","id":22899832855,"side":"Sell"},{"symbol":"XBTZ17","id":22899833105,"side":"Sell"},{"symbol":"XBTZ17","id":22899833350,"side":"Sell"},{"symbol":"XBTZ17","id":22899836635,"side":"Buy"},{"symbol":"XBTZ17","id":22899836880,"side":"Buy"},{"symbol":"XBTZ17","id":22899837125,"side":"Buy"},{"symbol":"XBTZ17","id":22899837375,"side":"Buy"},{"symbol":"XBTZ17","id":22899837620,"side":"Buy"},{"symbol":"XBTZ17","id":22899837865,"side":"Buy"}]}
09:57:42   {"table":"orderBookL2","action":"update","data":[{"symbol":"XBTZ17","id":22899838115,"side":"Buy","size":152},{"symbol":"XBTZ17","id":22899838285,"side":"Buy","size":5305},{"symbol":"XBTZ17","id":22899838360,"side":"Buy","size":152},{"symbol":"XBTZ17","id":22899838530,"side":"Buy","size":5152}]}
09:57:42   {"table":"orderBookL2","action":"insert","data":[{"symbol":"XBTZ17","id":22899831990,"side":"Sell","size":5000,"price":16801},{"symbol":"XBTZ17","id":22899832235,"side":"Sell","size":5000,"price":16776.5},{"symbol":"XBTZ17","id":22899832485,"side":"Sell","size":5000,"price":16751.5},{"symbol":"XBTZ17","id":22899832735,"side":"Sell","size":5000,"price":16726.5},{"symbol":"XBTZ17","id":22899832980,"side":"Sell","size":5000,"price":16702},{"symbol":"XBTZ17","id":22899833230,"side":"Sell","size":5000,"price":16677},{"symbol":"XBTZ17","id":22899833475,"side":"Sell","size":5000,"price":16652.5},{"symbol":"XBTZ17","id":22899833725,"side":"Sell","size":5000,"price":16627.5},{"symbol":"XBTZ17","id":22899836805,"side":"Buy","size":5000,"price":16319.5},{"symbol":"XBTZ17","id":22899837050,"side":"Buy","size":5000,"price":16295},{"symbol":"XBTZ17","id":22899837300,"side":"Buy","size":5000,"price":16270},{"symbol":"XBTZ17","id":22899837545,"side":"Buy","size":5000,"price":16245.5},{"symbol":"XBTZ17","id":22899837790,"side":"Buy","size":5000,"price":16221},{"symbol":"XBTZ17","id":22899838035,"side":"Buy","size":5000,"price":16196.5}]}
09:57:42   {"table":"orderBookL2","action":"delete","data":[{"symbol":"XBTZ17","id":22899833300,"side":"Sell"},{"symbol":"XBTZ17","id":22899833610,"side":"Sell"},{"symbol":"XBTZ17","id":22899833780,"side":"Sell"},{"symbol":"XBTZ17","id":22899833915,"side":"Sell"}]}
09:57:42   {"table":"orderBookL2","action":"update","data":[{"symbol":"XBTZ17","id":22899833795,"side":"Sell","size":47000},{"symbol":"XBTZ17","id":22899833820,"side":"Sell","size":5850}]}
09:57:42   {"table":"orderBookL2","action":"insert","data":[{"symbol":"XBTZ17","id":22899833385,"side":"Sell","size":7000,"price":16661.5},{"symbol":"XBTZ17","id":22899833670,"side":"Sell","size":7000,"price":16633},{"symbol":"XBTZ17","id":22899833755,"side":"Sell","size":7000,"price":16624.5},{"symbol":"XBTZ17","id":22899833970,"side":"Sell","size":5059,"price":16603}]}
09:57:42   {"table":"orderBookL2","action":"insert","data":[{"symbol":"XBTZ17","id":22899833960,"side":"Sell","size":1000,"price":16604}]}
09:57:42   {"table":"orderBookL2","action":"update","data":[{"symbol":"XBTZ17","id":22899834375,"side":"Sell","size":4700}]}
09:57:42   {"table":"orderBookL2","action":"update","data":[{"symbol":"XBTUSD","id":8798370000,"side":"Buy","size":201610}]}
09:57:42   {"table":"orderBookL2","action":"delete","data":[{"symbol":"XBTUSD","id":8798353250,"side":"Sell"},{"symbol":"XBTUSD","id":8798355650,"side":"Sell"},{"symbol":"XBTUSD","id":8798359300,"side":"Sell"},{"symbol":"XBTUSD","id":8798366600,"side":"Buy"},{"symbol":"XBTUSD","id":8798368350,"side":"Buy"}]}
09:57:42   {"table":"orderBookL2","action":"update","data":[{"symbol":"XBTUSD","id":8798352050,"side":"Sell","size":3072},{"symbol":"XBTUSD","id":8798357600,"side":"Sell","size":18900},{"symbol":"XBTUSD","id":8798360550,"side":"Sell","size":5455},{"symbol":"XBTUSD","id":8798365300,"side":"Buy","size":3776}]}
09:57:42   {"table":"orderBookL2","action":"insert","data":[{"symbol":"XBTUSD","id":8798354150,"side":"Sell","size":1536,"price":16458.5},{"symbol":"XBTUSD","id":8798356150,"side":"Sell","size":768,"price":16438.5},{"symbol":"XBTUSD","id":8798358250,"side":"Sell","size":384,"price":16417.5},{"symbol":"XBTUSD","id":8798360250,"side":"Sell","size":192,"price":16397.5},{"symbol":"XBTUSD","id":8798366350,"side":"Buy","size":1514,"price":16336.5},{"symbol":"XBTUSD","id":8798368100,"side":"Buy","size":1734,"price":16319},{"symbol":"XBTUSD","id":8798369550,"side":"Buy","size":1978,"price":16304.5}]}
09:57:42   {"table":"orderBookL2","action":"update","data":[{"symbol":"XBTUSD","id":8798362400,"side":"Buy","size":480}]}
09:57:42   {"table":"orderBookL2","action":"update","data":[{"symbol":"XBTUSD","id":8798364850,"side":"Buy","size":3000},{"symbol":"XBTUSD","id":8798366900,"side":"Buy","size":5599}]}
09:57:42   {"table":"orderBookL2","action":"delete","data":[{"symbol":"XBTUSD","id":8798364450,"side":"Buy"}]}
09:57:42   {"table":"orderBookL2","action":"update","data":[{"symbol":"XBTUSD","id":8798356550,"side":"Sell","size":3442},{"symbol":"XBTUSD","id":8798358200,"side":"Sell","size":1200},{"symbol":"XBTUSD","id":8798366100,"side":"Buy","size":10200}]}
09:57:42   {"table":"orderBookL2","action":"update","data":[{"symbol":"XBTUSD","id":8798360550,"side":"Sell","size":4800}]}
09:57:42   {"table":"orderBookL2","action":"update","data":[{"symbol":"XBTZ17","id":22899834340,"side":"Sell","size":62125}]}
09:57:42   {"table":"orderBookL2","action":"update","data":[{"symbol":"XBTZ17","id":22899834340,"side":"Sell","size":52688}]}
09:57:42   {"table":"orderBookL2","action":"insert","data":[{"symbol":"XBTZ17","id":22899834400,"side":"Sell","size":9437,"price":16560}]}
09:57:42   {"table":"orderBookL2","action":"update","data":[{"symbol":"XBTZ17","id":22899834340,"side":"Sell","size":51250},{"symbol":"XBTZ17","id":22899834400,"side":"Sell","size":10709}]}
09:57:42   {"table":"orderBookL2","action":"update","data":[{"symbol":"XBTZ17","id":22899834340,"side":"Sell","size":50},{"symbol":"XBTZ17","id":22899834400,"side":"Sell","size":61909}]}
09:57:42   {"table":"orderBookL2","action":"delete","data":[{"symbol":"XBTUSD","id":8798364350,"side":"Buy"}]}
09:57:42   {"table":"orderBookL2","action":"update","data":[{"symbol":"XBTUSD","id":8798365400,"side":"Buy","size":5459},{"symbol":"XBTUSD","id":8798366200,"side":"Buy","size":10166}]}
09:57:42   {"table":"orderBookL2","action":"insert","data":[{"symbol":"XBTUSD","id":8798366600,"side":"Buy","size":10050,"price":16334}]}
09:57:42   {"table":"orderBookL2","action":"update","data":[{"symbol":"XBTUSD","id":8798362150,"side":"Sell","size":3222}]}
09:57:42   {"table":"orderBookL2","action":"update","data":[{"symbol":"XBTUSD","id":8798368150,"side":"Buy","size":9350}]}
09:57:42   {"table":"orderBookL2","action":"update","data":[{"symbol":"XBTUSD","id":8798351200,"side":"Sell","size":185352}]}
09:57:42   {"table":"orderBookL2","action":"update","data":[{"symbol":"XBTUSD","id":8798368150,"side":"Buy","size":8600}]}
09:57:42   {"table":"orderBookL2","action":"update","data":[{"symbol":"XBTUSD","id":8798362150,"side":"Sell","size":5222}]}
09:57:42   {"table":"orderBookL2","action":"delete","data":[{"symbol":"XBTUSD","id":8798364600,"side":"Buy"}]}
09:57:42   {"table":"orderBookL2","action":"update","data":[{"symbol":"XBTUSD","id":8798356400,"side":"Sell","size":367},{"symbol":"XBTUSD","id":8798358050,"side":"Sell","size":250}]}
09:57:42   {"table":"orderBookL2","action":"delete","data":[{"symbol":"XBTZ17","id":22899833870,"side":"Sell"},{"symbol":"XBTZ17","id":22899835510,"side":"Buy"}]}
09:57:42   {"table":"orderBookL2","action":"update","data":[{"symbol":"XBTZ17","id":22899835195,"side":"Buy","size":3488}]}
09:57:42   {"table":"orderBookL2","action":"insert","data":[{"symbol":"XBTZ17","id":22899833550,"side":"Sell","size":2902,"price":16645}]}
09:57:42   {"table":"orderBookL2","action":"update","data":[{"symbol":"XBTZ17","id":22899831300,"side":"Sell","size":183}]}
09:57:42   {"table":"orderBookL2","action":"insert","data":[{"symbol":"XBTZ17","id":22899835100,"side":"Buy","size":14000,"price":16490}]}
09:57:42   {"table":"orderBookL2","action":"update","data":[{"symbol":"XBTZ17","id":22899836400,"side":"Buy","size":180}]}
09:57:42   {"table":"orderBookL2","action":"insert","data":[{"symbol":"XBTZ17","id":22899833710,"side":"Sell","size":14000,"price":16629}]}
09:57:42   {"table":"orderBookL2","action":"insert","data":[{"symbol":"XBTUSD","id":8798366250,"side":"Buy","size":200,"price":16337.5}]}
09:57:42   {"table":"orderBookL2","action":"insert","data":[{"symbol":"XBTUSD","id":8798359700,"side":"Sell","size":260,"price":16403}]}
09:57:42   {"table":"orderBookL2","action":"update","data":[{"symbol":"XBTUSD","id":8798360500,"side":"Sell","size":21100}]}
09:57:42   {"table":"orderBookL2","action":"delete","data":[{"symbol":"XBTZ17","id":22899834085,"side":"Sell"}]}
09:57:42   {"table":"orderBookL2","action":"insert","data":[{"symbol":"XBTZ17","id":22899834105,"side":"Sell","size":60,"price":16589.5}]}
09:57:42   {"table":"orderBookL2","action":"delete","data":[{"symbol":"XBTZ17","id":22899835810,"side":"Buy"}]}
09:57:42   {"table":"orderBookL2","action":"insert","data":[{"symbol":"XBTZ17","id":22899834860,"side":"Buy","size":35,"price":16514},{"symbol":"XBTZ17","id":22899836100,"side":"Buy","size":97,"price":16390}]}
09:57:42   {"table":"orderBookL2","action":"delete","data":[{"symbol":"XBTZ17","id":22899832765,"side":"Sell"},{"symbol":"XBTZ17","id":22899833025,"side":"Sell"},{"symbol":"XBTZ17","id":22899833440,"side":"Sell"}]}
09:57:42   {"table":"orderBookL2","action":"update","data":[{"symbol":"XBTUSD","id":8798367200,"side":"Buy","size":20167}]}
09:57:42   {"table":"orderBookL2","action":"update","data":[{"symbol":"XBTUSD","id":8798364800,"side":"Buy","size":2693}]}
09:57:42   {"table":"orderBookL2","action":"update","data":[{"symbol":"XBTUSD","id":8798368150,"side":"Buy","size":5100}]}
09:57:42   {"table":"orderBookL2","action":"update","data":[{"symbol":"XBTUSD","id":8798364800,"side":"Buy","size":5693}]}
09:57:42   {"table":"orderBookL2","action":"delete","data":[{"symbol":"XBTUSD","id":8798365300,"side":"Buy"}]}
09:57:42   {"table":"orderBookL2","action":"update","data":[{"symbol":"XBTZ17","id":22899832980,"side":"Sell","size":12000}]}
09:57:42   {"table":"orderBookL2","action":"insert","data":[{"symbol":"XBTZ17","id":22899833225,"side":"Sell","size":7000,"price":16677.5},{"symbol":"XBTZ17","id":22899833650,"side":"Sell","size":7000,"price":16635}]}
09:57:42   {"table":"orderBookL2","action":"insert","data":[{"symbol":"XBTZ17","id":22899834355,"side":"Sell","size":75,"price":16564.5}]}
09:57:42   {"table":"orderBookL2","action":"delete","data":[{"symbol":"XBTZ17","id":22899841555,"side":"Buy"}]}
09:57:42   {"table":"orderBookL2","action":"delete","data":[{"symbol":"XBTZ17","id":22899833410,"side":"Sell"}]}
09:57:42   {"table":"orderBookL2","action":"update","data":[{"symbol":"XBTUSD","id":8798366900,"side":"Buy","size":9375}]}
09:57:43   {"table":"orderBookL2","action":"update","data":[{"symbol":"XBTUSD","id":8798359950,"side":"Sell","size":732}]}
09:57:43   {"table":"orderBookL2","action":"insert","data":[{"symbol":"XBTZ17","id":22899833870,"side":"Sell","size":7000,"price":16613}]}
09:57:43   {"table":"orderBookL2","action":"delete","data":[{"symbol":"XBTZ17","id":22899834190,"side":"Sell"},{"symbol":"XBTZ17","id":22899834220,"side":"Sell"},{"symbol":"XBTZ17","id":22899834255,"side":"Sell"}]}
09:57:43   {"table":"orderBookL2","action":"insert","data":[{"symbol":"XBTZ17","id":22899834315,"side":"Sell","size":8000,"price":16568.5},{"symbol":"XBTZ17","id":22899834345,"side":"Sell","size":8000,"price":16565.5},{"symbol":"XBTZ17","id":22899834380,"side":"Sell","size":8000,"price":16562}]}
09:57:43   {"table":"orderBookL2","action":"delete","data":[{"symbol":"XBTZ17","id":22899833385,"side":"Sell"},{"symbol":"XBTZ17","id":22899833670,"side":"Sell"},{"symbol":"XBTZ17","id":22899833755,"side":"Sell"},{"symbol":"XBTZ17","id":22899833970,"side":"Sell"}]}
09:57:43   {"table":"orderBookL2","action":"update","data":[{"symbol":"XBTZ17","id":22899833795,"side":"Sell","size":40000},{"symbol":"XBTZ17","id":22899833820,"side":"Sell","size":12850}]}
09:57:43   {"table":"orderBookL2","action":"insert","data":[{"symbol":"XBTZ17","id":22899833470,"side":"Sell","size":7000,"price":16653},{"symbol":"XBTZ17","id":22899833735,"side":"Sell","size":7000,"price":16626.5},{"symbol":"XBTZ17","id":22899833780,"side":"Sell","size":7000,"price":16622},{"symbol":"XBTZ17","id":22899834005,"side":"Sell","size":5059,"price":16599.5}]}
09:57:43   {"table":"orderBookL2","action":"delete","data":[{"symbol":"XBTZ17","id":22899833500,"side":"Sell"},{"symbol":"XBTZ17","id":22899833835,"side":"Sell"},{"symbol":"XBTZ17","id":22899834135,"side":"Sell"}]}
09:57:43   {"table":"orderBookL2","action":"update","data":[{"symbol":"XBTUSD","id":8798360000,"side":"Sell","size":13100}]}
09:57:43   {"table":"orderBookL2","action":"insert","data":[{"symbol":"XBTUSD","id":8798551250,"side":"Buy","size":100,"price":14487.5}]}
09:57:43   {"table":"orderBookL2","action":"insert","data":[{"symbol":"XBTZ17","id":22899833585,"side":"Sell","size":7000,"price":16641.5},{"symbol":"XBTZ17","id":22899833900,"side":"Sell","size":7000,"price":16610},{"symbol":"XBTZ17","id":22899834170,"side":"Sell","size":7000,"price":16583}]}
09:57:43   {"table":"orderBookL2","action":"insert","data":[{"symbol":"XBTZ17","id":22899834990,"side":"Buy","size":6000,"price":16501}]}
09:57:43   {"table":"orderBookL2","action":"delete","data":[{"symbol":"XBTZ17","id":22899834720,"side":"Buy"},{"symbol":"XBTZ17","id":22899835060,"side":"Buy"},{"symbol":"XBTZ17","id":22899835250,"side":"Buy"},{"symbol":"XBTZ17","id":22899835930,"side":"Buy"}]}
09:57:43   {"table":"orderBookL2","action":"update","data":[{"symbol":"XBTZ17","id":22899834860,"side":"Buy","size":158},{"symbol":"XBTZ17","id":22899835590,"side":"Buy","size":90537},{"symbol":"XBTZ17","id":22899836220,"side":"Buy","size":521}]}
09:57:43   {"table":"orderBookL2","action":"insert","data":[{"symbol":"XBTUSD","id":8798324050,"side":"Sell","size":500,"price":16759.5}]}
09:57:43   {"table":"orderBookL2","action":"delete","data":[{"symbol":"XBTUSD","id":8798362350,"side":"Sell"}]}
09:57:43   {"table":"orderBookL2","action":"insert","data":[{"symbol":"XBTZ17","id":22899835200,"side":"Buy","size":193,"price":16480},{"symbol":"XBTZ17","id":22899835540,"side":"Buy","size":264,"price":16446},{"symbol":"XBTZ17","id":22899835880,"side":"Buy","size":334,"price":16412}]}
09:57:43   {"table":"orderBookL2","action":"delete","data":[{"symbol":"XBTZ17","id":22899831300,"side":"Sell"},{"symbol":"XBTZ17","id":22899835110,"side":"Buy"},{"symbol":"XBTZ17","id":22899835420,"side":"Buy"},{"symbol":"XBTZ17","id":22899836060,"side":"Buy"},{"symbol":"XBTZ17","id":22899836380,"side":"Buy"},{"symbol":"XBTZ17","id":22899836700,"side":"Buy"}]}
09:57:43   {"table":"orderBookL2","action":"update","data":[{"symbol":"XBTUSD","id":8798365400,"side":"Buy","size":7459}]}
09:57:43   {"table":"orderBookL2","action":"insert","data":[{"symbol":"XBTUSD","id":8798358400,"side":"Sell","size":2000,"price":16416}]}
09:57:43   {"table":"orderBookL2","action":"delete","data":[{"symbol":"XBTUSD","id":8798362050,"side":"Sell"}]}
09:57:43   {"table":"orderBookL2","action":"update","data":[{"symbol":"XBTZ17","id":22899829600,"side":"Sell","size":168},{"symbol":"XBTZ17","id":22899834990,"side":"Buy","size":6250},{"symbol":"XBTZ17","id":22899835630,"side":"Buy","size":509},{"symbol":"XBTZ17","id":22899835740,"side":"Buy","size":39900},{"symbol":"XBTZ17","id":22899835940,"side":"Buy","size":767}]}
09:57:43   {"table":"orderBookL2","action":"insert","data":[{"symbol":"XBTZ17","id":22899828820,"side":"Sell","size":250,"price":17118},{"symbol":"XBTZ17","id":22899830520,"side":"Sell","size":183,"price":16948},{"symbol":"XBTZ17","id":22899834680,"side":"Buy","size":183,"price":16532},{"symbol":"XBTZ17","id":22899835310,"side":"Buy","size":316,"price":16469}]}
09:57:43   {"table":"orderBookL2","action":"insert","data":[{"symbol":"XBTUSD","id":8798374200,"side":"Buy","size":934,"price":16258},{"symbol":"XBTUSD","id":8798389800,"side":"Buy","size":934,"price":16102}]}
09:57:43   {"table":"orderBookL2","action":"update","data":[{"symbol":"XBTUSD","id":8798378500,"side":"Buy","size":9295}]}
09:57:43   {"table":"orderBookL2","action":"delete","data":[{"symbol":"XBTZ17","id":22899834375,"side":"Sell"}]}
09:57:43   {"table":"orderBookL2","action":"delete","data":[{"symbol":"XBTZ17","id":22899833960,"side":"Sell"}]}
09:57:43   {"table":"orderBookL2","action":"update","data":[{"symbol":"XBTUSD","id":8798360550,"side":"Sell","size":3200}]}
09:57:43   {"table":"orderBookL2","action":"delete","data":[{"symbol":"XBTUSD","id":8798373000,"side":"Buy"}]}
09:57:43   {"table":"orderBookL2","action":"insert","data":[{"symbol":"XBTZ17","id":22899834970,"side":"Buy","size":3140,"price":16503}]}
09:57:43   {"table":"orderBookL2","action":"update","data":[{"symbol":"XBTZ17","id":22899834380,"side":"Sell","size":8859},{"symbol":"XBTZ17","id":22899834400,"side":"Sell","size":60637}]}
09:57:43   {"table":"orderBookL2","action":"insert","data":[{"symbol":"XBTZ17","id":22899833675,"side":"Sell","size":2000,"price":16632.5}]}
09:57:43   {"table":"orderBookL2","action":"insert","data":[{"symbol":"XBTUSD","id":8798374300,"side":"Buy","size":7000,"price":16257}]}
09:57:43   {"table":"orderBookL2","action":"delete","data":[{"symbol":"XBTUSD","id":8798360550,"side":"Sell"}]}
09:57:43   {"table":"orderBookL2","action":"delete","data":[{"symbol":"XBTZ17","id":22899832830,"side":"Sell"},{"symbol":"XBTZ17","id":22899836105,"side":"Buy"}]}
09:57:43   {"table":"orderBookL2","action":"insert","data":[{"symbol":"XBTZ17","id":22899832910,"side":"Sell","size":30000,"price":16709},{"symbol":"XBTZ17","id":22899836210,"side":"Buy","size":30000,"price":16379}]}
09:57:43   {"table":"orderBookL2","action":"delete","data":[{"symbol":"XBTZ17","id":22899833395,"side":"Sell"},{"symbol":"XBTZ17","id":22899833525,"side":"Sell"},{"symbol":"XBTZ17","id":22899833565,"side":"Sell"},{"symbol":"XBTZ17","id":22899833570,"side":"Sell"},{"symbol":"XBTZ17","id":22899833740,"side":"Sell"}]}
09:57:43   {"table":"orderBookL2","action":"update","data":[{"symbol":"XBTUSD","id":8798381800,"side":"Buy","size":100}]}
09:57:43   {"table":"orderBookL2","action":"delete","data":[{"symbol":"XBTUSD","id":8798366850,"side":"Buy"}]}
09:57:43   {"table":"orderBookL2","action":"update","data":[{"symbol":"XBTZ17","id":22899833430,"side":"Sell","size":13850},{"symbol":"XBTZ17","id":22899833595,"side":"Sell","size":3630},{"symbol":"XBTZ17","id":22899833820,"side":"Sell","size":7000}]}
09:57:43   {"table":"orderBookL2","action":"insert","data":[{"symbol":"XBTZ17","id":22899833610,"side":"Sell","size":13740,"price":16639},{"symbol":"XBTZ17","id":22899833770,"side":"Sell","size":6890,"price":16623},{"symbol":"XBTZ17","id":22899833850,"side":"Sell","size":5850,"price":16615}]}
09:57:43   {"table":"orderBookL2","action":"update","data":[{"symbol":"XBTUSD","id":8798365800,"side":"Buy","size":759},{"symbol":"XBTUSD","id":8798367200,"side":"Buy","size":13167},{"symbol":"XBTUSD","id":8798367500,"side":"Buy","size":9420},{"symbol":"XBTUSD","id":8798368000,"side":"Buy","size":7800}]}
09:57:43   {"table":"orderBookL2","action":"insert","data":[{"symbol":"XBTUSD","id":8798367650,"side":"Buy","size":7000,"price":16323.5}]}
09:57:43   {"table":"orderBookL2","action":"update","data":[{"symbol":"XBTZ17","id":22899834380,"side":"Sell","size":60059},{"symbol":"XBTZ17","id":22899834400,"side":"Sell","size":9437}]}
09:57:43   {"table":"orderBookL2","action":"update","data":[{"symbol":"XBTZ17","id":22899835540,"side":"Buy","size":2264}]}
09:57:43   {"table":"orderBookL2","action":"delete","data":[{"symbol":"XBTZ17","id":22899834400,"side":"Sell"}]}
09:57:43   {"table":"orderBookL2","action":"update","data":[{"symbol":"XBTUSD","id":8798358150,"side":"Sell","size":42800}]}
09:57:43   {"table":"orderBookL2","action":"update","data":[{"symbol":"XBTZ17","id":22899834345,"side":"Sell","size":17437}]}
09:57:43   {"table":"orderBookL2","action":"update","data":[{"symbol":"XBTZ17","id":22899834355,"side":"Sell","size":658}]}
09:57:43   {"table":"orderBookL2","action":"delete","data":[{"symbol":"XBTZ17","id":22899834105,"side":"Sell"}]}
09:57:43   {"table":"orderBookL2","action":"insert","data":[{"symbol":"XBTZ17","id":22899834140,"side":"Sell","size":60,"price":16586}]}
09:57:43   {"table":"orderBookL2","action":"delete","data":[{"symbol":"XBTZ17","id":22899833800,"side":"Sell"}]}
09:57:43   {"table":"orderBookL2","action":"update","data":[{"symbol":"XBTUSD","id":8798359200,"side":"Sell","size":38275}]}
09:57:43   {"table":"orderBookL2","action":"update","data":[{"symbol":"XBTUSD","id":8798362200,"side":"Sell","size":87562}]}
09:57:43   {"table":"orderBookL2","action":"update","data":[{"symbol":"XBTUSD","id":8798362000,"side":"Sell","size":28000}]}
09:57:43   {"table":"orderBookL2","action":"update","data":[{"symbol":"XBTZ17","id":22899834380,"side":"Sell","size":59259}]}
09:57:43   {"table":"orderBookL2","action":"delete","data":[{"symbol":"XBTZ17","id":22899835240,"side":"Buy"}]}
09:57:43   {"table":"orderBookL2","action":"update","data":[{"symbol":"XBTZ17","id":22899835630,"side":"Buy","size":383}]}
09:57:43   {"table":"orderBookL2","action":"insert","data":[{"symbol":"XBTZ17","id":22899834750,"side":"Buy","size":46,"price":16525},{"symbol":"XBTZ17","id":22899835520,"side":"Buy","size":100,"price":16448},{"symbol":"XBTZ17","id":22899835910,"side":"Buy","size":127,"price":16409}]}
09:57:43   {"table":"orderBookL2","action":"update","data":[{"symbol":"XBTUSD","id":8798368150,"side":"Buy","size":4100}]}
09:57:43   {"table":"orderBookL2","action":"update","data":[{"symbol":"XBTUSD","id":8798355000,"side":"Sell","size":18610}]}
09:57:43   {"table":"orderBookL2","action":"delete","data":[{"symbol":"XBTZ17","id":22899831990,"side":"Sell"},{"symbol":"XBTZ17","id":22899832235,"side":"Sell"},{"symbol":"XBTZ17","id":22899832485,"side":"Sell"},{"symbol":"XBTZ17","id":22899832735,"side":"Sell"},{"symbol":"XBTZ17","id":22899833230,"side":"Sell"},{"symbol":"XBTZ17","id":22899833475,"side":"Sell"},{"symbol":"XBTZ17","id":22899833725,"side":"Sell"},{"symbol":"XBTZ17","id":22899836805,"side":"Buy"},{"symbol":"XBTZ17","id":22899837050,"side":"Buy"},{"symbol":"XBTZ17","id":22899837300,"side":"Buy"},{"symbol":"XBTZ17","id":22899837545,"side":"Buy"},{"symbol":"XBTZ17","id":22899837790,"side":"Buy"},{"symbol":"XBTZ17","id":22899838035,"side":"Buy"}]}
09:57:43   {"table":"orderBookL2","action":"update","data":[{"symbol":"XBTZ17","id":22899832980,"side":"Sell","size":7000},{"symbol":"XBTZ17","id":22899838000,"side":"Buy","size":5010},{"symbol":"XBTZ17","id":22899838250,"side":"Buy","size":5153},{"symbol":"XBTZ17","id":22899838285,"side":"Buy","size":305},{"symbol":"XBTZ17","id":22899838530,"side":"Buy","size":152}]}
09:57:43   {"table":"orderBookL2","action":"insert","data":[{"symbol":"XBTZ17","id":22899831890,"side":"Sell","size":5000,"price":16811},{"symbol":"XBTZ17","id":22899832135,"side":"Sell","size":5000,"price":16786.5},{"symbol":"XBTZ17","id":22899832385,"side":"Sell","size":5000,"price":16761.5},{"symbol":"XBTZ17","id":22899832630,"side":"Sell","size":5000,"price":16737},{"symbol":"XBTZ17","id":22899832880,"side":"Sell","size":5000,"price":16712},{"symbol":"XBTZ17","id":22899833125,"side":"Sell","size":5000,"price":16687.5},{"symbol":"XBTZ17","id":22899833375,"side":"Sell","size":5000,"price":16662.5},{"symbol":"XBTZ17","id":22899833625,"side":"Sell","size":5000,"price":16637.5},{"symbol":"XBTZ17","id":22899836770,"side":"Buy","size":5000,"price":16323},{"symbol":"XBTZ17","id":22899837015,"side":"Buy","size":5000,"price":16298.5},{"symbol":"XBTZ17","id":22899837265,"side":"Buy","size":5000,"price":16273.5},{"symbol":"XBTZ17","id":22899837510,"side":"Buy","size":5000,"price":16249},{"symbol":"XBTZ17","id":22899837755,"side":"Buy","size":5000,"price":16224.5},{"symbol":"XBTZ17","id":22899838495,"side":"Buy","size":5000,"price":16150.5}]}
09:57:43   {"table":"orderBookL2","action":"insert","data":[{"symbol":"XBTZ17","id":22899832180,"side":"Sell","size":20000,"price":16782}]}
09:57:43   {"table":"orderBookL2","action":"update","data":[{"symbol":"XBTZ17","id":22899834355,"side":"Sell","size":583}]}
09:57:43   {"table":"orderBookL2","action":"update","data":[{"symbol":"XBTZ17","id":22899834380,"side":"Sell","size":58400}]}
09:57:43   {"table":"orderBookL2","action":"update","data":[{"symbol":"XBTUSD","id":8798368150,"side":"Buy","size":3600}]}
09:57:43   {"table":"orderBookL2","action":"update","data":[{"symbol":"XBTUSD","id":8798314000,"side":"Sell","size":300040},{"symbol":"XBTUSD","id":8798328850,"side":"Sell","size":50}]}
09:57:43   {"table":"orderBookL2","action":"insert","data":[{"symbol":"XBTZ17","id":22899834405,"side":"Sell","size":1189,"price":16559.5}]}
09:57:43   {"table":"orderBookL2","action":"update","data":[{"symbol":"XBTZ17","id":22899833430,"side":"Sell","size":6850}]}
09:57:43   {"table":"orderBookL2","action":"update","data":[{"symbol":"XBTUSD","id":8798366750,"side":"Buy","size":10000},{"symbol":"XBTUSD","id":8798367400,"side":"Buy","size":12518}]}
09:57:43   {"table":"orderBookL2","action":"delete","data":[{"symbol":"XBTUSD","id":8798347600,"side":"Sell"},{"symbol":"XBTUSD","id":8798370150,"side":"Buy"},{"symbol":"XBTUSD","id":8798372250,"side":"Buy"}]}
09:57:43   {"table":"orderBookL2","action":"insert","data":[{"symbol":"XBTZ17","id":22899833885,"side":"Sell","size":7000,"price":16611.5}]}
09:57:43   {"table":"orderBookL2","action":"delete","data":[{"symbol":"XBTZ17","id":22899835100,"side":"Buy"}]}
09:57:43   {"table":"orderBookL2","action":"delete","data":[{"symbol":"XBTZ17","id":22899834335,"side":"Sell"}]}
09:57:43   {"table":"orderBookL2","action":"insert","data":[{"symbol":"XBTUSD","id":8798348100,"side":"Sell","size":3390,"price":16519},{"symbol":"XBTUSD","id":8798372600,"side":"Buy","size":3390,"price":16274},{"symbol":"XBTUSD","id":8798375200,"side":"Buy","size":6780,"price":16248}]}
09:57:43   {"table":"orderBookL2","action":"update","data":[{"symbol":"XBTUSD","id":8798367500,"side":"Buy","size":11840}]}
09:57:43   {"table":"orderBookL2","action":"update","data":[{"symbol":"XBTZ17","id":22899834405,"side":"Sell","size":31189}]}
09:57:43   {"table":"orderBookL2","action":"delete","data":[{"symbol":"XBTZ17","id":22899833710,"side":"Sell"}]}
09:57:43   {"table":"orderBookL2","action":"update","data":[{"symbol":"XBTUSD","id":8798364800,"side":"Buy","size":8693}]}
09:57:43   {"table":"orderBookL2","action":"delete","data":[{"symbol":"XBTUSD","id":8798363300,"side":"Buy"}]}
09:57:43   {"table":"orderBookL2","action":"delete","data":[{"symbol":"XBTZ17","id":22899835005,"side":"Buy"}]}
09:57:43   {"table":"orderBookL2","action":"update","data":[{"symbol":"XBTZ17","id":22899834345,"side":"Sell","size":16637},{"symbol":"XBTZ17","id":22899834380,"side":"Sell","size":51200},{"symbol":"XBTZ17","id":22899835030,"side":"Buy","size":8073}]}
09:57:43   {"table":"orderBookL2","action":"update","data":[{"symbol":"XBTUSD","id":8798363800,"side":"Buy","size":5221}]}
09:57:43   {"table":"orderBookL2","action":"delete","data":[{"symbol":"XBTUSD","id":8798331300,"side":"Sell"},{"symbol":"XBTUSD","id":8798340600,"side":"Sell"},{"symbol":"XBTUSD","id":8798349600,"side":"Sell"},{"symbol":"XBTUSD","id":8798365600,"side":"Buy"}]}
09:57:43   {"table":"orderBookL2","action":"insert","data":[{"symbol":"XBTZ17","id":22899834280,"side":"Sell","size":8000,"price":16572}]}
09:57:43   {"table":"orderBookL2","action":"delete","data":[{"symbol":"XBTZ17","id":22899834380,"side":"Sell"}]}
09:57:43   {"table":"orderBookL2","action":"update","data":[{"symbol":"XBTUSD","id":8798303200,"side":"Sell","size":30000},{"symbol":"XBTUSD","id":8798312600,"side":"Sell","size":150},{"symbol":"XBTUSD","id":8798322000,"side":"Sell","size":8000},{"symbol":"XBTUSD","id":8798344200,"side":"Sell","size":1436},{"symbol":"XBTUSD","id":8798348000,"side":"Sell","size":347417},{"symbol":"XBTUSD","id":8798351800,"side":"Sell","size":271},{"symbol":"XBTUSD","id":8798355600,"side":"Sell","size":7155},{"symbol":"XBTUSD","id":8798364000,"side":"Buy","size":882},{"symbol":"XBTUSD","id":8798367400,"side":"Buy","size":12301},{"symbol":"XBTUSD","id":8798369400,"side":"Buy","size":76},{"symbol":"XBTUSD","id":8798369800,"side":"Buy","size":2625},{"symbol":"XBTUSD","id":8798372000,"side":"Buy","size":950},{"symbol":"XBTUSD","id":8798373600,"side":"Buy","size":429},{"symbol":"XBTUSD","id":8798385000,"side":"Buy","size":19168}]}
09:57:43   {"table":"orderBookL2","action":"insert","data":[{"symbol":"XBTUSD","id":8798340400,"side":"Sell","size":308,"price":16596},{"symbol":"XBTUSD","id":8798359400,"side":"Sell","size":80,"price":16406},{"symbol":"XBTUSD","id":8798377400,"side":"Buy","size":217,"price":16226},{"symbol":"XBTUSD","id":8798381200,"side":"Buy","size":263,"price":16188}]}
09:57:43   {"table":"orderBookL2","action":"update","data":[{"symbol":"XBTZ17","id":22899834405,"side":"Sell","size":82389}]}
09:57:43   {"table":"orderBookL2","action":"delete","data":[{"symbol":"XBTZ17","id":22899834320,"side":"Sell"}]}
09:57:43   {"table":"orderBookL2","action":"update","data":[{"symbol":"XBTZ17","id":22899839205,"side":"Buy","size":152}]}
09:57:43   {"table":"orderBookL2","action":"insert","data":[{"symbol":"XBTZ17","id":22899834350,"side":"Sell","size":6717,"price":16565},{"symbol":"XBTZ17","id":22899839285,"side":"Buy","size":9233,"price":16071.5}]}
09:57:43   {"table":"orderBookL2","action":"delete","data":[{"symbol":"XBTZ17","id":22899832980,"side":"Sell"},{"symbol":"XBTZ17","id":22899833225,"side":"Sell"},{"symbol":"XBTZ17","id":22899833650,"side":"Sell"}]}
09:57:43   {"table":"orderBookL2","action":"update","data":[{"symbol":"XBTUSD","id":8798355200,"side":"Sell","size":2500},{"symbol":"XBTUSD","id":8798355700,"side":"Sell","size":7750}]}
09:57:43   {"table":"orderBookL2","action":"update","data":[{"symbol":"XBTUSD","id":8798361200,"side":"Sell","size":3000}]}
09:57:43   {"table":"orderBookL2","action":"update","data":[{"symbol":"XBTUSD","id":8798360050,"side":"Sell","size":11350}]}
09:57:43   {"table":"orderBookL2","action":"insert","data":[{"symbol":"XBTZ17","id":22899833230,"side":"Sell","size":7000,"price":16677},{"symbol":"XBTZ17","id":22899833480,"side":"Sell","size":7000,"price":16652},{"symbol":"XBTZ17","id":22899833905,"side":"Sell","size":7000,"price":16609.5}]}
09:57:43   {"table":"orderBookL2","action":"delete","data":[{"symbol":"XBTZ17","id":22899833660,"side":"Sell"}]}
09:57:43   {"table":"orderBookL2","action":"insert","data":[{"symbol":"XBTZ17","id":22899833800,"side":"Sell","size":88526,"price":16620}]}
09:57:43   {"table":"orderBookL2","action":"update","data":[{"symbol":"XBTUSD","id":8798369050,"side":"Buy","size":1138}]}
09:57:43   {"table":"orderBookL2","action":"update","data":[{"symbol":"XBTUSD","id":8798360050,"side":"Sell","size":11600}]}
09:57:43   {"table":"orderBookL2","action":"insert","data":[{"symbol":"XBTZ17","id":22899833235,"side":"Sell","size":1000,"price":16676.5}]}
09:57:43   {"table":"orderBookL2","action":"delete","data":[{"symbol":"XBTZ17","id":22899832910,"side":"Sell"},{"symbol":"XBTZ17","id":22899836210,"side":"Buy"}]}
09:57:43   {"table":"orderBookL2","action":"insert","data":[{"symbol":"XBTUSD","id":8798493350,"side":"Buy","size":50,"price":15066.5}]}
09:57:43   {"table":"orderBookL2","action":"update","data":[{"symbol":"XBTUSD","id":8798359200,"side":"Sell","size":36975}]}
09:57:43   {"table":"orderBookL2","action":"update","data":[{"symbol":"XBTZ17","id":22899832880,"side":"Sell","size":35000}]}
09:57:43   {"table":"orderBookL2","action":"insert","data":[{"symbol":"XBTZ17","id":22899836190,"side":"Buy","size":30000,"price":16381}]}
09:57:43   {"table":"orderBookL2","action":"update","data":[{"symbol":"XBTZ17","id":22899834345,"side":"Sell","size":7200}]}
09:57:43   {"table":"orderBookL2","action":"update","data":[{"symbol":"XBTZ17","id":22899834345,"side":"Sell","size":6400}]}
09:57:43   {"table":"orderBookL2","action":"insert","data":[{"symbol":"XBTZ17","id":22899835210,"side":"Buy","size":800,"price":16479}]}
09:57:43   {"table":"orderBookL2","action":"update","data":[{"symbol":"XBTUSD","id":8798360050,"side":"Sell","size":12600}]}
09:57:43   {"table":"orderBookL2","action":"delete","data":[{"symbol":"XBTUSD","id":8798354650,"side":"Sell"}]}
09:57:43   {"table":"orderBookL2","action":"update","data":[{"symbol":"XBTUSD","id":8798356100,"side":"Sell","size":18000}]}
09:57:43   {"table":"orderBookL2","action":"delete","data":[{"symbol":"XBTUSD","id":8798321700,"side":"Sell"},{"symbol":"XBTUSD","id":8798356900,"side":"Sell"},{"symbol":"XBTUSD","id":8798373700,"side":"Buy"},{"symbol":"XBTUSD","id":8798398300,"side":"Buy"}]}
09:57:43   {"table":"orderBookL2","action":"update","data":[{"symbol":"XBTUSD","id":8798340000,"side":"Sell","size":73060},{"symbol":"XBTUSD","id":8798346300,"side":"Sell","size":14437},{"symbol":"XBTUSD","id":8798352000,"side":"Sell","size":4150},{"symbol":"XBTUSD","id":8798367900,"side":"Buy","size":5000},{"symbol":"XBTUSD","id":8798380000,"side":"Buy","size":1960}]}
09:57:43   {"table":"orderBookL2","action":"delete","data":[{"symbol":"XBTZ17","id":22899835360,"side":"Buy"}]}
09:57:43   {"table":"orderBookL2","action":"update","data":[{"symbol":"XBTZ17","id":22899834820,"side":"Buy","size":21984},{"symbol":"XBTZ17","id":22899835000,"side":"Buy","size":8000},{"symbol":"XBTZ17","id":22899835540,"side":"Buy","size":2377}]}
09:57:43   {"table":"orderBookL2","action":"update","data":[{"symbol":"XBTUSD","id":8798357500,"side":"Sell","size":139500},{"symbol":"XBTUSD","id":8798362150,"side":"Sell","size":7355}]}
09:57:43   {"table":"orderBookL2","action":"update","data":[{"symbol":"XBTUSD","id":8798357600,"side":"Sell","size":3900}]}
09:57:43   {"table":"orderBookL2","action":"insert","data":[{"symbol":"XBTZ17","id":22899835180,"side":"Buy","size":83,"price":16482}]}
09:57:43   {"table":"orderBookL2","action":"delete","data":[{"symbol":"XBTZ17","id":22899834140,"side":"Sell"}]}
09:57:43   {"table":"orderBookL2","action":"insert","data":[{"symbol":"XBTZ17","id":22899834150,"side":"Sell","size":60,"price":16585}]}
09:57:43   {"table":"orderBookL2","action":"delete","data":[{"symbol":"XBTZ17","id":22899833870,"side":"Sell"}]}
09:57:43   {"table":"orderBookL2","action":"update","data":[{"symbol":"XBTUSD","id":8798357800,"side":"Sell","size":70392}]}
09:57:43   {"table":"orderBookL2","action":"insert","data":[{"symbol":"XBTZ17","id":22899833995,"side":"Sell","size":7000,"price":16600.5}]}
09:57:43   {"table":"orderBookL2","action":"update","data":[{"symbol":"XBTZ17","id":22899836490,"side":"Buy","size":258056}]}
09:57:43   {"table":"orderBookL2","action":"delete","data":[{"symbol":"XBTZ17","id":22899831890,"side":"Sell"},{"symbol":"XBTZ17","id":22899832135,"side":"Sell"},{"symbol":"XBTZ17","id":22899832385,"side":"Sell"},{"symbol":"XBTZ17","id":22899832630,"side":"Sell"},{"symbol":"XBTZ17","id":22899833125,"side":"Sell"},{"symbol":"XBTZ17","id":22899833375,"side":"Sell"},{"symbol":"XBTZ17","id":22899833625,"side":"Sell"},{"symbol":"XBTZ17","id":22899836770,"side":"Buy"},{"symbol":"XBTZ17","id":22899837015,"side":"Buy"},{"symbol":"XBTZ17","id":22899837265,"side":"Buy"},{"symbol":"XBTZ17","id":22899837510,"side":"Buy"},{"symbol":"XBTZ17","id":22899837755,"side":"Buy"},{"symbol":"XBTZ17","id":22899838495,"side":"Buy"}]}
09:57:43   {"table":"orderBookL2","action":"update","data":[{"symbol":"XBTZ17","id":22899832095,"side":"Sell","size":5080},{"symbol":"XBTZ17","id":22899832880,"side":"Sell","size":30000},{"symbol":"XBTZ17","id":22899833585,"side":"Sell","size":12000},{"symbol":"XBTZ17","id":22899838000,"side":"Buy","size":10},{"symbol":"XBTZ17","id":22899838225,"side":"Buy","size":5152},{"symbol":"XBTZ17","id":22899838250,"side":"Buy","size":153}]}
09:57:43   {"table":"orderBookL2","action":"update","data":[{"symbol":"XBTUSD","id":8798364300,"side":"Buy","size":3200}]}
09:57:43   {"table":"orderBookL2","action":"update","data":[{"symbol":"XBTUSD","id":8798358350,"side":"Sell","size":53500}]}
09:57:43   {"table":"orderBookL2","action":"insert","data":[{"symbol":"XBTZ17","id":22899831845,"side":"Sell","size":5000,"price":16815.5},{"symbol":"XBTZ17","id":22899832345,"side":"Sell","size":5000,"price":16765.5},{"symbol":"XBTZ17","id":22899832590,"side":"Sell","size":5000,"price":16741},{"symbol":"XBTZ17","id":22899832840,"side":"Sell","size":5000,"price":16716},{"symbol":"XBTZ17","id":22899833085,"side":"Sell","size":5000,"price":16691.5},{"symbol":"XBTZ17","id":22899833335,"side":"Sell","size":5000,"price":16666.5},{"symbol":"XBTZ17","id":22899836745,"side":"Buy","size":5000,"price":16325.5},{"symbol":"XBTZ17","id":22899836990,"side":"Buy","size":5000,"price":16301},{"symbol":"XBTZ17","id":22899837235,"side":"Buy","size":5000,"price":16276.5},{"symbol":"XBTZ17","id":22899837485,"side":"Buy","size":5000,"price":16251.5},{"symbol":"XBTZ17","id":22899837730,"side":"Buy","size":5000,"price":16227},{"symbol":"XBTZ17","id":22899837975,"side":"Buy","size":5000,"price":16202.5},{"symbol":"XBTZ17","id":22899838470,"side":"Buy","size":5000,"price":16153}]}
09:57:43   {"table":"orderBookL2","action":"delete","data":[{"symbol":"XBTZ17","id":22899833900,"side":"Sell"},{"symbol":"XBTZ17","id":22899833945,"side":"Sell"},{"symbol":"XBTZ17","id":22899833985,"side":"Sell"}]}
09:57:43   {"table":"orderBookL2","action":"update","data":[{"symbol":"XBTZ17","id":22899833585,"side":"Sell","size":5000}]}
09:57:43   {"table":"orderBookL2","action":"update","data":[{"symbol":"XBTUSD","id":8798360050,"side":"Sell","size":15600}]}
09:57:43   {"table":"orderBookL2","action":"update","data":[{"symbol":"XBTUSD","id":8798362400,"side":"Buy","size":380}]}
09:57:43   {"table":"orderBookL2","action":"insert","data":[{"symbol":"XBTZ17","id":22899833670,"side":"Sell","size":7000,"price":16633},{"symbol":"XBTZ17","id":22899833950,"side":"Sell","size":7000,"price":16605},{"symbol":"XBTZ17","id":22899833975,"side":"Sell","size":7000,"price":16602.5},{"symbol":"XBTZ17","id":22899834015,"side":"Sell","size":7000,"price":16598.5}]}
09:57:43   {"table":"orderBookL2","action":"delete","data":[{"symbol":"XBTZ17","id":22899833470,"side":"Sell"},{"symbol":"XBTZ17","id":22899833735,"side":"Sell"}]}
09:57:43   {"table":"orderBookL2","action":"insert","data":[{"symbol":"XBTZ17","id":22899833555,"side":"Sell","size":7000,"price":16644.5},{"symbol":"XBTZ17","id":22899833790,"side":"Sell","size":7000,"price":16621}]}
09:57:43   {"table":"orderBookL2","action":"update","data":[{"symbol":"XBTUSD","id":8798370200,"side":"Buy","size":245}]}
09:57:43   {"table":"orderBookL2","action":"update","data":[{"symbol":"XBTUSD","id":8798369800,"side":"Buy","size":5625}]}
09:57:43   {"table":"orderBookL2","action":"insert","data":[{"symbol":"XBTZ17","id":22899834390,"side":"Sell","size":75,"price":16561}]}
09:57:43   {"table":"orderBookL2","action":"update","data":[{"symbol":"XBTZ17","id":22899834405,"side":"Sell","size":81200}]}
09:57:43   {"table":"orderBookL2","action":"insert","data":[{"symbol":"XBTZ17","id":22899834385,"side":"Sell","size":1189,"price":16561.5}]}
09:57:43   {"table":"orderBookL2","action":"update","data":[{"symbol":"XBTUSD","id":8798357500,"side":"Sell","size":8700}]}
