09:22:20   SubViewModel.XBTUSD_Main 异常：Could not create an instance of type BitMex.BitMexMsg.BitMexMsgBase. Type is an interface or abstract class and cannot be instantiated. Path 'table', line 1, position 9.
09:22:20   {"table":"orderBookL2","action":"delete","data":[{"symbol":"XBTUSD","id":8798356750,"side":"Buy"}]}
09:22:20   {"table":"orderBookL2","action":"update","data":[{"symbol":"XBTUSD","id":8798357750,"side":"Buy","size":26921}]}
09:22:20   {"table":"orderBookL2","action":"delete","data":[{"symbol":"XBTUSD","id":8798344950,"side":"Sell"},{"symbol":"XBTUSD","id":8798359600,"side":"Buy"},{"symbol":"XBTUSD","id":8798363250,"side":"Buy"}]}
09:22:20   SubViewModel.XBTUSD_Main 异常：Could not create an instance of type BitMex.BitMexMsg.BitMexMsgBase. Type is an interface or abstract class and cannot be instantiated. Path 'table', line 1, position 9.
09:22:20   {"table":"orderBookL2","action":"update","data":[{"symbol":"XBTUSD","id":8798344050,"side":"Sell","size":3750},{"symbol":"XBTUSD","id":8798344750,"side":"Sell","size":9362},{"symbol":"XBTUSD","id":8798346450,"side":"Sell","size":353000},{"symbol":"XBTUSD","id":8798350950,"side":"Sell","size":4426},{"symbol":"XBTUSD","id":8798352000,"side":"Sell","size":5162},{"symbol":"XBTUSD","id":8798352500,"side":"Sell","size":20448},{"symbol":"XBTUSD","id":8798359650,"side":"Buy","size":2343}]}
09:22:20   {"table":"orderBookL2","action":"insert","data":[{"symbol":"XBTUSD","id":8798347050,"side":"Sell","size":4362,"price":16529.5},{"symbol":"XBTUSD","id":8798357700,"side":"Buy","size":2100,"price":16423}]}
09:22:20   {"table":"orderBookL2","action":"delete","data":[{"symbol":"XBTUSD","id":8798353650,"side":"Sell"}]}
09:22:20   {"table":"orderBookL2","action":"insert","data":[{"symbol":"XBTUSD","id":8798352700,"side":"Sell","size":200,"price":16473}]}
09:22:20   {"table":"orderBookL2","action":"update","data":[{"symbol":"XBTUSD","id":8798354050,"side":"Sell","size":2228}]}
09:22:20   {"table":"orderBookL2","action":"delete","data":[{"symbol":"XBTUSD","id":8798359850,"side":"Buy"}]}
09:22:20   SubViewModel.XBTUSD_Main 异常：Could not create an instance of type BitMex.BitMexMsg.BitMexMsgBase. Type is an interface or abstract class and cannot be instantiated. Path 'table', line 1, position 9.
09:22:20   {"table":"orderBookL2","action":"update","data":[{"symbol":"XBTUSD","id":8798356700,"side":"Sell","size":8777}]}
09:22:20   {"table":"orderBookL2","action":"update","data":[{"symbol":"XBTUSD","id":8798354050,"side":"Sell","size":1228}]}
09:22:20   {"table":"orderBookL2","action":"delete","data":[{"symbol":"XBTUSD","id":8798331100,"side":"Sell"},{"symbol":"XBTUSD","id":8798335200,"side":"Sell"},{"symbol":"XBTUSD","id":8798339200,"side":"Sell"},{"symbol":"XBTUSD","id":8798347400,"side":"Sell"},{"symbol":"XBTUSD","id":8798362600,"side":"Buy"},{"symbol":"XBTUSD","id":8798366600,"side":"Buy"},{"symbol":"XBTUSD","id":8798374800,"side":"Buy"}]}
09:22:20   {"table":"orderBookL2","action":"update","data":[{"symbol":"XBTUSD","id":8798343800,"side":"Sell","size":145},{"symbol":"XBTUSD","id":8798348400,"side":"Sell","size":398440},{"symbol":"XBTUSD","id":8798350800,"side":"Sell","size":228},{"symbol":"XBTUSD","id":8798351400,"side":"Sell","size":10000},{"symbol":"XBTUSD","id":8798358600,"side":"Buy","size":177},{"symbol":"XBTUSD","id":8798370800,"side":"Buy","size":379200},{"symbol":"XBTUSD","id":8798378900,"side":"Buy","size":50291},{"symbol":"XBTUSD","id":8798407500,"side":"Buy","size":563}]}
09:22:20   {"table":"orderBookL2","action":"insert","data":[{"symbol":"XBTUSD","id":8798343900,"side":"Sell","size":308,"price":16561},{"symbol":"XBTUSD","id":8798346200,"side":"Sell","size":262,"price":16538},{"symbol":"XBTUSD","id":8798353000,"side":"Sell","size":125,"price":16470},{"symbol":"XBTUSD","id":8798355200,"side":"Sell","size":80,"price":16448},{"symbol":"XBTUSD","id":8798367500,"side":"Buy","size":80,"price":16325},{"symbol":"XBTUSD","id":8798377500,"side":"Buy","size":125,"price":16225},{"symbol":"XBTUSD","id":8798387500,"side":"Buy","size":171,"price":16125},{"symbol":"XBTUSD","id":8798397500,"side":"Buy","size":216,"price":16025},{"symbol":"XBTUSD","id":8798417500,"side":"Buy","size":308,"price":15825}]}
09:22:20   {"table":"orderBookL2","action":"delete","data":[{"symbol":"XBTUSD","id":8798305300,"side":"Sell"}]}
09:22:20   SubViewModel.XBTUSD_Main 异常：Could not create an instance of type BitMex.BitMexMsg.BitMexMsgBase. Type is an interface or abstract class and cannot be instantiated. Path 'table', line 1, position 9.
09:22:20   {"table":"orderBookL2","action":"insert","data":[{"symbol":"XBTUSD","id":8798307700,"side":"Sell","size":40,"price":16923}]}
09:22:20   {"table":"orderBookL2","action":"insert","data":[{"symbol":"XBTUSD","id":8798350200,"side":"Sell","size":380200,"price":16498},{"symbol":"XBTUSD","id":8798374550,"side":"Buy","size":356000,"price":16254.5}]}
09:22:20   SubViewModel.XBTUSD_Main 异常：Could not create an instance of type BitMex.BitMexMsg.BitMexMsgBase. Type is an interface or abstract class and cannot be instantiated. Path 'table', line 1, position 9.
09:22:20   {"table":"orderBookL2","action":"update","data":[{"symbol":"XBTUSD","id":8798342900,"side":"Sell","size":760}]}
09:22:20   {"table":"orderBookL2","action":"insert","data":[{"symbol":"XBTUSD","id":8798356750,"side":"Sell","size":6000,"price":16432.5}]}
09:22:20   SubViewModel.XBTUSD_Main 异常：Could not create an instance of type BitMex.BitMexMsg.BitMexMsgBase. Type is an interface or abstract class and cannot be instantiated. Path 'table', line 1, position 9.
09:22:20   {"table":"orderBookL2","action":"delete","data":[{"symbol":"XBTUSD","id":8798352950,"side":"Sell"}]}
09:22:20   {"table":"orderBookL2","action":"update","data":[{"symbol":"XBTUSD","id":8798351800,"side":"Sell","size":21383},{"symbol":"XBTUSD","id":8798353800,"side":"Sell","size":10050}]}
09:22:20   {"table":"orderBookL2","action":"update","data":[{"symbol":"XBTUSD","id":8798346500,"side":"Sell","size":100}]}
09:22:20   {"table":"orderBookL2","action":"insert","data":[{"symbol":"XBTUSD","id":8798348450,"side":"Sell","size":2000,"price":16515.5}]}
09:22:20   {"table":"orderBookL2","action":"delete","data":[{"symbol":"XBTUSD","id":8798351400,"side":"Sell"}]}
09:22:20   {"table":"orderBookL2","action":"update","data":[{"symbol":"XBTUSD","id":8798306000,"side":"Sell","size":300}]}
09:22:20   SubViewModel.XBTUSD_Main 异常：Could not create an instance of type BitMex.BitMexMsg.BitMexMsgBase. Type is an interface or abstract class and cannot be instantiated. Path 'table', line 1, position 9.
09:22:20   {"table":"orderBookL2","action":"insert","data":[{"symbol":"XBTUSD","id":8798305600,"side":"Sell","size":50,"price":16944},{"symbol":"XBTUSD","id":8798352750,"side":"Sell","size":10000,"price":16472.5}]}
09:22:20   {"table":"orderBookL2","action":"insert","data":[{"symbol":"XBTUSD","id":8798357150,"side":"Sell","size":6000,"price":16428.5}]}
09:22:20   {"table":"orderBookL2","action":"update","data":[{"symbol":"XBTUSD","id":8798376000,"side":"Buy","size":850}]}
09:22:20   SubViewModel.XBTUSD_Main 异常：Could not create an instance of type BitMex.BitMexMsg.BitMexMsgBase. Type is an interface or abstract class and cannot be instantiated. Path 'table', line 1, position 9.
09:22:20   {"table":"orderBookL2","action":"delete","data":[{"symbol":"XBTUSD","id":8798357700,"side":"Buy"},{"symbol":"XBTUSD","id":8798357750,"side":"Buy"},{"symbol":"XBTUSD","id":8798357800,"side":"Buy"},{"symbol":"XBTUSD","id":8798357900,"side":"Buy"},{"symbol":"XBTUSD","id":8798358000,"side":"Buy"},{"symbol":"XBTUSD","id":8798358300,"side":"Buy"},{"symbol":"XBTUSD","id":8798358600,"side":"Buy"},{"symbol":"XBTUSD","id":8798358750,"side":"Buy"},{"symbol":"XBTUSD","id":8798359650,"side":"Buy"}]}
09:22:20   {"table":"orderBookL2","action":"update","data":[{"symbol":"XBTUSD","id":8798359700,"side":"Buy","size":254792}]}
09:22:20   {"table":"orderBookL2","action":"insert","data":[{"symbol":"XBTUSD","id":8798355700,"side":"Sell","size":50,"price":16443}]}
09:22:20   {"table":"orderBookL2","action":"update","data":[{"symbol":"XBTUSD","id":8798355500,"side":"Sell","size":9345}]}
09:22:20   {"table":"orderBookL2","action":"delete","data":[{"symbol":"XBTUSD","id":8798343450,"side":"Sell"}]}
09:22:20   SubViewModel.XBTUSD_Main 异常：Could not create an instance of type BitMex.BitMexMsg.BitMexMsgBase. Type is an interface or abstract class and cannot be instantiated. Path 'table', line 1, position 9.
09:22:20   {"table":"orderBookL2","action":"update","data":[{"symbol":"XBTUSD","id":8798344350,"side":"Sell","size":7500}]}
09:22:20   {"table":"orderBookL2","action":"insert","data":[{"symbol":"XBTUSD","id":8798346100,"side":"Sell","size":6920,"price":16539},{"symbol":"XBTUSD","id":8798346400,"side":"Sell","size":6970,"price":16536}]}
09:22:20   SubViewModel.XBTUSD_Main 异常：Could not create an instance of type BitMex.BitMexMsg.BitMexMsgBase. Type is an interface or abstract class and cannot be instantiated. Path 'table', line 1, position 9.
09:22:20   {"table":"orderBookL2","action":"delete","data":[{"symbol":"XBTUSD","id":8798344200,"side":"Sell"},{"symbol":"XBTUSD","id":8798351350,"side":"Sell"},{"symbol":"XBTUSD","id":8798370300,"side":"Buy"}]}
09:22:20   {"table":"orderBookL2","action":"update","data":[{"symbol":"XBTUSD","id":8798348450,"side":"Sell","size":2064},{"symbol":"XBTUSD","id":8798349000,"side":"Sell","size":987},{"symbol":"XBTUSD","id":8798350950,"side":"Sell","size":4362},{"symbol":"XBTUSD","id":8798364200,"side":"Buy","size":414},{"symbol":"XBTUSD","id":8798374100,"side":"Buy","size":240}]}
09:22:20   {"table":"orderBookL2","action":"insert","data":[{"symbol":"XBTUSD","id":8798345750,"side":"Sell","size":14,"price":16542.5},{"symbol":"XBTUSD","id":8798348850,"side":"Sell","size":64,"price":16511.5},{"symbol":"XBTUSD","id":8798349550,"side":"Sell","size":64,"price":16504.5},{"symbol":"XBTUSD","id":8798367550,"side":"Buy","size":50,"price":16324.5}]}
09:22:20   {"table":"orderBookL2","action":"update","data":[{"symbol":"XBTUSD","id":8798353200,"side":"Sell","size":13248}]}
09:22:20   {"table":"orderBookL2","action":"insert","data":[{"symbol":"XBTUSD","id":8798354150,"side":"Sell","size":10000,"price":16458.5}]}
09:22:20   {"table":"orderBookL2","action":"delete","data":[{"symbol":"XBTUSD","id":8798405850,"side":"Buy"}]}
09:22:20   SubViewModel.XBTUSD_Main 异常：Could not create an instance of type BitMex.BitMexMsg.BitMexMsgBase. Type is an interface or abstract class and cannot be instantiated. Path 'table', line 1, position 9.
09:22:20   {"table":"orderBookL2","action":"insert","data":[{"symbol":"XBTUSD","id":8798407800,"side":"Buy","size":40,"price":15922}]}
09:22:20   {"table":"orderBookL2","action":"update","data":[{"symbol":"XBTUSD","id":8798350000,"side":"Sell","size":80310}]}
09:22:20   {"table":"orderBookL2","action":"delete","data":[{"symbol":"XBTUSD","id":8798307250,"side":"Sell"}]}
09:22:20   {"table":"orderBookL2","action":"insert","data":[{"symbol":"XBTUSD","id":8798307100,"side":"Sell","size":40,"price":16929}]}
09:22:20   SubViewModel.XBTUSD_Main 异常：Could not create an instance of type BitMex.BitMexMsg.BitMexMsgBase. Type is an interface or abstract class and cannot be instantiated. Path 'table', line 1, position 9.
09:22:20   {"table":"orderBookL2","action":"delete","data":[{"symbol":"XBTUSD","id":8798349800,"side":"Sell"},{"symbol":"XBTUSD","id":8798351050,"side":"Sell"},{"symbol":"XBTUSD","id":8798351100,"side":"Sell"}]}
09:22:20   {"table":"orderBookL2","action":"update","data":[{"symbol":"XBTUSD","id":8798350700,"side":"Sell","size":2367},{"symbol":"XBTUSD","id":8798352550,"side":"Sell","size":24000}]}
09:22:20   {"table":"orderBookL2","action":"insert","data":[{"symbol":"XBTUSD","id":8798351250,"side":"Sell","size":10050,"price":16487.5},{"symbol":"XBTUSD","id":8798352100,"side":"Sell","size":10000,"price":16479},{"symbol":"XBTUSD","id":8798352600,"side":"Sell","size":10000,"price":16474}]}
09:22:20   {"table":"orderBookL2","action":"update","data":[{"symbol":"XBTUSD","id":8798700000,"side":"Buy","size":25235}]}
09:22:20   SubViewModel.XBTUSD_Main 异常：Could not create an instance of type BitMex.BitMexMsg.BitMexMsgBase. Type is an interface or abstract class and cannot be instantiated. Path 'table', line 1, position 9.
09:22:20   {"table":"orderBookL2","action":"update","data":[{"symbol":"XBTUSD","id":8798357150,"side":"Sell","size":5900}]}
09:22:20   {"table":"orderBookL2","action":"delete","data":[{"symbol":"XBTUSD","id":8798351950,"side":"Sell"}]}
09:22:20   {"table":"orderBookL2","action":"insert","data":[{"symbol":"XBTUSD","id":8798352450,"side":"Sell","size":3776,"price":16475.5}]}
09:22:20   SubViewModel.XBTUSD_Main 异常：Could not create an instance of type BitMex.BitMexMsg.BitMexMsgBase. Type is an interface or abstract class and cannot be instantiated. Path 'table', line 1, position 9.
09:22:20   {"table":"orderBookL2","action":"insert","data":[{"symbol":"XBTUSD","id":8798356900,"side":"Sell","size":10000,"price":16431}]}
09:22:21   {"table":"orderBookL2","action":"update","data":[{"symbol":"XBTUSD","id":8798359700,"side":"Buy","size":239792}]}
09:22:21   {"table":"orderBookL2","action":"update","data":[{"symbol":"XBTUSD","id":8798351800,"side":"Sell","size":11333},{"symbol":"XBTUSD","id":8798352800,"side":"Sell","size":20100}]}
09:22:21   {"table":"orderBookL2","action":"update","data":[{"symbol":"XBTUSD","id":8798352500,"side":"Sell","size":10448}]}
09:22:21   {"table":"orderBookL2","action":"insert","data":[{"symbol":"XBTUSD","id":8798351500,"side":"Sell","size":10000,"price":16485}]}
09:22:21   SubViewModel.XBTUSD_Main 异常：Could not create an instance of type BitMex.BitMexMsg.BitMexMsgBase. Type is an interface or abstract class and cannot be instantiated. Path 'table', line 1, position 9.
09:22:21   {"table":"orderBookL2","action":"update","data":[{"symbol":"XBTUSD","id":8798353200,"side":"Sell","size":9472},{"symbol":"XBTUSD","id":8798353250,"side":"Sell","size":4376}]}
09:22:21   {"table":"orderBookL2","action":"delete","data":[{"symbol":"XBTUSD","id":8798307750,"side":"Sell"}]}
09:22:21   {"table":"orderBookL2","action":"insert","data":[{"symbol":"XBTUSD","id":8798306650,"side":"Sell","size":40,"price":16933.5}]}
09:22:21   SubViewModel.XBTUSD_Main 异常：Could not create an instance of type BitMex.BitMexMsg.BitMexMsgBase. Type is an interface or abstract class and cannot be instantiated. Path 'table', line 1, position 9.
09:22:21   {"table":"orderBookL2","action":"insert","data":[{"symbol":"XBTUSD","id":8798357650,"side":"Sell","size":10,"price":16423.5}]}
09:22:21   {"table":"orderBookL2","action":"update","data":[{"symbol":"XBTUSD","id":8798348400,"side":"Sell","size":392340},{"symbol":"XBTUSD","id":8798356700,"side":"Sell","size":15919}]}
09:22:21   SubViewModel.XBTUSD_Main 异常：Could not create an instance of type BitMex.BitMexMsg.BitMexMsgBase. Type is an interface or abstract class and cannot be instantiated. Path 'table', line 1, position 9.
09:22:21   {"table":"orderBookL2","action":"insert","data":[{"symbol":"XBTUSD","id":8798357700,"side":"Sell","size":50762,"price":16423}]}
09:22:21   {"table":"orderBookL2","action":"insert","data":[{"symbol":"XBTUSD","id":8798356800,"side":"Sell","size":2,"price":16432}]}
09:22:21   {"table":"orderBookL2","action":"update","data":[{"symbol":"XBTUSD","id":8798357650,"side":"Sell","size":10010}]}
09:22:21   {"table":"orderBookL2","action":"update","data":[{"symbol":"XBTUSD","id":8798355500,"side":"Sell","size":9245}]}
09:22:21   {"table":"orderBookL2","action":"insert","data":[{"symbol":"XBTUSD","id":8798355250,"side":"Sell","size":100,"price":16447.5}]}
09:22:21   SubViewModel.XBTUSD_Main 异常：Could not create an instance of type BitMex.BitMexMsg.BitMexMsgBase. Type is an interface or abstract class and cannot be instantiated. Path 'table', line 1, position 9.
09:22:21   {"table":"orderBookL2","action":"insert","data":[{"symbol":"XBTUSD","id":8798298650,"side":"Sell","size":603,"price":17013.5}]}
09:22:21   {"table":"orderBookL2","action":"delete","data":[{"symbol":"XBTUSD","id":8798328600,"side":"Sell"},{"symbol":"XBTUSD","id":8798337700,"side":"Sell"},{"symbol":"XBTUSD","id":8798344050,"side":"Sell"},{"symbol":"XBTUSD","id":8798351300,"side":"Sell"},{"symbol":"XBTUSD","id":8798364100,"side":"Buy"},{"symbol":"XBTUSD","id":8798366950,"side":"Buy"},{"symbol":"XBTUSD","id":8798386300,"side":"Buy"}]}
09:22:21   {"table":"orderBookL2","action":"update","data":[{"symbol":"XBTUSD","id":8798329400,"side":"Sell","size":28074},{"symbol":"XBTUSD","id":8798348400,"side":"Sell","size":389840},{"symbol":"XBTUSD","id":8798370000,"side":"Buy","size":24160},{"symbol":"XBTUSD","id":8798371250,"side":"Buy","size":8103},{"symbol":"XBTUSD","id":8798377450,"side":"Buy","size":323000},{"symbol":"XBTUSD","id":8798385100,"side":"Buy","size":167740}]}
09:22:21   SubViewModel.XBTUSD_Main 异常：Could not create an instance of type BitMex.BitMexMsg.BitMexMsgBase. Type is an interface or abstract class and cannot be instantiated. Path 'table', line 1, position 9.
09:22:21   {"table":"orderBookL2","action":"insert","data":[{"symbol":"XBTUSD","id":8798338500,"side":"Sell","size":5000,"price":16615},{"symbol":"XBTUSD","id":8798344850,"side":"Sell","size":3750,"price":16551.5},{"symbol":"XBTUSD","id":8798349200,"side":"Sell","size":2500,"price":16508},{"symbol":"XBTUSD","id":8798352050,"side":"Sell","size":1250,"price":16479.5},{"symbol":"XBTUSD","id":8798362900,"side":"Buy","size":1250,"price":16371},{"symbol":"XBTUSD","id":8798365750,"side":"Buy","size":2500,"price":16342.5},{"symbol":"XBTUSD","id":8798376250,"side":"Buy","size":5000,"price":16237.5}]}
09:22:21   {"table":"orderBookL2","action":"update","data":[{"symbol":"XBTUSD","id":8798356750,"side":"Sell","size":6822}]}
09:22:21   {"table":"orderBookL2","action":"update","data":[{"symbol":"XBTUSD","id":8798356750,"side":"Sell","size":15822}]}
09:22:21   SubViewModel.XBTUSD_Main 异常：Could not create an instance of type BitMex.BitMexMsg.BitMexMsgBase. Type is an interface or abstract class and cannot be instantiated. Path 'table', line 1, position 9.
09:22:21   {"table":"orderBookL2","action":"update","data":[{"symbol":"XBTUSD","id":8798359700,"side":"Buy","size":229792}]}
09:22:21   {"table":"orderBookL2","action":"update","data":[{"symbol":"XBTUSD","id":8798357650,"side":"Sell","size":10020}]}
09:22:21   SubViewModel.XBTUSD_Main 异常：Could not create an instance of type BitMex.BitMexMsg.BitMexMsgBase. Type is an interface or abstract class and cannot be instantiated. Path 'table', line 1, position 9.
09:22:21   {"table":"orderBookL2","action":"delete","data":[{"symbol":"XBTUSD","id":8798363850,"side":"Buy"}]}
09:22:21   {"table":"orderBookL2","action":"update","data":[{"symbol":"XBTUSD","id":8798363650,"side":"Buy","size":43}]}
09:22:21   {"table":"orderBookL2","action":"insert","data":[{"symbol":"XBTUSD","id":8798358900,"side":"Sell","size":12920,"price":16411}]}
09:22:21   SubViewModel.XBTUSD_Main 异常：Could not create an instance of type BitMex.BitMexMsg.BitMexMsgBase. Type is an interface or abstract class and cannot be instantiated. Path 'table', line 1, position 9.
09:22:21   {"table":"orderBookL2","action":"update","data":[{"symbol":"XBTUSD","id":8798350350,"side":"Sell","size":612},{"symbol":"XBTUSD","id":8798358900,"side":"Sell","size":16613}]}
09:22:21   {"table":"orderBookL2","action":"insert","data":[{"symbol":"XBTUSD","id":8798359600,"side":"Sell","size":3693,"price":16404}]}
09:22:21   {"table":"orderBookL2","action":"update","data":[{"symbol":"XBTUSD","id":8798359700,"side":"Buy","size":219792}]}
09:22:21   {"table":"orderBookL2","action":"insert","data":[{"symbol":"XBTUSD","id":8798356500,"side":"Sell","size":25000,"price":16435}]}
09:22:21   {"table":"orderBookL2","action":"delete","data":[{"symbol":"XBTUSD","id":8798856750,"side":"Buy"}]}
09:22:21   {"table":"orderBookL2","action":"insert","data":[{"symbol":"XBTUSD","id":8798857750,"side":"Buy","size":1,"price":11422.5}]}
09:22:21   SubViewModel.XBTUSD_Main 异常：Could not create an instance of type BitMex.BitMexMsg.BitMexMsgBase. Type is an interface or abstract class and cannot be instantiated. Path 'table', line 1, position 9.
09:22:21   {"table":"orderBookL2","action":"update","data":[{"symbol":"XBTUSD","id":8798351200,"side":"Sell","size":10246},{"symbol":"XBTUSD","id":8798351700,"side":"Sell","size":4562}]}
09:22:21   {"table":"orderBookL2","action":"update","data":[{"symbol":"XBTUSD","id":8798359600,"side":"Sell","size":3493}]}
09:22:21   {"table":"orderBookL2","action":"insert","data":[{"symbol":"XBTUSD","id":8798356300,"side":"Sell","size":470,"price":16437}]}
09:22:21   {"table":"orderBookL2","action":"delete","data":[{"symbol":"XBTUSD","id":8798346750,"side":"Sell"},{"symbol":"XBTUSD","id":8798350050,"side":"Sell"},{"symbol":"XBTUSD","id":8798353350,"side":"Sell"}]}
09:22:21   {"table":"orderBookL2","action":"update","data":[{"symbol":"XBTUSD","id":8798322400,"side":"Sell","size":1647},{"symbol":"XBTUSD","id":8798329100,"side":"Sell","size":1712},{"symbol":"XBTUSD","id":8798348400,"side":"Sell","size":388530},{"symbol":"XBTUSD","id":8798351700,"side":"Sell","size":3776}]}
09:22:21   {"table":"orderBookL2","action":"insert","data":[{"symbol":"XBTUSD","id":8798335750,"side":"Sell","size":1048,"price":16642.5},{"symbol":"XBTUSD","id":8798342350,"side":"Sell","size":786,"price":16576.5},{"symbol":"XBTUSD","id":8798348950,"side":"Sell","size":524,"price":16510.5}]}
09:22:21   {"table":"orderBookL2","action":"update","data":[{"symbol":"XBTUSD","id":8798348850,"side":"Sell","size":106}]}
09:22:21   SubViewModel.XBTUSD_Main 异常：Could not create an instance of type BitMex.BitMexMsg.BitMexMsgBase. Type is an interface or abstract class and cannot be instantiated. Path 'table', line 1, position 9.
09:22:21   {"table":"orderBookL2","action":"update","data":[{"symbol":"XBTUSD","id":8798357700,"side":"Sell","size":50772}]}
09:22:21   {"table":"orderBookL2","action":"update","data":[{"symbol":"XBTUSD","id":8798359600,"side":"Sell","size":3394}]}
09:22:21   {"table":"orderBookL2","action":"insert","data":[{"symbol":"XBTUSD","id":8798357350,"side":"Sell","size":3000,"price":16426.5}]}
09:22:21   {"table":"orderBookL2","action":"delete","data":[{"symbol":"XBTUSD","id":8798355950,"side":"Sell"}]}
09:22:21   {"table":"orderBookL2","action":"update","data":[{"symbol":"XBTUSD","id":8798352750,"side":"Sell","size":14000}]}
09:22:21   SubViewModel.XBTUSD_Main 异常：Could not create an instance of type BitMex.BitMexMsg.BitMexMsgBase. Type is an interface or abstract class and cannot be instantiated. Path 'table', line 1, position 9.
09:22:21   {"table":"orderBookL2","action":"update","data":[{"symbol":"XBTUSD","id":8798356800,"side":"Sell","size":2744}]}
09:22:21   {"table":"orderBookL2","action":"delete","data":[{"symbol":"XBTUSD","id":8798307200,"side":"Sell"}]}
09:22:21   {"table":"orderBookL2","action":"update","data":[{"symbol":"XBTUSD","id":8798305350,"side":"Sell","size":20850}]}
09:22:21   {"table":"orderBookL2","action":"delete","data":[{"symbol":"XBTUSD","id":8798349700,"side":"Sell"},{"symbol":"XBTUSD","id":8798365300,"side":"Buy"}]}
09:22:21   {"table":"orderBookL2","action":"update","data":[{"symbol":"XBTUSD","id":8798366900,"side":"Buy","size":7290}]}
09:22:21   {"table":"orderBookL2","action":"insert","data":[{"symbol":"XBTUSD","id":8798349800,"side":"Sell","size":2598,"price":16502}]}
09:22:21   SubViewModel.XBTUSD_Main 异常：Could not create an instance of type BitMex.BitMexMsg.BitMexMsgBase. Type is an interface or abstract class and cannot be instantiated. Path 'table', line 1, position 9.
09:22:21   {"table":"orderBookL2","action":"delete","data":[{"symbol":"XBTUSD","id":8798352700,"side":"Sell"}]}
09:22:21   {"table":"orderBookL2","action":"insert","data":[{"symbol":"XBTUSD","id":8798352650,"side":"Sell","size":200,"price":16473.5}]}
09:22:21   {"table":"orderBookL2","action":"update","data":[{"symbol":"XBTUSD","id":8798359600,"side":"Sell","size":2393}]}
09:22:21   {"table":"orderBookL2","action":"update","data":[{"symbol":"XBTUSD","id":8798351200,"side":"Sell","size":246},{"symbol":"XBTUSD","id":8798352500,"side":"Sell","size":448}]}
09:22:21   SubViewModel.XBTUSD_Main 异常：Could not create an instance of type BitMex.BitMexMsg.BitMexMsgBase. Type is an interface or abstract class and cannot be instantiated. Path 'table', line 1, position 9.
09:22:21   {"table":"orderBookL2","action":"insert","data":[{"symbol":"XBTUSD","id":8798353150,"side":"Sell","size":10000,"price":16468.5},{"symbol":"XBTUSD","id":8798354450,"side":"Sell","size":10000,"price":16455.5}]}
09:22:21   {"table":"orderBookL2","action":"update","data":[{"symbol":"XBTUSD","id":8798353250,"side":"Sell","size":3776},{"symbol":"XBTUSD","id":8798354050,"side":"Sell","size":464}]}
09:22:21   {"table":"orderBookL2","action":"update","data":[{"symbol":"XBTUSD","id":8798356750,"side":"Sell","size":25822}]}
09:22:21   {"table":"orderBookL2","action":"insert","data":[{"symbol":"XBTUSD","id":8798356950,"side":"Sell","size":3000,"price":16430.5}]}
09:22:21   SubViewModel.XBTUSD_Main 异常：Could not create an instance of type BitMex.BitMexMsg.BitMexMsgBase. Type is an interface or abstract class and cannot be instantiated. Path 'table', line 1, position 9.
09:22:21   {"table":"orderBookL2","action":"delete","data":[{"symbol":"XBTUSD","id":8798354050,"side":"Sell"}]}
09:22:21   {"table":"orderBookL2","action":"update","data":[{"symbol":"XBTUSD","id":8798356000,"side":"Sell","size":1379},{"symbol":"XBTUSD","id":8798361550,"side":"Buy","size":4100},{"symbol":"XBTUSD","id":8798363200,"side":"Buy","size":2100},{"symbol":"XBTUSD","id":8798365200,"side":"Buy","size":163781}]}
09:22:21   {"table":"orderBookL2","action":"insert","data":[{"symbol":"XBTUSD","id":8798366850,"side":"Buy","size":465,"price":16331.5}]}
09:22:21   {"table":"orderBookL2","action":"update","data":[{"symbol":"XBTUSD","id":8798357350,"side":"Sell","size":9000}]}
09:22:21   {"table":"orderBookL2","action":"update","data":[{"symbol":"XBTUSD","id":8798356700,"side":"Sell","size":15890}]}
09:22:21   SubViewModel.XBTUSD_Main 异常：Could not create an instance of type BitMex.BitMexMsg.BitMexMsgBase. Type is an interface or abstract class and cannot be instantiated. Path 'table', line 1, position 9.
09:22:21   {"table":"orderBookL2","action":"insert","data":[{"symbol":"XBTUSD","id":8798357100,"side":"Sell","size":3000,"price":16429}]}
09:22:21   {"table":"orderBookL2","action":"insert","data":[{"symbol":"XBTUSD","id":8798368900,"side":"Buy","size":600,"price":16311}]}
09:22:21   {"table":"orderBookL2","action":"update","data":[{"symbol":"XBTUSD","id":8798359700,"side":"Buy","size":212792}]}
09:22:21   {"table":"orderBookL2","action":"update","data":[{"symbol":"XBTUSD","id":8798359600,"side":"Sell","size":2193}]}
09:22:21   {"table":"orderBookL2","action":"update","data":[{"symbol":"XBTUSD","id":8798470000,"side":"Buy","size":218300}]}
09:22:21   {"table":"orderBookL2","action":"update","data":[{"symbol":"XBTUSD","id":8798378900,"side":"Buy","size":54291}]}
09:22:21   SubViewModel.XBTUSD_Main 异常：Could not create an instance of type BitMex.BitMexMsg.BitMexMsgBase. Type is an interface or abstract class and cannot be instantiated. Path 'table', line 1, position 9.
09:22:21   {"table":"orderBookL2","action":"update","data":[{"symbol":"XBTUSD","id":8798356750,"side":"Sell","size":25890}]}
09:22:21   {"table":"orderBookL2","action":"update","data":[{"symbol":"XBTUSD","id":8798352400,"side":"Sell","size":2769},{"symbol":"XBTUSD","id":8798352900,"side":"Sell","size":4776}]}
09:22:21   {"table":"orderBookL2","action":"delete","data":[{"symbol":"XBTUSD","id":8798303200,"side":"Sell"}]}
09:22:21   {"table":"orderBookL2","action":"update","data":[{"symbol":"XBTUSD","id":8798306700,"side":"Sell","size":90}]}
09:22:21   {"table":"orderBookL2","action":"update","data":[{"symbol":"XBTUSD","id":8798352400,"side":"Sell","size":12769},{"symbol":"XBTUSD","id":8798352750,"side":"Sell","size":4000}]}
09:22:22   {"table":"orderBookL2","action":"update","data":[{"symbol":"XBTUSD","id":8798351800,"side":"Sell","size":1333},{"symbol":"XBTUSD","id":8798352750,"side":"Sell","size":14000},{"symbol":"XBTUSD","id":8798352800,"side":"Sell","size":10100}]}
09:22:22   {"table":"orderBookL2","action":"insert","data":[{"symbol":"XBTUSD","id":8798353750,"side":"Sell","size":10000,"price":16462.5}]}
09:22:22   SubViewModel.XBTUSD_Main 异常：Could not create an instance of type BitMex.BitMexMsg.BitMexMsgBase. Type is an interface or abstract class and cannot be instantiated. Path 'table', line 1, position 9.
09:22:22   {"table":"orderBookL2","action":"delete","data":[{"symbol":"XBTUSD","id":8798369950,"side":"Buy"},{"symbol":"XBTUSD","id":8798385300,"side":"Buy"}]}
09:22:22   {"table":"orderBookL2","action":"update","data":[{"symbol":"XBTUSD","id":8798359950,"side":"Buy","size":36214},{"symbol":"XBTUSD","id":8798360200,"side":"Buy","size":8200},{"symbol":"XBTUSD","id":8798364950,"side":"Buy","size":170090},{"symbol":"XBTUSD","id":8798365200,"side":"Buy","size":163981},{"symbol":"XBTUSD","id":8798370200,"side":"Buy","size":15960},{"symbol":"XBTUSD","id":8798374950,"side":"Buy","size":5000},{"symbol":"XBTUSD","id":8798376400,"side":"Buy","size":1142},{"symbol":"XBTUSD","id":8798380300,"side":"Buy","size":185},{"symbol":"XBTUSD","id":8798381400,"side":"Buy","size":802},{"symbol":"XBTUSD","id":8798419050,"side":"Buy","size":650},{"symbol":"XBTUSD","id":8798421100,"side":"Buy","size":240},{"symbol":"XBTUSD","id":8798436000,"side":"Buy","size":210},{"symbol":"XBTUSD","id":8798436200,"side":"Buy","size":176580},{"symbol":"XBTUSD","id":8798449950,"side":"Buy","size":2200},{"symbol":"XBTUSD","id":8798455600,"side":"Buy","size":240},{"symbol":"XBTUSD","id":8798469900,"side":"Buy","size":1275},{"symbol":"XBTUSD","id":8798475500,"side":"Buy","size":92},{"symbol":"XBTUSD","id":8798489900,"side":"Buy","size":275},{"symbol":"XBTUSD","id":8798495000,"side":"Buy","size":5000},{"symbol":"XBTUSD","id":8798509900,"side":"Buy","size":10195},{"symbol":"XBTUSD","id":8798515000,"side":"Buy","size":405000},{"symbol":"XBTUSD","id":8798529900,"side":"Buy","size":275},{"symbol":"XBTUSD","id":8798535000,"side":"Buy","size":105200},{"symbol":"XBTUSD","id":8798540000,"side":"Buy","size":24000},{"symbol":"XBTUSD","id":8798545000,"side":"Buy","size":8000},{"symbol":"XBTUSD","id":8798549900,"side":"Buy","size":475},{"symbol":"XBTUSD","id":8798550000,"side":"Buy","size":148000},{"symbol":"XBTUSD","id":8798554900,"side":"Buy","size":550},{"symbol":"XBTUSD","id":8798555000,"side":"Buy","size":1550},{"symbol":"XBTUSD","id":8798559900,"side":"Buy","size":275},{"symbol":"XBTUSD","id":8798564900,"side":"Buy","size":20350},{"symbol":"XBTUSD","id":8798569900,"side":"Buy","size":275}]}
09:22:22   {"table":"orderBookL2","action":"update","data":[{"symbol":"XBTUSD","id":8798359600,"side":"Sell","size":1042}]}
09:22:22   {"table":"orderBookL2","action":"update","data":[{"symbol":"XBTUSD","id":8798348600,"side":"Sell","size":9245}]}
09:22:22   SubViewModel.XBTUSD_Main 异常：Could not create an instance of type BitMex.BitMexMsg.BitMexMsgBase. Type is an interface or abstract class and cannot be instantiated. Path 'table', line 1, position 9.
09:22:22   {"table":"orderBookL2","action":"insert","data":[{"symbol":"XBTUSD","id":8798358600,"side":"Sell","size":3403,"price":16414}]}
09:22:22   {"table":"orderBookL2","action":"update","data":[{"symbol":"XBTUSD","id":8798359600,"side":"Sell","size":42}]}
09:22:22   {"table":"orderBookL2","action":"update","data":[{"symbol":"XBTUSD","id":8798530000,"side":"Buy","size":89600}]}
09:22:22   {"table":"orderBookL2","action":"update","data":[{"symbol":"XBTUSD","id":8798340000,"side":"Sell","size":4319}]}
09:22:22   SubViewModel.XBTUSD_Main 异常：Could not create an instance of type BitMex.BitMexMsg.BitMexMsgBase. Type is an interface or abstract class and cannot be instantiated. Path 'table', line 1, position 9.
09:22:22   {"table":"orderBookL2","action":"update","data":[{"symbol":"XBTUSD","id":8798200000,"side":"Sell","size":349073}]}
09:22:22   {"table":"orderBookL2","action":"delete","data":[{"symbol":"XBTUSD","id":8798353550,"side":"Sell"}]}
09:22:22   {"table":"orderBookL2","action":"update","data":[{"symbol":"XBTUSD","id":8798353750,"side":"Sell","size":13776}]}
09:22:22   {"table":"orderBookL2","action":"update","data":[{"symbol":"XBTUSD","id":8798361550,"side":"Buy","size":2100}]}
09:22:22   {"table":"orderBookL2","action":"insert","data":[{"symbol":"XBTUSD","id":8798363400,"side":"Buy","size":2000,"price":16366}]}
09:22:22   SubViewModel.XBTUSD_Main 异常：Could not create an instance of type BitMex.BitMexMsg.BitMexMsgBase. Type is an interface or abstract class and cannot be instantiated. Path 'table', line 1, position 9.
09:22:22   {"table":"orderBookL2","action":"delete","data":[{"symbol":"XBTUSD","id":8798346100,"side":"Sell"},{"symbol":"XBTUSD","id":8798346400,"side":"Sell"}]}
09:22:22   {"table":"orderBookL2","action":"insert","data":[{"symbol":"XBTUSD","id":8798345150,"side":"Sell","size":6920,"price":16548.5},{"symbol":"XBTUSD","id":8798345550,"side":"Sell","size":6970,"price":16544.5}]}
09:22:22   {"table":"orderBookL2","action":"delete","data":[{"symbol":"XBTUSD","id":8798345750,"side":"Sell"},{"symbol":"XBTUSD","id":8798349550,"side":"Sell"},{"symbol":"XBTUSD","id":8798367550,"side":"Buy"}]}
09:22:22   {"table":"orderBookL2","action":"update","data":[{"symbol":"XBTUSD","id":8798348450,"side":"Sell","size":2000},{"symbol":"XBTUSD","id":8798348850,"side":"Sell","size":42},{"symbol":"XBTUSD","id":8798352200,"side":"Sell","size":249},{"symbol":"XBTUSD","id":8798364200,"side":"Buy","size":300},{"symbol":"XBTUSD","id":8798374950,"side":"Buy","size":5050}]}
09:22:22   SubViewModel.XBTUSD_Main 异常：Could not create an instance of type BitMex.BitMexMsg.BitMexMsgBase. Type is an interface or abstract class and cannot be instantiated. Path 'table', line 1, position 9.
09:22:22   {"table":"orderBookL2","action":"insert","data":[{"symbol":"XBTUSD","id":8798344550,"side":"Sell","size":14,"price":16554.5},{"symbol":"XBTUSD","id":8798348900,"side":"Sell","size":64,"price":16511},{"symbol":"XBTUSD","id":8798351750,"side":"Sell","size":64,"price":16482.5},{"symbol":"XBTUSD","id":8798371450,"side":"Buy","size":114,"price":16285.5}]}
09:22:22   {"table":"orderBookL2","action":"delete","data":[{"symbol":"XBTUSD","id":8798359600,"side":"Sell"}]}
09:22:22   {"table":"orderBookL2","action":"update","data":[{"symbol":"XBTUSD","id":8798358900,"side":"Sell","size":16535}]}
09:22:22   {"table":"orderBookL2","action":"delete","data":[{"symbol":"XBTUSD","id":8798331450,"side":"Sell"}]}
09:22:22   {"table":"orderBookL2","action":"update","data":[{"symbol":"XBTUSD","id":8798331500,"side":"Sell","size":151850}]}
09:22:22   {"table":"orderBookL2","action":"delete","data":[{"symbol":"XBTUSD","id":8798350350,"side":"Sell"},{"symbol":"XBTUSD","id":8798351800,"side":"Sell"}]}
09:22:22   {"table":"orderBookL2","action":"update","data":[{"symbol":"XBTUSD","id":8798358900,"side":"Sell","size":18480}]}
09:22:22   SubViewModel.XBTUSD_Main 异常：Could not create an instance of type BitMex.BitMexMsg.BitMexMsgBase. Type is an interface or abstract class and cannot be instantiated. Path 'table', line 1, position 9.
09:22:22   {"table":"orderBookL2","action":"update","data":[{"symbol":"XBTUSD","id":8798358900,"side":"Sell","size":18230}]}
09:22:22   {"table":"orderBookL2","action":"delete","data":[{"symbol":"XBTUSD","id":8798304500,"side":"Sell"}]}
09:22:22   {"table":"orderBookL2","action":"update","data":[{"symbol":"XBTUSD","id":8798314500,"side":"Sell","size":53500}]}
09:22:22   SubViewModel.XBTUSD_Main 异常：Could not create an instance of type BitMex.BitMexMsg.BitMexMsgBase. Type is an interface or abstract class and cannot be instantiated. Path 'table', line 1, position 9.
09:22:22   {"table":"orderBookL2","action":"delete","data":[{"symbol":"XBTUSD","id":8798351250,"side":"Sell"},{"symbol":"XBTUSD","id":8798352100,"side":"Sell"}]}
09:22:22   {"table":"orderBookL2","action":"update","data":[{"symbol":"XBTUSD","id":8798352500,"side":"Sell","size":10498},{"symbol":"XBTUSD","id":8798352550,"side":"Sell","size":4000},{"symbol":"XBTUSD","id":8798353750,"side":"Sell","size":23776}]}
09:22:22   {"table":"orderBookL2","action":"insert","data":[{"symbol":"XBTUSD","id":8798353400,"side":"Sell","size":10000,"price":16466},{"symbol":"XBTUSD","id":8798353650,"side":"Sell","size":10000,"price":16463.5}]}
09:22:22   SubViewModel.XBTUSD_Main 异常：Could not create an instance of type BitMex.BitMexMsg.BitMexMsgBase. Type is an interface or abstract class and cannot be instantiated. Path 'table', line 1, position 9.
09:22:22   {"table":"orderBookL2","action":"update","data":[{"symbol":"XBTUSD","id":8798351500,"side":"Sell","size":11000}]}
09:22:22   {"table":"orderBookL2","action":"delete","data":[{"symbol":"XBTUSD","id":8798346500,"side":"Sell"},{"symbol":"XBTUSD","id":8798354600,"side":"Sell"}]}
09:22:22   {"table":"orderBookL2","action":"update","data":[{"symbol":"XBTUSD","id":8798348400,"side":"Sell","size":388630},{"symbol":"XBTUSD","id":8798355100,"side":"Sell","size":166}]}
09:22:22   {"table":"orderBookL2","action":"update","data":[{"symbol":"XBTUSD","id":8798354000,"side":"Sell","size":153474}]}
09:22:22   SubViewModel.XBTUSD_Main 异常：Could not create an instance of type BitMex.BitMexMsg.BitMexMsgBase. Type is an interface or abstract class and cannot be instantiated. Path 'table', line 1, position 9.
09:22:22   {"table":"orderBookL2","action":"delete","data":[{"symbol":"XBTUSD","id":8798353800,"side":"Sell"}]}
09:22:22   {"table":"orderBookL2","action":"insert","data":[{"symbol":"XBTUSD","id":8798355750,"side":"Sell","size":10050,"price":16442.5}]}
09:22:22   {"table":"orderBookL2","action":"update","data":[{"symbol":"XBTUSD","id":8798352200,"side":"Sell","size":3661}]}
09:22:22   {"table":"orderBookL2","action":"insert","data":[{"symbol":"XBTUSD","id":8798346500,"side":"Sell","size":3412,"price":16535},{"symbol":"XBTUSD","id":8798434700,"side":"Buy","size":5118,"price":15653}]}
09:22:22   {"table":"orderBookL2","action":"update","data":[{"symbol":"XBTUSD","id":8798347000,"side":"Sell","size":10721}]}
09:22:22   {"table":"orderBookL2","action":"update","data":[{"symbol":"XBTUSD","id":8798351500,"side":"Sell","size":1000},{"symbol":"XBTUSD","id":8798352800,"side":"Sell","size":50},{"symbol":"XBTUSD","id":8798354450,"side":"Sell","size":20000},{"symbol":"XBTUSD","id":8798354800,"side":"Sell","size":10175}]}
09:22:22   SubViewModel.XBTUSD_Main 异常：Could not create an instance of type BitMex.BitMexMsg.BitMexMsgBase. Type is an interface or abstract class and cannot be instantiated. Path 'table', line 1, position 9.
09:22:22   {"table":"orderBookL2","action":"insert","data":[{"symbol":"XBTUSD","id":8798359600,"side":"Buy","size":6548,"price":16404}]}
09:22:22   {"table":"orderBookL2","action":"insert","data":[{"symbol":"XBTUSD","id":8798347450,"side":"Sell","size":3500,"price":16525.5}]}
09:22:22   {"table":"orderBookL2","action":"delete","data":[{"symbol":"XBTUSD","id":8798356900,"side":"Sell"}]}
09:22:22   {"table":"orderBookL2","action":"update","data":[{"symbol":"XBTUSD","id":8798373650,"side":"Buy","size":207}]}
09:22:22   {"table":"orderBookL2","action":"update","data":[{"symbol":"XBTUSD","id":8798370000,"side":"Buy","size":25160}]}
09:22:22   {"table":"orderBookL2","action":"delete","data":[{"symbol":"XBTUSD","id":8798352150,"side":"Sell"}]}
09:22:22   {"table":"orderBookL2","action":"insert","data":[{"symbol":"XBTUSD","id":8798353350,"side":"Sell","size":3776,"price":16466.5}]}
09:22:22   {"table":"orderBookL2","action":"update","data":[{"symbol":"XBTUSD","id":8798357700,"side":"Sell","size":10}]}
09:22:22   SubViewModel.XBTUSD_Main 异常：Could not create an instance of type BitMex.BitMexMsg.BitMexMsgBase. Type is an interface or abstract class and cannot be instantiated. Path 'table', line 1, position 9.
09:22:22   {"table":"orderBookL2","action":"update","data":[{"symbol":"XBTUSD","id":8798357650,"side":"Sell","size":10010}]}
09:22:22   {"table":"orderBookL2","action":"update","data":[{"symbol":"XBTUSD","id":8798356300,"side":"Sell","size":920}]}
09:22:22   {"table":"orderBookL2","action":"update","data":[{"symbol":"XBTUSD","id":8798356300,"side":"Sell","size":1170}]}
09:22:22   SubViewModel.XBTUSD_Main 异常：Could not create an instance of type BitMex.BitMexMsg.BitMexMsgBase. Type is an interface or abstract class and cannot be instantiated. Path 'table', line 1, position 9.
09:22:22   {"table":"orderBookL2","action":"insert","data":[{"symbol":"XBTUSD","id":8798357200,"side":"Sell","size":328,"price":16428}]}
09:22:22   {"table":"orderBookL2","action":"update","data":[{"symbol":"XBTUSD","id":8798358900,"side":"Sell","size":17230}]}
09:22:22   {"table":"orderBookL2","action":"update","data":[{"symbol":"XBTUSD","id":8798356300,"side":"Sell","size":4170}]}
09:22:22   {"table":"orderBookL2","action":"update","data":[{"symbol":"XBTUSD","id":8798356300,"side":"Sell","size":4420}]}
09:22:22   {"table":"orderBookL2","action":"update","data":[{"symbol":"XBTUSD","id":8798357650,"side":"Sell","size":10}]}
09:22:22   {"table":"orderBookL2","action":"delete","data":[{"symbol":"XBTUSD","id":8798355250,"side":"Sell"}]}
09:22:22   SubViewModel.XBTUSD_Main 异常：Could not create an instance of type BitMex.BitMexMsg.BitMexMsgBase. Type is an interface or abstract class and cannot be instantiated. Path 'table', line 1, position 9.
09:22:22   {"table":"orderBookL2","action":"update","data":[{"symbol":"XBTUSD","id":8798355500,"side":"Sell","size":9345}]}
09:22:22   {"table":"orderBookL2","action":"update","data":[{"symbol":"XBTUSD","id":8798346500,"side":"Sell","size":6824},{"symbol":"XBTUSD","id":8798352200,"side":"Sell","size":7073},{"symbol":"XBTUSD","id":8798434700,"side":"Buy","size":10236}]}
09:22:22   {"table":"orderBookL2","action":"delete","data":[{"symbol":"XBTUSD","id":8798355800,"side":"Sell"},{"symbol":"XBTUSD","id":8798366800,"side":"Buy"},{"symbol":"XBTUSD","id":8798374400,"side":"Buy"}]}
09:22:22   SubViewModel.XBTUSD_Main 异常：Could not create an instance of type BitMex.BitMexMsg.BitMexMsgBase. Type is an interface or abstract class and cannot be instantiated. Path 'table', line 1, position 9.
09:22:23   {"table":"orderBookL2","action":"update","data":[{"symbol":"XBTUSD","id":8798349000,"side":"Sell","size":767},{"symbol":"XBTUSD","id":8798350700,"side":"Sell","size":2587},{"symbol":"XBTUSD","id":8798351200,"side":"Sell","size":73},{"symbol":"XBTUSD","id":8798352800,"side":"Sell","size":223},{"symbol":"XBTUSD","id":8798353200,"side":"Sell","size":9345},{"symbol":"XBTUSD","id":8798355000,"side":"Sell","size":345},{"symbol":"XBTUSD","id":8798377800,"side":"Buy","size":40728},{"symbol":"XBTUSD","id":8798396800,"side":"Buy","size":267}]}
09:22:23   {"table":"orderBookL2","action":"insert","data":[{"symbol":"XBTUSD","id":8798357000,"side":"Sell","size":81,"price":16430},{"symbol":"XBTUSD","id":8798368500,"side":"Buy","size":81,"price":16315},{"symbol":"XBTUSD","id":8798405900,"side":"Buy","size":266,"price":15941}]}
09:22:23   {"table":"orderBookL2","action":"update","data":[{"symbol":"XBTUSD","id":8798356300,"side":"Sell","size":6920}]}
09:22:23   {"table":"orderBookL2","action":"update","data":[{"symbol":"XBTUSD","id":8798356300,"side":"Sell","size":7520}]}
09:22:23   {"table":"orderBookL2","action":"update","data":[{"symbol":"XBTUSD","id":8798301600,"side":"Sell","size":5601}]}
09:22:23   {"table":"orderBookL2","action":"update","data":[{"symbol":"XBTUSD","id":8798348000,"side":"Sell","size":800},{"symbol":"XBTUSD","id":8798350000,"side":"Sell","size":80610}]}
09:22:23   {"table":"orderBookL2","action":"insert","data":[{"symbol":"XBTUSD","id":8798359550,"side":"Buy","size":6520,"price":16404.5}]}
09:22:23   SubViewModel.XBTUSD_Main 异常：Could not create an instance of type BitMex.BitMexMsg.BitMexMsgBase. Type is an interface or abstract class and cannot be instantiated. Path 'table', line 1, position 9.
09:22:23   {"table":"orderBookL2","action":"update","data":[{"symbol":"XBTUSD","id":8798356500,"side":"Sell","size":25500}]}
09:22:23   {"table":"orderBookL2","action":"delete","data":[{"symbol":"XBTUSD","id":8798357650,"side":"Sell"}]}
09:22:23   {"table":"orderBookL2","action":"update","data":[{"symbol":"XBTUSD","id":8798356300,"side":"Sell","size":7770}]}
09:22:23   {"table":"orderBookL2","action":"update","data":[{"symbol":"XBTUSD","id":8798358900,"side":"Sell","size":16430}]}
09:22:23   {"table":"orderBookL2","action":"update","data":[{"symbol":"XBTUSD","id":8798354800,"side":"Sell","size":10675}]}
09:22:23   {"table":"orderBookL2","action":"delete","data":[{"symbol":"XBTUSD","id":8798340200,"side":"Sell"}]}
09:22:23   SubViewModel.XBTUSD_Main 异常：Could not create an instance of type BitMex.BitMexMsg.BitMexMsgBase. Type is an interface or abstract class and cannot be instantiated. Path 'table', line 1, position 9.
09:22:23   {"table":"orderBookL2","action":"update","data":[{"symbol":"XBTUSD","id":8798344600,"side":"Sell","size":10338}]}
09:22:23   {"table":"orderBookL2","action":"update","data":[{"symbol":"XBTUSD","id":8798346300,"side":"Sell","size":17210}]}
09:22:23   {"table":"orderBookL2","action":"insert","data":[{"symbol":"XBTUSD","id":8798344700,"side":"Sell","size":25000,"price":16553}]}
09:22:23   {"table":"orderBookL2","action":"delete","data":[{"symbol":"XBTUSD","id":8798359550,"side":"Buy"},{"symbol":"XBTUSD","id":8798359600,"side":"Buy"}]}
09:22:23   {"table":"orderBookL2","action":"update","data":[{"symbol":"XBTUSD","id":8798359700,"side":"Buy","size":135860}]}
09:22:23   SubViewModel.XBTUSD_Main 异常：Could not create an instance of type BitMex.BitMexMsg.BitMexMsgBase. Type is an interface or abstract class and cannot be instantiated. Path 'table', line 1, position 9.
09:22:23   {"table":"orderBookL2","action":"update","data":[{"symbol":"XBTUSD","id":8798359700,"side":"Buy","size":125860}]}
09:22:23   {"table":"orderBookL2","action":"update","data":[{"symbol":"XBTUSD","id":8798356300,"side":"Sell","size":10770}]}
09:22:23   {"table":"orderBookL2","action":"update","data":[{"symbol":"XBTUSD","id":8798359700,"side":"Buy","size":131560}]}
09:22:23   {"table":"orderBookL2","action":"update","data":[{"symbol":"XBTUSD","id":8798356700,"side":"Sell","size":15613}]}
09:22:23   {"table":"orderBookL2","action":"insert","data":[{"symbol":"XBTUSD","id":8798256400,"side":"Sell","size":1000,"price":17436}]}
09:22:23   {"table":"orderBookL2","action":"insert","data":[{"symbol":"XBTUSD","id":8798359550,"side":"Buy","size":6515,"price":16404.5}]}
09:22:23   {"table":"orderBookL2","action":"update","data":[{"symbol":"XBTUSD","id":8798358900,"side":"Sell","size":13146}]}
09:22:23   {"table":"orderBookL2","action":"insert","data":[{"symbol":"XBTUSD","id":8798357750,"side":"Sell","size":3700,"price":16422.5}]}
09:22:23   SubViewModel.XBTUSD_Main 异常：Could not create an instance of type BitMex.BitMexMsg.BitMexMsgBase. Type is an interface or abstract class and cannot be instantiated. Path 'table', line 1, position 9.
09:22:23   {"table":"orderBookL2","action":"insert","data":[{"symbol":"XBTUSD","id":8798359500,"side":"Buy","size":6528,"price":16405}]}
09:22:23   {"table":"orderBookL2","action":"update","data":[{"symbol":"XBTUSD","id":8798353200,"side":"Sell","size":9245}]}
09:22:23   {"table":"orderBookL2","action":"delete","data":[{"symbol":"XBTUSD","id":8798354400,"side":"Sell"}]}
09:22:23   {"table":"orderBookL2","action":"insert","data":[{"symbol":"XBTUSD","id":8798354900,"side":"Sell","size":36,"price":16451}]}
09:22:23   {"table":"orderBookL2","action":"update","data":[{"symbol":"XBTUSD","id":8798356300,"side":"Sell","size":11170}]}
09:22:23   {"table":"orderBookL2","action":"update","data":[{"symbol":"XBTUSD","id":8798358900,"side":"Sell","size":8146}]}
09:22:23   {"table":"orderBookL2","action":"delete","data":[{"symbol":"XBTUSD","id":8798356700,"side":"Sell"},{"symbol":"XBTUSD","id":8798356750,"side":"Sell"},{"symbol":"XBTUSD","id":8798356800,"side":"Sell"},{"symbol":"XBTUSD","id":8798356950,"side":"Sell"},{"symbol":"XBTUSD","id":8798357000,"side":"Sell"},{"symbol":"XBTUSD","id":8798357100,"side":"Sell"},{"symbol":"XBTUSD","id":8798357150,"side":"Sell"},{"symbol":"XBTUSD","id":8798357200,"side":"Sell"},{"symbol":"XBTUSD","id":8798357350,"side":"Sell"},{"symbol":"XBTUSD","id":8798357700,"side":"Sell"},{"symbol":"XBTUSD","id":8798357750,"side":"Sell"},{"symbol":"XBTUSD","id":8798358600,"side":"Sell"},{"symbol":"XBTUSD","id":8798358900,"side":"Sell"}]}
09:22:23   {"table":"orderBookL2","action":"delete","data":[{"symbol":"XBTUSD","id":8798352450,"side":"Sell"}]}
09:22:23   SubViewModel.XBTUSD_Main 异常：Could not create an instance of type BitMex.BitMexMsg.BitMexMsgBase. Type is an interface or abstract class and cannot be instantiated. Path 'table', line 1, position 9.
09:22:23   {"table":"orderBookL2","action":"insert","data":[{"symbol":"XBTUSD","id":8798353950,"side":"Sell","size":3776,"price":16460.5}]}
09:22:23   {"table":"orderBookL2","action":"delete","data":[{"symbol":"XBTUSD","id":8798353250,"side":"Sell"}]}
09:22:23   {"table":"orderBookL2","action":"update","data":[{"symbol":"XBTUSD","id":8798354700,"side":"Sell","size":3829}]}
09:22:23   SubViewModel.XBTUSD_Main 异常：Could not create an instance of type BitMex.BitMexMsg.BitMexMsgBase. Type is an interface or abstract class and cannot be instantiated. Path 'table', line 1, position 9.
09:22:23   {"table":"orderBookL2","action":"update","data":[{"symbol":"XBTUSD","id":8798370900,"side":"Buy","size":601}]}
09:22:23   {"table":"orderBookL2","action":"insert","data":[{"symbol":"XBTUSD","id":8798382500,"side":"Buy","size":100000,"price":16175}]}
09:22:23   {"table":"orderBookL2","action":"update","data":[{"symbol":"XBTUSD","id":8798356300,"side":"Sell","size":14670}]}
09:22:23   {"table":"orderBookL2","action":"delete","data":[{"symbol":"XBTUSD","id":8798329300,"side":"Sell"},{"symbol":"XBTUSD","id":8798333600,"side":"Sell"},{"symbol":"XBTUSD","id":8798338000,"side":"Sell"},{"symbol":"XBTUSD","id":8798342400,"side":"Sell"},{"symbol":"XBTUSD","id":8798363000,"side":"Buy"},{"symbol":"XBTUSD","id":8798371800,"side":"Buy"}]}
09:22:23   {"table":"orderBookL2","action":"update","data":[{"symbol":"XBTUSD","id":8798325000,"side":"Sell","size":26460},{"symbol":"XBTUSD","id":8798335600,"side":"Sell","size":666},{"symbol":"XBTUSD","id":8798340000,"side":"Sell","size":4538},{"symbol":"XBTUSD","id":8798346800,"side":"Sell","size":2000},{"symbol":"XBTUSD","id":8798348600,"side":"Sell","size":9372},{"symbol":"XBTUSD","id":8798353000,"side":"Sell","size":206},{"symbol":"XBTUSD","id":8798367400,"side":"Buy","size":75},{"symbol":"XBTUSD","id":8798376100,"side":"Buy","size":10653},{"symbol":"XBTUSD","id":8798377800,"side":"Buy","size":40994}]}
09:22:23   {"table":"orderBookL2","action":"insert","data":[{"symbol":"XBTUSD","id":8798331200,"side":"Sell","size":312,"price":16688},{"symbol":"XBTUSD","id":8798344300,"side":"Sell","size":173,"price":16557},{"symbol":"XBTUSD","id":8798364800,"side":"Buy","size":127,"price":16352},{"symbol":"XBTUSD","id":8798369200,"side":"Buy","size":173,"price":16308},{"symbol":"XBTUSD","id":8798373500,"side":"Buy","size":219,"price":16265},{"symbol":"XBTUSD","id":8798382200,"side":"Buy","size":312,"price":16178}]}
09:22:23   {"table":"orderBookL2","action":"insert","data":[{"symbol":"XBTUSD","id":8798357750,"side":"Buy","size":4800,"price":16422.5}]}
09:22:23   {"table":"orderBookL2","action":"delete","data":[{"symbol":"XBTUSD","id":8798366850,"side":"Buy"}]}
09:22:23   {"table":"orderBookL2","action":"update","data":[{"symbol":"XBTUSD","id":8798356000,"side":"Sell","size":15},{"symbol":"XBTUSD","id":8798365200,"side":"Buy","size":163680},{"symbol":"XBTUSD","id":8798368900,"side":"Buy","size":1065}]}
09:22:23   {"table":"orderBookL2","action":"insert","data":[{"symbol":"XBTUSD","id":8798366600,"side":"Buy","size":301,"price":16334}]}
09:22:23   {"table":"orderBookL2","action":"delete","data":[{"symbol":"XBTUSD","id":8798395800,"side":"Buy"}]}
09:22:23   SubViewModel.XBTUSD_Main 异常：Could not create an instance of type BitMex.BitMexMsg.BitMexMsgBase. Type is an interface or abstract class and cannot be instantiated. Path 'table', line 1, position 9.
09:22:23   {"table":"orderBookL2","action":"update","data":[{"symbol":"XBTUSD","id":8798355100,"side":"Sell","size":46}]}
09:22:23   {"table":"orderBookL2","action":"insert","data":[{"symbol":"XBTUSD","id":8798355600,"side":"Sell","size":120,"price":16444},{"symbol":"XBTUSD","id":8798403700,"side":"Buy","size":325,"price":15963}]}
09:22:23   {"table":"orderBookL2","action":"insert","data":[{"symbol":"XBTUSD","id":8798369950,"side":"Buy","size":600,"price":16300.5}]}
09:22:23   {"table":"orderBookL2","action":"update","data":[{"symbol":"XBTUSD","id":8798356500,"side":"Sell","size":24500}]}
09:22:23   {"table":"orderBookL2","action":"update","data":[{"symbol":"XBTUSD","id":8798356500,"side":"Sell","size":22500}]}
09:22:23   {"table":"orderBookL2","action":"update","data":[{"symbol":"XBTUSD","id":8798356300,"side":"Sell","size":14920}]}
09:22:23   {"table":"orderBookL2","action":"delete","data":[{"symbol":"XBTUSD","id":8798307150,"side":"Sell"},{"symbol":"XBTUSD","id":8798407150,"side":"Buy"}]}
09:22:23   {"table":"orderBookL2","action":"update","data":[{"symbol":"XBTUSD","id":8798309800,"side":"Sell","size":28},{"symbol":"XBTUSD","id":8798409800,"side":"Buy","size":320}]}
09:22:23   {"table":"orderBookL2","action":"update","data":[{"symbol":"XBTUSD","id":8798359700,"side":"Buy","size":137260}]}
09:22:23   {"table":"orderBookL2","action":"update","data":[{"symbol":"XBTUSD","id":8798357750,"side":"Buy","size":166}]}
09:22:23   {"table":"orderBookL2","action":"update","data":[{"symbol":"XBTUSD","id":8798356300,"side":"Sell","size":15920}]}
09:22:23   {"table":"orderBookL2","action":"delete","data":[{"symbol":"XBTUSD","id":8798322950,"side":"Sell"}]}
09:22:23   SubViewModel.XBTUSD_Main 异常：Could not create an instance of type BitMex.BitMexMsg.BitMexMsgBase. Type is an interface or abstract class and cannot be instantiated. Path 'table', line 1, position 9.
09:22:23   {"table":"orderBookL2","action":"insert","data":[{"symbol":"XBTUSD","id":8798322600,"side":"Sell","size":60,"price":16774}]}
09:22:23   {"table":"orderBookL2","action":"insert","data":[{"symbol":"XBTUSD","id":8798356250,"side":"Sell","size":500,"price":16437.5}]}
09:22:23   {"table":"orderBookL2","action":"delete","data":[{"symbol":"XBTUSD","id":8798352650,"side":"Sell"}]}
09:22:23   {"table":"orderBookL2","action":"update","data":[{"symbol":"XBTUSD","id":8798355600,"side":"Sell","size":320}]}
09:22:23   {"table":"orderBookL2","action":"insert","data":[{"symbol":"XBTUSD","id":8798359650,"side":"Buy","size":50000,"price":16403.5}]}
09:22:23   {"table":"orderBookL2","action":"update","data":[{"symbol":"XBTUSD","id":8798420000,"side":"Buy","size":15200}]}
09:22:23   {"table":"orderBookL2","action":"insert","data":[{"symbol":"XBTUSD","id":8798479100,"side":"Buy","size":1000,"price":15209}]}
09:22:23   {"table":"orderBookL2","action":"delete","data":[{"symbol":"XBTUSD","id":8798361950,"side":"Buy"}]}
09:22:23   {"table":"orderBookL2","action":"update","data":[{"symbol":"XBTUSD","id":8798365650,"side":"Buy","size":511}]}
09:22:23   {"table":"orderBookL2","action":"update","data":[{"symbol":"XBTUSD","id":8798300000,"side":"Sell","size":450286}]}
09:22:23   {"table":"orderBookL2","action":"delete","data":[{"symbol":"XBTUSD","id":8798355000,"side":"Sell"},{"symbol":"XBTUSD","id":8798355100,"side":"Sell"},{"symbol":"XBTUSD","id":8798355200,"side":"Sell"},{"symbol":"XBTUSD","id":8798355300,"side":"Sell"},{"symbol":"XBTUSD","id":8798355500,"side":"Sell"},{"symbol":"XBTUSD","id":8798355600,"side":"Sell"},{"symbol":"XBTUSD","id":8798355650,"side":"Sell"},{"symbol":"XBTUSD","id":8798355700,"side":"Sell"},{"symbol":"XBTUSD","id":8798355750,"side":"Sell"},{"symbol":"XBTUSD","id":8798356000,"side":"Sell"},{"symbol":"XBTUSD","id":8798356250,"side":"Sell"},{"symbol":"XBTUSD","id":8798356300,"side":"Sell"},{"symbol":"XBTUSD","id":8798356500,"side":"Sell"}]}
09:22:23   SubViewModel.XBTUSD_Main 异常：Could not create an instance of type BitMex.BitMexMsg.BitMexMsgBase. Type is an interface or abstract class and cannot be instantiated. Path 'table', line 1, position 9.
09:22:23   {"table":"orderBookL2","action":"update","data":[{"symbol":"XBTUSD","id":8798354950,"side":"Sell","size":8171}]}
09:22:23   {"table":"orderBookL2","action":"insert","data":[{"symbol":"XBTUSD","id":8798357250,"side":"Buy","size":200,"price":16427.5}]}
09:22:23   {"table":"orderBookL2","action":"update","data":[{"symbol":"XBTUSD","id":8798306950,"side":"Sell","size":881},{"symbol":"XBTUSD","id":8798352750,"side":"Sell","size":4000},{"symbol":"XBTUSD","id":8798353750,"side":"Sell","size":13776},{"symbol":"XBTUSD","id":8798354800,"side":"Sell","size":20675}]}
09:22:23   {"table":"orderBookL2","action":"insert","data":[{"symbol":"XBTUSD","id":8798307300,"side":"Sell","size":40,"price":16927},{"symbol":"XBTUSD","id":8798355750,"side":"Sell","size":10000,"price":16442.5}]}
09:22:23   {"table":"orderBookL2","action":"update","data":[{"symbol":"XBTUSD","id":8798354000,"side":"Sell","size":10000}]}
09:22:23   {"table":"orderBookL2","action":"insert","data":[{"symbol":"XBTUSD","id":8798373900,"side":"Buy","size":9245,"price":16261}]}
09:22:23   SubViewModel.XBTUSD_Main 异常：Could not create an instance of type BitMex.BitMexMsg.BitMexMsgBase. Type is an interface or abstract class and cannot be instantiated. Path 'table', line 1, position 9.
09:22:23   {"table":"orderBookL2","action":"insert","data":[{"symbol":"XBTUSD","id":8798358950,"side":"Buy","size":100,"price":16410.5}]}
09:22:23   {"table":"orderBookL2","action":"delete","data":[{"symbol":"XBTUSD","id":8798345150,"side":"Sell"},{"symbol":"XBTUSD","id":8798345550,"side":"Sell"}]}
09:22:23   {"table":"orderBookL2","action":"update","data":[{"symbol":"XBTUSD","id":8798346200,"side":"Sell","size":7232}]}
09:22:23   {"table":"orderBookL2","action":"insert","data":[{"symbol":"XBTUSD","id":8798346100,"side":"Sell","size":6920,"price":16539}]}
09:22:23   {"table":"orderBookL2","action":"update","data":[{"symbol":"XBTUSD","id":8798359650,"side":"Buy","size":50010}]}
09:22:23   {"table":"orderBookL2","action":"delete","data":[{"symbol":"XBTUSD","id":8798408200,"side":"Buy"}]}
09:22:23   SubViewModel.XBTUSD_Main 异常：Could not create an instance of type BitMex.BitMexMsg.BitMexMsgBase. Type is an interface or abstract class and cannot be instantiated. Path 'table', line 1, position 9.
09:22:23   {"table":"orderBookL2","action":"insert","data":[{"symbol":"XBTUSD","id":8798409950,"side":"Buy","size":40,"price":15900.5}]}
09:22:23   {"table":"orderBookL2","action":"delete","data":[{"symbol":"XBTUSD","id":8798357250,"side":"Buy"},{"symbol":"XBTUSD","id":8798357750,"side":"Buy"}]}
09:22:23   {"table":"orderBookL2","action":"insert","data":[{"symbol":"XBTUSD","id":8798357750,"side":"Sell","size":232,"price":16422.5}]}
09:22:23   {"table":"orderBookL2","action":"update","data":[{"symbol":"XBTUSD","id":8798333550,"side":"Sell","size":400}]}
09:22:23   SubViewModel.XBTUSD_Main 异常：Could not create an instance of type BitMex.BitMexMsg.BitMexMsgBase. Type is an interface or abstract class and cannot be instantiated. Path 'table', line 1, position 9.
09:22:23   {"table":"orderBookL2","action":"delete","data":[{"symbol":"XBTUSD","id":8798335750,"side":"Sell"},{"symbol":"XBTUSD","id":8798342350,"side":"Sell"},{"symbol":"XBTUSD","id":8798348950,"side":"Sell"}]}
09:22:23   {"table":"orderBookL2","action":"update","data":[{"symbol":"XBTUSD","id":8798322400,"side":"Sell","size":75},{"symbol":"XBTUSD","id":8798329100,"side":"Sell","size":402},{"symbol":"XBTUSD","id":8798342850,"side":"Sell","size":167828},{"symbol":"XBTUSD","id":8798346150,"side":"Sell","size":1548},{"symbol":"XBTUSD","id":8798349450,"side":"Sell","size":1086},{"symbol":"XBTUSD","id":8798352750,"side":"Sell","size":4524}]}
09:22:23   {"table":"orderBookL2","action":"insert","data":[{"symbol":"XBTUSD","id":8798339550,"side":"Sell","size":1572,"price":16604.5}]}
09:22:23   {"table":"orderBookL2","action":"update","data":[{"symbol":"XBTUSD","id":8798358950,"side":"Buy","size":600}]}
09:22:23   {"table":"orderBookL2","action":"insert","data":[{"symbol":"XBTUSD","id":8798357250,"side":"Sell","size":2500,"price":16427.5}]}
09:22:23   {"table":"orderBookL2","action":"update","data":[{"symbol":"XBTUSD","id":8798357250,"side":"Sell","size":6000}]}
09:22:23   {"table":"orderBookL2","action":"delete","data":[{"symbol":"XBTUSD","id":8798348450,"side":"Sell"}]}
09:22:23   {"table":"orderBookL2","action":"insert","data":[{"symbol":"XBTUSD","id":8798350250,"side":"Sell","size":2000,"price":16497.5}]}
09:22:23   SubViewModel.XBTUSD_Main 异常：Could not create an instance of type BitMex.BitMexMsg.BitMexMsgBase. Type is an interface or abstract class and cannot be instantiated. Path 'table', line 1, position 9.
09:22:23   {"table":"orderBookL2","action":"delete","data":[{"symbol":"XBTUSD","id":8798349800,"side":"Sell"}]}
09:22:23   {"table":"orderBookL2","action":"update","data":[{"symbol":"XBTUSD","id":8798350800,"side":"Sell","size":2826},{"symbol":"XBTUSD","id":8798366900,"side":"Buy","size":240},{"symbol":"XBTUSD","id":8798367800,"side":"Buy","size":16150}]}
09:22:23   {"table":"orderBookL2","action":"delete","data":[{"symbol":"XBTUSD","id":8798351700,"side":"Sell"}]}
09:22:23   {"table":"orderBookL2","action":"update","data":[{"symbol":"XBTUSD","id":8798353750,"side":"Sell","size":17552}]}
09:22:23   {"table":"orderBookL2","action":"delete","data":[{"symbol":"XBTUSD","id":8798344550,"side":"Sell"},{"symbol":"XBTUSD","id":8798348900,"side":"Sell"},{"symbol":"XBTUSD","id":8798371450,"side":"Buy"}]}
09:22:23   SubViewModel.XBTUSD_Main 异常：Could not create an instance of type BitMex.BitMexMsg.BitMexMsgBase. Type is an interface or abstract class and cannot be instantiated. Path 'table', line 1, position 9.
09:22:23   {"table":"orderBookL2","action":"update","data":[{"symbol":"XBTUSD","id":8798352200,"side":"Sell","size":7009},{"symbol":"XBTUSD","id":8798373950,"side":"Buy","size":350},{"symbol":"XBTUSD","id":8798374950,"side":"Buy","size":5000}]}
09:22:23   {"table":"orderBookL2","action":"insert","data":[{"symbol":"XBTUSD","id":8798345700,"side":"Sell","size":14,"price":16543},{"symbol":"XBTUSD","id":8798349700,"side":"Sell","size":64,"price":16503},{"symbol":"XBTUSD","id":8798352450,"side":"Sell","size":64,"price":16475.5},{"symbol":"XBTUSD","id":8798370700,"side":"Buy","size":114,"price":16293}]}
09:22:23   {"table":"orderBookL2","action":"delete","data":[{"symbol":"XBTUSD","id":8798857750,"side":"Buy"}]}
09:22:23   {"table":"orderBookL2","action":"insert","data":[{"symbol":"XBTUSD","id":8798859700,"side":"Buy","size":1,"price":11403}]}
09:22:24   {"table":"orderBookL2","action":"update","data":[{"symbol":"XBTUSD","id":8798363400,"side":"Buy","size":4100}]}
09:22:24   {"table":"orderBookL2","action":"insert","data":[{"symbol":"XBTUSD","id":8798364900,"side":"Buy","size":2100,"price":16351}]}
09:22:24   {"table":"orderBookL2","action":"update","data":[{"symbol":"XBTUSD","id":8798358950,"side":"Buy","size":406}]}
09:22:24   {"table":"orderBookL2","action":"delete","data":[{"symbol":"XBTUSD","id":8798346000,"side":"Sell"},{"symbol":"XBTUSD","id":8798346800,"side":"Sell"}]}
09:22:24   SubViewModel.XBTUSD_Main 异常：Could not create an instance of type BitMex.BitMexMsg.BitMexMsgBase. Type is an interface or abstract class and cannot be instantiated. Path 'table', line 1, position 9.
09:22:24   {"table":"orderBookL2","action":"insert","data":[{"symbol":"XBTUSD","id":8798357700,"side":"Sell","size":500,"price":16423}]}
09:22:24   {"table":"orderBookL2","action":"insert","data":[{"symbol":"XBTUSD","id":8798356800,"side":"Sell","size":250,"price":16432}]}
09:22:24   {"table":"orderBookL2","action":"insert","data":[{"symbol":"XBTUSD","id":8798356300,"side":"Sell","size":2500,"price":16437}]}
09:22:24   {"table":"orderBookL2","action":"update","data":[{"symbol":"XBTUSD","id":8798357250,"side":"Sell","size":6400}]}
09:22:24   {"table":"orderBookL2","action":"update","data":[{"symbol":"XBTUSD","id":8798356300,"side":"Sell","size":2700}]}
09:22:24   {"table":"orderBookL2","action":"update","data":[{"symbol":"XBTUSD","id":8798378900,"side":"Buy","size":54341}]}
09:22:24   {"table":"orderBookL2","action":"update","data":[{"symbol":"XBTUSD","id":8798266850,"side":"Sell","size":3412},{"symbol":"XBTUSD","id":8798272550,"side":"Sell","size":3412}]}
09:22:24   {"table":"orderBookL2","action":"update","data":[{"symbol":"XBTUSD","id":8798357750,"side":"Sell","size":132}]}
09:22:24   {"table":"orderBookL2","action":"delete","data":[{"symbol":"XBTUSD","id":8798352600,"side":"Sell"},{"symbol":"XBTUSD","id":8798353400,"side":"Sell"},{"symbol":"XBTUSD","id":8798353650,"side":"Sell"}]}
09:22:24   {"table":"orderBookL2","action":"update","data":[{"symbol":"XBTUSD","id":8798352500,"side":"Sell","size":448},{"symbol":"XBTUSD","id":8798353750,"side":"Sell","size":17602},{"symbol":"XBTUSD","id":8798353900,"side":"Sell","size":10050},{"symbol":"XBTUSD","id":8798354950,"side":"Sell","size":18171}]}
09:22:24   {"table":"orderBookL2","action":"insert","data":[{"symbol":"XBTUSD","id":8798354650,"side":"Sell","size":10000,"price":16453.5},{"symbol":"XBTUSD","id":8798355000,"side":"Sell","size":10000,"price":16450}]}
09:22:24   {"table":"orderBookL2","action":"update","data":[{"symbol":"XBTUSD","id":8798641250,"side":"Buy","size":200}]}
09:22:24   {"table":"orderBookL2","action":"update","data":[{"symbol":"XBTUSD","id":8798354700,"side":"Sell","size":3776}]}
09:22:24   {"table":"orderBookL2","action":"insert","data":[{"symbol":"XBTUSD","id":8798355200,"side":"Sell","size":53,"price":16448}]}
09:22:24   {"table":"orderBookL2","action":"update","data":[{"symbol":"XBTUSD","id":8798356300,"side":"Sell","size":3700}]}
09:22:24   {"table":"orderBookL2","action":"delete","data":[{"symbol":"XBTUSD","id":8798358950,"side":"Buy"},{"symbol":"XBTUSD","id":8798359500,"side":"Buy"},{"symbol":"XBTUSD","id":8798359550,"side":"Buy"}]}
09:22:24   {"table":"orderBookL2","action":"update","data":[{"symbol":"XBTUSD","id":8798359650,"side":"Buy","size":23459}]}
09:22:24   SubViewModel.XBTUSD_Main 异常：Could not create an instance of type BitMex.BitMexMsg.BitMexMsgBase. Type is an interface or abstract class and cannot be instantiated. Path 'table', line 1, position 9.
09:22:24   {"table":"orderBookL2","action":"update","data":[{"symbol":"XBTUSD","id":8798354450,"side":"Sell","size":22000}]}
09:22:24   {"table":"orderBookL2","action":"insert","data":[{"symbol":"XBTUSD","id":8798358950,"side":"Sell","size":13,"price":16410.5}]}
09:22:24   {"table":"orderBookL2","action":"update","data":[{"symbol":"XBTUSD","id":8798359700,"side":"Buy","size":143860}]}
09:22:24   SubViewModel.XBTUSD_Main 异常：Could not create an instance of type BitMex.BitMexMsg.BitMexMsgBase. Type is an interface or abstract class and cannot be instantiated. Path 'table', line 1, position 9.
09:22:24   {"table":"orderBookL2","action":"delete","data":[{"symbol":"XBTUSD","id":8798368100,"side":"Buy"}]}
09:22:24   {"table":"orderBookL2","action":"update","data":[{"symbol":"XBTUSD","id":8798342200,"side":"Sell","size":963}]}
09:22:24   {"table":"orderBookL2","action":"insert","data":[{"symbol":"XBTUSD","id":8798344400,"side":"Sell","size":387,"price":16556},{"symbol":"XBTUSD","id":8798355500,"side":"Sell","size":118,"price":16445},{"symbol":"XBTUSD","id":8798370400,"side":"Buy","size":118,"price":16296}]}
09:22:24   SubViewModel.XBTUSD_Main 异常：Could not create an instance of type BitMex.BitMexMsg.BitMexMsgBase. Type is an interface or abstract class and cannot be instantiated. Path 'table', line 1, position 9.
09:22:24   {"table":"orderBookL2","action":"delete","data":[{"symbol":"XBTUSD","id":8798364650,"side":"Buy"},{"symbol":"XBTUSD","id":8798374650,"side":"Buy"}]}
09:22:24   {"table":"orderBookL2","action":"update","data":[{"symbol":"XBTUSD","id":8798141800,"side":"Sell","size":200},{"symbol":"XBTUSD","id":8798146800,"side":"Sell","size":200},{"symbol":"XBTUSD","id":8798149800,"side":"Sell","size":250},{"symbol":"XBTUSD","id":8798151800,"side":"Sell","size":200},{"symbol":"XBTUSD","id":8798156800,"side":"Sell","size":7526},{"symbol":"XBTUSD","id":8798159800,"side":"Sell","size":1100},{"symbol":"XBTUSD","id":8798171200,"side":"Sell","size":7954},{"symbol":"XBTUSD","id":8798175000,"side":"Sell","size":5610},{"symbol":"XBTUSD","id":8798191100,"side":"Sell","size":700},{"symbol":"XBTUSD","id":8798195000,"side":"Sell","size":4860},{"symbol":"XBTUSD","id":8798211100,"side":"Sell","size":60200},{"symbol":"XBTUSD","id":8798214950,"side":"Sell","size":27900},{"symbol":"XBTUSD","id":8798231000,"side":"Sell","size":250},{"symbol":"XBTUSD","id":8798234600,"side":"Sell","size":260},{"symbol":"XBTUSD","id":8798250850,"side":"Sell","size":400},{"symbol":"XBTUSD","id":8798254600,"side":"Sell","size":2500},{"symbol":"XBTUSD","id":8798270800,"side":"Sell","size":460},{"symbol":"XBTUSD","id":8798274600,"side":"Sell","size":1602},{"symbol":"XBTUSD","id":8798290500,"side":"Sell","size":802},{"symbol":"XBTUSD","id":8798291700,"side":"Sell","size":602},{"symbol":"XBTUSD","id":8798312200,"side":"Sell","size":250},{"symbol":"XBTUSD","id":8798327500,"side":"Sell","size":1450},{"symbol":"XBTUSD","id":8798328550,"side":"Sell","size":200},{"symbol":"XBTUSD","id":8798332500,"side":"Sell","size":9545},{"symbol":"XBTUSD","id":8798333550,"side":"Sell","size":200},{"symbol":"XBTUSD","id":8798337500,"side":"Sell","size":2567},{"symbol":"XBTUSD","id":8798338550,"side":"Sell","size":200},{"symbol":"XBTUSD","id":8798343550,"side":"Sell","size":200},{"symbol":"XBTUSD","id":8798348550,"side":"Sell","size":700},{"symbol":"XBTUSD","id":8798352500,"side":"Sell","size":648},{"symbol":"XBTUSD","id":8798364050,"side":"Buy","size":10200},{"symbol":"XBTUSD","id":8798369650,"side":"Buy","size":43},{"symbol":"XBTUSD","id":8798379900,"side":"Buy","size":165085},{"symbol":"XBTUSD","id":8798384050,"side":"Buy","size":803},{"symbol":"XBTUSD","id":8798384900,"side":"Buy","size":75},{"symbol":"XBTUSD","id":8798421100,"side":"Buy","size":440},{"symbol":"XBTUSD","id":8798421250,"side":"Buy","size":1274200},{"symbol":"XBTUSD","id":8798428000,"side":"Buy","size":70440},{"symbol":"XBTUSD","id":8798436200,"side":"Buy","size":176380},{"symbol":"XBTUSD","id":8798438400,"side":"Buy","size":1000},{"symbol":"XBTUSD","id":8798444100,"side":"Buy","size":240},{"symbol":"XBTUSD","id":8798457900,"side":"Buy","size":440},{"symbol":"XBTUSD","id":8798464000,"side":"Buy","size":100},{"symbol":"XBTUSD","id":8798477800,"side":"Buy","size":1200},{"symbol":"XBTUSD","id":8798484000,"side":"Buy","size":100100},{"symbol":"XBTUSD","id":8798491950,"side":"Buy","size":11300},{"symbol":"XBTUSD","id":8798499950,"side":"Buy","size":50750},{"symbol":"XBTUSD","id":8798511700,"side":"Buy","size":300},{"symbol":"XBTUSD","id":8798519900,"side":"Buy","size":75},{"symbol":"XBTUSD","id":8798531700,"side":"Buy","size":10200},{"symbol":"XBTUSD","id":8798539900,"side":"Buy","size":75},{"symbol":"XBTUSD","id":8798544900,"side":"Buy","size":150},{"symbol":"XBTUSD","id":8798549900,"side":"Buy","size":275},{"symbol":"XBTUSD","id":8798551500,"side":"Buy","size":244},{"symbol":"XBTUSD","id":8798554900,"side":"Buy","size":350},{"symbol":"XBTUSD","id":8798559550,"side":"Buy","size":4200}]}
09:22:24   {"table":"orderBookL2","action":"insert","data":[{"symbol":"XBTUSD","id":8798154800,"side":"Sell","size":200,"price":18452},{"symbol":"XBTUSD","id":8798316500,"side":"Sell","size":200,"price":16835},{"symbol":"XBTUSD","id":8798342500,"side":"Sell","size":200,"price":16575},{"symbol":"XBTUSD","id":8798347500,"side":"Sell","size":200,"price":16525},{"symbol":"XBTUSD","id":8798369050,"side":"Buy","size":200,"price":16309.5},{"symbol":"XBTUSD","id":8798374050,"side":"Buy","size":200,"price":16259.5},{"symbol":"XBTUSD","id":8798379050,"side":"Buy","size":200,"price":16209.5},{"symbol":"XBTUSD","id":8798564550,"side":"Buy","size":200,"price":14354.5}]}
09:22:24   {"table":"orderBookL2","action":"insert","data":[{"symbol":"XBTUSD","id":8798356500,"side":"Sell","size":250,"price":16435}]}
09:22:24   {"table":"orderBookL2","action":"update","data":[{"symbol":"XBTUSD","id":8798356800,"side":"Sell","size":1000}]}
09:22:24   {"table":"orderBookL2","action":"delete","data":[{"symbol":"XBTUSD","id":8798345200,"side":"Sell"},{"symbol":"XBTUSD","id":8798346900,"side":"Sell"},{"symbol":"XBTUSD","id":8798406200,"side":"Buy"}]}
09:22:24   SubViewModel.XBTUSD_Main 异常：Could not create an instance of type BitMex.BitMexMsg.BitMexMsgBase. Type is an interface or abstract class and cannot be instantiated. Path 'table', line 1, position 9.
09:22:24   {"table":"orderBookL2","action":"update","data":[{"symbol":"XBTUSD","id":8798347200,"side":"Sell","size":390},{"symbol":"XBTUSD","id":8798349400,"side":"Sell","size":518},{"symbol":"XBTUSD","id":8798416000,"side":"Buy","size":9808}]}
09:22:24   {"table":"orderBookL2","action":"insert","data":[{"symbol":"XBTUSD","id":8798355800,"side":"Sell","size":127,"price":16442},{"symbol":"XBTUSD","id":8798357900,"side":"Sell","size":81,"price":16421}]}
09:22:24   {"table":"orderBookL2","action":"delete","data":[{"symbol":"XBTUSD","id":8798354650,"side":"Sell"},{"symbol":"XBTUSD","id":8798354700,"side":"Sell"},{"symbol":"XBTUSD","id":8798354800,"side":"Sell"},{"symbol":"XBTUSD","id":8798354900,"side":"Sell"},{"symbol":"XBTUSD","id":8798354950,"side":"Sell"},{"symbol":"XBTUSD","id":8798355000,"side":"Sell"},{"symbol":"XBTUSD","id":8798355200,"side":"Sell"},{"symbol":"XBTUSD","id":8798355500,"side":"Sell"},{"symbol":"XBTUSD","id":8798355750,"side":"Sell"},{"symbol":"XBTUSD","id":8798355800,"side":"Sell"},{"symbol":"XBTUSD","id":8798356300,"side":"Sell"},{"symbol":"XBTUSD","id":8798356500,"side":"Sell"},{"symbol":"XBTUSD","id":8798356800,"side":"Sell"},{"symbol":"XBTUSD","id":8798357250,"side":"Sell"},{"symbol":"XBTUSD","id":8798357700,"side":"Sell"},{"symbol":"XBTUSD","id":8798357750,"side":"Sell"},{"symbol":"XBTUSD","id":8798357900,"side":"Sell"},{"symbol":"XBTUSD","id":8798358950,"side":"Sell"}]}
09:22:24   SubViewModel.XBTUSD_Main 异常：Could not create an instance of type BitMex.BitMexMsg.BitMexMsgBase. Type is an interface or abstract class and cannot be instantiated. Path 'table', line 1, position 9.
09:22:24   {"table":"orderBookL2","action":"update","data":[{"symbol":"XBTUSD","id":8798354450,"side":"Sell","size":7032}]}
09:22:24   {"table":"orderBookL2","action":"delete","data":[{"symbol":"XBTUSD","id":8798354150,"side":"Sell"}]}
09:22:24   SubViewModel.XBTUSD_Main 异常：Could not create an instance of type BitMex.BitMexMsg.BitMexMsgBase. Type is an interface or abstract class and cannot be instantiated. Path 'table', line 1, position 9.
09:22:24   {"table":"orderBookL2","action":"update","data":[{"symbol":"XBTUSD","id":8798352400,"side":"Sell","size":2769},{"symbol":"XBTUSD","id":8798354450,"side":"Sell","size":17032}]}
09:22:24   {"table":"orderBookL2","action":"insert","data":[{"symbol":"XBTUSD","id":8798353850,"side":"Sell","size":10000,"price":16461.5}]}
09:22:24   {"table":"orderBookL2","action":"delete","data":[{"symbol":"XBTUSD","id":8798266850,"side":"Sell"},{"symbol":"XBTUSD","id":8798272550,"side":"Sell"}]}
09:22:24   {"table":"orderBookL2","action":"update","data":[{"symbol":"XBTUSD","id":8798352900,"side":"Sell","size":1000}]}
09:22:24   SubViewModel.XBTUSD_Main 异常：Could not create an instance of type BitMex.BitMexMsg.BitMexMsgBase. Type is an interface or abstract class and cannot be instantiated. Path 'table', line 1, position 9.
09:22:24   {"table":"orderBookL2","action":"insert","data":[{"symbol":"XBTUSD","id":8798354950,"side":"Sell","size":3776,"price":16450.5}]}
09:22:24   {"table":"orderBookL2","action":"update","data":[{"symbol":"XBTUSD","id":8798365250,"side":"Buy","size":378193}]}
09:22:24   {"table":"orderBookL2","action":"insert","data":[{"symbol":"XBTUSD","id":8798364650,"side":"Buy","size":9806,"price":16353.5}]}
09:22:24   {"table":"orderBookL2","action":"insert","data":[{"symbol":"XBTUSD","id":8798300700,"side":"Sell","size":602,"price":16993}]}
09:22:24   SubViewModel.XBTUSD_Main 异常：Could not create an instance of type BitMex.BitMexMsg.BitMexMsgBase. Type is an interface or abstract class and cannot be instantiated. Path 'table', line 1, position 9.
09:22:24   {"table":"orderBookL2","action":"update","data":[{"symbol":"XBTUSD","id":8798338300,"side":"Sell","size":114710}]}
09:22:24   {"table":"orderBookL2","action":"update","data":[{"symbol":"XBTUSD","id":8798353750,"side":"Sell","size":13826}]}
09:22:24   {"table":"orderBookL2","action":"insert","data":[{"symbol":"XBTUSD","id":8798355600,"side":"Sell","size":3776,"price":16444}]}
09:22:24   {"table":"orderBookL2","action":"insert","data":[{"symbol":"XBTUSD","id":8798359500,"side":"Buy","size":5000,"price":16405}]}
09:22:24   SubViewModel.XBTUSD_Main 异常：Could not create an instance of type BitMex.BitMexMsg.BitMexMsgBase. Type is an interface or abstract class and cannot be instantiated. Path 'table', line 1, position 9.
09:22:24   {"table":"orderBookL2","action":"delete","data":[{"symbol":"XBTUSD","id":8798334400,"side":"Sell"},{"symbol":"XBTUSD","id":8798344350,"side":"Sell"},{"symbol":"XBTUSD","id":8798349300,"side":"Sell"},{"symbol":"XBTUSD","id":8798354250,"side":"Sell"},{"symbol":"XBTUSD","id":8798361450,"side":"Buy"},{"symbol":"XBTUSD","id":8798366350,"side":"Buy"},{"symbol":"XBTUSD","id":8798380950,"side":"Buy"},{"symbol":"XBTUSD","id":8798385800,"side":"Buy"}]}
09:22:24   {"table":"orderBookL2","action":"update","data":[{"symbol":"XBTUSD","id":8798329400,"side":"Sell","size":13074},{"symbol":"XBTUSD","id":8798339400,"side":"Sell","size":12138},{"symbol":"XBTUSD","id":8798341600,"side":"Sell","size":10410},{"symbol":"XBTUSD","id":8798351500,"side":"Sell","size":6000},{"symbol":"XBTUSD","id":8798371250,"side":"Buy","size":603},{"symbol":"XBTUSD","id":8798376100,"side":"Buy","size":653}]}
09:22:24   SubViewModel.XBTUSD_Main 异常：Could not create an instance of type BitMex.BitMexMsg.BitMexMsgBase. Type is an interface or abstract class and cannot be instantiated. Path 'table', line 1, position 9.
09:22:24   {"table":"orderBookL2","action":"insert","data":[{"symbol":"XBTUSD","id":8798331650,"side":"Sell","size":15000,"price":16683.5},{"symbol":"XBTUSD","id":8798336650,"side":"Sell","size":12500,"price":16633.5},{"symbol":"XBTUSD","id":8798346550,"side":"Sell","size":7500,"price":16534.5},{"symbol":"XBTUSD","id":8798356450,"side":"Sell","size":2500,"price":16435.5},{"symbol":"XBTUSD","id":8798363250,"side":"Buy","size":2500,"price":16367.5},{"symbol":"XBTUSD","id":8798368150,"side":"Buy","size":5000,"price":16318.5},{"symbol":"XBTUSD","id":8798373000,"side":"Buy","size":7500,"price":16270},{"symbol":"XBTUSD","id":8798377900,"side":"Buy","size":10000,"price":16221},{"symbol":"XBTUSD","id":8798382750,"side":"Buy","size":12500,"price":16172.5},{"symbol":"XBTUSD","id":8798387600,"side":"Buy","size":15000,"price":16124}]}
09:22:24   {"table":"orderBookL2","action":"update","data":[{"symbol":"XBTUSD","id":8798359500,"side":"Buy","size":4526}]}
09:22:24   {"table":"orderBookL2","action":"insert","data":[{"symbol":"XBTUSD","id":8798360600,"side":"Buy","size":450,"price":16394}]}
09:22:24   SubViewModel.XBTUSD_Main 异常：Could not create an instance of type BitMex.BitMexMsg.BitMexMsgBase. Type is an interface or abstract class and cannot be instantiated. Path 'table', line 1, position 9.
09:22:24   {"table":"orderBookL2","action":"delete","data":[{"symbol":"XBTUSD","id":8798359500,"side":"Buy"}]}
09:22:24   {"table":"orderBookL2","action":"update","data":[{"symbol":"XBTUSD","id":8798359650,"side":"Buy","size":19985}]}
09:22:24   {"table":"orderBookL2","action":"insert","data":[{"symbol":"XBTUSD","id":8798360550,"side":"Buy","size":250,"price":16394.5}]}
09:22:24   {"table":"orderBookL2","action":"update","data":[{"symbol":"XBTUSD","id":8798360600,"side":"Buy","size":3450}]}
09:22:24   SubViewModel.XBTUSD_Main 异常：Could not create an instance of type BitMex.BitMexMsg.BitMexMsgBase. Type is an interface or abstract class and cannot be instantiated. Path 'table', line 1, position 9.
09:22:24   {"table":"orderBookL2","action":"update","data":[{"symbol":"XBTUSD","id":8798359650,"side":"Buy","size":16985}]}
09:22:24   {"table":"orderBookL2","action":"insert","data":[{"symbol":"XBTUSD","id":8798346000,"side":"Sell","size":50000,"price":16540}]}
09:22:24   {"table":"orderBookL2","action":"update","data":[{"symbol":"XBTUSD","id":8798360550,"side":"Buy","size":500}]}
09:22:24   SubViewModel.XBTUSD_Main 异常：Could not create an instance of type BitMex.BitMexMsg.BitMexMsgBase. Type is an interface or abstract class and cannot be instantiated. Path 'table', line 1, position 9.
09:22:24   {"table":"orderBookL2","action":"update","data":[{"symbol":"XBTUSD","id":8798360550,"side":"Buy","size":3000}]}
09:22:24   {"table":"orderBookL2","action":"delete","data":[{"symbol":"XBTUSD","id":8798338500,"side":"Sell"},{"symbol":"XBTUSD","id":8798344850,"side":"Sell"},{"symbol":"XBTUSD","id":8798349200,"side":"Sell"},{"symbol":"XBTUSD","id":8798352050,"side":"Sell"},{"symbol":"XBTUSD","id":8798362900,"side":"Buy"},{"symbol":"XBTUSD","id":8798365750,"side":"Buy"},{"symbol":"XBTUSD","id":8798376250,"side":"Buy"}]}
09:22:24   {"table":"orderBookL2","action":"update","data":[{"symbol":"XBTUSD","id":8798329400,"side":"Sell","size":6824},{"symbol":"XBTUSD","id":8798331650,"side":"Sell","size":21250},{"symbol":"XBTUSD","id":8798347050,"side":"Sell","size":8112},{"symbol":"XBTUSD","id":8798364650,"side":"Buy","size":11056},{"symbol":"XBTUSD","id":8798370000,"side":"Buy","size":21410},{"symbol":"XBTUSD","id":8798385100,"side":"Buy","size":161490}]}
09:22:24   {"table":"orderBookL2","action":"insert","data":[{"symbol":"XBTUSD","id":8798340750,"side":"Sell","size":5000,"price":16592.5},{"symbol":"XBTUSD","id":8798351400,"side":"Sell","size":2500,"price":16486},{"symbol":"XBTUSD","id":8798354300,"side":"Sell","size":1250,"price":16457},{"symbol":"XBTUSD","id":8798367550,"side":"Buy","size":2500,"price":16324.5},{"symbol":"XBTUSD","id":8798371800,"side":"Buy","size":3750,"price":16282},{"symbol":"XBTUSD","id":8798378000,"side":"Buy","size":5000,"price":16220},{"symbol":"XBTUSD","id":8798386850,"side":"Buy","size":6250,"price":16131.5}]}
09:22:24   {"table":"orderBookL2","action":"delete","data":[{"symbol":"XBTUSD","id":8798343950,"side":"Sell"},{"symbol":"XBTUSD","id":8798347450,"side":"Sell"}]}
09:22:24   {"table":"orderBookL2","action":"delete","data":[{"symbol":"XBTUSD","id":8798351750,"side":"Sell"}]}
09:22:24   {"table":"orderBookL2","action":"update","data":[{"symbol":"XBTUSD","id":8798353200,"side":"Sell","size":9309}]}
09:22:24   SubViewModel.XBTUSD_Main 异常：Could not create an instance of type BitMex.BitMexMsg.BitMexMsgBase. Type is an interface or abstract class and cannot be instantiated. Path 'table', line 1, position 9.
09:22:24   {"table":"orderBookL2","action":"delete","data":[{"symbol":"XBTUSD","id":8798353350,"side":"Sell"}]}
09:22:24   {"table":"orderBookL2","action":"insert","data":[{"symbol":"XBTUSD","id":8798354100,"side":"Sell","size":3776,"price":16459}]}
09:22:24   {"table":"orderBookL2","action":"insert","data":[{"symbol":"XBTUSD","id":8798368250,"side":"Buy","size":50,"price":16317.5}]}
09:22:24   SubViewModel.XBTUSD_Main 异常：Could not create an instance of type BitMex.BitMexMsg.BitMexMsgBase. Type is an interface or abstract class and cannot be instantiated. Path 'table', line 1, position 9.
09:22:24   {"table":"orderBookL2","action":"update","data":[{"symbol":"XBTUSD","id":8798342850,"side":"Sell","size":1310},{"symbol":"XBTUSD","id":8798344800,"side":"Sell","size":166912},{"symbol":"XBTUSD","id":8798364950,"side":"Buy","size":100}]}
09:22:24   {"table":"orderBookL2","action":"insert","data":[{"symbol":"XBTUSD","id":8798366950,"side":"Buy","size":169990,"price":16330.5}]}
09:22:24   {"table":"orderBookL2","action":"update","data":[{"symbol":"XBTUSD","id":8798360550,"side":"Buy","size":3500}]}
09:22:24   {"table":"orderBookL2","action":"update","data":[{"symbol":"XBTUSD","id":8798344600,"side":"Sell","size":10000}]}
09:22:24   SubViewModel.XBTUSD_Main 异常：Could not create an instance of type BitMex.BitMexMsg.BitMexMsgBase. Type is an interface or abstract class and cannot be instantiated. Path 'table', line 1, position 9.
09:22:24   {"table":"orderBookL2","action":"insert","data":[{"symbol":"XBTUSD","id":8798346400,"side":"Sell","size":338,"price":16536},{"symbol":"XBTUSD","id":8798355300,"side":"Sell","size":124,"price":16447}]}
09:22:24   {"table":"orderBookL2","action":"insert","data":[{"symbol":"XBTUSD","id":8798356700,"side":"Buy","size":100,"price":16433}]}
09:22:24   {"table":"orderBookL2","action":"insert","data":[{"symbol":"XBTUSD","id":8798360700,"side":"Buy","size":250,"price":16393}]}
09:22:24   {"table":"orderBookL2","action":"update","data":[{"symbol":"XBTUSD","id":8798295000,"side":"Sell","size":1162}]}
09:22:24   {"table":"orderBookL2","action":"update","data":[{"symbol":"XBTUSD","id":8798360550,"side":"Buy","size":4100}]}
09:22:24   SubViewModel.XBTUSD_Main 异常：Could not create an instance of type BitMex.BitMexMsg.BitMexMsgBase. Type is an interface or abstract class and cannot be instantiated. Path 'table', line 1, position 9.
09:22:24   {"table":"orderBookL2","action":"update","data":[{"symbol":"XBTUSD","id":8798360550,"side":"Buy","size":4600}]}
09:22:24   {"table":"orderBookL2","action":"insert","data":[{"symbol":"XBTUSD","id":8798360500,"side":"Buy","size":81,"price":16395}]}
09:22:24   {"table":"orderBookL2","action":"update","data":[{"symbol":"XBTUSD","id":8798352750,"side":"Sell","size":524}]}
09:22:24   {"table":"orderBookL2","action":"insert","data":[{"symbol":"XBTUSD","id":8798353300,"side":"Sell","size":4000,"price":16467}]}
09:22:24   {"table":"orderBookL2","action":"insert","data":[{"symbol":"XBTUSD","id":8798356550,"side":"Buy","size":4800,"price":16434.5}]}
09:22:24   SubViewModel.XBTUSD_Main 异常：Could not create an instance of type BitMex.BitMexMsg.BitMexMsgBase. Type is an interface or abstract class and cannot be instantiated. Path 'table', line 1, position 9.
09:22:24   {"table":"orderBookL2","action":"update","data":[{"symbol":"XBTUSD","id":8798360500,"side":"Buy","size":3081}]}
09:22:24   {"table":"orderBookL2","action":"delete","data":[{"symbol":"XBTUSD","id":8798356550,"side":"Buy"},{"symbol":"XBTUSD","id":8798356700,"side":"Buy"}]}
09:22:24   {"table":"orderBookL2","action":"update","data":[{"symbol":"XBTUSD","id":8798359650,"side":"Buy","size":12051}]}
09:22:24   {"table":"orderBookL2","action":"update","data":[{"symbol":"XBTUSD","id":8798348400,"side":"Sell","size":388414},{"symbol":"XBTUSD","id":8798350200,"side":"Sell","size":380416},{"symbol":"XBTUSD","id":8798350800,"side":"Sell","size":2655},{"symbol":"XBTUSD","id":8798352400,"side":"Sell","size":2940},{"symbol":"XBTUSD","id":8798353000,"side":"Sell","size":81}]}
09:22:24   {"table":"orderBookL2","action":"insert","data":[{"symbol":"XBTUSD","id":8798354700,"side":"Sell","size":125,"price":16453},{"symbol":"XBTUSD","id":8798357000,"side":"Sell","size":80,"price":16430}]}
09:22:24   SubViewModel.XBTUSD_Main 异常：Could not create an instance of type BitMex.BitMexMsg.BitMexMsgBase. Type is an interface or abstract class and cannot be instantiated. Path 'table', line 1, position 9.
09:22:24   {"table":"orderBookL2","action":"update","data":[{"symbol":"XBTUSD","id":8798354000,"side":"Sell","size":109640}]}
09:22:24   {"table":"orderBookL2","action":"delete","data":[{"symbol":"XBTUSD","id":8798366600,"side":"Buy"}]}
09:22:24   {"table":"orderBookL2","action":"update","data":[{"symbol":"XBTUSD","id":8798368900,"side":"Buy","size":301},{"symbol":"XBTUSD","id":8798371800,"side":"Buy","size":4350}]}
09:22:24   {"table":"orderBookL2","action":"insert","data":[{"symbol":"XBTUSD","id":8798370150,"side":"Buy","size":465,"price":16298.5}]}
09:22:24   {"table":"orderBookL2","action":"delete","data":[{"symbol":"XBTUSD","id":8798337600,"side":"Sell"}]}
09:22:24   {"table":"orderBookL2","action":"insert","data":[{"symbol":"XBTUSD","id":8798356550,"side":"Sell","size":1366,"price":16434.5}]}
09:22:24   {"table":"orderBookL2","action":"insert","data":[{"symbol":"XBTUSD","id":8798353500,"side":"Sell","size":8000,"price":16465}]}
09:22:24   {"table":"orderBookL2","action":"update","data":[{"symbol":"XBTUSD","id":8798331200,"side":"Sell","size":2312}]}
09:22:25   {"table":"orderBookL2","action":"update","data":[{"symbol":"XBTUSD","id":8798360500,"side":"Buy","size":3481}]}
09:22:25   {"table":"orderBookL2","action":"update","data":[{"symbol":"XBTUSD","id":8798360500,"side":"Buy","size":6981}]}
09:22:24   SubViewModel.XBTUSD_Main 异常：Could not create an instance of type BitMex.BitMexMsg.BitMexMsgBase. Type is an interface or abstract class and cannot be instantiated. Path 'table', line 1, position 9.
09:22:25   {"table":"orderBookL2","action":"delete","data":[{"symbol":"XBTUSD","id":8798487650,"side":"Buy"}]}
09:22:25   {"table":"orderBookL2","action":"insert","data":[{"symbol":"XBTUSD","id":8798552300,"side":"Buy","size":20,"price":14477}]}
09:22:25   {"table":"orderBookL2","action":"update","data":[{"symbol":"XBTUSD","id":8798359650,"side":"Buy","size":10}]}
09:22:25   {"table":"orderBookL2","action":"delete","data":[{"symbol":"XBTUSD","id":8798357000,"side":"Sell"}]}
09:22:25   {"table":"orderBookL2","action":"update","data":[{"symbol":"XBTUSD","id":8798356550,"side":"Sell","size":446}]}
09:22:25   {"table":"orderBookL2","action":"insert","data":[{"symbol":"XBTUSD","id":8798358750,"side":"Buy","size":3000,"price":16412.5}]}
09:22:25   {"table":"orderBookL2","action":"delete","data":[{"symbol":"XBTUSD","id":8798354700,"side":"Sell"},{"symbol":"XBTUSD","id":8798354950,"side":"Sell"},{"symbol":"XBTUSD","id":8798355300,"side":"Sell"},{"symbol":"XBTUSD","id":8798355600,"side":"Sell"},{"symbol":"XBTUSD","id":8798356450,"side":"Sell"},{"symbol":"XBTUSD","id":8798356550,"side":"Sell"}]}
09:22:25   {"table":"orderBookL2","action":"update","data":[{"symbol":"XBTUSD","id":8798354450,"side":"Sell","size":11779}]}
09:22:25   {"table":"orderBookL2","action":"insert","data":[{"symbol":"XBTUSD","id":8798357250,"side":"Sell","size":200,"price":16427.5}]}
09:22:25   {"table":"orderBookL2","action":"delete","data":[{"symbol":"XBTUSD","id":8798353950,"side":"Sell"}]}
09:22:25   {"table":"orderBookL2","action":"update","data":[{"symbol":"XBTUSD","id":8798352350,"side":"Sell","size":3976}]}
09:22:25   {"table":"orderBookL2","action":"update","data":[{"symbol":"XBTUSD","id":8798358750,"side":"Buy","size":500}]}
09:22:25   {"table":"orderBookL2","action":"update","data":[{"symbol":"XBTUSD","id":8798474000,"side":"Buy","size":100100}]}
09:22:25   {"table":"orderBookL2","action":"delete","data":[{"symbol":"XBTUSD","id":8798322600,"side":"Sell"}]}
09:22:25   SubViewModel.XBTUSD_Main 异常：Could not create an instance of type BitMex.BitMexMsg.BitMexMsgBase. Type is an interface or abstract class and cannot be instantiated. Path 'table', line 1, position 9.
09:22:25   {"table":"orderBookL2","action":"update","data":[{"symbol":"XBTUSD","id":8798321450,"side":"Sell","size":1453060}]}
09:22:25   {"table":"orderBookL2","action":"update","data":[{"symbol":"XBTUSD","id":8798340000,"side":"Sell","size":3098}]}
09:22:25   {"table":"orderBookL2","action":"update","data":[{"symbol":"XBTUSD","id":8798358750,"side":"Buy","size":750}]}
09:22:25   {"table":"orderBookL2","action":"update","data":[{"symbol":"XBTUSD","id":8798358750,"side":"Buy","size":1250}]}
09:22:25   {"table":"orderBookL2","action":"update","data":[{"symbol":"XBTUSD","id":8798358750,"side":"Buy","size":2250}]}
09:22:25   {"table":"orderBookL2","action":"insert","data":[{"symbol":"XBTUSD","id":8798360450,"side":"Buy","size":10000,"price":16395.5}]}
09:22:25   {"table":"orderBookL2","action":"insert","data":[{"symbol":"XBTUSD","id":8798357700,"side":"Buy","size":5000,"price":16423}]}
09:22:25   {"table":"orderBookL2","action":"update","data":[{"symbol":"XBTUSD","id":8798357250,"side":"Sell","size":186}]}
09:22:25   {"table":"orderBookL2","action":"insert","data":[{"symbol":"XBTUSD","id":8798357800,"side":"Buy","size":9245,"price":16422}]}
09:22:25   {"table":"orderBookL2","action":"update","data":[{"symbol":"XBTUSD","id":8798357250,"side":"Sell","size":171}]}
09:22:25   {"table":"orderBookL2","action":"delete","data":[{"symbol":"XBTUSD","id":8798348850,"side":"Sell"}]}
09:22:25   SubViewModel.XBTUSD_Main 异常：Could not create an instance of type BitMex.BitMexMsg.BitMexMsgBase. Type is an interface or abstract class and cannot be instantiated. Path 'table', line 1, position 9.
09:22:25   {"table":"orderBookL2","action":"update","data":[{"symbol":"XBTUSD","id":8798349450,"side":"Sell","size":786}]}
09:22:25   {"table":"orderBookL2","action":"insert","data":[{"symbol":"XBTUSD","id":8798322050,"side":"Sell","size":300,"price":16779.5}]}
09:22:25   {"table":"orderBookL2","action":"update","data":[{"symbol":"XBTUSD","id":8798357700,"side":"Buy","size":10000}]}
09:22:25   {"table":"orderBookL2","action":"delete","data":[{"symbol":"XBTUSD","id":8798350950,"side":"Sell"},{"symbol":"XBTUSD","id":8798363200,"side":"Buy"}]}
09:22:25   {"table":"orderBookL2","action":"update","data":[{"symbol":"XBTUSD","id":8798344750,"side":"Sell","size":5000},{"symbol":"XBTUSD","id":8798347050,"side":"Sell","size":3750},{"symbol":"XBTUSD","id":8798350250,"side":"Sell","size":7202},{"symbol":"XBTUSD","id":8798352000,"side":"Sell","size":800},{"symbol":"XBTUSD","id":8798359650,"side":"Buy","size":2110}]}
09:22:25   {"table":"orderBookL2","action":"insert","data":[{"symbol":"XBTUSD","id":8798351250,"side":"Sell","size":5202,"price":16487.5},{"symbol":"XBTUSD","id":8798352850,"side":"Sell","size":5202,"price":16471.5},{"symbol":"XBTUSD","id":8798354050,"side":"Sell","size":5202,"price":16459.5}]}
09:22:25   {"table":"orderBookL2","action":"update","data":[{"symbol":"XBTUSD","id":8798250850,"side":"Sell","size":200}]}
09:22:25   {"table":"orderBookL2","action":"insert","data":[{"symbol":"XBTUSD","id":8798250900,"side":"Sell","size":200,"price":17491}]}
09:22:25   {"table":"orderBookL2","action":"insert","data":[{"symbol":"XBTUSD","id":8798388450,"side":"Buy","size":5000,"price":16115.5}]}
09:22:25   SubViewModel.XBTUSD_Main 异常：Could not create an instance of type BitMex.BitMexMsg.BitMexMsgBase. Type is an interface or abstract class and cannot be instantiated. Path 'table', line 1, position 9.
09:22:25   {"table":"orderBookL2","action":"delete","data":[{"symbol":"XBTUSD","id":8798383900,"side":"Buy"}]}
09:22:25   {"table":"orderBookL2","action":"delete","data":[{"symbol":"XBTUSD","id":8798328550,"side":"Sell"},{"symbol":"XBTUSD","id":8798333550,"side":"Sell"},{"symbol":"XBTUSD","id":8798338550,"side":"Sell"},{"symbol":"XBTUSD","id":8798343550,"side":"Sell"}]}
09:22:25   {"table":"orderBookL2","action":"update","data":[{"symbol":"XBTUSD","id":8798292850,"side":"Sell","size":803},{"symbol":"XBTUSD","id":8798293300,"side":"Sell","size":861},{"symbol":"XBTUSD","id":8798301700,"side":"Sell","size":18312},{"symbol":"XBTUSD","id":8798302050,"side":"Sell","size":603},{"symbol":"XBTUSD","id":8798340500,"side":"Sell","size":7210},{"symbol":"XBTUSD","id":8798348550,"side":"Sell","size":500},{"symbol":"XBTUSD","id":8798350500,"side":"Sell","size":17850},{"symbol":"XBTUSD","id":8798360200,"side":"Buy","size":8000},{"symbol":"XBTUSD","id":8798363400,"side":"Buy","size":4300},{"symbol":"XBTUSD","id":8798365200,"side":"Buy","size":163480},{"symbol":"XBTUSD","id":8798370200,"side":"Buy","size":15760},{"symbol":"XBTUSD","id":8798376400,"side":"Buy","size":942},{"symbol":"XBTUSD","id":8798378500,"side":"Buy","size":853},{"symbol":"XBTUSD","id":8798381400,"side":"Buy","size":602}]}
09:22:25   {"table":"orderBookL2","action":"insert","data":[{"symbol":"XBTUSD","id":8798330500,"side":"Sell","size":200,"price":16695},{"symbol":"XBTUSD","id":8798335500,"side":"Sell","size":200,"price":16645},{"symbol":"XBTUSD","id":8798345500,"side":"Sell","size":200,"price":16545},{"symbol":"XBTUSD","id":8798368400,"side":"Buy","size":200,"price":16316},{"symbol":"XBTUSD","id":8798373400,"side":"Buy","size":200,"price":16266},{"symbol":"XBTUSD","id":8798383500,"side":"Buy","size":200,"price":16165}]}
09:22:25   {"table":"orderBookL2","action":"insert","data":[{"symbol":"XBTUSD","id":8798358600,"side":"Buy","size":50,"price":16414}]}
09:22:25   SubViewModel.XBTUSD_Main 异常：Could not create an instance of type BitMex.BitMexMsg.BitMexMsgBase. Type is an interface or abstract class and cannot be instantiated. Path 'table', line 1, position 9.
09:22:25   {"table":"orderBookL2","action":"update","data":[{"symbol":"XBTUSD","id":8798399900,"side":"Buy","size":1575}]}
09:22:25   {"table":"orderBookL2","action":"delete","data":[{"symbol":"XBTUSD","id":8798479100,"side":"Buy"}]}
09:22:25   {"table":"orderBookL2","action":"update","data":[{"symbol":"XBTUSD","id":8798354450,"side":"Sell","size":20778}]}
09:22:25   {"table":"orderBookL2","action":"update","data":[{"symbol":"XBTUSD","id":8798359950,"side":"Buy","size":38714}]}
09:22:25   {"table":"orderBookL2","action":"insert","data":[{"symbol":"XBTUSD","id":8798359000,"side":"Buy","size":100,"price":16410}]}
09:22:25   {"table":"orderBookL2","action":"insert","data":[{"symbol":"XBTUSD","id":8798356550,"side":"Sell","size":328,"price":16434.5}]}
09:22:25   {"table":"orderBookL2","action":"update","data":[{"symbol":"XBTUSD","id":8798359950,"side":"Buy","size":42214}]}
09:22:25   {"table":"orderBookL2","action":"delete","data":[{"symbol":"XBTUSD","id":8798307700,"side":"Sell"}]}
09:22:25   {"table":"orderBookL2","action":"insert","data":[{"symbol":"XBTUSD","id":8798305150,"side":"Sell","size":40,"price":16948.5}]}
09:22:25   {"table":"orderBookL2","action":"update","data":[{"symbol":"XBTUSD","id":8798361550,"side":"Buy","size":4100},{"symbol":"XBTUSD","id":8798363400,"side":"Buy","size":2300}]}
09:22:25   {"table":"orderBookL2","action":"delete","data":[{"symbol":"XBTUSD","id":8798339550,"side":"Sell"},{"symbol":"XBTUSD","id":8798342850,"side":"Sell"}]}
09:22:25   {"table":"orderBookL2","action":"update","data":[{"symbol":"XBTUSD","id":8798346150,"side":"Sell","size":500},{"symbol":"XBTUSD","id":8798349450,"side":"Sell","size":1310},{"symbol":"XBTUSD","id":8798352750,"side":"Sell","size":786}]}
09:22:25   {"table":"orderBookL2","action":"insert","data":[{"symbol":"XBTUSD","id":8798347800,"side":"Sell","size":1572,"price":16522},{"symbol":"XBTUSD","id":8798351100,"side":"Sell","size":1048,"price":16489},{"symbol":"XBTUSD","id":8798354400,"side":"Sell","size":524,"price":16456}]}
09:22:25   {"table":"orderBookL2","action":"insert","data":[{"symbol":"XBTUSD","id":8798359450,"side":"Buy","size":1000,"price":16405.5}]}
09:22:25   {"table":"orderBookL2","action":"insert","data":[{"symbol":"XBTUSD","id":8798362250,"side":"Buy","size":10000,"price":16377.5},{"symbol":"XBTUSD","id":8798362350,"side":"Buy","size":10000,"price":16376.5},{"symbol":"XBTUSD","id":8798362850,"side":"Buy","size":10000,"price":16371.5}]}
09:22:25   {"table":"orderBookL2","action":"insert","data":[{"symbol":"XBTUSD","id":8798355000,"side":"Sell","size":26551,"price":16450}]}
09:22:25   SubViewModel.XBTUSD_Main 异常：Could not create an instance of type BitMex.BitMexMsg.BitMexMsgBase. Type is an interface or abstract class and cannot be instantiated. Path 'table', line 1, position 9.
09:22:25   {"table":"orderBookL2","action":"update","data":[{"symbol":"XBTUSD","id":8798359950,"side":"Buy","size":44714}]}
09:22:25   {"table":"orderBookL2","action":"update","data":[{"symbol":"XBTUSD","id":8798359950,"side":"Buy","size":45114}]}
09:22:25   {"table":"orderBookL2","action":"delete","data":[{"symbol":"XBTUSD","id":8798305600,"side":"Sell"}]}
09:22:25   {"table":"orderBookL2","action":"insert","data":[{"symbol":"XBTUSD","id":8798310500,"side":"Sell","size":50,"price":16895}]}
09:22:25   {"table":"orderBookL2","action":"update","data":[{"symbol":"XBTUSD","id":8798359950,"side":"Buy","size":45364}]}
09:22:25   {"table":"orderBookL2","action":"update","data":[{"symbol":"XBTUSD","id":8798359650,"side":"Buy","size":2100}]}
09:22:25   SubViewModel.XBTUSD_Main 异常：Could not create an instance of type BitMex.BitMexMsg.BitMexMsgBase. Type is an interface or abstract class and cannot be instantiated. Path 'table', line 1, position 9.
09:22:25   {"table":"orderBookL2","action":"insert","data":[{"symbol":"XBTUSD","id":8798569550,"side":"Buy","size":200,"price":14304.5}]}
09:22:25   {"table":"orderBookL2","action":"delete","data":[{"symbol":"XBTUSD","id":8798352550,"side":"Sell"},{"symbol":"XBTUSD","id":8798353300,"side":"Sell"}]}
09:22:25   {"table":"orderBookL2","action":"insert","data":[{"symbol":"XBTUSD","id":8798359600,"side":"Buy","size":5000,"price":16404}]}
09:22:25   {"table":"orderBookL2","action":"update","data":[{"symbol":"XBTUSD","id":8798359950,"side":"Buy","size":45564}]}
09:22:25   SubViewModel.XBTUSD_Main 异常：Could not create an instance of type BitMex.BitMexMsg.BitMexMsgBase. Type is an interface or abstract class and cannot be instantiated. Path 'table', line 1, position 9.
09:22:25   {"table":"orderBookL2","action":"insert","data":[{"symbol":"XBTUSD","id":8798358950,"side":"Buy","size":2000,"price":16410.5}]}
09:22:25   {"table":"orderBookL2","action":"delete","data":[{"symbol":"XBTUSD","id":8798859700,"side":"Buy"}]}
09:22:25   {"table":"orderBookL2","action":"insert","data":[{"symbol":"XBTUSD","id":8798858950,"side":"Buy","size":1,"price":11410.5}]}
09:22:25   {"table":"orderBookL2","action":"update","data":[{"symbol":"XBTUSD","id":8798350800,"side":"Sell","size":57},{"symbol":"XBTUSD","id":8798350900,"side":"Sell","size":12093},{"symbol":"XBTUSD","id":8798367800,"side":"Buy","size":10000}]}
09:22:25   {"table":"orderBookL2","action":"insert","data":[{"symbol":"XBTUSD","id":8798368700,"side":"Buy","size":3118,"price":16313}]}
09:22:25   {"table":"orderBookL2","action":"delete","data":[{"symbol":"XBTUSD","id":8798353850,"side":"Sell"}]}
09:22:25   {"table":"orderBookL2","action":"insert","data":[{"symbol":"XBTUSD","id":8798352250,"side":"Sell","size":10000,"price":16477.5}]}
09:22:25   {"table":"orderBookL2","action":"insert","data":[{"symbol":"XBTUSD","id":8798357750,"side":"Buy","size":1,"price":16422.5}]}
09:22:25   SubViewModel.XBTUSD_Main 异常：Could not create an instance of type BitMex.BitMexMsg.BitMexMsgBase. Type is an interface or abstract class and cannot be instantiated. Path 'table', line 1, position 9.
09:22:25   {"table":"orderBookL2","action":"delete","data":[{"symbol":"XBTUSD","id":8798357700,"side":"Buy"},{"symbol":"XBTUSD","id":8798357750,"side":"Buy"},{"symbol":"XBTUSD","id":8798357800,"side":"Buy"},{"symbol":"XBTUSD","id":8798358600,"side":"Buy"},{"symbol":"XBTUSD","id":8798358750,"side":"Buy"},{"symbol":"XBTUSD","id":8798358950,"side":"Buy"},{"symbol":"XBTUSD","id":8798359000,"side":"Buy"},{"symbol":"XBTUSD","id":8798359450,"side":"Buy"},{"symbol":"XBTUSD","id":8798359600,"side":"Buy"},{"symbol":"XBTUSD","id":8798359650,"side":"Buy"}]}
09:22:25   {"table":"orderBookL2","action":"update","data":[{"symbol":"XBTUSD","id":8798359700,"side":"Buy","size":25606}]}
09:22:25   {"table":"orderBookL2","action":"insert","data":[{"symbol":"XBTUSD","id":8798355500,"side":"Sell","size":9245,"price":16445}]}
09:22:25   {"table":"orderBookL2","action":"insert","data":[{"symbol":"XBTUSD","id":8798355700,"side":"Sell","size":50,"price":16443}]}
09:22:25   SubViewModel.XBTUSD_Main 异常：Could not create an instance of type BitMex.BitMexMsg.BitMexMsgBase. Type is an interface or abstract class and cannot be instantiated. Path 'table', line 1, position 9.
09:22:25   {"table":"orderBookL2","action":"delete","data":[{"symbol":"XBTUSD","id":8798307100,"side":"Sell"}]}
09:22:25   {"table":"orderBookL2","action":"insert","data":[{"symbol":"XBTUSD","id":8798307500,"side":"Sell","size":40,"price":16925}]}
09:22:25   {"table":"orderBookL2","action":"delete","data":[{"symbol":"XBTUSD","id":8798346100,"side":"Sell"},{"symbol":"XBTUSD","id":8798407800,"side":"Buy"}]}
09:22:25   {"table":"orderBookL2","action":"update","data":[{"symbol":"XBTUSD","id":8798346200,"side":"Sell","size":262},{"symbol":"XBTUSD","id":8798346550,"side":"Sell","size":14470}]}
09:22:25   {"table":"orderBookL2","action":"insert","data":[{"symbol":"XBTUSD","id":8798346700,"side":"Sell","size":6920,"price":16533},{"symbol":"XBTUSD","id":8798409700,"side":"Buy","size":40,"price":15903}]}
09:22:25   SubViewModel.XBTUSD_Main 异常：Could not create an instance of type BitMex.BitMexMsg.BitMexMsgBase. Type is an interface or abstract class and cannot be instantiated. Path 'table', line 1, position 9.
09:22:25   {"table":"orderBookL2","action":"update","data":[{"symbol":"XBTUSD","id":8798352500,"side":"Sell","size":4424},{"symbol":"XBTUSD","id":8798353750,"side":"Sell","size":10050}]}
09:22:25   {"table":"orderBookL2","action":"delete","data":[{"symbol":"XBTUSD","id":8798345700,"side":"Sell"},{"symbol":"XBTUSD","id":8798349700,"side":"Sell"}]}
09:22:25   {"table":"orderBookL2","action":"update","data":[{"symbol":"XBTUSD","id":8798346350,"side":"Sell","size":9918},{"symbol":"XBTUSD","id":8798350250,"side":"Sell","size":7266},{"symbol":"XBTUSD","id":8798353200,"side":"Sell","size":9245}]}
09:22:25   {"table":"orderBookL2","action":"insert","data":[{"symbol":"XBTUSD","id":8798349650,"side":"Sell","size":64,"price":16503.5}]}
09:22:25   {"table":"orderBookL2","action":"delete","data":[{"symbol":"XBTUSD","id":8798352450,"side":"Sell"},{"symbol":"XBTUSD","id":8798370700,"side":"Buy"}]}
09:22:25   SubViewModel.XBTUSD_Main 异常：Could not create an instance of type BitMex.BitMexMsg.BitMexMsgBase. Type is an interface or abstract class and cannot be instantiated. Path 'table', line 1, position 9.
09:22:25   {"table":"orderBookL2","action":"update","data":[{"symbol":"XBTUSD","id":8798349950,"side":"Sell","size":814},{"symbol":"XBTUSD","id":8798368250,"side":"Buy","size":100},{"symbol":"XBTUSD","id":8798373950,"side":"Buy","size":300}]}
09:22:26   {"table":"orderBookL2","action":"insert","data":[{"symbol":"XBTUSD","id":8798365150,"side":"Buy","size":114,"price":16348.5}]}
09:22:26   {"table":"orderBookL2","action":"update","data":[{"symbol":"XBTUSD","id":8798354450,"side":"Sell","size":10778}]}
09:22:26   {"table":"orderBookL2","action":"insert","data":[{"symbol":"XBTUSD","id":8798354800,"side":"Sell","size":10000,"price":16452}]}
09:22:26   SubViewModel.XBTUSD_Main 异常：Could not create an instance of type BitMex.BitMexMsg.BitMexMsgBase. Type is an interface or abstract class and cannot be instantiated. Path 'table', line 1, position 9.
09:22:26   {"table":"orderBookL2","action":"insert","data":[{"symbol":"XBTUSD","id":8798360650,"side":"Buy","size":250,"price":16393.5}]}
09:22:26   {"table":"orderBookL2","action":"update","data":[{"symbol":"XBTUSD","id":8798359700,"side":"Buy","size":35606},{"symbol":"XBTUSD","id":8798361200,"side":"Buy","size":11000}]}
09:22:26   {"table":"orderBookL2","action":"insert","data":[{"symbol":"XBTUSD","id":8798361000,"side":"Buy","size":4968,"price":16390},{"symbol":"XBTUSD","id":8798362150,"side":"Buy","size":10000,"price":16378.5},{"symbol":"XBTUSD","id":8798363850,"side":"Buy","size":10000,"price":16361.5}]}
09:22:26   {"table":"orderBookL2","action":"insert","data":[{"symbol":"XBTUSD","id":8798359600,"side":"Buy","size":5000,"price":16404}]}
09:22:26   {"table":"orderBookL2","action":"delete","data":[{"symbol":"XBTUSD","id":8798306650,"side":"Sell"}]}
09:22:26   {"table":"orderBookL2","action":"insert","data":[{"symbol":"XBTUSD","id":8798307700,"side":"Sell","size":40,"price":16923}]}
09:22:26   SubViewModel.XBTUSD_Main 异常：Could not create an instance of type BitMex.BitMexMsg.BitMexMsgBase. Type is an interface or abstract class and cannot be instantiated. Path 'table', line 1, position 9.
09:22:26   {"table":"orderBookL2","action":"update","data":[{"symbol":"XBTUSD","id":8798359600,"side":"Buy","size":5200}]}
09:22:26   {"table":"orderBookL2","action":"insert","data":[{"symbol":"XBTUSD","id":8798356450,"side":"Sell","size":1992,"price":16435.5}]}
09:22:26   {"table":"orderBookL2","action":"delete","data":[{"symbol":"XBTUSD","id":8798359600,"side":"Buy"},{"symbol":"XBTUSD","id":8798359700,"side":"Buy"},{"symbol":"XBTUSD","id":8798359800,"side":"Buy"}]}
09:22:26   {"table":"orderBookL2","action":"update","data":[{"symbol":"XBTUSD","id":8798359900,"side":"Buy","size":21626}]}
09:22:26   SubViewModel.XBTUSD_Main 异常：Could not create an instance of type BitMex.BitMexMsg.BitMexMsgBase. Type is an interface or abstract class and cannot be instantiated. Path 'table', line 1, position 9.
09:22:26   {"table":"orderBookL2","action":"update","data":[{"symbol":"XBTUSD","id":8798338300,"side":"Sell","size":50},{"symbol":"XBTUSD","id":8798373650,"side":"Buy","size":43}]}
09:22:26   {"table":"orderBookL2","action":"insert","data":[{"symbol":"XBTUSD","id":8798345850,"side":"Sell","size":8000,"price":16541.5}]}
09:22:26   {"table":"orderBookL2","action":"insert","data":[{"symbol":"XBTUSD","id":8798366300,"side":"Buy","size":2800,"price":16337}]}
09:22:26   {"table":"orderBookL2","action":"delete","data":[{"symbol":"XBTUSD","id":8798368900,"side":"Buy"},{"symbol":"XBTUSD","id":8798370150,"side":"Buy"}]}
09:22:26   SubViewModel.XBTUSD_Main 异常：Could not create an instance of type BitMex.BitMexMsg.BitMexMsgBase. Type is an interface or abstract class and cannot be instantiated. Path 'table', line 1, position 9.
09:22:26   {"table":"orderBookL2","action":"update","data":[{"symbol":"XBTUSD","id":8798364950,"side":"Buy","size":460},{"symbol":"XBTUSD","id":8798369950,"side":"Buy","size":464},{"symbol":"XBTUSD","id":8798371800,"side":"Buy","size":3750}]}
09:22:26   {"table":"orderBookL2","action":"insert","data":[{"symbol":"XBTUSD","id":8798363150,"side":"Buy","size":90,"price":16368.5},{"symbol":"XBTUSD","id":8798366400,"side":"Buy","size":720,"price":16336}]}
09:22:26   {"table":"orderBookL2","action":"delete","data":[{"symbol":"XBTUSD","id":8798354050,"side":"Sell"},{"symbol":"XBTUSD","id":8798354100,"side":"Sell"},{"symbol":"XBTUSD","id":8798354300,"side":"Sell"},{"symbol":"XBTUSD","id":8798354400,"side":"Sell"},{"symbol":"XBTUSD","id":8798354450,"side":"Sell"},{"symbol":"XBTUSD","id":8798354800,"side":"Sell"},{"symbol":"XBTUSD","id":8798355000,"side":"Sell"},{"symbol":"XBTUSD","id":8798355500,"side":"Sell"},{"symbol":"XBTUSD","id":8798355700,"side":"Sell"},{"symbol":"XBTUSD","id":8798356450,"side":"Sell"},{"symbol":"XBTUSD","id":8798356550,"side":"Sell"},{"symbol":"XBTUSD","id":8798357250,"side":"Sell"}]}
09:22:26   {"table":"orderBookL2","action":"update","data":[{"symbol":"XBTUSD","id":8798354000,"side":"Sell","size":54507}]}
09:22:26   {"table":"orderBookL2","action":"update","data":[{"symbol":"XBTUSD","id":8798363850,"side":"Buy","size":10180},{"symbol":"XBTUSD","id":8798371050,"side":"Buy","size":1201}]}
09:22:26   {"table":"orderBookL2","action":"insert","data":[{"symbol":"XBTUSD","id":8798355650,"side":"Sell","size":1030,"price":16443.5},{"symbol":"XBTUSD","id":8798356500,"side":"Sell","size":1610,"price":16435},{"symbol":"XBTUSD","id":8798367950,"side":"Buy","size":300,"price":16320.5}]}
09:22:26   SubViewModel.XBTUSD_Main 异常：Could not create an instance of type BitMex.BitMexMsg.BitMexMsgBase. Type is an interface or abstract class and cannot be instantiated. Path 'table', line 1, position 9.
09:22:26   {"table":"orderBookL2","action":"update","data":[{"symbol":"XBTUSD","id":8798360650,"side":"Buy","size":1000}]}
09:22:26   {"table":"orderBookL2","action":"update","data":[{"symbol":"XBTUSD","id":8798330400,"side":"Sell","size":410}]}
09:22:26   {"table":"orderBookL2","action":"insert","data":[{"symbol":"XBTUSD","id":8798330450,"side":"Sell","size":200,"price":16695.5}]}
09:22:26   {"table":"orderBookL2","action":"update","data":[{"symbol":"XBTUSD","id":8798360650,"side":"Buy","size":2000}]}
09:22:26   {"table":"orderBookL2","action":"delete","data":[{"symbol":"XBTUSD","id":8798336650,"side":"Sell"},{"symbol":"XBTUSD","id":8798363250,"side":"Buy"},{"symbol":"XBTUSD","id":8798368150,"side":"Buy"},{"symbol":"XBTUSD","id":8798373000,"side":"Buy"},{"symbol":"XBTUSD","id":8798377900,"side":"Buy"},{"symbol":"XBTUSD","id":8798382750,"side":"Buy"},{"symbol":"XBTUSD","id":8798387600,"side":"Buy"}]}
09:22:26   SubViewModel.XBTUSD_Main 异常：Could not create an instance of type BitMex.BitMexMsg.BitMexMsgBase. Type is an interface or abstract class and cannot be instantiated. Path 'table', line 1, position 9.
09:22:26   {"table":"orderBookL2","action":"update","data":[{"symbol":"XBTUSD","id":8798331650,"side":"Sell","size":6250},{"symbol":"XBTUSD","id":8798341600,"side":"Sell","size":410},{"symbol":"XBTUSD","id":8798344650,"side":"Sell","size":356500},{"symbol":"XBTUSD","id":8798346550,"side":"Sell","size":6970},{"symbol":"XBTUSD","id":8798351500,"side":"Sell","size":1000},{"symbol":"XBTUSD","id":8798367500,"side":"Buy","size":5080},{"symbol":"XBTUSD","id":8798372400,"side":"Buy","size":7575},{"symbol":"XBTUSD","id":8798386950,"side":"Buy","size":15603}]}
09:22:26   {"table":"orderBookL2","action":"insert","data":[{"symbol":"XBTUSD","id":8798329700,"side":"Sell","size":15000,"price":16703},{"symbol":"XBTUSD","id":8798334700,"side":"Sell","size":12500,"price":16653},{"symbol":"XBTUSD","id":8798339700,"side":"Sell","size":10000,"price":16603},{"symbol":"XBTUSD","id":8798349600,"side":"Sell","size":5000,"price":16504},{"symbol":"XBTUSD","id":8798362600,"side":"Buy","size":2500,"price":16374},{"symbol":"XBTUSD","id":8798377250,"side":"Buy","size":10000,"price":16227.5},{"symbol":"XBTUSD","id":8798382100,"side":"Buy","size":12500,"price":16179}]}
09:22:26   SubViewModel.XBTUSD_Main 异常：Could not create an instance of type BitMex.BitMexMsg.BitMexMsgBase. Type is an interface or abstract class and cannot be instantiated. Path 'table', line 1, position 9.
09:22:26   {"table":"orderBookL2","action":"update","data":[{"symbol":"XBTUSD","id":8798305350,"side":"Sell","size":20810}]}
09:22:26   {"table":"orderBookL2","action":"insert","data":[{"symbol":"XBTUSD","id":8798308850,"side":"Sell","size":40,"price":16911.5}]}
09:22:26   {"table":"orderBookL2","action":"update","data":[{"symbol":"XBTUSD","id":8798200000,"side":"Sell","size":347073}]}
09:22:26   {"table":"orderBookL2","action":"insert","data":[{"symbol":"XBTUSD","id":8798354900,"side":"Sell","size":2000,"price":16451}]}
09:22:26   SubViewModel.XBTUSD_Main 异常：Could not create an instance of type BitMex.BitMexMsg.BitMexMsgBase. Type is an interface or abstract class and cannot be instantiated. Path 'table', line 1, position 9.
09:22:26   {"table":"orderBookL2","action":"update","data":[{"symbol":"XBTUSD","id":8798356500,"side":"Sell","size":1601}]}
09:22:26   {"table":"orderBookL2","action":"insert","data":[{"symbol":"XBTUSD","id":8798353300,"side":"Sell","size":2000,"price":16467}]}
09:22:26   {"table":"orderBookL2","action":"delete","data":[{"symbol":"XBTUSD","id":8798360450,"side":"Buy"}]}
09:22:26   {"table":"orderBookL2","action":"insert","data":[{"symbol":"XBTUSD","id":8798358700,"side":"Buy","size":10000,"price":16413}]}
09:22:26   SubViewModel.XBTUSD_Main 异常：Could not create an instance of type BitMex.BitMexMsg.BitMexMsgBase. Type is an interface or abstract class and cannot be instantiated. Path 'table', line 1, position 9.
09:22:26   {"table":"orderBookL2","action":"delete","data":[{"symbol":"XBTUSD","id":8798176400,"side":"Sell"},{"symbol":"XBTUSD","id":8798181400,"side":"Sell"},{"symbol":"XBTUSD","id":8798361650,"side":"Buy"},{"symbol":"XBTUSD","id":8798363650,"side":"Buy"},{"symbol":"XBTUSD","id":8798367650,"side":"Buy"},{"symbol":"XBTUSD","id":8798369650,"side":"Buy"},{"symbol":"XBTUSD","id":8798371650,"side":"Buy"},{"symbol":"XBTUSD","id":8798373650,"side":"Buy"},{"symbol":"XBTUSD","id":8798375650,"side":"Buy"},{"symbol":"XBTUSD","id":8798377650,"side":"Buy"},{"symbol":"XBTUSD","id":8798379650,"side":"Buy"},{"symbol":"XBTUSD","id":8798381650,"side":"Buy"},{"symbol":"XBTUSD","id":8798383650,"side":"Buy"},{"symbol":"XBTUSD","id":8798385650,"side":"Buy"},{"symbol":"XBTUSD","id":8798389650,"side":"Buy"},{"symbol":"XBTUSD","id":8798391650,"side":"Buy"},{"symbol":"XBTUSD","id":8798393650,"side":"Buy"},{"symbol":"XBTUSD","id":8798395650,"side":"Buy"},{"symbol":"XBTUSD","id":8798399650,"side":"Buy"},{"symbol":"XBTUSD","id":8798401650,"side":"Buy"},{"symbol":"XBTUSD","id":8798403650,"side":"Buy"},{"symbol":"XBTUSD","id":8798405650,"side":"Buy"},{"symbol":"XBTUSD","id":8798407650,"side":"Buy"},{"symbol":"XBTUSD","id":8798409650,"side":"Buy"},{"symbol":"XBTUSD","id":8798411650,"side":"Buy"},{"symbol":"XBTUSD","id":8798413650,"side":"Buy"},{"symbol":"XBTUSD","id":8798415650,"side":"Buy"},{"symbol":"XBTUSD","id":8798417650,"side":"Buy"},{"symbol":"XBTUSD","id":8798419650,"side":"Buy"},{"symbol":"XBTUSD","id":8798421650,"side":"Buy"},{"symbol":"XBTUSD","id":8798423650,"side":"Buy"},{"symbol":"XBTUSD","id":8798425650,"side":"Buy"},{"symbol":"XBTUSD","id":8798427650,"side":"Buy"},{"symbol":"XBTUSD","id":8798429650,"side":"Buy"},{"symbol":"XBTUSD","id":8798435650,"side":"Buy"},{"symbol":"XBTUSD","id":8798437650,"side":"Buy"},{"symbol":"XBTUSD","id":8798439650,"side":"Buy"},{"symbol":"XBTUSD","id":8798441650,"side":"Buy"},{"symbol":"XBTUSD","id":8798443650,"side":"Buy"},{"symbol":"XBTUSD","id":8798445650,"side":"Buy"},{"symbol":"XBTUSD","id":8798447650,"side":"Buy"},{"symbol":"XBTUSD","id":8798449650,"side":"Buy"},{"symbol":"XBTUSD","id":8798451650,"side":"Buy"},{"symbol":"XBTUSD","id":8798453650,"side":"Buy"},{"symbol":"XBTUSD","id":8798455650,"side":"Buy"}]}
09:22:26   {"table":"orderBookL2","action":"update","data":[{"symbol":"XBTUSD","id":8798365650,"side":"Buy","size":468},{"symbol":"XBTUSD","id":8798387650,"side":"Buy","size":602},{"symbol":"XBTUSD","id":8798397650,"side":"Buy","size":302},{"symbol":"XBTUSD","id":8798431650,"side":"Buy","size":5000},{"symbol":"XBTUSD","id":8798433650,"side":"Buy","size":942}]}
09:22:26   SubViewModel.XBTUSD_Main 异常：Could not create an instance of type BitMex.BitMexMsg.BitMexMsgBase. Type is an interface or abstract class and cannot be instantiated. Path 'table', line 1, position 9.
09:22:26   {"table":"orderBookL2","action":"update","data":[{"symbol":"XBTUSD","id":8798376400,"side":"Buy","size":375942}]}
09:22:26   {"table":"orderBookL2","action":"insert","data":[{"symbol":"XBTUSD","id":8798430250,"side":"Buy","size":1491000,"price":15697.5}]}
09:22:26   SubViewModel.XBTUSD_Main 异常：Could not create an instance of type BitMex.BitMexMsg.BitMexMsgBase. Type is an interface or abstract class and cannot be instantiated. Path 'table', line 1, position 9.
09:22:26   {"table":"orderBookL2","action":"delete","data":[{"symbol":"XBTUSD","id":8798343100,"side":"Sell"},{"symbol":"XBTUSD","id":8798351200,"side":"Sell"}]}
09:22:26   {"table":"orderBookL2","action":"update","data":[{"symbol":"XBTUSD","id":8798336400,"side":"Sell","size":140},{"symbol":"XBTUSD","id":8798339800,"side":"Sell","size":500},{"symbol":"XBTUSD","id":8798343600,"side":"Sell","size":252},{"symbol":"XBTUSD","id":8798347000,"side":"Sell","size":10848},{"symbol":"XBTUSD","id":8798348400,"side":"Sell","size":388314},{"symbol":"XBTUSD","id":8798371400,"side":"Buy","size":603}]}
09:22:26   {"table":"orderBookL2","action":"insert","data":[{"symbol":"XBTUSD","id":8798340300,"side":"Sell","size":180,"price":16597},{"symbol":"XBTUSD","id":8798350400,"side":"Sell","size":100,"price":16496},{"symbol":"XBTUSD","id":8798353800,"side":"Sell","size":73,"price":16462},{"symbol":"XBTUSD","id":8798357100,"side":"Sell","size":46,"price":16429},{"symbol":"XBTUSD","id":8798375200,"side":"Buy","size":46,"price":16248}]}
09:22:26   {"table":"orderBookL2","action":"insert","data":[{"symbol":"XBTUSD","id":8798355250,"side":"Sell","size":150000,"price":16447.5}]}
09:22:26   {"table":"orderBookL2","action":"delete","data":[{"symbol":"XBTUSD","id":8798358700,"side":"Buy"}]}
09:22:26   {"table":"orderBookL2","action":"update","data":[{"symbol":"XBTUSD","id":8798359900,"side":"Buy","size":11626}]}
09:22:26   SubViewModel.XBTUSD_Main 异常：Could not create an instance of type BitMex.BitMexMsg.BitMexMsgBase. Type is an interface or abstract class and cannot be instantiated. Path 'table', line 1, position 9.
09:22:26   {"table":"orderBookL2","action":"insert","data":[{"symbol":"XBTUSD","id":8798359750,"side":"Buy","size":200,"price":16402.5}]}
09:22:26   {"table":"orderBookL2","action":"insert","data":[{"symbol":"XBTUSD","id":8798357250,"side":"Sell","size":40,"price":16427.5}]}
09:22:26   SubViewModel.XBTUSD_Main 异常：Could not create an instance of type BitMex.BitMexMsg.BitMexMsgBase. Type is an interface or abstract class and cannot be instantiated. Path 'table', line 1, position 9.
09:22:26   {"table":"orderBookL2","action":"update","data":[{"symbol":"XBTUSD","id":8798300000,"side":"Sell","size":455286}]}
09:22:26   {"table":"orderBookL2","action":"update","data":[{"symbol":"XBTUSD","id":8798361250,"side":"Buy","size":93},{"symbol":"XBTUSD","id":8798365250,"side":"Buy","size":378236},{"symbol":"XBTUSD","id":8798369250,"side":"Buy","size":293},{"symbol":"XBTUSD","id":8798371250,"side":"Buy","size":646},{"symbol":"XBTUSD","id":8798377250,"side":"Buy","size":10043},{"symbol":"XBTUSD","id":8798381250,"side":"Buy","size":644},{"symbol":"XBTUSD","id":8798387250,"side":"Buy","size":1043},{"symbol":"XBTUSD","id":8798389250,"side":"Buy","size":644},{"symbol":"XBTUSD","id":8798407250,"side":"Buy","size":1645},{"symbol":"XBTUSD","id":8798421250,"side":"Buy","size":1274243},{"symbol":"XBTUSD","id":8798427250,"side":"Buy","size":3643},{"symbol":"XBTUSD","id":8798435250,"side":"Buy","size":1843},{"symbol":"XBTUSD","id":8798441250,"side":"Buy","size":443}]}
09:22:26   {"table":"orderBookL2","action":"insert","data":[{"symbol":"XBTUSD","id":8798176400,"side":"Sell","size":47890,"price":18236},{"symbol":"XBTUSD","id":8798181400,"side":"Sell","size":47891,"price":18186},{"symbol":"XBTUSD","id":8798359250,"side":"Buy","size":43,"price":16407.5},{"symbol":"XBTUSD","id":8798363250,"side":"Buy","size":43,"price":16367.5},{"symbol":"XBTUSD","id":8798367250,"side":"Buy","size":43,"price":16327.5},{"symbol":"XBTUSD","id":8798373250,"side":"Buy","size":43,"price":16267.5},{"symbol":"XBTUSD","id":8798375250,"side":"Buy","size":43,"price":16247.5},{"symbol":"XBTUSD","id":8798379250,"side":"Buy","size":43,"price":16207.5},{"symbol":"XBTUSD","id":8798383250,"side":"Buy","size":43,"price":16167.5},{"symbol":"XBTUSD","id":8798385250,"side":"Buy","size":43,"price":16147.5},{"symbol":"XBTUSD","id":8798391250,"side":"Buy","size":43,"price":16087.5},{"symbol":"XBTUSD","id":8798393250,"side":"Buy","size":43,"price":16067.5},{"symbol":"XBTUSD","id":8798395250,"side":"Buy","size":43,"price":16047.5},{"symbol":"XBTUSD","id":8798397250,"side":"Buy","size":43,"price":16027.5},{"symbol":"XBTUSD","id":8798399250,"side":"Buy","size":43,"price":16007.5},{"symbol":"XBTUSD","id":8798401250,"side":"Buy","size":43,"price":15987.5},{"symbol":"XBTUSD","id":8798403250,"side":"Buy","size":43,"price":15967.5},{"symbol":"XBTUSD","id":8798405250,"side":"Buy","size":43,"price":15947.5},{"symbol":"XBTUSD","id":8798409250,"side":"Buy","size":43,"price":15907.5},{"symbol":"XBTUSD","id":8798411250,"side":"Buy","size":43,"price":15887.5},{"symbol":"XBTUSD","id":8798413250,"side":"Buy","size":43,"price":15867.5},{"symbol":"XBTUSD","id":8798415250,"side":"Buy","size":43,"price":15847.5},{"symbol":"XBTUSD","id":8798417250,"side":"Buy","size":43,"price":15827.5},{"symbol":"XBTUSD","id":8798419250,"side":"Buy","size":43,"price":15807.5},{"symbol":"XBTUSD","id":8798423250,"side":"Buy","size":43,"price":15767.5},{"symbol":"XBTUSD","id":8798425250,"side":"Buy","size":43,"price":15747.5},{"symbol":"XBTUSD","id":8798429250,"side":"Buy","size":43,"price":15707.5},{"symbol":"XBTUSD","id":8798431250,"side":"Buy","size":43,"price":15687.5},{"symbol":"XBTUSD","id":8798433250,"side":"Buy","size":43,"price":15667.5},{"symbol":"XBTUSD","id":8798437250,"side":"Buy","size":43,"price":15627.5},{"symbol":"XBTUSD","id":8798439250,"side":"Buy","size":43,"price":15607.5},{"symbol":"XBTUSD","id":8798443250,"side":"Buy","size":43,"price":15567.5},{"symbol":"XBTUSD","id":8798445250,"side":"Buy","size":43,"price":15547.5},{"symbol":"XBTUSD","id":8798447250,"side":"Buy","size":43,"price":15527.5},{"symbol":"XBTUSD","id":8798449250,"side":"Buy","size":43,"price":15507.5},{"symbol":"XBTUSD","id":8798451250,"side":"Buy","size":43,"price":15487.5},{"symbol":"XBTUSD","id":8798453250,"side":"Buy","size":43,"price":15467.5},{"symbol":"XBTUSD","id":8798455250,"side":"Buy","size":43,"price":15447.5}]}
09:22:26   SubViewModel.XBTUSD_Main 异常：Could not create an instance of type BitMex.BitMexMsg.BitMexMsgBase. Type is an interface or abstract class and cannot be instantiated. Path 'table', line 1, position 9.
09:22:26   {"table":"orderBookL2","action":"insert","data":[{"symbol":"XBTUSD","id":8798358600,"side":"Buy","size":50,"price":16414}]}
09:22:26   {"table":"orderBookL2","action":"update","data":[{"symbol":"XBTUSD","id":8798352350,"side":"Sell","size":200}]}
09:22:26   {"table":"orderBookL2","action":"insert","data":[{"symbol":"XBTUSD","id":8798352700,"side":"Sell","size":3776,"price":16473}]}
09:22:26   {"table":"orderBookL2","action":"update","data":[{"symbol":"XBTUSD","id":8798357250,"side":"Sell","size":39}]}
09:22:26   {"table":"orderBookL2","action":"delete","data":[{"symbol":"XBTUSD","id":8798386000,"side":"Buy"}]}
09:22:26   {"table":"orderBookL2","action":"delete","data":[{"symbol":"XBTUSD","id":8798358600,"side":"Buy"},{"symbol":"XBTUSD","id":8798359250,"side":"Buy"}]}
09:22:26   SubViewModel.XBTUSD_Main 异常：Could not create an instance of type BitMex.BitMexMsg.BitMexMsgBase. Type is an interface or abstract class and cannot be instantiated. Path 'table', line 1, position 9.
09:22:26   {"table":"orderBookL2","action":"update","data":[{"symbol":"XBTUSD","id":8798359750,"side":"Buy","size":193}]}
09:22:26   {"table":"orderBookL2","action":"insert","data":[{"symbol":"XBTUSD","id":8798355700,"side":"Sell","size":50,"price":16443}]}
09:22:26   {"table":"orderBookL2","action":"delete","data":[{"symbol":"XBTUSD","id":8798359750,"side":"Buy"}]}
09:22:26   {"table":"orderBookL2","action":"update","data":[{"symbol":"XBTUSD","id":8798359900,"side":"Buy","size":11119}]}
09:22:26   {"table":"orderBookL2","action":"insert","data":[{"symbol":"XBTUSD","id":8798355000,"side":"Sell","size":10000,"price":16450}]}
09:22:26   {"table":"orderBookL2","action":"update","data":[{"symbol":"XBTUSD","id":8798359900,"side":"Buy","size":6119}]}
09:22:26   {"table":"orderBookL2","action":"update","data":[{"symbol":"XBTUSD","id":8798357250,"side":"Sell","size":30}]}
09:22:26   {"table":"orderBookL2","action":"insert","data":[{"symbol":"XBTUSD","id":8798357300,"side":"Buy","size":80000,"price":16427}]}
09:22:26   SubViewModel.XBTUSD_Main 异常：Could not create an instance of type BitMex.BitMexMsg.BitMexMsgBase. Type is an interface or abstract class and cannot be instantiated. Path 'table', line 1, position 9.
09:22:26   {"table":"orderBookL2","action":"insert","data":[{"symbol":"XBTUSD","id":8798356000,"side":"Sell","size":400,"price":16440}]}
09:22:26   {"table":"orderBookL2","action":"delete","data":[{"symbol":"XBTUSD","id":8798357100,"side":"Sell"},{"symbol":"XBTUSD","id":8798357250,"side":"Sell"}]}
09:22:26   {"table":"orderBookL2","action":"update","data":[{"symbol":"XBTUSD","id":8798356500,"side":"Sell","size":1237}]}
09:22:26   {"table":"orderBookL2","action":"delete","data":[{"symbol":"XBTUSD","id":8798360350,"side":"Buy"}]}
09:22:26   {"table":"orderBookL2","action":"insert","data":[{"symbol":"XBTUSD","id":8798386600,"side":"Buy","size":50000,"price":16134}]}
09:22:26   SubViewModel.XBTUSD_Main 异常：Could not create an instance of type BitMex.BitMexMsg.BitMexMsgBase. Type is an interface or abstract class and cannot be instantiated. Path 'table', line 1, position 9.
09:22:26   {"table":"orderBookL2","action":"insert","data":[{"symbol":"XBTUSD","id":8798356050,"side":"Sell","size":262,"price":16439.5}]}
09:22:26   {"table":"orderBookL2","action":"insert","data":[{"symbol":"XBTUSD","id":8798359650,"side":"Buy","size":10000,"price":16403.5}]}
09:22:26   {"table":"orderBookL2","action":"update","data":[{"symbol":"XBTUSD","id":8798342900,"side":"Sell","size":325415}]}
09:22:26   {"table":"orderBookL2","action":"update","data":[{"symbol":"XBTUSD","id":8798357300,"side":"Buy","size":124868}]}
09:22:26   {"table":"orderBookL2","action":"update","data":[{"symbol":"XBTUSD","id":8798348400,"side":"Sell","size":595425}]}
09:22:26   {"table":"orderBookL2","action":"update","data":[{"symbol":"XBTUSD","id":8798355000,"side":"Sell","size":11000}]}
09:22:26   SubViewModel.XBTUSD_Main 异常：Could not create an instance of type BitMex.BitMexMsg.BitMexMsgBase. Type is an interface or abstract class and cannot be instantiated. Path 'table', line 1, position 9.
09:22:26   {"table":"orderBookL2","action":"delete","data":[{"symbol":"XBTUSD","id":8798350800,"side":"Sell"}]}
09:22:26   {"table":"orderBookL2","action":"update","data":[{"symbol":"XBTUSD","id":8798343600,"side":"Sell","size":153},{"symbol":"XBTUSD","id":8798346200,"side":"Sell","size":361},{"symbol":"XBTUSD","id":8798347200,"side":"Sell","size":312},{"symbol":"XBTUSD","id":8798353300,"side":"Sell","size":2057}]}
09:22:26   {"table":"orderBookL2","action":"insert","data":[{"symbol":"XBTUSD","id":8798349700,"side":"Sell","size":78,"price":16503},{"symbol":"XBTUSD","id":8798356900,"side":"Sell","size":36,"price":16431}]}
09:22:26   {"table":"orderBookL2","action":"update","data":[{"symbol":"XBTUSD","id":8798364650,"side":"Buy","size":1250},{"symbol":"XBTUSD","id":8798365250,"side":"Buy","size":375043}]}
09:22:27   {"table":"orderBookL2","action":"delete","data":[{"symbol":"XBTUSD","id":8798356900,"side":"Sell"}]}
09:22:27   {"table":"orderBookL2","action":"update","data":[{"symbol":"XBTUSD","id":8798356500,"side":"Sell","size":773}]}
09:22:27   {"table":"orderBookL2","action":"update","data":[{"symbol":"XBTUSD","id":8798353750,"side":"Sell","size":50},{"symbol":"XBTUSD","id":8798353900,"side":"Sell","size":100}]}
09:22:27   {"table":"orderBookL2","action":"update","data":[{"symbol":"XBTUSD","id":8798309800,"side":"Sell","size":8},{"symbol":"XBTUSD","id":8798409800,"side":"Buy","size":300}]}
09:22:27   SubViewModel.XBTUSD_Main 异常：Could not create an instance of type BitMex.BitMexMsg.BitMexMsgBase. Type is an interface or abstract class and cannot be instantiated. Path 'table', line 1, position 9.
09:22:27   {"table":"orderBookL2","action":"insert","data":[{"symbol":"XBTUSD","id":8798308050,"side":"Sell","size":20,"price":16919.5},{"symbol":"XBTUSD","id":8798408050,"side":"Buy","size":20,"price":15919.5}]}
09:22:27   {"table":"orderBookL2","action":"delete","data":[{"symbol":"XBTUSD","id":8798307300,"side":"Sell"}]}
09:22:27   {"table":"orderBookL2","action":"insert","data":[{"symbol":"XBTUSD","id":8798307900,"side":"Sell","size":40,"price":16921}]}
09:22:27   {"table":"orderBookL2","action":"update","data":[{"symbol":"XBTUSD","id":8798340000,"side":"Sell","size":4538}]}
09:22:27   {"table":"orderBookL2","action":"delete","data":[{"symbol":"XBTUSD","id":8798366300,"side":"Buy"}]}
09:22:27   {"table":"orderBookL2","action":"insert","data":[{"symbol":"XBTUSD","id":8798357250,"side":"Sell","size":3000,"price":16427.5}]}
09:22:27   {"table":"orderBookL2","action":"delete","data":[{"symbol":"XBTUSD","id":8798409950,"side":"Buy"}]}
09:22:27   {"table":"orderBookL2","action":"insert","data":[{"symbol":"XBTUSD","id":8798405600,"side":"Buy","size":40,"price":15944}]}
09:22:27   SubViewModel.XBTUSD_Main 异常：Could not create an instance of type BitMex.BitMexMsg.BitMexMsgBase. Type is an interface or abstract class and cannot be instantiated. Path 'table', line 1, position 9.
09:22:27   {"table":"orderBookL2","action":"delete","data":[{"symbol":"XBTUSD","id":8798362250,"side":"Buy"},{"symbol":"XBTUSD","id":8798362350,"side":"Buy"},{"symbol":"XBTUSD","id":8798362850,"side":"Buy"}]}
09:22:27   {"table":"orderBookL2","action":"update","data":[{"symbol":"XBTUSD","id":8798360500,"side":"Buy","size":16981},{"symbol":"XBTUSD","id":8798360550,"side":"Buy","size":14600}]}
09:22:27   {"table":"orderBookL2","action":"insert","data":[{"symbol":"XBTUSD","id":8798361050,"side":"Buy","size":10000,"price":16389.5}]}
09:22:27   {"table":"orderBookL2","action":"delete","data":[{"symbol":"XBTUSD","id":8798345850,"side":"Sell"}]}
09:22:27   {"table":"orderBookL2","action":"update","data":[{"symbol":"XBTUSD","id":8798357300,"side":"Buy","size":124608}]}
09:22:27   SubViewModel.XBTUSD_Main 异常：Could not create an instance of type BitMex.BitMexMsg.BitMexMsgBase. Type is an interface or abstract class and cannot be instantiated. Path 'table', line 1, position 9.
09:22:27   {"table":"orderBookL2","action":"insert","data":[{"symbol":"XBTUSD","id":8798357800,"side":"Buy","size":9245,"price":16422}]}
09:22:27   {"table":"orderBookL2","action":"insert","data":[{"symbol":"XBTUSD","id":8798358850,"side":"Buy","size":2715,"price":16411.5}]}
09:22:27   {"table":"orderBookL2","action":"delete","data":[{"symbol":"XBTUSD","id":8798363150,"side":"Buy"},{"symbol":"XBTUSD","id":8798366400,"side":"Buy"},{"symbol":"XBTUSD","id":8798369950,"side":"Buy"}]}
09:22:27   SubViewModel.XBTUSD_Main 异常：Could not create an instance of type BitMex.BitMexMsg.BitMexMsgBase. Type is an interface or abstract class and cannot be instantiated. Path 'table', line 1, position 9.
09:22:27   {"table":"orderBookL2","action":"update","data":[{"symbol":"XBTUSD","id":8798364950,"side":"Buy","size":100},{"symbol":"XBTUSD","id":8798367400,"side":"Buy","size":779}]}
09:22:27   {"table":"orderBookL2","action":"insert","data":[{"symbol":"XBTUSD","id":8798363200,"side":"Buy","size":88,"price":16368},{"symbol":"XBTUSD","id":8798364450,"side":"Buy","size":176,"price":16355.5},{"symbol":"XBTUSD","id":8798368900,"side":"Buy","size":1408,"price":16311}]}
09:22:27   SubViewModel.XBTUSD_Main 异常：Could not create an instance of type BitMex.BitMexMsg.BitMexMsgBase. Type is an interface or abstract class and cannot be instantiated. Path 'table', line 1, position 9.
09:22:27   {"table":"orderBookL2","action":"insert","data":[{"symbol":"XBTUSD","id":8798354450,"side":"Sell","size":10000,"price":16455.5}]}
09:22:27   {"table":"orderBookL2","action":"insert","data":[{"symbol":"XBTUSD","id":8798359600,"side":"Buy","size":500,"price":16404}]}
09:22:27   {"table":"orderBookL2","action":"insert","data":[{"symbol":"XBTUSD","id":8798359850,"side":"Buy","size":10000,"price":16401.5}]}
09:22:27   {"table":"orderBookL2","action":"update","data":[{"symbol":"XBTUSD","id":8798361550,"side":"Buy","size":2100}]}
09:22:27   SubViewModel.XBTUSD_Main 异常：Could not create an instance of type BitMex.BitMexMsg.BitMexMsgBase. Type is an interface or abstract class and cannot be instantiated. Path 'table', line 1, position 9.
09:22:27   {"table":"orderBookL2","action":"insert","data":[{"symbol":"XBTUSD","id":8798362200,"side":"Buy","size":2000,"price":16378}]}
09:22:27   {"table":"orderBookL2","action":"delete","data":[{"symbol":"XBTUSD","id":8798344700,"side":"Sell"}]}
09:22:27   {"table":"orderBookL2","action":"delete","data":[{"symbol":"XBTUSD","id":8798346550,"side":"Sell"}]}
09:22:27   {"table":"orderBookL2","action":"insert","data":[{"symbol":"XBTUSD","id":8798347450,"side":"Sell","size":6970,"price":16525.5}]}
09:22:27   SubViewModel.XBTUSD_Main 异常：Could not create an instance of type BitMex.BitMexMsg.BitMexMsgBase. Type is an interface or abstract class and cannot be instantiated. Path 'table', line 1, position 9.
09:22:27   {"table":"orderBookL2","action":"delete","data":[{"symbol":"XBTUSD","id":8798349650,"side":"Sell"},{"symbol":"XBTUSD","id":8798365150,"side":"Buy"}]}
09:22:27   {"table":"orderBookL2","action":"update","data":[{"symbol":"XBTUSD","id":8798346350,"side":"Sell","size":9904},{"symbol":"XBTUSD","id":8798349950,"side":"Sell","size":750},{"symbol":"XBTUSD","id":8798350250,"side":"Sell","size":7202},{"symbol":"XBTUSD","id":8798368250,"side":"Buy","size":50},{"symbol":"XBTUSD","id":8798371250,"side":"Buy","size":760},{"symbol":"XBTUSD","id":8798374900,"side":"Buy","size":125}]}
09:22:27   {"table":"orderBookL2","action":"insert","data":[{"symbol":"XBTUSD","id":8798344950,"side":"Sell","size":14,"price":16550.5},{"symbol":"XBTUSD","id":8798350850,"side":"Sell","size":64,"price":16491.5},{"symbol":"XBTUSD","id":8798352950,"side":"Sell","size":64,"price":16470.5},{"symbol":"XBTUSD","id":8798353400,"side":"Sell","size":64,"price":16466}]}
09:22:27   {"table":"orderBookL2","action":"update","data":[{"symbol":"XBTUSD","id":8798357300,"side":"Buy","size":121108}]}
09:22:27   {"table":"orderBookL2","action":"insert","data":[{"symbol":"XBTUSD","id":8798354550,"side":"Sell","size":2500,"price":16454.5}]}
09:22:27   {"table":"orderBookL2","action":"update","data":[{"symbol":"XBTUSD","id":8798359850,"side":"Buy","size":30000}]}
09:22:28   {"table":"orderBookL2","action":"update","data":[{"symbol":"XBTUSD","id":8798370550,"side":"Buy","size":3270}]}
09:22:28   SubViewModel.XBTUSD_Main 异常：Could not create an instance of type BitMex.BitMexMsg.BitMexMsgBase. Type is an interface or abstract class and cannot be instantiated. Path 'table', line 1, position 9.
09:22:28   {"table":"orderBookL2","action":"insert","data":[{"symbol":"XBTUSD","id":8798354500,"side":"Sell","size":3468,"price":16455},{"symbol":"XBTUSD","id":8798365950,"side":"Buy","size":352,"price":16340.5},{"symbol":"XBTUSD","id":8798372250,"side":"Buy","size":464,"price":16277.5},{"symbol":"XBTUSD","id":8798373850,"side":"Buy","size":600,"price":16261.5}]}
09:22:28   {"table":"orderBookL2","action":"delete","data":[{"symbol":"XBTUSD","id":8798858950,"side":"Buy"}]}
09:22:28   {"table":"orderBookL2","action":"insert","data":[{"symbol":"XBTUSD","id":8798857700,"side":"Buy","size":1,"price":11423}]}
09:22:28   {"table":"orderBookL2","action":"update","data":[{"symbol":"XBTUSD","id":8798359850,"side":"Buy","size":40000}]}
09:22:28   {"table":"orderBookL2","action":"update","data":[{"symbol":"XBTUSD","id":8798357250,"side":"Sell","size":4000}]}
09:22:28   SubViewModel.XBTUSD_Main 异常：Could not create an instance of type BitMex.BitMexMsg.BitMexMsgBase. Type is an interface or abstract class and cannot be instantiated. Path 'table', line 1, position 9.
09:22:28   {"table":"orderBookL2","action":"update","data":[{"symbol":"XBTUSD","id":8798357250,"side":"Sell","size":4500}]}
09:22:28   {"table":"orderBookL2","action":"update","data":[{"symbol":"XBTUSD","id":8798356500,"side":"Sell","size":3026}]}
09:22:28   {"table":"orderBookL2","action":"update","data":[{"symbol":"XBTUSD","id":8798352400,"side":"Sell","size":4940}]}
09:22:28   {"table":"orderBookL2","action":"delete","data":[{"symbol":"XBTUSD","id":8798368700,"side":"Buy"}]}
09:22:28   {"table":"orderBookL2","action":"update","data":[{"symbol":"XBTUSD","id":8798350900,"side":"Sell","size":9495},{"symbol":"XBTUSD","id":8798367100,"side":"Buy","size":368176}]}
09:22:28   {"table":"orderBookL2","action":"insert","data":[{"symbol":"XBTUSD","id":8798352300,"side":"Sell","size":2598,"price":16477}]}
09:22:28   SubViewModel.XBTUSD_Main 异常：Could not create an instance of type BitMex.BitMexMsg.BitMexMsgBase. Type is an interface or abstract class and cannot be instantiated. Path 'table', line 1, position 9.
09:22:28   {"table":"orderBookL2","action":"update","data":[{"symbol":"XBTUSD","id":8798357250,"side":"Sell","size":2500}]}
09:22:28   {"table":"orderBookL2","action":"update","data":[{"symbol":"XBTUSD","id":8798360000,"side":"Buy","size":41760}]}
09:22:28   SubViewModel.XBTUSD_Main 异常：Could not create an instance of type BitMex.BitMexMsg.BitMexMsgBase. Type is an interface or abstract class and cannot be instantiated. Path 'table', line 1, position 9.
09:22:28   {"table":"orderBookL2","action":"update","data":[{"symbol":"XBTUSD","id":8798352350,"side":"Sell","size":3976},{"symbol":"XBTUSD","id":8798352500,"side":"Sell","size":648}]}
09:22:28   {"table":"orderBookL2","action":"delete","data":[{"symbol":"XBTUSD","id":8798428150,"side":"Buy"}]}
09:22:28   {"table":"orderBookL2","action":"update","data":[{"symbol":"XBTUSD","id":8798439550,"side":"Buy","size":201800}]}
09:22:28   {"table":"orderBookL2","action":"delete","data":[{"symbol":"XBTUSD","id":8798353150,"side":"Sell"}]}
09:22:28   {"table":"orderBookL2","action":"insert","data":[{"symbol":"XBTUSD","id":8798353550,"side":"Sell","size":10000,"price":16464.5}]}
09:22:28   {"table":"orderBookL2","action":"update","data":[{"symbol":"XBTUSD","id":8798357250,"side":"Sell","size":2400}]}
09:22:28   {"table":"orderBookL2","action":"update","data":[{"symbol":"XBTUSD","id":8798346300,"side":"Sell","size":9710}]}
09:22:28   SubViewModel.XBTUSD_Main 异常：Could not create an instance of type BitMex.BitMexMsg.BitMexMsgBase. Type is an interface or abstract class and cannot be instantiated. Path 'table', line 1, position 9.
09:22:28   {"table":"orderBookL2","action":"delete","data":[{"symbol":"XBTUSD","id":8798357250,"side":"Sell"}]}
09:22:28   {"table":"orderBookL2","action":"insert","data":[{"symbol":"XBTUSD","id":8798357250,"side":"Buy","size":2600,"price":16427.5}]}
09:22:28   {"table":"orderBookL2","action":"insert","data":[{"symbol":"XBTUSD","id":8798354800,"side":"Sell","size":10000,"price":16452}]}
09:22:28   {"table":"orderBookL2","action":"delete","data":[{"symbol":"XBTUSD","id":8798346700,"side":"Sell"}]}
09:22:28   {"table":"orderBookL2","action":"insert","data":[{"symbol":"XBTUSD","id":8798345450,"side":"Sell","size":6920,"price":16545.5}]}
09:22:28   SubViewModel.XBTUSD_Main 异常：Could not create an instance of type BitMex.BitMexMsg.BitMexMsgBase. Type is an interface or abstract class and cannot be instantiated. Path 'table', line 1, position 9.
09:22:28   {"table":"orderBookL2","action":"update","data":[{"symbol":"XBTUSD","id":8798321450,"side":"Sell","size":1453000}]}
09:22:28   {"table":"orderBookL2","action":"insert","data":[{"symbol":"XBTUSD","id":8798321750,"side":"Sell","size":60,"price":16782.5}]}
09:22:28   {"table":"orderBookL2","action":"delete","data":[{"symbol":"XBTUSD","id":8798366950,"side":"Buy"}]}
09:22:28   SubViewModel.XBTUSD_Main 异常：Could not create an instance of type BitMex.BitMexMsg.BitMexMsgBase. Type is an interface or abstract class and cannot be instantiated. Path 'table', line 1, position 9.
09:22:28   {"table":"orderBookL2","action":"update","data":[{"symbol":"XBTUSD","id":8798344800,"side":"Sell","size":394}]}
09:22:28   {"table":"orderBookL2","action":"insert","data":[{"symbol":"XBTUSD","id":8798342850,"side":"Sell","size":166518,"price":16571.5},{"symbol":"XBTUSD","id":8798365150,"side":"Buy","size":169990,"price":16348.5}]}
09:22:28   {"table":"orderBookL2","action":"update","data":[{"symbol":"XBTUSD","id":8798357250,"side":"Buy","size":2350}]}
09:22:28   {"table":"orderBookL2","action":"insert","data":[{"symbol":"XBTUSD","id":8798362500,"side":"Buy","size":2000,"price":16375}]}
09:22:28   SubViewModel.XBTUSD_Main 异常：Could not create an instance of type BitMex.BitMexMsg.BitMexMsgBase. Type is an interface or abstract class and cannot be instantiated. Path 'table', line 1, position 9.
09:22:28   {"table":"orderBookL2","action":"update","data":[{"symbol":"XBTUSD","id":8798290000,"side":"Sell","size":20360}]}
09:22:28   {"table":"orderBookL2","action":"delete","data":[{"symbol":"XBTUSD","id":8798357250,"side":"Buy"}]}
09:22:28   {"table":"orderBookL2","action":"update","data":[{"symbol":"XBTUSD","id":8798357300,"side":"Buy","size":23458}]}
09:22:28   {"table":"orderBookL2","action":"delete","data":[{"symbol":"XBTUSD","id":8798331650,"side":"Sell"},{"symbol":"XBTUSD","id":8798340750,"side":"Sell"},{"symbol":"XBTUSD","id":8798347050,"side":"Sell"},{"symbol":"XBTUSD","id":8798351400,"side":"Sell"}]}
09:22:28   {"table":"orderBookL2","action":"update","data":[{"symbol":"XBTUSD","id":8798329700,"side":"Sell","size":21250},{"symbol":"XBTUSD","id":8798338800,"side":"Sell","size":5200}]}
09:22:28   {"table":"orderBookL2","action":"insert","data":[{"symbol":"XBTUSD","id":8798345150,"side":"Sell","size":3750,"price":16548.5},{"symbol":"XBTUSD","id":8798349500,"side":"Sell","size":2500,"price":16505}]}
09:22:28   SubViewModel.XBTUSD_Main 异常：Could not create an instance of type BitMex.BitMexMsg.BitMexMsgBase. Type is an interface or abstract class and cannot be instantiated. Path 'table', line 1, position 9.
09:22:28   {"table":"orderBookL2","action":"update","data":[{"symbol":"XBTUSD","id":8798376100,"side":"Buy","size":603}]}
09:22:28   {"table":"orderBookL2","action":"update","data":[{"symbol":"XBTUSD","id":8798362500,"side":"Buy","size":5776}]}
09:22:28   {"table":"orderBookL2","action":"insert","data":[{"symbol":"XBTUSD","id":8798358600,"side":"Buy","size":50,"price":16414}]}
09:22:28   {"table":"orderBookL2","action":"update","data":[{"symbol":"XBTUSD","id":8798357300,"side":"Buy","size":22258}]}
09:22:28   {"table":"orderBookL2","action":"update","data":[{"symbol":"XBTUSD","id":8798357300,"side":"Buy","size":19258}]}
09:22:28   SubViewModel.XBTUSD_Main 异常：Could not create an instance of type BitMex.BitMexMsg.BitMexMsgBase. Type is an interface or abstract class and cannot be instantiated. Path 'table', line 1, position 9.
09:22:28   {"table":"orderBookL2","action":"insert","data":[{"symbol":"XBTUSD","id":8798350050,"side":"Sell","size":4581,"price":16499.5},{"symbol":"XBTUSD","id":8798363800,"side":"Buy","size":2100,"price":16362}]}
09:22:28   {"table":"orderBookL2","action":"delete","data":[{"symbol":"XBTUSD","id":8798141800,"side":"Sell"},{"symbol":"XBTUSD","id":8798146800,"side":"Sell"},{"symbol":"XBTUSD","id":8798151800,"side":"Sell"},{"symbol":"XBTUSD","id":8798330500,"side":"Sell"},{"symbol":"XBTUSD","id":8798335500,"side":"Sell"},{"symbol":"XBTUSD","id":8798345500,"side":"Sell"}]}
09:22:28   {"table":"orderBookL2","action":"update","data":[{"symbol":"XBTUSD","id":8798136800,"side":"Sell","size":74},{"symbol":"XBTUSD","id":8798156800,"side":"Sell","size":7326},{"symbol":"XBTUSD","id":8798157350,"side":"Sell","size":400},{"symbol":"XBTUSD","id":8798340500,"side":"Sell","size":7010},{"symbol":"XBTUSD","id":8798350250,"side":"Sell","size":7402},{"symbol":"XBTUSD","id":8798350500,"side":"Sell","size":17650}]}
09:22:28   SubViewModel.XBTUSD_Main 异常：Could not create an instance of type BitMex.BitMexMsg.BitMexMsgBase. Type is an interface or abstract class and cannot be instantiated. Path 'table', line 1, position 9.
09:22:28   {"table":"orderBookL2","action":"insert","data":[{"symbol":"XBTUSD","id":8798137350,"side":"Sell","size":200,"price":18626.5},{"symbol":"XBTUSD","id":8798142350,"side":"Sell","size":200,"price":18576.5},{"symbol":"XBTUSD","id":8798147350,"side":"Sell","size":200,"price":18526.5},{"symbol":"XBTUSD","id":8798152350,"side":"Sell","size":200,"price":18476.5},{"symbol":"XBTUSD","id":8798330250,"side":"Sell","size":200,"price":16697.5},{"symbol":"XBTUSD","id":8798335250,"side":"Sell","size":200,"price":16647.5},{"symbol":"XBTUSD","id":8798340250,"side":"Sell","size":200,"price":16597.5},{"symbol":"XBTUSD","id":8798345250,"side":"Sell","size":200,"price":16547.5}]}
09:22:28   {"table":"orderBookL2","action":"delete","data":[{"symbol":"XBTUSD","id":8798357300,"side":"Buy"}]}
09:22:28   {"table":"orderBookL2","action":"update","data":[{"symbol":"XBTUSD","id":8798357800,"side":"Buy","size":8503}]}
09:22:28   SubViewModel.XBTUSD_Main 异常：Could not create an instance of type BitMex.BitMexMsg.BitMexMsgBase. Type is an interface or abstract class and cannot be instantiated. Path 'table', line 1, position 9.
09:22:28   {"table":"orderBookL2","action":"insert","data":[{"symbol":"XBTUSD","id":8798357300,"side":"Buy","size":2500,"price":16427}]}
09:22:28   {"table":"orderBookL2","action":"insert","data":[{"symbol":"XBTUSD","id":8798356950,"side":"Buy","size":3000,"price":16430.5}]}
09:22:28   {"table":"orderBookL2","action":"update","data":[{"symbol":"XBTUSD","id":8798356500,"side":"Sell","size":6026}]}
09:22:28   SubViewModel.XBTUSD_Main 异常：Could not create an instance of type BitMex.BitMexMsg.BitMexMsgBase. Type is an interface or abstract class and cannot be instantiated. Path 'table', line 1, position 9.
09:22:28   {"table":"orderBookL2","action":"insert","data":[{"symbol":"XBTUSD","id":8798356550,"side":"Buy","size":6000,"price":16434.5}]}
09:22:28   {"table":"orderBookL2","action":"update","data":[{"symbol":"XBTUSD","id":8798356550,"side":"Buy","size":12000}]}
09:22:28   {"table":"orderBookL2","action":"update","data":[{"symbol":"XBTUSD","id":8798364050,"side":"Buy","size":200},{"symbol":"XBTUSD","id":8798380800,"side":"Buy","size":10601}]}
09:22:28   SubViewModel.XBTUSD_Main 异常：Could not create an instance of type BitMex.BitMexMsg.BitMexMsgBase. Type is an interface or abstract class and cannot be instantiated. Path 'table', line 1, position 9.
09:22:28   {"table":"orderBookL2","action":"delete","data":[{"symbol":"XBTUSD","id":8798353500,"side":"Sell"}]}
09:22:28   {"table":"orderBookL2","action":"update","data":[{"symbol":"XBTUSD","id":8798439550,"side":"Buy","size":1800}]}
09:22:28   {"table":"orderBookL2","action":"insert","data":[{"symbol":"XBTUSD","id":8798457150,"side":"Buy","size":200000,"price":15428.5}]}
09:22:28   SubViewModel.XBTUSD_Main 异常：Could not create an instance of type BitMex.BitMexMsg.BitMexMsgBase. Type is an interface or abstract class and cannot be instantiated. Path 'table', line 1, position 9.
09:22:28   {"table":"orderBookL2","action":"update","data":[{"symbol":"XBTUSD","id":8798356550,"side":"Buy","size":20162}]}
09:22:28   {"table":"orderBookL2","action":"insert","data":[{"symbol":"XBTUSD","id":8798359300,"side":"Buy","size":44868,"price":16407}]}
09:22:28   {"table":"orderBookL2","action":"update","data":[{"symbol":"XBTUSD","id":8798356550,"side":"Buy","size":20112}]}
09:22:28   {"table":"orderBookL2","action":"update","data":[{"symbol":"XBTUSD","id":8798356550,"side":"Buy","size":19612}]}
09:22:28   SubViewModel.XBTUSD_Main 异常：Could not create an instance of type BitMex.BitMexMsg.BitMexMsgBase. Type is an interface or abstract class and cannot be instantiated. Path 'table', line 1, position 9.
09:22:28   {"table":"orderBookL2","action":"delete","data":[{"symbol":"XBTUSD","id":8798352700,"side":"Sell"}]}
09:22:28   {"table":"orderBookL2","action":"insert","data":[{"symbol":"XBTUSD","id":8798352150,"side":"Sell","size":3776,"price":16478.5}]}
09:22:28   {"table":"orderBookL2","action":"delete","data":[{"symbol":"XBTUSD","id":8798356550,"side":"Buy"},{"symbol":"XBTUSD","id":8798356950,"side":"Buy"},{"symbol":"XBTUSD","id":8798357300,"side":"Buy"},{"symbol":"XBTUSD","id":8798357800,"side":"Buy"},{"symbol":"XBTUSD","id":8798358600,"side":"Buy"},{"symbol":"XBTUSD","id":8798358850,"side":"Buy"}]}
09:22:28   {"table":"orderBookL2","action":"insert","data":[{"symbol":"XBTUSD","id":8798359000,"side":"Sell","size":3720,"price":16410}]}
09:22:28   {"table":"orderBookL2","action":"insert","data":[{"symbol":"XBTUSD","id":8798355500,"side":"Sell","size":9245,"price":16445}]}
09:22:28   SubViewModel.XBTUSD_Main 异常：Could not create an instance of type BitMex.BitMexMsg.BitMexMsgBase. Type is an interface or abstract class and cannot be instantiated. Path 'table', line 1, position 9.
09:22:28   {"table":"orderBookL2","action":"update","data":[{"symbol":"XBTUSD","id":8798355700,"side":"Sell","size":100}]}
09:22:28   {"table":"orderBookL2","action":"update","data":[{"symbol":"XBTUSD","id":8798359300,"side":"Buy","size":44568}]}
09:22:28   {"table":"orderBookL2","action":"delete","data":[{"symbol":"XBTUSD","id":8798335800,"side":"Sell"},{"symbol":"XBTUSD","id":8798365650,"side":"Buy"}]}
09:22:29   {"table":"orderBookL2","action":"delete","data":[{"symbol":"XBTUSD","id":8798154800,"side":"Sell"},{"symbol":"XBTUSD","id":8798250850,"side":"Sell"},{"symbol":"XBTUSD","id":8798316500,"side":"Sell"},{"symbol":"XBTUSD","id":8798342500,"side":"Sell"},{"symbol":"XBTUSD","id":8798347500,"side":"Sell"},{"symbol":"XBTUSD","id":8798364050,"side":"Buy"},{"symbol":"XBTUSD","id":8798369050,"side":"Buy"},{"symbol":"XBTUSD","id":8798374050,"side":"Buy"},{"symbol":"XBTUSD","id":8798379050,"side":"Buy"},{"symbol":"XBTUSD","id":8798564550,"side":"Buy"},{"symbol":"XBTUSD","id":8798569550,"side":"Buy"}]}
09:22:29   SubViewModel.XBTUSD_Main 异常：Could not create an instance of type BitMex.BitMexMsg.BitMexMsgBase. Type is an interface or abstract class and cannot be instantiated. Path 'table', line 1, position 9.
09:22:29   {"table":"orderBookL2","action":"update","data":[{"symbol":"XBTUSD","id":8798142350,"side":"Sell","size":400},{"symbol":"XBTUSD","id":8798147350,"side":"Sell","size":400},{"symbol":"XBTUSD","id":8798149800,"side":"Sell","size":50},{"symbol":"XBTUSD","id":8798152350,"side":"Sell","size":400},{"symbol":"XBTUSD","id":8798157350,"side":"Sell","size":600},{"symbol":"XBTUSD","id":8798159800,"side":"Sell","size":900},{"symbol":"XBTUSD","id":8798171200,"side":"Sell","size":7754},{"symbol":"XBTUSD","id":8798175000,"side":"Sell","size":5810},{"symbol":"XBTUSD","id":8798191100,"side":"Sell","size":500},{"symbol":"XBTUSD","id":8798195000,"side":"Sell","size":5060},{"symbol":"XBTUSD","id":8798211100,"side":"Sell","size":60000},{"symbol":"XBTUSD","id":8798214950,"side":"Sell","size":28100},{"symbol":"XBTUSD","id":8798231000,"side":"Sell","size":50},{"symbol":"XBTUSD","id":8798234600,"side":"Sell","size":460},{"symbol":"XBTUSD","id":8798254600,"side":"Sell","size":2700},{"symbol":"XBTUSD","id":8798270800,"side":"Sell","size":260},{"symbol":"XBTUSD","id":8798274600,"side":"Sell","size":1802},{"symbol":"XBTUSD","id":8798290500,"side":"Sell","size":602},{"symbol":"XBTUSD","id":8798291700,"side":"Sell","size":802},{"symbol":"XBTUSD","id":8798312200,"side":"Sell","size":450},{"symbol":"XBTUSD","id":8798327500,"side":"Sell","size":1250},{"symbol":"XBTUSD","id":8798330250,"side":"Sell","size":400},{"symbol":"XBTUSD","id":8798332500,"side":"Sell","size":9345},{"symbol":"XBTUSD","id":8798335250,"side":"Sell","size":400},{"symbol":"XBTUSD","id":8798337500,"side":"Sell","size":2367},{"symbol":"XBTUSD","id":8798340250,"side":"Sell","size":400},{"symbol":"XBTUSD","id":8798345250,"side":"Sell","size":400},{"symbol":"XBTUSD","id":8798350250,"side":"Sell","size":7602},{"symbol":"XBTUSD","id":8798352500,"side":"Sell","size":448},{"symbol":"XBTUSD","id":8798374100,"side":"Buy","size":440},{"symbol":"XBTUSD","id":8798384050,"side":"Buy","size":603},{"symbol":"XBTUSD","id":8798384100,"side":"Buy","size":284},{"symbol":"XBTUSD","id":8798435200,"side":"Buy","size":250},{"symbol":"XBTUSD","id":8798438400,"side":"Buy","size":800},{"symbol":"XBTUSD","id":8798457900,"side":"Buy","size":240},{"symbol":"XBTUSD","id":8798460200,"side":"Buy","size":440},{"symbol":"XBTUSD","id":8798477800,"side":"Buy","size":1000},{"symbol":"XBTUSD","id":8798480000,"side":"Buy","size":464373},{"symbol":"XBTUSD","id":8798491950,"side":"Buy","size":11100},{"symbol":"XBTUSD","id":8798495000,"side":"Buy","size":5200},{"symbol":"XBTUSD","id":8798511700,"side":"Buy","size":100},{"symbol":"XBTUSD","id":8798515000,"side":"Buy","size":405200},{"symbol":"XBTUSD","id":8798531700,"side":"Buy","size":10000},{"symbol":"XBTUSD","id":8798535000,"side":"Buy","size":105400},{"symbol":"XBTUSD","id":8798540000,"side":"Buy","size":24200},{"symbol":"XBTUSD","id":8798545000,"side":"Buy","size":8200},{"symbol":"XBTUSD","id":8798550000,"side":"Buy","size":148200},{"symbol":"XBTUSD","id":8798551500,"side":"Buy","size":44},{"symbol":"XBTUSD","id":8798559550,"side":"Buy","size":4000}]}
09:22:29   {"table":"orderBookL2","action":"insert","data":[{"symbol":"XBTUSD","id":8798364100,"side":"Buy","size":200,"price":16359},{"symbol":"XBTUSD","id":8798369100,"side":"Buy","size":200,"price":16309},{"symbol":"XBTUSD","id":8798379100,"side":"Buy","size":200,"price":16209},{"symbol":"XBTUSD","id":8798440200,"side":"Buy","size":200,"price":15598}]}
09:22:29   {"table":"orderBookL2","action":"update","data":[{"symbol":"XBTUSD","id":8798348000,"side":"Sell","size":30800}]}
09:22:29   {"table":"orderBookL2","action":"update","data":[{"symbol":"XBTUSD","id":8798359300,"side":"Buy","size":34568}]}
09:22:29   SubViewModel.XBTUSD_Main 异常：Could not create an instance of type BitMex.BitMexMsg.BitMexMsgBase. Type is an interface or abstract class and cannot be instantiated. Path 'table', line 1, position 9.
09:22:29   {"table":"orderBookL2","action":"update","data":[{"symbol":"XBTUSD","id":8798361000,"side":"Buy","size":50},{"symbol":"XBTUSD","id":8798361200,"side":"Buy","size":1050},{"symbol":"XBTUSD","id":8798362150,"side":"Buy","size":50},{"symbol":"XBTUSD","id":8798363850,"side":"Buy","size":230}]}
09:22:29   {"table":"orderBookL2","action":"delete","data":[{"symbol":"XBTUSD","id":8798356050,"side":"Sell"}]}
09:22:29   {"table":"orderBookL2","action":"insert","data":[{"symbol":"XBTUSD","id":8798354400,"side":"Sell","size":524,"price":16456}]}
09:22:29   {"table":"orderBookL2","action":"delete","data":[{"symbol":"XBTUSD","id":8798344300,"side":"Sell"},{"symbol":"XBTUSD","id":8798353000,"side":"Sell"},{"symbol":"XBTUSD","id":8798364800,"side":"Buy"},{"symbol":"XBTUSD","id":8798369200,"side":"Buy"},{"symbol":"XBTUSD","id":8798373500,"side":"Buy"},{"symbol":"XBTUSD","id":8798382200,"side":"Buy"}]}
09:22:29   {"table":"orderBookL2","action":"update","data":[{"symbol":"XBTUSD","id":8798331200,"side":"Sell","size":2000},{"symbol":"XBTUSD","id":8798335600,"side":"Sell","size":400},{"symbol":"XBTUSD","id":8798340000,"side":"Sell","size":4319},{"symbol":"XBTUSD","id":8798343400,"side":"Sell","size":7311},{"symbol":"XBTUSD","id":8798348600,"side":"Sell","size":9245},{"symbol":"XBTUSD","id":8798350700,"side":"Sell","size":2760},{"symbol":"XBTUSD","id":8798353200,"side":"Sell","size":9372},{"symbol":"XBTUSD","id":8798377800,"side":"Buy","size":40728},{"symbol":"XBTUSD","id":8798390000,"side":"Buy","size":37343}]}
09:22:29   SubViewModel.XBTUSD_Main 异常：Could not create an instance of type BitMex.BitMexMsg.BitMexMsgBase. Type is an interface or abstract class and cannot be instantiated. Path 'table', line 1, position 9.
09:22:29   {"table":"orderBookL2","action":"insert","data":[{"symbol":"XBTUSD","id":8798345800,"side":"Sell","size":265,"price":16542},{"symbol":"XBTUSD","id":8798348300,"side":"Sell","size":219,"price":16517},{"symbol":"XBTUSD","id":8798355600,"side":"Sell","size":80,"price":16444},{"symbol":"XBTUSD","id":8798379300,"side":"Buy","size":127,"price":16207},{"symbol":"XBTUSD","id":8798400600,"side":"Buy","size":219,"price":15994},{"symbol":"XBTUSD","id":8798411400,"side":"Buy","size":265,"price":15886},{"symbol":"XBTUSD","id":8798422000,"side":"Buy","size":311,"price":15780}]}
09:22:29   {"table":"orderBookL2","action":"delete","data":[{"symbol":"XBTUSD","id":8798344800,"side":"Sell"},{"symbol":"XBTUSD","id":8798347300,"side":"Sell"},{"symbol":"XBTUSD","id":8798380400,"side":"Buy"},{"symbol":"XBTUSD","id":8798391800,"side":"Buy"},{"symbol":"XBTUSD","id":8798403700,"side":"Buy"},{"symbol":"XBTUSD","id":8798407200,"side":"Buy"},{"symbol":"XBTUSD","id":8798418700,"side":"Buy"}]}
09:22:29   {"table":"orderBookL2","action":"update","data":[{"symbol":"XBTUSD","id":8798329900,"side":"Sell","size":7365},{"symbol":"XBTUSD","id":8798342200,"side":"Sell","size":500},{"symbol":"XBTUSD","id":8798343800,"side":"Sell","size":402},{"symbol":"XBTUSD","id":8798348400,"side":"Sell","size":595613},{"symbol":"XBTUSD","id":8798349900,"side":"Sell","size":50},{"symbol":"XBTUSD","id":8798352500,"side":"Sell","size":260},{"symbol":"XBTUSD","id":8798370400,"side":"Buy","size":375},{"symbol":"XBTUSD","id":8798375000,"side":"Buy","size":13771}]}
09:22:29   SubViewModel.XBTUSD_Main 异常：Could not create an instance of type BitMex.BitMexMsg.BitMexMsgBase. Type is an interface or abstract class and cannot be instantiated. Path 'table', line 1, position 9.
09:22:29   {"table":"orderBookL2","action":"insert","data":[{"symbol":"XBTUSD","id":8798334600,"side":"Sell","size":394,"price":16654},{"symbol":"XBTUSD","id":8798339200,"side":"Sell","size":325,"price":16608},{"symbol":"XBTUSD","id":8798353100,"side":"Sell","size":120,"price":16469},{"symbol":"XBTUSD","id":8798365800,"side":"Buy","size":188,"price":16342},{"symbol":"XBTUSD","id":8798379700,"side":"Buy","size":394,"price":16203},{"symbol":"XBTUSD","id":8798384400,"side":"Buy","size":463,"price":16156}]}
09:22:29   {"table":"orderBookL2","action":"update","data":[{"symbol":"XBTUSD","id":8798331500,"side":"Sell","size":151250}]}
09:22:29   {"table":"orderBookL2","action":"insert","data":[{"symbol":"XBTUSD","id":8798331550,"side":"Sell","size":600,"price":16684.5}]}
09:22:29   SubViewModel.XBTUSD_Main 异常：Could not create an instance of type BitMex.BitMexMsg.BitMexMsgBase. Type is an interface or abstract class and cannot be instantiated. Path 'table', line 1, position 9.
09:22:29   {"table":"orderBookL2","action":"delete","data":[{"symbol":"XBTUSD","id":8798359300,"side":"Buy"},{"symbol":"XBTUSD","id":8798359600,"side":"Buy"},{"symbol":"XBTUSD","id":8798359650,"side":"Buy"},{"symbol":"XBTUSD","id":8798359850,"side":"Buy"},{"symbol":"XBTUSD","id":8798359900,"side":"Buy"}]}
09:22:29   {"table":"orderBookL2","action":"update","data":[{"symbol":"XBTUSD","id":8798359950,"side":"Buy","size":6751}]}
09:22:29   {"table":"orderBookL2","action":"insert","data":[{"symbol":"XBTUSD","id":8798358250,"side":"Sell","size":200,"price":16417.5}]}
09:22:29   SubViewModel.XBTUSD_Main 异常：Could not create an instance of type BitMex.BitMexMsg.BitMexMsgBase. Type is an interface or abstract class and cannot be instantiated. Path 'table', line 1, position 9.
09:22:29   {"table":"orderBookL2","action":"delete","data":[{"symbol":"XBTUSD","id":8798355500,"side":"Sell"},{"symbol":"XBTUSD","id":8798355600,"side":"Sell"},{"symbol":"XBTUSD","id":8798355650,"side":"Sell"},{"symbol":"XBTUSD","id":8798355700,"side":"Sell"},{"symbol":"XBTUSD","id":8798356000,"side":"Sell"},{"symbol":"XBTUSD","id":8798356500,"side":"Sell"},{"symbol":"XBTUSD","id":8798358250,"side":"Sell"},{"symbol":"XBTUSD","id":8798359000,"side":"Sell"}]}
09:22:29   {"table":"orderBookL2","action":"update","data":[{"symbol":"XBTUSD","id":8798355250,"side":"Sell","size":129663}]}
09:22:29   {"table":"orderBookL2","action":"delete","data":[{"symbol":"XBTUSD","id":8798359950,"side":"Buy"}]}
09:22:29   SubViewModel.XBTUSD_Main 异常：Could not create an instance of type BitMex.BitMexMsg.BitMexMsgBase. Type is an interface or abstract class and cannot be instantiated. Path 'table', line 1, position 9.
09:22:29   {"table":"orderBookL2","action":"update","data":[{"symbol":"XBTUSD","id":8798360000,"side":"Buy","size":28511}]}
09:22:29   {"table":"orderBookL2","action":"update","data":[{"symbol":"XBTUSD","id":8798355000,"side":"Sell","size":11250}]}
09:22:29   {"table":"orderBookL2","action":"update","data":[{"symbol":"XBTUSD","id":8798355000,"side":"Sell","size":11310}]}
09:22:29   {"table":"orderBookL2","action":"update","data":[{"symbol":"XBTUSD","id":8798450000,"side":"Buy","size":187175}]}
09:22:29   {"table":"orderBookL2","action":"update","data":[{"symbol":"XBTUSD","id":8798360000,"side":"Buy","size":28461}]}
09:22:29   {"table":"orderBookL2","action":"insert","data":[{"symbol":"XBTUSD","id":8798357250,"side":"Sell","size":100,"price":16427.5}]}
09:22:29   {"table":"orderBookL2","action":"insert","data":[{"symbol":"XBTUSD","id":8798375500,"side":"Buy","size":600,"price":16245}]}
09:22:29   {"table":"orderBookL2","action":"delete","data":[{"symbol":"XBTUSD","id":8798353750,"side":"Sell"}]}
09:22:29   {"table":"orderBookL2","action":"update","data":[{"symbol":"XBTUSD","id":8798350500,"side":"Sell","size":27700},{"symbol":"XBTUSD","id":8798353900,"side":"Sell","size":50}]}
09:22:29   {"table":"orderBookL2","action":"insert","data":[{"symbol":"XBTUSD","id":8798351800,"side":"Sell","size":10000,"price":16482}]}
09:22:29   SubViewModel.XBTUSD_Main 异常：Could not create an instance of type BitMex.BitMexMsg.BitMexMsgBase. Type is an interface or abstract class and cannot be instantiated. Path 'table', line 1, position 9.
09:22:29   {"table":"orderBookL2","action":"update","data":[{"symbol":"XBTUSD","id":8798360500,"side":"Buy","size":6981},{"symbol":"XBTUSD","id":8798360550,"side":"Buy","size":4600}]}
09:22:29   {"table":"orderBookL2","action":"insert","data":[{"symbol":"XBTUSD","id":8798359650,"side":"Buy","size":20000,"price":16403.5}]}
09:22:29   {"table":"orderBookL2","action":"update","data":[{"symbol":"XBTUSD","id":8798352250,"side":"Sell","size":50}]}
09:22:29   {"table":"orderBookL2","action":"delete","data":[{"symbol":"XBTUSD","id":8798363200,"side":"Buy"},{"symbol":"XBTUSD","id":8798364450,"side":"Buy"},{"symbol":"XBTUSD","id":8798367950,"side":"Buy"},{"symbol":"XBTUSD","id":8798368900,"side":"Buy"}]}
09:22:29   {"table":"orderBookL2","action":"update","data":[{"symbol":"XBTUSD","id":8798363850,"side":"Buy","size":150},{"symbol":"XBTUSD","id":8798365150,"side":"Buy","size":170190},{"symbol":"XBTUSD","id":8798367400,"side":"Buy","size":75},{"symbol":"XBTUSD","id":8798371050,"side":"Buy","size":601},{"symbol":"XBTUSD","id":8798371800,"side":"Buy","size":4050},{"symbol":"XBTUSD","id":8798373850,"side":"Buy","size":1064}]}
09:22:29   {"table":"orderBookL2","action":"insert","data":[{"symbol":"XBTUSD","id":8798355300,"side":"Sell","size":3681,"price":16447},{"symbol":"XBTUSD","id":8798366850,"side":"Buy","size":400,"price":16331.5},{"symbol":"XBTUSD","id":8798368650,"side":"Buy","size":800,"price":16313.5},{"symbol":"XBTUSD","id":8798370150,"side":"Buy","size":1600,"price":16298.5}]}
09:22:29   {"table":"orderBookL2","action":"delete","data":[{"symbol":"XBTUSD","id":8798354450,"side":"Sell"}]}
09:22:29   {"table":"orderBookL2","action":"insert","data":[{"symbol":"XBTUSD","id":8798352050,"side":"Sell","size":10000,"price":16479.5}]}
09:22:29   {"table":"orderBookL2","action":"update","data":[{"symbol":"XBTUSD","id":8798357250,"side":"Sell","size":50862}]}
09:22:29   {"table":"orderBookL2","action":"update","data":[{"symbol":"XBTUSD","id":8798550000,"side":"Buy","size":149200}]}
09:22:29   {"table":"orderBookL2","action":"update","data":[{"symbol":"XBTUSD","id":8798357250,"side":"Sell","size":50872}]}
09:22:29   SubViewModel.XBTUSD_Main 异常：Could not create an instance of type BitMex.BitMexMsg.BitMexMsgBase. Type is an interface or abstract class and cannot be instantiated. Path 'table', line 1, position 9.
09:22:29   {"table":"orderBookL2","action":"insert","data":[{"symbol":"XBTUSD","id":8798358300,"side":"Buy","size":3000,"price":16417}]}
09:22:29   {"table":"orderBookL2","action":"insert","data":[{"symbol":"XBTUSD","id":8798357300,"side":"Buy","size":10,"price":16427}]}
09:22:29   {"table":"orderBookL2","action":"delete","data":[{"symbol":"XBTUSD","id":8798362200,"side":"Buy"}]}
09:22:29   {"table":"orderBookL2","action":"insert","data":[{"symbol":"XBTUSD","id":8798361650,"side":"Buy","size":2000,"price":16383.5}]}
09:22:29   {"table":"orderBookL2","action":"update","data":[{"symbol":"XBTUSD","id":8798357300,"side":"Buy","size":3010}]}
09:22:29   {"table":"orderBookL2","action":"delete","data":[{"symbol":"XBTUSD","id":8798305150,"side":"Sell"}]}
09:22:29   {"table":"orderBookL2","action":"update","data":[{"symbol":"XBTUSD","id":8798308800,"side":"Sell","size":30040}]}
09:22:29   {"table":"orderBookL2","action":"update","data":[{"symbol":"XBTUSD","id":8798357300,"side":"Buy","size":5168}]}
09:22:29   {"table":"orderBookL2","action":"delete","data":[{"symbol":"XBTUSD","id":8798334700,"side":"Sell"},{"symbol":"XBTUSD","id":8798339700,"side":"Sell"},{"symbol":"XBTUSD","id":8798349600,"side":"Sell"},{"symbol":"XBTUSD","id":8798354550,"side":"Sell"},{"symbol":"XBTUSD","id":8798362600,"side":"Buy"},{"symbol":"XBTUSD","id":8798382100,"side":"Buy"}]}
09:22:29   {"table":"orderBookL2","action":"update","data":[{"symbol":"XBTUSD","id":8798329700,"side":"Sell","size":6250},{"symbol":"XBTUSD","id":8798344650,"side":"Sell","size":349000},{"symbol":"XBTUSD","id":8798344900,"side":"Sell","size":7550},{"symbol":"XBTUSD","id":8798349850,"side":"Sell","size":11330},{"symbol":"XBTUSD","id":8798354800,"side":"Sell","size":12500},{"symbol":"XBTUSD","id":8798367100,"side":"Buy","size":373176},{"symbol":"XBTUSD","id":8798367500,"side":"Buy","size":80},{"symbol":"XBTUSD","id":8798372000,"side":"Buy","size":8300},{"symbol":"XBTUSD","id":8798372400,"side":"Buy","size":75},{"symbol":"XBTUSD","id":8798376850,"side":"Buy","size":10602},{"symbol":"XBTUSD","id":8798377250,"side":"Buy","size":43},{"symbol":"XBTUSD","id":8798381700,"side":"Buy","size":13103},{"symbol":"XBTUSD","id":8798386950,"side":"Buy","size":603}]}
09:22:29   {"table":"orderBookL2","action":"insert","data":[{"symbol":"XBTUSD","id":8798329950,"side":"Sell","size":15000,"price":16700.5},{"symbol":"XBTUSD","id":8798334950,"side":"Sell","size":12500,"price":16650.5},{"symbol":"XBTUSD","id":8798339950,"side":"Sell","size":10000,"price":16600.5},{"symbol":"XBTUSD","id":8798362200,"side":"Buy","size":2500,"price":16378},{"symbol":"XBTUSD","id":8798386550,"side":"Buy","size":15000,"price":16134.5}]}
09:22:29   {"table":"orderBookL2","action":"update","data":[{"symbol":"XBTUSD","id":8798357250,"side":"Sell","size":60872}]}
09:22:29   {"table":"orderBookL2","action":"delete","data":[{"symbol":"XBTUSD","id":8798310500,"side":"Sell"}]}
09:22:29   {"table":"orderBookL2","action":"insert","data":[{"symbol":"XBTUSD","id":8798306800,"side":"Sell","size":50,"price":16932}]}
09:22:29   {"table":"orderBookL2","action":"update","data":[{"symbol":"XBTUSD","id":8798354900,"side":"Sell","size":2260}]}
09:22:29   {"table":"orderBookL2","action":"insert","data":[{"symbol":"XBTUSD","id":8798356550,"side":"Sell","size":2642,"price":16434.5}]}
09:22:29   {"table":"orderBookL2","action":"delete","data":[{"symbol":"XBTUSD","id":8798353550,"side":"Sell"}]}
09:22:29   SubViewModel.XBTUSD_Main 异常：Could not create an instance of type BitMex.BitMexMsg.BitMexMsgBase. Type is an interface or abstract class and cannot be instantiated. Path 'table', line 1, position 9.
09:22:29   {"table":"orderBookL2","action":"insert","data":[{"symbol":"XBTUSD","id":8798350750,"side":"Sell","size":10000,"price":16492.5}]}
09:22:29   {"table":"orderBookL2","action":"update","data":[{"symbol":"XBTUSD","id":8798353800,"side":"Sell","size":483}]}
09:22:29   {"table":"orderBookL2","action":"insert","data":[{"symbol":"XBTUSD","id":8798347950,"side":"Sell","size":410,"price":16520.5},{"symbol":"XBTUSD","id":8798441900,"side":"Buy","size":820,"price":15581}]}
09:22:29   {"table":"orderBookL2","action":"insert","data":[{"symbol":"XBTUSD","id":8798354050,"side":"Sell","size":100,"price":16459.5},{"symbol":"XBTUSD","id":8798354600,"side":"Sell","size":100,"price":16454}]}
09:22:29   {"table":"orderBookL2","action":"update","data":[{"symbol":"XBTUSD","id":8798298300,"side":"Sell","size":15351}]}
09:22:29   {"table":"orderBookL2","action":"update","data":[{"symbol":"XBTUSD","id":8798357250,"side":"Sell","size":72280}]}
09:22:29   {"table":"orderBookL2","action":"update","data":[{"symbol":"XBTUSD","id":8798357250,"side":"Sell","size":71280}]}
09:22:29   {"table":"orderBookL2","action":"delete","data":[{"symbol":"XBTUSD","id":8798344950,"side":"Sell"},{"symbol":"XBTUSD","id":8798350850,"side":"Sell"},{"symbol":"XBTUSD","id":8798352950,"side":"Sell"},{"symbol":"XBTUSD","id":8798353400,"side":"Sell"}]}
09:22:29   SubViewModel.XBTUSD_Main 异常：Could not create an instance of type BitMex.BitMexMsg.BitMexMsgBase. Type is an interface or abstract class and cannot be instantiated. Path 'table', line 1, position 9.
09:22:30   {"table":"orderBookL2","action":"update","data":[{"symbol":"XBTUSD","id":8798352150,"side":"Sell","size":3840},{"symbol":"XBTUSD","id":8798371250,"side":"Buy","size":646},{"symbol":"XBTUSD","id":8798374900,"side":"Buy","size":75}]}
09:22:30   {"table":"orderBookL2","action":"insert","data":[{"symbol":"XBTUSD","id":8798347150,"side":"Sell","size":14,"price":16528.5},{"symbol":"XBTUSD","id":8798350650,"side":"Sell","size":64,"price":16493.5},{"symbol":"XBTUSD","id":8798351150,"side":"Sell","size":64,"price":16488.5},{"symbol":"XBTUSD","id":8798364750,"side":"Buy","size":114,"price":16352.5},{"symbol":"XBTUSD","id":8798368050,"side":"Buy","size":50,"price":16319.5}]}
09:22:30   {"table":"orderBookL2","action":"delete","data":[{"symbol":"XBTUSD","id":8798345450,"side":"Sell"}]}
09:22:30   {"table":"orderBookL2","action":"update","data":[{"symbol":"XBTUSD","id":8798347450,"side":"Sell","size":13890}]}
09:22:30   {"table":"orderBookL2","action":"update","data":[{"symbol":"XBTUSD","id":8798357250,"side":"Sell","size":71290}]}
09:22:30   {"table":"orderBookL2","action":"update","data":[{"symbol":"XBTUSD","id":8798354800,"side":"Sell","size":2500}]}
09:22:30   {"table":"orderBookL2","action":"insert","data":[{"symbol":"XBTUSD","id":8798353400,"side":"Sell","size":10000,"price":16466}]}
09:22:30   {"table":"orderBookL2","action":"delete","data":[{"symbol":"XBTUSD","id":8798857700,"side":"Buy"}]}
09:22:30   {"table":"orderBookL2","action":"insert","data":[{"symbol":"XBTUSD","id":8798857300,"side":"Buy","size":1,"price":11427}]}
09:22:30   {"table":"orderBookL2","action":"delete","data":[{"symbol":"XBTUSD","id":8798337400,"side":"Sell"},{"symbol":"XBTUSD","id":8798340600,"side":"Sell"},{"symbol":"XBTUSD","id":8798351600,"side":"Sell"}]}
09:22:30   {"table":"orderBookL2","action":"update","data":[{"symbol":"XBTUSD","id":8798341600,"side":"Sell","size":616},{"symbol":"XBTUSD","id":8798343800,"side":"Sell","size":257},{"symbol":"XBTUSD","id":8798347800,"side":"Sell","size":1717},{"symbol":"XBTUSD","id":8798348400,"side":"Sell","size":595499},{"symbol":"XBTUSD","id":8798370200,"side":"Buy","size":15707}]}
09:22:30   SubViewModel.XBTUSD_Main 异常：Could not create an instance of type BitMex.BitMexMsg.BitMexMsgBase. Type is an interface or abstract class and cannot be instantiated. Path 'table', line 1, position 9.
09:22:30   {"table":"orderBookL2","action":"insert","data":[{"symbol":"XBTUSD","id":8798344700,"side":"Sell","size":176,"price":16553},{"symbol":"XBTUSD","id":8798351000,"side":"Sell","size":114,"price":16490},{"symbol":"XBTUSD","id":8798354200,"side":"Sell","size":84,"price":16458},{"symbol":"XBTUSD","id":8798374200,"side":"Buy","size":53,"price":16258}]}
09:22:30   {"table":"orderBookL2","action":"delete","data":[{"symbol":"XBTUSD","id":8798409700,"side":"Buy"}]}
09:22:30   {"table":"orderBookL2","action":"update","data":[{"symbol":"XBTUSD","id":8798405500,"side":"Buy","size":118}]}
09:22:30   {"table":"orderBookL2","action":"delete","data":[{"symbol":"XBTUSD","id":8798307500,"side":"Sell"}]}
09:22:30   {"table":"orderBookL2","action":"update","data":[{"symbol":"XBTUSD","id":8798307900,"side":"Sell","size":80}]}
09:22:30   SubViewModel.XBTUSD_Main 异常：Could not create an instance of type BitMex.BitMexMsg.BitMexMsgBase. Type is an interface or abstract class and cannot be instantiated. Path 'table', line 1, position 9.
09:22:30   {"table":"orderBookL2","action":"update","data":[{"symbol":"XBTUSD","id":8798357250,"side":"Sell","size":72403}]}
09:22:30   {"table":"orderBookL2","action":"update","data":[{"symbol":"XBTUSD","id":8798357300,"side":"Buy","size":2453}]}
09:22:30   {"table":"orderBookL2","action":"update","data":[{"symbol":"XBTUSD","id":8798357300,"side":"Buy","size":1453}]}
09:22:30   {"table":"orderBookL2","action":"update","data":[{"symbol":"XBTUSD","id":8798357250,"side":"Sell","size":72413}]}
09:22:30   {"table":"orderBookL2","action":"delete","data":[{"symbol":"XBTUSD","id":8798307700,"side":"Sell"}]}
09:22:30   {"table":"orderBookL2","action":"insert","data":[{"symbol":"XBTUSD","id":8798308250,"side":"Sell","size":40,"price":16917.5}]}
09:22:30   {"table":"orderBookL2","action":"update","data":[{"symbol":"XBTUSD","id":8798357250,"side":"Sell","size":72423}]}
09:22:30   SubViewModel.XBTUSD_Main 异常：Could not create an instance of type BitMex.BitMexMsg.BitMexMsgBase. Type is an interface or abstract class and cannot be instantiated. Path 'table', line 1, position 9.
09:22:30   {"table":"orderBookL2","action":"update","data":[{"symbol":"XBTUSD","id":8798358300,"side":"Buy","size":3500}]}
09:22:30   {"table":"orderBookL2","action":"insert","data":[{"symbol":"XBTUSD","id":8798355600,"side":"Sell","size":10000,"price":16444}]}
09:22:30   {"table":"orderBookL2","action":"update","data":[{"symbol":"XBTUSD","id":8798358300,"side":"Buy","size":4500}]}
09:22:30   {"table":"orderBookL2","action":"update","data":[{"symbol":"XBTUSD","id":8798352350,"side":"Sell","size":5226}]}
09:22:30   {"table":"orderBookL2","action":"update","data":[{"symbol":"XBTUSD","id":8798289000,"side":"Sell","size":50}]}
09:22:30   {"table":"orderBookL2","action":"insert","data":[{"symbol":"XBTUSD","id":8798302300,"side":"Sell","size":100000,"price":16977}]}
09:22:30   {"table":"orderBookL2","action":"update","data":[{"symbol":"XBTUSD","id":8798360600,"side":"Buy","size":7226}]}
09:22:30   {"table":"orderBookL2","action":"update","data":[{"symbol":"XBTUSD","id":8798357300,"side":"Buy","size":1257}]}
09:22:30   {"table":"orderBookL2","action":"update","data":[{"symbol":"XBTUSD","id":8798361200,"side":"Buy","size":4826}]}
09:22:30   SubViewModel.XBTUSD_Main 异常：Could not create an instance of type BitMex.BitMexMsg.BitMexMsgBase. Type is an interface or abstract class and cannot be instantiated. Path 'table', line 1, position 9.
09:22:30   {"table":"orderBookL2","action":"insert","data":[{"symbol":"XBTUSD","id":8798351950,"side":"Sell","size":12999,"price":16480.5}]}
09:22:30   {"table":"orderBookL2","action":"insert","data":[{"symbol":"XBTUSD","id":8798362000,"side":"Buy","size":3776,"price":16380}]}
09:22:30   {"table":"orderBookL2","action":"delete","data":[{"symbol":"XBTUSD","id":8798352300,"side":"Sell"}]}
09:22:30   SubViewModel.XBTUSD_Main 异常：Could not create an instance of type BitMex.BitMexMsg.BitMexMsgBase. Type is an interface or abstract class and cannot be instantiated. Path 'table', line 1, position 9.
09:22:30   {"table":"orderBookL2","action":"update","data":[{"symbol":"XBTUSD","id":8798352800,"side":"Sell","size":2821},{"symbol":"XBTUSD","id":8798367100,"side":"Buy","size":371000}]}
09:22:30   {"table":"orderBookL2","action":"insert","data":[{"symbol":"XBTUSD","id":8798370700,"side":"Buy","size":10701,"price":16293}]}
09:22:30   {"table":"orderBookL2","action":"update","data":[{"symbol":"XBTUSD","id":8798460000,"side":"Buy","size":166690}]}
09:22:30   {"table":"orderBookL2","action":"delete","data":[{"symbol":"XBTUSD","id":8798308850,"side":"Sell"}]}
09:22:30   SubViewModel.XBTUSD_Main 异常：Could not create an instance of type BitMex.BitMexMsg.BitMexMsgBase. Type is an interface or abstract class and cannot be instantiated. Path 'table', line 1, position 9.
09:22:30   {"table":"orderBookL2","action":"insert","data":[{"symbol":"XBTUSD","id":8798306900,"side":"Sell","size":40,"price":16931}]}
09:22:30   {"table":"orderBookL2","action":"update","data":[{"symbol":"XBTUSD","id":8798357250,"side":"Sell","size":79023}]}
09:22:30   {"table":"orderBookL2","action":"delete","data":[{"symbol":"XBTUSD","id":8798357300,"side":"Buy"},{"symbol":"XBTUSD","id":8798358300,"side":"Buy"},{"symbol":"XBTUSD","id":8798359650,"side":"Buy"},{"symbol":"XBTUSD","id":8798360000,"side":"Buy"},{"symbol":"XBTUSD","id":8798360100,"side":"Buy"},{"symbol":"XBTUSD","id":8798360200,"side":"Buy"},{"symbol":"XBTUSD","id":8798360500,"side":"Buy"},{"symbol":"XBTUSD","id":8798360550,"side":"Buy"},{"symbol":"XBTUSD","id":8798360600,"side":"Buy"},{"symbol":"XBTUSD","id":8798360650,"side":"Buy"},{"symbol":"XBTUSD","id":8798360700,"side":"Buy"},{"symbol":"XBTUSD","id":8798360750,"side":"Buy"}]}
09:22:30   {"table":"orderBookL2","action":"update","data":[{"symbol":"XBTUSD","id":8798360800,"side":"Buy","size":11120}]}
09:22:30   SubViewModel.XBTUSD_Main 异常：Could not create an instance of type BitMex.BitMexMsg.BitMexMsgBase. Type is an interface or abstract class and cannot be instantiated. Path 'table', line 1, position 9.
09:22:30   {"table":"orderBookL2","action":"insert","data":[{"symbol":"XBTUSD","id":8798357800,"side":"Sell","size":9245,"price":16422}]}
09:22:30   {"table":"orderBookL2","action":"delete","data":[{"symbol":"XBTUSD","id":8798348700,"side":"Sell"},{"symbol":"XBTUSD","id":8798351250,"side":"Sell"},{"symbol":"XBTUSD","id":8798352850,"side":"Sell"},{"symbol":"XBTUSD","id":8798364900,"side":"Buy"}]}
09:22:30   {"table":"orderBookL2","action":"update","data":[{"symbol":"XBTUSD","id":8798350250,"side":"Sell","size":2400},{"symbol":"XBTUSD","id":8798353200,"side":"Sell","size":13953},{"symbol":"XBTUSD","id":8798354050,"side":"Sell","size":4681},{"symbol":"XBTUSD","id":8798363400,"side":"Buy","size":200}]}
09:22:30   SubViewModel.XBTUSD_Main 异常：Could not create an instance of type BitMex.BitMexMsg.BitMexMsgBase. Type is an interface or abstract class and cannot be instantiated. Path 'table', line 1, position 9.
09:22:30   {"table":"orderBookL2","action":"insert","data":[{"symbol":"XBTUSD","id":8798350950,"side":"Sell","size":4581,"price":16490.5},{"symbol":"XBTUSD","id":8798352300,"side":"Sell","size":4581,"price":16477},{"symbol":"XBTUSD","id":8798359950,"side":"Buy","size":2100,"price":16400.5},{"symbol":"XBTUSD","id":8798362800,"side":"Buy","size":2100,"price":16372}]}
09:22:30   {"table":"orderBookL2","action":"insert","data":[{"symbol":"XBTUSD","id":8798357200,"side":"Sell","size":10000,"price":16428}]}
09:22:30   {"table":"orderBookL2","action":"insert","data":[{"symbol":"XBTUSD","id":8798358300,"side":"Buy","size":250,"price":16417}]}
09:22:30   {"table":"orderBookL2","action":"delete","data":[{"symbol":"XBTUSD","id":8798346600,"side":"Sell"}]}
09:22:30   SubViewModel.XBTUSD_Main 异常：Could not create an instance of type BitMex.BitMexMsg.BitMexMsgBase. Type is an interface or abstract class and cannot be instantiated. Path 'table', line 1, position 9.
09:22:30   {"table":"orderBookL2","action":"update","data":[{"symbol":"XBTUSD","id":8798339400,"side":"Sell","size":11684},{"symbol":"XBTUSD","id":8798342800,"side":"Sell","size":347454},{"symbol":"XBTUSD","id":8798348300,"side":"Sell","size":539},{"symbol":"XBTUSD","id":8798349400,"side":"Sell","size":266},{"symbol":"XBTUSD","id":8798351000,"side":"Sell","size":366},{"symbol":"XBTUSD","id":8798352200,"side":"Sell","size":6824},{"symbol":"XBTUSD","id":8798353800,"side":"Sell","size":668}]}
09:22:30   {"table":"orderBookL2","action":"insert","data":[{"symbol":"XBTUSD","id":8798356600,"side":"Sell","size":118,"price":16434}]}
09:22:30   {"table":"orderBookL2","action":"update","data":[{"symbol":"XBTUSD","id":8798352350,"side":"Sell","size":1450}]}
09:22:30   {"table":"orderBookL2","action":"insert","data":[{"symbol":"XBTUSD","id":8798351350,"side":"Sell","size":3776,"price":16486.5}]}
09:22:30   {"table":"orderBookL2","action":"delete","data":[{"symbol":"XBTUSD","id":8798386600,"side":"Buy"}]}
09:22:30   {"table":"orderBookL2","action":"insert","data":[{"symbol":"XBTUSD","id":8798381600,"side":"Buy","size":50000,"price":16184}]}
09:22:30   {"table":"orderBookL2","action":"insert","data":[{"symbol":"XBTUSD","id":8798356800,"side":"Sell","size":3000,"price":16432}]}
09:22:30   SubViewModel.XBTUSD_Main 异常：Could not create an instance of type BitMex.BitMexMsg.BitMexMsgBase. Type is an interface or abstract class and cannot be instantiated. Path 'table', line 1, position 9.
09:22:30   {"table":"orderBookL2","action":"update","data":[{"symbol":"XBTUSD","id":8798356550,"side":"Sell","size":4642}]}
09:22:30   {"table":"orderBookL2","action":"insert","data":[{"symbol":"XBTUSD","id":8798356650,"side":"Sell","size":3000,"price":16433.5}]}
09:22:30   {"table":"orderBookL2","action":"update","data":[{"symbol":"XBTUSD","id":8798358300,"side":"Buy","size":154}]}
09:22:30   {"table":"orderBookL2","action":"insert","data":[{"symbol":"XBTUSD","id":8798356500,"side":"Sell","size":10,"price":16435}]}
09:22:30   SubViewModel.XBTUSD_Main 异常：Could not create an instance of type BitMex.BitMexMsg.BitMexMsgBase. Type is an interface or abstract class and cannot be instantiated. Path 'table', line 1, position 9.
09:22:30   {"table":"orderBookL2","action":"update","data":[{"symbol":"XBTUSD","id":8798356500,"side":"Sell","size":5710}]}
09:22:30   SubViewModel.XBTUSD_Main 异常：Could not create an instance of type BitMex.BitMexMsg.BitMexMsgBase. Type is an interface or abstract class and cannot be instantiated. Path 'table', line 1, position 9.
09:22:30   SubViewModel.XBTUSD_Main 异常：Could not create an instance of type BitMex.BitMexMsg.BitMexMsgBase. Type is an interface or abstract class and cannot be instantiated. Path 'table', line 1, position 9.
09:22:30   SubViewModel.XBTUSD_Main 异常：Could not create an instance of type BitMex.BitMexMsg.BitMexMsgBase. Type is an interface or abstract class and cannot be instantiated. Path 'table', line 1, position 9.
09:22:30   SubViewModel.XBTUSD_Main 异常：Could not create an instance of type BitMex.BitMexMsg.BitMexMsgBase. Type is an interface or abstract class and cannot be instantiated. Path 'table', line 1, position 9.
09:22:30   SubViewModel.XBTUSD_Main 异常：Could not create an instance of type BitMex.BitMexMsg.BitMexMsgBase. Type is an interface or abstract class and cannot be instantiated. Path 'table', line 1, position 9.
09:22:30   SubViewModel.XBTUSD_Main 异常：Could not create an instance of type BitMex.BitMexMsg.BitMexMsgBase. Type is an interface or abstract class and cannot be instantiated. Path 'table', line 1, position 9.
09:22:30   SubViewModel.XBTUSD_Main 异常：Could not create an instance of type BitMex.BitMexMsg.BitMexMsgBase. Type is an interface or abstract class and cannot be instantiated. Path 'table', line 1, position 9.
09:22:30   SubViewModel.XBTUSD_Main 异常：Could not create an instance of type BitMex.BitMexMsg.BitMexMsgBase. Type is an interface or abstract class and cannot be instantiated. Path 'table', line 1, position 9.
09:22:30   SubViewModel.XBTUSD_Main 异常：Could not create an instance of type BitMex.BitMexMsg.BitMexMsgBase. Type is an interface or abstract class and cannot be instantiated. Path 'table', line 1, position 9.
09:22:31   SubViewModel.XBTUSD_Main 异常：Could not create an instance of type BitMex.BitMexMsg.BitMexMsgBase. Type is an interface or abstract class and cannot be instantiated. Path 'table', line 1, position 9.
09:22:31   SubViewModel.XBTUSD_Main 异常：Could not create an instance of type BitMex.BitMexMsg.BitMexMsgBase. Type is an interface or abstract class and cannot be instantiated. Path 'table', line 1, position 9.
09:22:31   SubViewModel.XBTUSD_Main 异常：Could not create an instance of type BitMex.BitMexMsg.BitMexMsgBase. Type is an interface or abstract class and cannot be instantiated. Path 'table', line 1, position 9.
09:22:31   SubViewModel.XBTUSD_Main 异常：Could not create an instance of type BitMex.BitMexMsg.BitMexMsgBase. Type is an interface or abstract class and cannot be instantiated. Path 'table', line 1, position 9.
09:22:31   SubViewModel.XBTUSD_Main 异常：Could not create an instance of type BitMex.BitMexMsg.BitMexMsgBase. Type is an interface or abstract class and cannot be instantiated. Path 'table', line 1, position 9.
09:22:31   SubViewModel.XBTUSD_Main 异常：Could not create an instance of type BitMex.BitMexMsg.BitMexMsgBase. Type is an interface or abstract class and cannot be instantiated. Path 'table', line 1, position 9.
09:22:31   SubViewModel.XBTUSD_Main 异常：Could not create an instance of type BitMex.BitMexMsg.BitMexMsgBase. Type is an interface or abstract class and cannot be instantiated. Path 'table', line 1, position 9.
09:22:31   SubViewModel.XBTUSD_Main 异常：Could not create an instance of type BitMex.BitMexMsg.BitMexMsgBase. Type is an interface or abstract class and cannot be instantiated. Path 'table', line 1, position 9.
09:22:31   SubViewModel.XBTUSD_Main 异常：Could not create an instance of type BitMex.BitMexMsg.BitMexMsgBase. Type is an interface or abstract class and cannot be instantiated. Path 'table', line 1, position 9.
09:22:31   SubViewModel.XBTUSD_Main 异常：Could not create an instance of type BitMex.BitMexMsg.BitMexMsgBase. Type is an interface or abstract class and cannot be instantiated. Path 'table', line 1, position 9.
09:22:31   SubViewModel.XBTUSD_Main 异常：Could not create an instance of type BitMex.BitMexMsg.BitMexMsgBase. Type is an interface or abstract class and cannot be instantiated. Path 'table', line 1, position 9.
09:22:31   SubViewModel.XBTUSD_Main 异常：Could not create an instance of type BitMex.BitMexMsg.BitMexMsgBase. Type is an interface or abstract class and cannot be instantiated. Path 'table', line 1, position 9.
09:22:31   {"table":"orderBookL2","action":"update","data":[{"symbol":"XBTUSD","id":8798325000,"side":"Sell","size":11460}]}
09:22:31   {"table":"orderBookL2","action":"delete","data":[{"symbol":"XBTUSD","id":8798358300,"side":"Buy"},{"symbol":"XBTUSD","id":8798359950,"side":"Buy"}]}
09:22:31   {"table":"orderBookL2","action":"insert","data":[{"symbol":"XBTUSD","id":8798360400,"side":"Sell","size":12746,"price":16396}]}
09:22:31   {"table":"orderBookL2","action":"update","data":[{"symbol":"XBTUSD","id":8798360800,"side":"Buy","size":9120}]}
09:22:31   {"table":"orderBookL2","action":"update","data":[{"symbol":"XBTUSD","id":8798360800,"side":"Buy","size":9058}]}
09:22:31   {"table":"orderBookL2","action":"update","data":[{"symbol":"XBTUSD","id":8798362500,"side":"Buy","size":2000}]}
09:22:31   SubViewModel.XBTUSD_Main 异常：Could not create an instance of type BitMex.BitMexMsg.BitMexMsgBase. Type is an interface or abstract class and cannot be instantiated. Path 'table', line 1, position 9.
09:22:32   {"table":"orderBookL2","action":"insert","data":[{"symbol":"XBTUSD","id":8798360550,"side":"Buy","size":3776,"price":16394.5}]}
09:22:32   {"table":"orderBookL2","action":"update","data":[{"symbol":"XBTUSD","id":8798374000,"side":"Buy","size":51100}]}
09:22:32   {"table":"orderBookL2","action":"update","data":[{"symbol":"XBTUSD","id":8798350000,"side":"Sell","size":154110}]}
09:22:32   {"table":"orderBookL2","action":"update","data":[{"symbol":"XBTUSD","id":8798356550,"side":"Sell","size":4714}]}
09:22:32   {"table":"orderBookL2","action":"update","data":[{"symbol":"XBTUSD","id":8798360550,"side":"Buy","size":2976}]}
09:22:32   {"table":"orderBookL2","action":"update","data":[{"symbol":"XBTUSD","id":8798600000,"side":"Buy","size":192545}]}
09:22:32   {"table":"orderBookL2","action":"update","data":[{"symbol":"XBTUSD","id":8798306700,"side":"Sell","size":50}]}
09:22:32   {"table":"orderBookL2","action":"insert","data":[{"symbol":"XBTUSD","id":8798308600,"side":"Sell","size":40,"price":16914}]}
09:22:32   {"table":"orderBookL2","action":"update","data":[{"symbol":"XBTUSD","id":8798357250,"side":"Sell","size":79024}]}
09:22:32   SubViewModel.XBTUSD_Main 异常：Could not create an instance of type BitMex.BitMexMsg.BitMexMsgBase. Type is an interface or abstract class and cannot be instantiated. Path 'table', line 1, position 9.
09:22:32   {"table":"orderBookL2","action":"update","data":[{"symbol":"XBTUSD","id":8798200000,"side":"Sell","size":348073}]}
09:22:32   {"table":"orderBookL2","action":"update","data":[{"symbol":"XBTUSD","id":8798356500,"side":"Sell","size":8710}]}
09:22:32   {"table":"orderBookL2","action":"update","data":[{"symbol":"XBTUSD","id":8798356500,"side":"Sell","size":8810}]}
09:22:32   {"table":"orderBookL2","action":"update","data":[{"symbol":"XBTUSD","id":8798352150,"side":"Sell","size":64}]}
09:22:32   {"table":"orderBookL2","action":"insert","data":[{"symbol":"XBTUSD","id":8798351750,"side":"Sell","size":3776,"price":16482.5}]}
09:22:32   {"table":"orderBookL2","action":"update","data":[{"symbol":"XBTUSD","id":8798356550,"side":"Sell","size":10714}]}
09:22:32   {"table":"orderBookL2","action":"insert","data":[{"symbol":"XBTUSD","id":8798356950,"side":"Sell","size":6000,"price":16430.5}]}
09:22:32   SubViewModel.XBTUSD_Main 异常：Could not create an instance of type BitMex.BitMexMsg.BitMexMsgBase. Type is an interface or abstract class and cannot be instantiated. Path 'table', line 1, position 9.
09:22:32   {"table":"orderBookL2","action":"update","data":[{"symbol":"XBTUSD","id":8798360400,"side":"Sell","size":12246}]}
09:22:32   {"table":"orderBookL2","action":"delete","data":[{"symbol":"XBTUSD","id":8798357800,"side":"Sell"},{"symbol":"XBTUSD","id":8798360400,"side":"Sell"}]}
09:22:32   {"table":"orderBookL2","action":"update","data":[{"symbol":"XBTUSD","id":8798357250,"side":"Sell","size":77059}]}
09:22:32   {"table":"orderBookL2","action":"delete","data":[{"symbol":"XBTUSD","id":8798380100,"side":"Buy"},{"symbol":"XBTUSD","id":8798384050,"side":"Buy"}]}
09:22:32   {"table":"orderBookL2","action":"update","data":[{"symbol":"XBTUSD","id":8798384000,"side":"Buy","size":900}]}
09:22:32   {"table":"orderBookL2","action":"insert","data":[{"symbol":"XBTUSD","id":8798359450,"side":"Buy","size":1000,"price":16405.5}]}
09:22:32   {"table":"orderBookL2","action":"insert","data":[{"symbol":"XBTUSD","id":8798351050,"side":"Sell","size":4664,"price":16489.5},{"symbol":"XBTUSD","id":8798352600,"side":"Sell","size":2332,"price":16474},{"symbol":"XBTUSD","id":8798354150,"side":"Sell","size":1166,"price":16458.5}]}
09:22:32   {"table":"orderBookL2","action":"update","data":[{"symbol":"XBTUSD","id":8798357250,"side":"Sell","size":77009}]}
09:22:32   {"table":"orderBookL2","action":"delete","data":[{"symbol":"XBTUSD","id":8798344600,"side":"Sell"}]}
09:22:32   {"table":"orderBookL2","action":"update","data":[{"symbol":"XBTUSD","id":8798260000,"side":"Sell","size":9460},{"symbol":"XBTUSD","id":8798349000,"side":"Sell","size":10767}]}
09:22:32   SubViewModel.XBTUSD_Main 异常：Could not create an instance of type BitMex.BitMexMsg.BitMexMsgBase. Type is an interface or abstract class and cannot be instantiated. Path 'table', line 1, position 9.
09:22:32   {"table":"orderBookL2","action":"insert","data":[{"symbol":"XBTUSD","id":8798281600,"side":"Sell","size":100000,"price":17184}]}
09:22:33   {"table":"orderBookL2","action":"delete","data":[{"symbol":"XBTUSD","id":8798354500,"side":"Sell"},{"symbol":"XBTUSD","id":8798370150,"side":"Buy"},{"symbol":"XBTUSD","id":8798372250,"side":"Buy"}]}
09:22:33   {"table":"orderBookL2","action":"insert","data":[{"symbol":"XBTUSD","id":8798359850,"side":"Buy","size":50,"price":16401.5}]}
09:22:33   {"table":"orderBookL2","action":"update","data":[{"symbol":"XBTUSD","id":8798340000,"side":"Sell","size":4219}]}
09:22:33   {"table":"orderBookL2","action":"delete","data":[{"symbol":"XBTUSD","id":8798367800,"side":"Buy"}]}
09:22:33   {"table":"orderBookL2","action":"insert","data":[{"symbol":"XBTUSD","id":8798375300,"side":"Buy","size":10000,"price":16247}]}
09:22:33   {"table":"orderBookL2","action":"delete","data":[{"symbol":"XBTUSD","id":8798359450,"side":"Buy"},{"symbol":"XBTUSD","id":8798359850,"side":"Buy"},{"symbol":"XBTUSD","id":8798360550,"side":"Buy"},{"symbol":"XBTUSD","id":8798360800,"side":"Buy"},{"symbol":"XBTUSD","id":8798361000,"side":"Buy"},{"symbol":"XBTUSD","id":8798361050,"side":"Buy"},{"symbol":"XBTUSD","id":8798361200,"side":"Buy"},{"symbol":"XBTUSD","id":8798361250,"side":"Buy"},{"symbol":"XBTUSD","id":8798361400,"side":"Buy"},{"symbol":"XBTUSD","id":8798361500,"side":"Buy"},{"symbol":"XBTUSD","id":8798361550,"side":"Buy"}]}
09:22:33   SubViewModel.XBTUSD_Main 异常：Could not create an instance of type BitMex.BitMexMsg.BitMexMsgBase. Type is an interface or abstract class and cannot be instantiated. Path 'table', line 1, position 9.
09:22:33   {"table":"orderBookL2","action":"update","data":[{"symbol":"XBTUSD","id":8798361600,"side":"Buy","size":284030}]}
09:22:33   {"table":"orderBookL2","action":"update","data":[{"symbol":"XBTUSD","id":8798345000,"side":"Sell","size":4242}]}
09:22:33   {"table":"orderBookL2","action":"insert","data":[{"symbol":"XBTUSD","id":8798355500,"side":"Sell","size":50,"price":16445}]}
09:22:33   {"table":"orderBookL2","action":"insert","data":[{"symbol":"XBTUSD","id":8798358600,"side":"Sell","size":50,"price":16414}]}
09:22:33   {"table":"orderBookL2","action":"update","data":[{"symbol":"XBTUSD","id":8798356550,"side":"Sell","size":13714}]}
09:22:33   {"table":"orderBookL2","action":"insert","data":[{"symbol":"XBTUSD","id":8798357900,"side":"Sell","size":3000,"price":16421},{"symbol":"XBTUSD","id":8798357950,"side":"Sell","size":3000,"price":16420.5}]}
09:22:33   {"table":"orderBookL2","action":"update","data":[{"symbol":"XBTUSD","id":8798307900,"side":"Sell","size":40}]}
09:22:33   {"table":"orderBookL2","action":"insert","data":[{"symbol":"XBTUSD","id":8798308750,"side":"Sell","size":40,"price":16912.5}]}
09:22:33   {"table":"orderBookL2","action":"delete","data":[{"symbol":"XBTUSD","id":8798358600,"side":"Sell"}]}
09:22:33   {"table":"orderBookL2","action":"update","data":[{"symbol":"XBTUSD","id":8798357950,"side":"Sell","size":2950}]}
09:22:33   SubViewModel.XBTUSD_Main 异常：Could not create an instance of type BitMex.BitMexMsg.BitMexMsgBase. Type is an interface or abstract class and cannot be instantiated. Path 'table', line 1, position 9.
09:22:33   {"table":"orderBookL2","action":"delete","data":[{"symbol":"XBTUSD","id":8798365950,"side":"Buy"},{"symbol":"XBTUSD","id":8798366850,"side":"Buy"},{"symbol":"XBTUSD","id":8798368650,"side":"Buy"}]}
09:22:33   {"table":"orderBookL2","action":"update","data":[{"symbol":"XBTUSD","id":8798355300,"side":"Sell","size":3930},{"symbol":"XBTUSD","id":8798363850,"side":"Buy","size":50},{"symbol":"XBTUSD","id":8798365150,"side":"Buy","size":169990},{"symbol":"XBTUSD","id":8798370000,"side":"Buy","size":21858},{"symbol":"XBTUSD","id":8798370550,"side":"Buy","size":2970},{"symbol":"XBTUSD","id":8798371500,"side":"Buy","size":1716},{"symbol":"XBTUSD","id":8798371800,"side":"Buy","size":3750},{"symbol":"XBTUSD","id":8798373850,"side":"Buy","size":1792}]}
09:22:33   {"table":"orderBookL2","action":"insert","data":[{"symbol":"XBTUSD","id":8798365450,"side":"Buy","size":56,"price":16345.5},{"symbol":"XBTUSD","id":8798366950,"side":"Buy","size":112,"price":16330.5},{"symbol":"XBTUSD","id":8798368900,"side":"Buy","size":224,"price":16311},{"symbol":"XBTUSD","id":8798374650,"side":"Buy","size":300,"price":16253.5},{"symbol":"XBTUSD","id":8798376350,"side":"Buy","size":464,"price":16236.5},{"symbol":"XBTUSD","id":8798377950,"side":"Buy","size":600,"price":16220.5}]}
09:22:33   {"table":"orderBookL2","action":"delete","data":[{"symbol":"XBTUSD","id":8798308050,"side":"Sell"},{"symbol":"XBTUSD","id":8798408050,"side":"Buy"}]}
09:22:33   {"table":"orderBookL2","action":"insert","data":[{"symbol":"XBTUSD","id":8798309750,"side":"Sell","size":20,"price":16902.5},{"symbol":"XBTUSD","id":8798409750,"side":"Buy","size":20,"price":15902.5}]}
09:22:33   {"table":"orderBookL2","action":"insert","data":[{"symbol":"XBTUSD","id":8798359050,"side":"Sell","size":20000,"price":16409.5}]}
09:22:33   {"table":"orderBookL2","action":"delete","data":[{"symbol":"XBTUSD","id":8798405600,"side":"Buy"}]}
09:22:33   {"table":"orderBookL2","action":"insert","data":[{"symbol":"XBTUSD","id":8798406850,"side":"Buy","size":40,"price":15931.5}]}
09:22:33   {"table":"orderBookL2","action":"delete","data":[{"symbol":"XBTUSD","id":8798354600,"side":"Sell"}]}
09:22:33   SubViewModel.XBTUSD_Main 异常：Could not create an instance of type BitMex.BitMexMsg.BitMexMsgBase. Type is an interface or abstract class and cannot be instantiated. Path 'table', line 1, position 9.
09:22:33   {"table":"orderBookL2","action":"update","data":[{"symbol":"XBTUSD","id":8798353900,"side":"Sell","size":150}]}
09:22:33   {"table":"orderBookL2","action":"delete","data":[{"symbol":"XBTUSD","id":8798352050,"side":"Sell"}]}
